Workbook

Sheet Data
B1: Market Name | C1: Spectral Sensor Market
AB2: =VLOOKUP(AB3,$B$60:$D$87,3,0) -> 0.08846537 | AC2: =VLOOKUP(AC3,$B$60:$D$87,3,0) -> 0.08046537 | AD2: =VLOOKUP(AD3,$B$60:$D$87,3,0) -> 0.086978328 | AE2: =VLOOKUP(AE3,$B$60:$D$87,3,0) -> 0.093104837 | AF2: =VLOOKUP(AF3,$B$60:$D$87,3,0) -> 0.063161446 | AG2: =VLOOKUP(AG3,$B$60:$D$87,3,0) -> 0.081207933 | AH2: =VLOOKUP(AH3,$B$60:$D$87,3,0) -> 0.069264643 | AI2: =VLOOKUP(AI3,$B$60:$D$87,3,0) -> 0.057072357 | ... AX2: =VLOOKUP(AX3,$B$60:$D$87,3,0) -> 0.067367342
C3: U.S. | D3: Canada | E3: U.K. | F3: Germany | G3: Italy | H3: France | I3: Spain | J3: Russia | K3: Rest of Europe | L3: China | M3: India | N3: Japan | O3: South Korea | P3: ASEAN | Q3: Australia | R3: Rest of Asia Pacific | S3: GCC | T3: South Africa | U3: Rest of Middle East & Africa | V3: Brazil | W3: Argentina | X3: Mexico | Y3: Rest of Latin America | AB3: U.S. | AC3: Canada | AD3: U.K. | AE3: Germany | AF3: Italy | AG3: France | AH3: Spain | AI3: Russia | AJ3: Rest of Europe | AK3: China | AL3: India | AM3: Japan | AN3: South Korea | AO3: ASEAN | AP3: Australia | AQ3: Rest of Asia Pacific | AR3: GCC | AS3: South Africa | AT3: Rest of Middle East & Africa | AU3: Brazil | AV3: Argentina | AW3: Mexico | AX3: Rest of Latin America | BA3: U.S. | BB3: Canada | BC3: U.K. | BD3: Germany | BE3: Italy | BF3: France | BG3: Spain | BH3: Russia | BI3: Rest of Europe | BJ3: China | BK3: India | BL3: Japan | BM3: South Korea | BN3: ASEAN | BO3: Australia | BP3: Rest of Asia Pacific | BQ3: GCC | BR3: South Africa | BS3: Rest of Middle East & Africa | BT3: Brazil | BU3: Argentina | BV3: Mexico | BW3: Rest of Latin America
B4: By Product Type | AA4: By Product Type | AZ4: By Product Type
B5: Hyperspectral Imaging Systems | C5: 0.115 | D5: 0.108 | E5: 0.119 | F5: 0.112 | G5: 0.107 | H5: 0.114 | I5: 0.107 | J5: 0.121 | K5: 0.112 | L5: 0.104 | M5: 0.101 | N5: 0.113 | O5: 0.113 | P5: 0.101 | Q5: 0.109 | R5: 0.101 | S5: 0.114 | T5: 0.103 | U5: 0.104 | V5: 0.099 | W5: 0.098 | X5: 0.101 | Y5: 0.101 | AA5: Hyperspectral Imaging Systems | AB5: 0.11779537 | AC5: 0.10960737 | AD5: 0.11616433 | AE5: 0.12259284 | AF5: 0.092709446 | AG5: 0.11050393 | AH5: 0.098682643 | AI5: 0.085936357 | AJ5: 0.10443919 | AK5: 0.14606772 | AL5: 0.13782572 | AM5: 0.10422917 | AN5: 0.12417096 | AO5: 0.13098572 | AP5: 0.10909528 | AQ5: 0.11691023 | AR5: 0.10776021 | AS5: 0.092424011 | AT5: 0.10103332 | AU5: 0.10319 | AV5: 0.081227036 | AW5: 0.089765331 | AX5: 0.096511342 | AZ5: Hyperspectral Imaging Systems | BA5: CMI_Trend_46 | BB5: CMI_Trend_20 | BC5: CMI_Trend_60 | BD5: CMI_Trend_46 | BE5: CMI_Trend_60 | BF5: CMI_Trend_56 | BG5: CMI_Trend_20 | BH5: CMI_Trend_20 | BI5: CMI_Trend_56 | BJ5: CMI_Trend_46 | BK5: CMI_Trend_52 | BL5: CMI_Trend_38 | BM5: CMI_Trend_20 | BN5: CMI_Trend_38 | BO5: CMI_Trend_56 | BP5: CMI_Trend_56 | BQ5: CMI_Trend_20 | BR5: CMI_Trend_60 | BS5: CMI_Trend_20 | BT5: CMI_Trend_52 | BU5: CMI_Trend_25 | BV5: CMI_Trend_20 | BW5: CMI_Trend_46
B6: Multispectral Imaging Systems | C6: 0.253 | D6: 0.297 | E6: 0.253 | F6: 0.248 | G6: 0.26 | H6: 0.26 | I6: 0.273 | J6: 0.278 | K6: 0.259 | L6: 0.27 | M6: 0.305 | N6: 0.241 | O6: 0.242 | P6: 0.289 | Q6: 0.304 | R6: 0.3 | S6: 0.266 | T6: 0.301 | U6: 0.31 | V6: 0.323 | W6: 0.325 | X6: 0.285 | Y6: 0.322 | AA6: Multispectral Imaging Systems | AB6: 0.09179537 | AC6: 0.08360737 | AD6: 0.090164328 | AE6: 0.096592837 | AF6: 0.066709446 | AG6: 0.084503933 | AH6: 0.072682643 | AI6: 0.059936357 | AJ6: 0.078439189 | AK6: 0.12006772 | AL6: 0.11182572 | AM6: 0.078229167 | AN6: 0.098170962 | AO6: 0.10498572 | AP6: 0.083095282 | AQ6: 0.09091023 | AR6: 0.081760209 | AS6: 0.066424011 | AT6: 0.075033322 | AU6: 0.077190004 | AV6: 0.055227036 | AW6: 0.063765331 | AX6: 0.070511342 | AZ6: Multispectral Imaging Systems | BA6: CMI_Trend_52 | BB6: CMI_Trend_52 | BC6: CMI_Trend_56 | BD6: CMI_Trend_25 | BE6: CMI_Trend_25 | BF6: CMI_Trend_20 | BG6: CMI_Trend_38 | BH6: CMI_Trend_38 | BI6: CMI_Trend_46 | BJ6: CMI_Trend_46 | BK6: CMI_Trend_60 | BL6: CMI_Trend_46 | BM6: CMI_Trend_25 | BN6: CMI_Trend_60 | BO6: CMI_Trend_25 | BP6: CMI_Trend_52 | BQ6: CMI_Trend_20 | BR6: CMI_Trend_46 | BS6: CMI_Trend_52 | BT6: CMI_Trend_25 | BU6: CMI_Trend_56 | BV6: CMI_Trend_46 | BW6: CMI_Trend_56
B7: Non-Imaging Spectral Systems | C7: 0.632 | D7: 0.595 | E7: 0.628 | F7: 0.64 | G7: 0.633 | H7: 0.626 | I7: 0.62 | J7: 0.601 | K7: 0.629 | L7: 0.626 | M7: 0.594 | N7: 0.646 | O7: 0.645 | P7: 0.61 | Q7: 0.587 | R7: 0.599 | S7: 0.62 | T7: 0.596 | U7: 0.586 | V7: 0.578 | W7: 0.577 | X7: 0.614 | Y7: 0.577 | AA7: Non-Imaging Spectral Systems | AB7: 0.08179537 | AC7: 0.07360737 | AD7: 0.080164328 | AE7: 0.086592837 | AF7: 0.056709446 | AG7: 0.074503933 | AH7: 0.062682643 | AI7: 0.049936357 | AJ7: 0.068439189 | AK7: 0.11006772 | AL7: 0.10182572 | AM7: 0.068229167 | AN7: 0.088170962 | AO7: 0.094985717 | AP7: 0.073095282 | AQ7: 0.08091023 | AR7: 0.071760209 | AS7: 0.056424011 | AT7: 0.065033322 | AU7: 0.067190004 | AV7: 0.045227036 | AW7: 0.053765331 | AX7: 0.060511342 | AZ7: Non-Imaging Spectral Systems | BA7: CMI_Trend_56 | BB7: CMI_Trend_52 | BC7: CMI_Trend_20 | BD7: CMI_Trend_46 | BE7: CMI_Trend_25 | BF7: CMI_Trend_56 | BG7: CMI_Trend_38 | BH7: CMI_Trend_60 | BI7: CMI_Trend_20 | BJ7: CMI_Trend_20 | BK7: CMI_Trend_60 | BL7: CMI_Trend_60 | BM7: CMI_Trend_25 | BN7: CMI_Trend_20 | BO7: CMI_Trend_46 | BP7: CMI_Trend_38 | BQ7: CMI_Trend_20 | BR7: CMI_Trend_56 | BS7: CMI_Trend_25 | BT7: CMI_Trend_46 | BU7: CMI_Trend_46 | BV7: CMI_Trend_20 | BW7: CMI_Trend_25
B9: By Offering | AA9: By Offering | AZ9: By Offering
B10: Hardware | C10: =1-SUM(C20,C26) -> 0.816 | D10: =1-SUM(D20,D26) -> 0.821 | E10: =1-SUM(E20,E26) -> 0.817 | F10: =1-SUM(F20,F26) -> 0.82 | G10: =1-SUM(G20,G26) -> 0.825 | H10: =1-SUM(H20,H26) -> 0.819 | I10: =1-SUM(I20,I26) -> 0.825 | J10: =1-SUM(J20,J26) -> 0.824 | ... Y10: =1-SUM(Y20,Y26) -> 0.833 | AA10: Hardware | AB10: =AB11*C11+SUMPRODUCT(AB15:AB19,C15:C19) -> 0.084040673 | AC10: =AC11*D11+SUMPRODUCT(AC15:AC19,D15:D19) -> 0.076267967 | AD10: =AD11*E11+SUMPRODUCT(AD15:AD19,E15:E19) -> 0.082534751 | AE10: =AE11*F11+SUMPRODUCT(AE15:AE19,F15:F19) -> 0.08883158 | AF10: =AF11*G11+SUMPRODUCT(AF15:AF19,G15:G19) -> 0.059105519 | AG10: =AG11*H11+SUMPRODUCT(AG15:AG19,H15:H19) -> 0.076910403 | AH10: =AH11*I11+SUMPRODUCT(AH15:AH19,I15:I19) -> 0.065241357 | AI10: =AI11*J11+SUMPRODUCT(AI15:AI19,J15:J19) -> 0.053110975 | ... AX10: =AX11*Y11+SUMPRODUCT(AX15:AX19,Y15:Y19) -> 0.063698785 | AZ10: Hardware | BA10: CMI_Trend_60 | BB10: CMI_Trend_56 | BC10: CMI_Trend_25 | BD10: CMI_Trend_20 | BE10: CMI_Trend_25 | BF10: CMI_Trend_20 | BG10: CMI_Trend_46 | BH10: CMI_Trend_60 | BI10: CMI_Trend_20 | BJ10: CMI_Trend_52 | BK10: CMI_Trend_56 | BL10: CMI_Trend_20 | BM10: CMI_Trend_52 | BN10: CMI_Trend_52 | BO10: CMI_Trend_60 | BP10: CMI_Trend_25 | BQ10: CMI_Trend_46 | BR10: CMI_Trend_20 | BS10: CMI_Trend_52 | BT10: CMI_Trend_52 | BU10: CMI_Trend_46 | BV10: CMI_Trend_52 | BW10: CMI_Trend_46
B11: Sensors & Detectors | C11: =1-SUM(C15:C19) -> 0.249 | D11: =1-SUM(D15:D19) -> 0.252 | E11: =1-SUM(E15:E19) -> 0.25 | F11: =1-SUM(F15:F19) -> 0.249 | G11: =1-SUM(G15:G19) -> 0.25 | H11: =1-SUM(H15:H19) -> 0.249 | I11: =1-SUM(I15:I19) -> 0.25 | J11: =1-SUM(J15:J19) -> 0.251 | ... Y11: =1-SUM(Y15:Y19) -> 0.253 | AA11: Sensors & Detectors | AB11: =SUMPRODUCT(AB12:AB14,C12:C14) -> 0.093276954 | AC11: =SUMPRODUCT(AC12:AC14,D12:D14) -> 0.085459736 | AD11: =SUMPRODUCT(AD12:AD14,E12:E14) -> 0.091944545 | AE11: =SUMPRODUCT(AE12:AE14,F12:F14) -> 0.09789182 | AF11: =SUMPRODUCT(AF12:AF14,G12:G14) -> 0.067978919 | AG11: =SUMPRODUCT(AG12:AG14,H12:H14) -> 0.086120179 | AH11: =SUMPRODUCT(AH12:AH14,I12:I14) -> 0.074246467 | AI11: =SUMPRODUCT(AI12:AI14,J12:J14) -> 0.062701422 | ... AX11: =SUMPRODUCT(AX12:AX14,Y12:Y14) -> 0.072641391 | AZ11: Sensors & Detectors | BA11: CMI_Trend_20 | BB11: CMI_Trend_56 | BC11: CMI_Trend_56 | BD11: CMI_Trend_52 | BE11: CMI_Trend_56 | BF11: CMI_Trend_52 | BG11: CMI_Trend_25 | BH11: CMI_Trend_60 | BI11: CMI_Trend_20 | BJ11: CMI_Trend_20 | BK11: CMI_Trend_46 | BL11: CMI_Trend_52 | BM11: CMI_Trend_56 | BN11: CMI_Trend_56 | BO11: CMI_Trend_52 | BP11: CMI_Trend_60 | BQ11: CMI_Trend_38 | BR11: CMI_Trend_25 | BS11: CMI_Trend_25 | BT11: CMI_Trend_38 | BU11: CMI_Trend_56 | BV11: CMI_Trend_25 | BW11: CMI_Trend_25
B12: Hyperspectral Sensors | C12: 0.222 | D12: 0.203 | E12: 0.226 | F12: 0.216 | G12: 0.204 | H12: 0.216 | I12: 0.204 | J12: 0.227 | K12: 0.215 | L12: 0.195 | M12: 0.186 | N12: 0.217 | O12: 0.217 | P12: 0.192 | Q12: 0.202 | R12: 0.191 | S12: 0.213 | T12: 0.196 | U12: 0.194 | V12: 0.185 | W12: 0.18 | X12: 0.192 | Y12: 0.185 | AA12: Hyperspectral Sensors | AB12: 0.11822295 | AC12: 0.11041274 | AD12: 0.11669455 | AE12: 0.12307182 | AF12: 0.093398919 | AG12: 0.11112018 | AH12: 0.099498467 | AI12: 0.087114422 | AJ12: 0.10497732 | AK12: 0.14673157 | AL12: 0.13887593 | AM12: 0.10456301 | AN12: 0.1246111 | AO12: 0.13189861 | AP12: 0.11000065 | AQ12: 0.11799753 | AR12: 0.10870148 | AS12: 0.093512654 | AT12: 0.10237512 | AU12: 0.10436918 | AV12: 0.082495745 | AW12: 0.090621437 | AX12: 0.097888391 | AZ12: Hyperspectral Sensors | BA12: CMI_Trend_52 | BB12: CMI_Trend_25 | BC12: CMI_Trend_38 | BD12: CMI_Trend_46 | BE12: CMI_Trend_25 | BF12: CMI_Trend_56 | BG12: CMI_Trend_20 | BH12: CMI_Trend_52 | BI12: CMI_Trend_38 | BJ12: CMI_Trend_60 | BK12: CMI_Trend_20 | BL12: CMI_Trend_20 | BM12: CMI_Trend_46 | BN12: CMI_Trend_38 | BO12: CMI_Trend_20 | BP12: CMI_Trend_38 | BQ12: CMI_Trend_38 | BR12: CMI_Trend_20 | BS12: CMI_Trend_46 | BT12: CMI_Trend_52 | BU12: CMI_Trend_52 | BV12: CMI_Trend_52 | BW12: CMI_Trend_25
B13: Multispectral Sensors | C13: 0.32 | D13: 0.378 | E13: 0.324 | F13: 0.319 | G13: 0.336 | H13: 0.334 | I13: 0.35 | J13: 0.349 | K13: 0.332 | L13: 0.35 | M13: 0.394 | N13: 0.311 | O13: 0.311 | P13: 0.372 | Q13: 0.386 | R13: 0.384 | S13: 0.341 | T13: 0.384 | U13: 0.395 | V13: 0.414 | W13: 0.414 | X13: 0.367 | Y13: 0.409 | AA13: Multispectral Sensors | AB13: 0.093222954 | AC13: 0.085412736 | AD13: 0.091694545 | AE13: 0.09807182 | AF13: 0.068398919 | AG13: 0.086120179 | AH13: 0.074498467 | AI13: 0.062114422 | AJ13: 0.079977315 | AK13: 0.12173157 | AL13: 0.11387593 | AM13: 0.079563006 | AN13: 0.099611101 | AO13: 0.10689861 | AP13: 0.085000652 | AQ13: 0.092997528 | AR13: 0.083701477 | AS13: 0.068512654 | AT13: 0.077375118 | AU13: 0.079369177 | AV13: 0.057495745 | AW13: 0.065621437 | AX13: 0.072888391 | AZ13: Multispectral Sensors | BA13: CMI_Trend_56 | BB13: CMI_Trend_56 | BC13: CMI_Trend_56 | BD13: CMI_Trend_46 | BE13: CMI_Trend_56 | BF13: CMI_Trend_46 | BG13: CMI_Trend_25 | BH13: CMI_Trend_52 | BI13: CMI_Trend_38 | BJ13: CMI_Trend_20 | BK13: CMI_Trend_60 | BL13: CMI_Trend_56 | BM13: CMI_Trend_52 | BN13: CMI_Trend_60 | BO13: CMI_Trend_56 | BP13: CMI_Trend_20 | BQ13: CMI_Trend_20 | BR13: CMI_Trend_20 | BS13: CMI_Trend_52 | BT13: CMI_Trend_25 | BU13: CMI_Trend_46 | BV13: CMI_Trend_46 | BW13: CMI_Trend_46
B14: Non-Imaging Spectral Sensor Modules / Detector Modules | C14: =1-SUM(C12:C13) -> 0.458 | D14: =1-SUM(D12:D13) -> 0.419 | E14: =1-SUM(E12:E13) -> 0.45 | F14: =1-SUM(F12:F13) -> 0.465 | G14: =1-SUM(G12:G13) -> 0.46 | H14: =1-SUM(H12:H13) -> 0.45 | I14: =1-SUM(I12:I13) -> 0.446 | J14: =1-SUM(J12:J13) -> 0.424 | ... Y14: =1-SUM(Y12:Y13) -> 0.406 | AA14: Non-Imaging Spectral Sensor Modules / Detector Modules | AB14: 0.081222954 | AC14: 0.073412736 | AD14: 0.079694545 | AE14: 0.08607182 | AF14: 0.056398919 | AG14: 0.074120179 | AH14: 0.062498467 | AI14: 0.050114422 | AJ14: 0.067977315 | AK14: 0.10973157 | AL14: 0.10187593 | AM14: 0.067563006 | AN14: 0.087611101 | AO14: 0.094898607 | AP14: 0.073000652 | AQ14: 0.080997528 | AR14: 0.071701477 | AS14: 0.056512654 | AT14: 0.065375118 | AU14: 0.067369177 | AV14: 0.045495745 | AW14: 0.053621437 | AX14: 0.060888391 | AZ14: Non-Imaging Spectral Sensor Modules / Detector Modules | BA14: CMI_Trend_20 | BB14: CMI_Trend_56 | BC14: CMI_Trend_56 | BD14: CMI_Trend_56 | BE14: CMI_Trend_46 | BF14: CMI_Trend_52 | BG14: CMI_Trend_60 | BH14: CMI_Trend_56 | BI14: CMI_Trend_56 | BJ14: CMI_Trend_56 | BK14: CMI_Trend_56 | BL14: CMI_Trend_56 | BM14: CMI_Trend_56 | BN14: CMI_Trend_60 | BO14: CMI_Trend_60 | BP14: CMI_Trend_25 | BQ14: CMI_Trend_20 | BR14: CMI_Trend_46 | BS14: CMI_Trend_56 | BT14: CMI_Trend_52 | BU14: CMI_Trend_46 | BV14: CMI_Trend_52 | BW14: CMI_Trend_52
B15: Spectral Separation & Measurement Components | C15: 0.221 | D15: 0.217 | E15: 0.22 | F15: 0.222 | G15: 0.222 | H15: 0.221 | I15: 0.22 | J15: 0.217 | K15: 0.221 | L15: 0.22 | M15: 0.217 | N15: 0.222 | O15: 0.223 | P15: 0.218 | Q15: 0.215 | R15: 0.218 | S15: 0.22 | T15: 0.217 | U15: 0.216 | V15: 0.214 | W15: 0.215 | X15: 0.219 | Y15: 0.215 | AA15: Spectral Separation & Measurement Components | AB15: 0.085222954 | AC15: 0.077412736 | AD15: 0.083694545 | AE15: 0.09007182 | AF15: 0.060398919 | AG15: 0.078120179 | AH15: 0.066498467 | AI15: 0.054114422 | AJ15: 0.071977315 | AK15: 0.11373157 | AL15: 0.10587593 | AM15: 0.071563006 | AN15: 0.091611101 | AO15: 0.098898607 | AP15: 0.077000652 | AQ15: 0.084997528 | AR15: 0.075701477 | AS15: 0.060512654 | AT15: 0.069375118 | AU15: 0.071369177 | AV15: 0.049495745 | AW15: 0.057621437 | AX15: 0.064888391 | AZ15: Spectral Separation & Measurement Components | BA15: CMI_Trend_52 | BB15: CMI_Trend_46 | BC15: CMI_Trend_20 | BD15: CMI_Trend_38 | BE15: CMI_Trend_46 | BF15: CMI_Trend_20 | BG15: CMI_Trend_25 | BH15: CMI_Trend_38 | BI15: CMI_Trend_20 | BJ15: CMI_Trend_38 | BK15: CMI_Trend_25 | BL15: CMI_Trend_25 | BM15: CMI_Trend_52 | BN15: CMI_Trend_25 | BO15: CMI_Trend_38 | BP15: CMI_Trend_25 | BQ15: CMI_Trend_38 | BR15: CMI_Trend_60 | BS15: CMI_Trend_46 | BT15: CMI_Trend_60 | BU15: CMI_Trend_25 | BV15: CMI_Trend_52 | BW15: CMI_Trend_38
B16: Optical Components (Filters, Lenses, Diffraction Gratings) | C16: 0.135 | D16: 0.136 | E16: 0.135 | F16: 0.134 | G16: 0.132 | H16: 0.134 | I16: 0.135 | J16: 0.136 | K16: 0.134 | L16: 0.134 | M16: 0.136 | N16: 0.134 | O16: 0.134 | P16: 0.135 | Q16: 0.136 | R16: 0.136 | S16: 0.135 | T16: 0.136 | U16: 0.137 | V16: 0.137 | W16: 0.137 | X16: 0.135 | Y16: 0.137 | AA16: Optical Components (Filters, Lenses, Diffraction Gratings) | AB16: 0.078534346 | AC16: 0.070724128 | AD16: 0.077005937 | AE16: 0.083383213 | AF16: 0.053710311 | AG16: 0.071431572 | AH16: 0.059809859 | AI16: 0.047425814 | AJ16: 0.065288707 | AK16: 0.10704296 | AL16: 0.09918732 | AM16: 0.064874398 | AN16: 0.084922493 | AO16: 0.092209999 | AP16: 0.070312044 | AQ16: 0.078308921 | AR16: 0.06901287 | AS16: 0.053824046 | AT16: 0.06268651 | AU16: 0.064680569 | AV16: 0.042807137 | AW16: 0.050932829 | AX16: 0.058199784 | AZ16: Optical Components (Filters, Lenses, Diffraction Gratings) | BA16: CMI_Trend_52 | BB16: CMI_Trend_38 | BC16: CMI_Trend_56 | BD16: CMI_Trend_52 | BE16: CMI_Trend_20 | BF16: CMI_Trend_52 | BG16: CMI_Trend_56 | BH16: CMI_Trend_46 | BI16: CMI_Trend_46 | BJ16: CMI_Trend_56 | BK16: CMI_Trend_56 | BL16: CMI_Trend_38 | BM16: CMI_Trend_52 | BN16: CMI_Trend_52 | BO16: CMI_Trend_25 | BP16: CMI_Trend_52 | BQ16: CMI_Trend_56 | BR16: CMI_Trend_25 | BS16: CMI_Trend_56 | BT16: CMI_Trend_20 | BU16: CMI_Trend_25 | BV16: CMI_Trend_56 | BW16: CMI_Trend_38
B17: Light Sources (LED, Laser) | C17: 0.086 | D17: 0.084 | E17: 0.086 | F17: 0.085 | G17: 0.086 | H17: 0.086 | I17: 0.085 | J17: 0.084 | K17: 0.085 | L17: 0.085 | M17: 0.083 | N17: 0.087 | O17: 0.087 | P17: 0.084 | Q17: 0.083 | R17: 0.084 | S17: 0.085 | T17: 0.083 | U17: 0.083 | V17: 0.083 | W17: 0.083 | X17: 0.084 | Y17: 0.083 | AA17: Light Sources (LED, Laser) | AB17: 0.07086678 | AC17: 0.063056561 | AD17: 0.069338371 | AE17: 0.075715646 | AF17: 0.046042745 | AG17: 0.063764005 | AH17: 0.052142292 | AI17: 0.039758247 | AJ17: 0.057621141 | AK17: 0.099375394 | AL17: 0.091519753 | AM17: 0.057206831 | AN17: 0.077254927 | AO17: 0.084542433 | AP17: 0.062644477 | AQ17: 0.070641354 | AR17: 0.061345303 | AS17: 0.046156479 | AT17: 0.055018944 | AU17: 0.057013002 | AV17: 0.03513957 | AW17: 0.043265263 | AX17: 0.050532217 | AZ17: Light Sources (LED, Laser) | BA17: CMI_Trend_52 | BB17: CMI_Trend_25 | BC17: CMI_Trend_60 | BD17: CMI_Trend_38 | BE17: CMI_Trend_46 | BF17: CMI_Trend_60 | BG17: CMI_Trend_46 | BH17: CMI_Trend_46 | BI17: CMI_Trend_38 | BJ17: CMI_Trend_20 | BK17: CMI_Trend_20 | BL17: CMI_Trend_56 | BM17: CMI_Trend_52 | BN17: CMI_Trend_56 | BO17: CMI_Trend_52 | BP17: CMI_Trend_56 | BQ17: CMI_Trend_38 | BR17: CMI_Trend_56 | BS17: CMI_Trend_25 | BT17: CMI_Trend_52 | BU17: CMI_Trend_20 | BV17: CMI_Trend_25 | BW17: CMI_Trend_56
B18: Processing Units and Embedded Hardware | C18: 0.155 | D18: 0.156 | E18: 0.154 | F18: 0.155 | G18: 0.155 | H18: 0.155 | I18: 0.155 | J18: 0.157 | K18: 0.155 | L18: 0.155 | M18: 0.156 | N18: 0.154 | O18: 0.154 | P18: 0.157 | Q18: 0.157 | R18: 0.156 | S18: 0.154 | T18: 0.157 | U18: 0.156 | V18: 0.157 | W18: 0.156 | X18: 0.156 | Y18: 0.157 | AA18: Processing Units and Embedded Hardware | AB18: 0.099052054 | AC18: 0.091241836 | AD18: 0.097523645 | AE18: 0.10390092 | AF18: 0.074228019 | AG18: 0.091949279 | AH18: 0.080327567 | AI18: 0.067943522 | AJ18: 0.085806415 | AK18: 0.12756067 | AL18: 0.11970503 | AM18: 0.085392106 | AN18: 0.1054402 | AO18: 0.11272771 | AP18: 0.090829752 | AQ18: 0.098826628 | AR18: 0.089530577 | AS18: 0.074341754 | AT18: 0.083204218 | AU18: 0.085198277 | AV18: 0.063324845 | AW18: 0.071450537 | AX18: 0.078717491 | AZ18: Processing Units and Embedded Hardware | BA18: CMI_Trend_25 | BB18: CMI_Trend_25 | BC18: CMI_Trend_20 | BD18: CMI_Trend_60 | BE18: CMI_Trend_52 | BF18: CMI_Trend_20 | BG18: CMI_Trend_38 | BH18: CMI_Trend_60 | BI18: CMI_Trend_60 | BJ18: CMI_Trend_25 | BK18: CMI_Trend_20 | BL18: CMI_Trend_25 | BM18: CMI_Trend_20 | BN18: CMI_Trend_56 | BO18: CMI_Trend_20 | BP18: CMI_Trend_25 | BQ18: CMI_Trend_60 | BR18: CMI_Trend_52 | BS18: CMI_Trend_38 | BT18: CMI_Trend_20 | BU18: CMI_Trend_60 | BV18: CMI_Trend_52 | BW18: CMI_Trend_25
B19: Supporting Hardware (Power Supply, Thermal, Enclosures, Connectivity) | C19: 0.154 | D19: 0.155 | E19: 0.155 | F19: 0.155 | G19: 0.155 | H19: 0.155 | I19: 0.155 | J19: 0.155 | K19: 0.155 | L19: 0.155 | M19: 0.156 | N19: 0.155 | O19: 0.155 | P19: 0.155 | Q19: 0.156 | R19: 0.155 | S19: 0.156 | T19: 0.155 | U19: 0.155 | V19: 0.155 | W19: 0.155 | X19: 0.155 | Y19: 0.155 | AA19: Supporting Hardware (Power Supply, Thermal, Enclosures, Connectivity) | AB19: 0.064485001 | AC19: 0.056674782 | AD19: 0.062956592 | AE19: 0.069333867 | AF19: 0.039660966 | AG19: 0.057382226 | AH19: 0.045760513 | AI19: 0.033376468 | AJ19: 0.051239362 | AK19: 0.092993615 | AL19: 0.085137974 | AM19: 0.050825052 | AN19: 0.070873148 | AO19: 0.078160654 | AP19: 0.056262699 | AQ19: 0.064259575 | AR19: 0.054963524 | AS19: 0.0397747 | AT19: 0.048637165 | AU19: 0.050631223 | AV19: 0.028757791 | AW19: 0.036883484 | AX19: 0.044150438 | AZ19: Supporting Hardware (Power Supply, Thermal, Enclosures, Connectivity) | BA19: CMI_Trend_46 | BB19: CMI_Trend_56 | BC19: CMI_Trend_52 | BD19: CMI_Trend_52 | BE19: CMI_Trend_52 | BF19: CMI_Trend_52 | BG19: CMI_Trend_38 | BH19: CMI_Trend_20 | BI19: CMI_Trend_25 | BJ19: CMI_Trend_56 | BK19: CMI_Trend_52 | BL19: CMI_Trend_25 | BM19: CMI_Trend_25 | BN19: CMI_Trend_25 | BO19: CMI_Trend_52 | BP19: CMI_Trend_46 | BQ19: CMI_Trend_20 | BR19: CMI_Trend_52 | BS19: CMI_Trend_20 | BT19: CMI_Trend_56 | BU19: CMI_Trend_38 | BV19: CMI_Trend_38 | BW19: CMI_Trend_46
B20: Software | C20: 0.115 | D20: 0.107 | E20: 0.116 | F20: 0.109 | G20: 0.102 | H20: 0.112 | I20: 0.101 | J20: 0.1 | K20: 0.11 | L20: 0.105 | M20: 0.098 | N20: 0.114 | O20: 0.113 | P20: 0.096 | Q20: 0.107 | R20: 0.094 | S20: 0.1 | T20: 0.095 | U20: 0.09 | V20: 0.094 | W20: 0.092 | X20: 0.097 | Y20: 0.09 | AA20: Software | AB20: =SUMPRODUCT(AB21:AB25,C21:C25) -> 0.11623427 | AC20: =SUMPRODUCT(AC21:AC25,D21:D25) -> 0.1081588 | AD20: =SUMPRODUCT(AD21:AD25,E21:E25) -> 0.11468243 | AE20: =SUMPRODUCT(AE21:AE25,F21:F25) -> 0.12082943 | AF20: =SUMPRODUCT(AF21:AF25,G21:G25) -> 0.091139322 | AG20: =SUMPRODUCT(AG21:AG25,H21:H25) -> 0.10881396 | AH20: =SUMPRODUCT(AH21:AH25,I21:I25) -> 0.097058365 | AI20: =SUMPRODUCT(AI21:AI25,J21:J25) -> 0.084758493 | ... AX20: =SUMPRODUCT(AX21:AX25,Y21:Y25) -> 0.09554112 | AZ20: Software | BA20: CMI_Trend_38 | BB20: CMI_Trend_46 | BC20: CMI_Trend_52 | BD20: CMI_Trend_46 | BE20: CMI_Trend_56 | BF20: CMI_Trend_25 | BG20: CMI_Trend_25 | BH20: CMI_Trend_52 | BI20: CMI_Trend_20 | BJ20: CMI_Trend_60 | BK20: CMI_Trend_25 | BL20: CMI_Trend_20 | BM20: CMI_Trend_56 | BN20: CMI_Trend_20 | BO20: CMI_Trend_60 | BP20: CMI_Trend_52 | BQ20: CMI_Trend_52 | BR20: CMI_Trend_46 | BS20: CMI_Trend_38 | BT20: CMI_Trend_20 | BU20: CMI_Trend_46 | BV20: CMI_Trend_46 | BW20: CMI_Trend_46
B21: Spectral Data Processing & Analysis Software | C21: =1-SUM(C22:C25) -> 0.261 | D21: =1-SUM(D22:D25) -> 0.262 | E21: =1-SUM(E22:E25) -> 0.259 | F21: =1-SUM(F22:F25) -> 0.257 | G21: =1-SUM(G22:G25) -> 0.255 | H21: =1-SUM(H22:H25) -> 0.259 | I21: =1-SUM(I22:I25) -> 0.257 | J21: =1-SUM(J22:J25) -> 0.26 | ... Y21: =1-SUM(Y22:Y25) -> 0.255 | AA21: Spectral Data Processing & Analysis Software | AB21: 0.12299017 | AC21: 0.11517995 | AD21: 0.12146176 | AE21: 0.12783904 | AF21: 0.098166136 | AG21: 0.1158874 | AH21: 0.10426568 | AI21: 0.091881638 | AJ21: 0.10974453 | AK21: 0.15149878 | AL21: 0.14364314 | AM21: 0.10933022 | AN21: 0.12937832 | AO21: 0.13666582 | AP21: 0.11476787 | AQ21: 0.12276474 | AR21: 0.11346869 | AS21: 0.09827987 | AT21: 0.10714233 | AU21: 0.10913639 | AV21: 0.087262961 | AW21: 0.095388654 | AX21: 0.10265561 | AZ21: Spectral Data Processing & Analysis Software | BA21: CMI_Trend_38 | BB21: CMI_Trend_60 | BC21: CMI_Trend_20 | BD21: CMI_Trend_38 | BE21: CMI_Trend_60 | BF21: CMI_Trend_60 | BG21: CMI_Trend_52 | BH21: CMI_Trend_25 | BI21: CMI_Trend_60 | BJ21: CMI_Trend_60 | BK21: CMI_Trend_60 | BL21: CMI_Trend_60 | BM21: CMI_Trend_20 | BN21: CMI_Trend_25 | BO21: CMI_Trend_52 | BP21: CMI_Trend_20 | BQ21: CMI_Trend_38 | BR21: CMI_Trend_52 | BS21: CMI_Trend_38 | BT21: CMI_Trend_38 | BU21: CMI_Trend_25 | BV21: CMI_Trend_38 | BW21: CMI_Trend_38
B22: AI/ML-Based Spectral Interpretation Software | C22: 0.217 | D22: 0.205 | E22: 0.215 | F22: 0.211 | G22: 0.206 | H22: 0.205 | I22: 0.199 | J22: 0.2 | K22: 0.209 | L22: 0.21 | M22: 0.195 | N22: 0.219 | O22: 0.212 | P22: 0.198 | Q22: 0.196 | R22: 0.202 | S22: 0.21 | T22: 0.2 | U22: 0.2 | V22: 0.202 | W22: 0.196 | X22: 0.206 | Y22: 0.2 | AA22: AI/ML-Based Spectral Interpretation Software | AB22: 0.13493805 | AC22: 0.12712783 | AD22: 0.13340964 | AE22: 0.13978691 | AF22: 0.11011401 | AG22: 0.12783527 | AH22: 0.11621356 | AI22: 0.10382951 | AJ22: 0.12169241 | AK22: 0.16344666 | AL22: 0.15559102 | AM22: 0.1212781 | AN22: 0.14132619 | AO22: 0.1486137 | AP22: 0.12671574 | AQ22: 0.13471262 | AR22: 0.12541657 | AS22: 0.11022775 | AT22: 0.11909021 | AU22: 0.12108427 | AV22: 0.099210836 | AW22: 0.10733653 | AX22: 0.11460348 | AZ22: AI/ML-Based Spectral Interpretation Software | BA22: CMI_Trend_52 | BB22: CMI_Trend_25 | BC22: CMI_Trend_60 | BD22: CMI_Trend_60 | BE22: CMI_Trend_46 | BF22: CMI_Trend_46 | BG22: CMI_Trend_20 | BH22: CMI_Trend_25 | BI22: CMI_Trend_56 | BJ22: CMI_Trend_46 | BK22: CMI_Trend_25 | BL22: CMI_Trend_38 | BM22: CMI_Trend_60 | BN22: CMI_Trend_20 | BO22: CMI_Trend_60 | BP22: CMI_Trend_38 | BQ22: CMI_Trend_20 | BR22: CMI_Trend_46 | BS22: CMI_Trend_20 | BT22: CMI_Trend_46 | BU22: CMI_Trend_60 | BV22: CMI_Trend_52 | BW22: CMI_Trend_38
B23: Imaging & Visualization Software | C23: 0.165 | D23: 0.168 | E23: 0.164 | F23: 0.174 | G23: 0.166 | H23: 0.17 | I23: 0.168 | J23: 0.17 | K23: 0.164 | L23: 0.171 | M23: 0.173 | N23: 0.158 | O23: 0.168 | P23: 0.167 | Q23: 0.168 | R23: 0.17 | S23: 0.17 | T23: 0.179 | U23: 0.167 | V23: 0.17 | W23: 0.174 | X23: 0.165 | Y23: 0.167 | AA23: Imaging & Visualization Software | AB23: 0.096725202 | AC23: 0.088914983 | AD23: 0.095196793 | AE23: 0.10157407 | AF23: 0.071901167 | AG23: 0.089622427 | AH23: 0.078000714 | AI23: 0.065616669 | AJ23: 0.083479563 | AK23: 0.12523382 | AL23: 0.11737818 | AM23: 0.083065253 | AN23: 0.10311335 | AO23: 0.11040085 | AP23: 0.0885029 | AQ23: 0.096499776 | AR23: 0.087203725 | AS23: 0.072014901 | AT23: 0.080877366 | AU23: 0.082871424 | AV23: 0.060997993 | AW23: 0.069123685 | AX23: 0.076390639 | AZ23: Imaging & Visualization Software | BA23: CMI_Trend_46 | BB23: CMI_Trend_38 | BC23: CMI_Trend_38 | BD23: CMI_Trend_56 | BE23: CMI_Trend_60 | BF23: CMI_Trend_46 | BG23: CMI_Trend_20 | BH23: CMI_Trend_20 | BI23: CMI_Trend_56 | BJ23: CMI_Trend_46 | BK23: CMI_Trend_38 | BL23: CMI_Trend_38 | BM23: CMI_Trend_46 | BN23: CMI_Trend_38 | BO23: CMI_Trend_56 | BP23: CMI_Trend_46 | BQ23: CMI_Trend_25 | BR23: CMI_Trend_52 | BS23: CMI_Trend_25 | BT23: CMI_Trend_38 | BU23: CMI_Trend_20 | BV23: CMI_Trend_20 | BW23: CMI_Trend_52
B24: Calibration & Correction Software | C24: 0.209 | D24: 0.206 | E24: 0.207 | F24: 0.202 | G24: 0.206 | H24: 0.205 | I24: 0.208 | J24: 0.2 | K24: 0.2 | L24: 0.2 | M24: 0.204 | N24: 0.202 | O24: 0.204 | P24: 0.208 | Q24: 0.206 | R24: 0.202 | S24: 0.2 | T24: 0.2 | U24: 0.2 | V24: 0.202 | W24: 0.195 | X24: 0.206 | Y24: 0.2 | AA24: Calibration & Correction Software | AB24: 0.10520393 | AC24: 0.097393711 | AD24: 0.10367552 | AE24: 0.1100528 | AF24: 0.080379894 | AG24: 0.098101155 | AH24: 0.086479442 | AI24: 0.074095397 | AJ24: 0.091958291 | AK24: 0.13371254 | AL24: 0.1258569 | AM24: 0.091543981 | AN24: 0.11159208 | AO24: 0.11887958 | AP24: 0.096981627 | AQ24: 0.1049785 | AR24: 0.095682453 | AS24: 0.080493629 | AT24: 0.089356094 | AU24: 0.091350152 | AV24: 0.06947672 | AW24: 0.077602412 | AX24: 0.084869367 | AZ24: Calibration & Correction Software | BA24: CMI_Trend_38 | BB24: CMI_Trend_20 | BC24: CMI_Trend_56 | BD24: CMI_Trend_52 | BE24: CMI_Trend_46 | BF24: CMI_Trend_52 | BG24: CMI_Trend_25 | BH24: CMI_Trend_38 | BI24: CMI_Trend_60 | BJ24: CMI_Trend_46 | BK24: CMI_Trend_52 | BL24: CMI_Trend_20 | BM24: CMI_Trend_52 | BN24: CMI_Trend_52 | BO24: CMI_Trend_25 | BP24: CMI_Trend_52 | BQ24: CMI_Trend_60 | BR24: CMI_Trend_60 | BS24: CMI_Trend_56 | BT24: CMI_Trend_25 | BU24: CMI_Trend_56 | BV24: CMI_Trend_56 | BW24: CMI_Trend_56
B25: Data Management & Integration Platforms | C25: 0.148 | D25: 0.159 | E25: 0.155 | F25: 0.156 | G25: 0.167 | H25: 0.161 | I25: 0.168 | J25: 0.17 | K25: 0.164 | L25: 0.162 | M25: 0.173 | N25: 0.158 | O25: 0.159 | P25: 0.167 | Q25: 0.168 | R25: 0.17 | S25: 0.16 | T25: 0.168 | U25: 0.178 | V25: 0.17 | W25: 0.174 | X25: 0.165 | Y25: 0.178 | AA25: Data Management & Integration Platforms | AB25: 0.11422295 | AC25: 0.10641274 | AD25: 0.11269455 | AE25: 0.11907182 | AF25: 0.089398919 | AG25: 0.10712018 | AH25: 0.095498467 | AI25: 0.083114422 | AJ25: 0.10097732 | AK25: 0.14273157 | AL25: 0.13487593 | AM25: 0.10056301 | AN25: 0.1206111 | AO25: 0.12789861 | AP25: 0.10600065 | AQ25: 0.11399753 | AR25: 0.10470148 | AS25: 0.089512654 | AT25: 0.098375118 | AU25: 0.10036918 | AV25: 0.078495745 | AW25: 0.086621437 | AX25: 0.093888391 | AZ25: Data Management & Integration Platforms | BA25: CMI_Trend_25 | BB25: CMI_Trend_25 | BC25: CMI_Trend_56 | BD25: CMI_Trend_52 | BE25: CMI_Trend_60 | BF25: CMI_Trend_46 | BG25: CMI_Trend_38 | BH25: CMI_Trend_52 | BI25: CMI_Trend_38 | BJ25: CMI_Trend_25 | BK25: CMI_Trend_46 | BL25: CMI_Trend_52 | BM25: CMI_Trend_25 | BN25: CMI_Trend_60 | BO25: CMI_Trend_52 | BP25: CMI_Trend_52 | BQ25: CMI_Trend_25 | BR25: CMI_Trend_38 | BS25: CMI_Trend_38 | BT25: CMI_Trend_25 | BU25: CMI_Trend_38 | BV25: CMI_Trend_46 | BW25: CMI_Trend_56
B26: Services | C26: 0.069 | D26: 0.072 | E26: 0.067 | F26: 0.071 | G26: 0.073 | H26: 0.069 | I26: 0.074 | J26: 0.076 | K26: 0.07 | L26: 0.069 | M26: 0.073 | N26: 0.068 | O26: 0.067 | P26: 0.074 | Q26: 0.071 | R26: 0.075 | S26: 0.077 | T26: 0.075 | U26: 0.077 | V26: 0.075 | W26: 0.076 | X26: 0.075 | Y26: 0.077 | AA26: Services | AB26: =SUMPRODUCT(AB27:AB31,C27:C31) -> 0.094510732 | AC26: =SUMPRODUCT(AC27:AC31,D27:D31) -> 0.08717191 | AD26: =SUMPRODUCT(AD27:AD31,E27:E31) -> 0.093198139 | AE26: =SUMPRODUCT(AE27:AE31,F27:F31) -> 0.099894845 | AF26: =SUMPRODUCT(AF27:AF31,G27:G31) -> 0.069906596 | AG26: =SUMPRODUCT(AG27:AG31,H27:H31) -> 0.087407958 | AH26: =SUMPRODUCT(AH27:AH31,I27:I31) -> 0.07618416 | AI26: =SUMPRODUCT(AI27:AI31,J27:J31) -> 0.063592947 | ... AX26: =SUMPRODUCT(AX27:AX31,Y27:Y31) -> 0.074124066 | AZ26: Services | BA26: CMI_Trend_38 | BB26: CMI_Trend_20 | BC26: CMI_Trend_25 | BD26: CMI_Trend_20 | BE26: CMI_Trend_38 | BF26: CMI_Trend_25 | BG26: CMI_Trend_20 | BH26: CMI_Trend_52 | BI26: CMI_Trend_20 | BJ26: CMI_Trend_38 | BK26: CMI_Trend_20 | BL26: CMI_Trend_20 | BM26: CMI_Trend_46 | BN26: CMI_Trend_56 | BO26: CMI_Trend_52 | BP26: CMI_Trend_46 | BQ26: CMI_Trend_52 | BR26: CMI_Trend_38 | BS26: CMI_Trend_25 | BT26: CMI_Trend_56 | BU26: CMI_Trend_52 | BV26: CMI_Trend_46 | BW26: CMI_Trend_46
B27: System Integration & Deployment Services | C27: =1-SUM(C28:C31) -> 0.29 | D27: =1-SUM(D28:D31) -> 0.292 | E27: =1-SUM(E28:E31) -> 0.284 | F27: =1-SUM(F28:F31) -> 0.296 | G27: =1-SUM(G28:G31) -> 0.288 | H27: =1-SUM(H28:H31) -> 0.29 | I27: =1-SUM(I28:I31) -> 0.297 | J27: =1-SUM(J28:J31) -> 0.303 | ... Y27: =1-SUM(Y28:Y31) -> 0.299 | AA27: System Integration & Deployment Services | AB27: 0.098950044 | AC27: 0.091139826 | AD27: 0.097421635 | AE27: 0.10379891 | AF27: 0.074126009 | AG27: 0.091847269 | AH27: 0.080225557 | AI27: 0.067841512 | AJ27: 0.085704405 | AK27: 0.12745866 | AL27: 0.11960302 | AM27: 0.085290096 | AN27: 0.10533819 | AO27: 0.1126257 | AP27: 0.090727742 | AQ27: 0.098724618 | AR27: 0.089428567 | AS27: 0.074239744 | AT27: 0.083102208 | AU27: 0.085096267 | AV27: 0.063222835 | AW27: 0.071348527 | AX27: 0.078615481 | AZ27: System Integration & Deployment Services | BA27: CMI_Trend_38 | BB27: CMI_Trend_25 | BC27: CMI_Trend_20 | BD27: CMI_Trend_56 | BE27: CMI_Trend_46 | BF27: CMI_Trend_52 | BG27: CMI_Trend_38 | BH27: CMI_Trend_56 | BI27: CMI_Trend_46 | BJ27: CMI_Trend_25 | BK27: CMI_Trend_56 | BL27: CMI_Trend_46 | BM27: CMI_Trend_60 | BN27: CMI_Trend_38 | BO27: CMI_Trend_20 | BP27: CMI_Trend_52 | BQ27: CMI_Trend_38 | BR27: CMI_Trend_56 | BS27: CMI_Trend_56 | BT27: CMI_Trend_52 | BU27: CMI_Trend_25 | BV27: CMI_Trend_46 | BW27: CMI_Trend_52
B28: Calibration & Maintenance Services | C28: 0.261 | D28: 0.264 | E28: 0.269 | F28: 0.267 | G28: 0.26 | H28: 0.261 | I28: 0.27 | J28: 0.263 | K28: 0.271 | L28: 0.261 | M28: 0.26 | N28: 0.265 | O28: 0.269 | P28: 0.27 | Q28: 0.253 | R28: 0.267 | S28: 0.26 | T28: 0.267 | U28: 0.26 | V28: 0.267 | W28: 0.263 | X28: 0.267 | Y28: 0.26 | AA28: Calibration & Maintenance Services | AB28: 0.083870166 | AC28: 0.076059948 | AD28: 0.082341757 | AE28: 0.088719032 | AF28: 0.059046131 | AG28: 0.076767391 | AH28: 0.065145678 | AI28: 0.052761633 | AJ28: 0.070624527 | AK28: 0.11237878 | AL28: 0.10452314 | AM28: 0.070210218 | AN28: 0.090258313 | AO28: 0.097545819 | AP28: 0.075647864 | AQ28: 0.08364474 | AR28: 0.074348689 | AS28: 0.059159865 | AT28: 0.06802233 | AU28: 0.070016388 | AV28: 0.048142957 | AW28: 0.056268649 | AX28: 0.063535603 | AZ28: Calibration & Maintenance Services | BA28: CMI_Trend_56 | BB28: CMI_Trend_52 | BC28: CMI_Trend_56 | BD28: CMI_Trend_60 | BE28: CMI_Trend_20 | BF28: CMI_Trend_60 | BG28: CMI_Trend_52 | BH28: CMI_Trend_56 | BI28: CMI_Trend_46 | BJ28: CMI_Trend_56 | BK28: CMI_Trend_25 | BL28: CMI_Trend_60 | BM28: CMI_Trend_52 | BN28: CMI_Trend_38 | BO28: CMI_Trend_46 | BP28: CMI_Trend_52 | BQ28: CMI_Trend_25 | BR28: CMI_Trend_46 | BS28: CMI_Trend_60 | BT28: CMI_Trend_52 | BU28: CMI_Trend_20 | BV28: CMI_Trend_60 | BW28: CMI_Trend_56
B29: Managed Data Analysis & Interpretation Services | C29: 0.174 | D29: 0.18 | E29: 0.179 | F29: 0.183 | G29: 0.178 | H29: 0.174 | I29: 0.176 | J29: 0.171 | K29: 0.172 | L29: 0.174 | M29: 0.178 | N29: 0.176 | O29: 0.179 | P29: 0.176 | Q29: 0.183 | R29: 0.173 | S29: 0.182 | T29: 0.173 | U29: 0.169 | V29: 0.173 | W29: 0.171 | X29: 0.173 | Y29: 0.169 | AA29: Managed Data Analysis & Interpretation Services | AB29: 0.12022295 | AC29: 0.11241274 | AD29: 0.11869455 | AE29: 0.12507182 | AF29: 0.095398919 | AG29: 0.11312018 | AH29: 0.10149847 | AI29: 0.089114422 | AJ29: 0.10697732 | AK29: 0.14873157 | AL29: 0.14087593 | AM29: 0.10656301 | AN29: 0.1266111 | AO29: 0.13389861 | AP29: 0.11200065 | AQ29: 0.11999753 | AR29: 0.11070148 | AS29: 0.095512654 | AT29: 0.10437512 | AU29: 0.10636918 | AV29: 0.084495745 | AW29: 0.092621437 | AX29: 0.099888391 | AZ29: Managed Data Analysis & Interpretation Services | BA29: CMI_Trend_38 | BB29: CMI_Trend_56 | BC29: CMI_Trend_56 | BD29: CMI_Trend_60 | BE29: CMI_Trend_46 | BF29: CMI_Trend_20 | BG29: CMI_Trend_56 | BH29: CMI_Trend_25 | BI29: CMI_Trend_20 | BJ29: CMI_Trend_60 | BK29: CMI_Trend_38 | BL29: CMI_Trend_52 | BM29: CMI_Trend_56 | BN29: CMI_Trend_25 | BO29: CMI_Trend_46 | BP29: CMI_Trend_25 | BQ29: CMI_Trend_60 | BR29: CMI_Trend_60 | BS29: CMI_Trend_60 | BT29: CMI_Trend_56 | BU29: CMI_Trend_25 | BV29: CMI_Trend_56 | BW29: CMI_Trend_20
B30: Training & Technical Support Services | C30: 0.13 | D30: 0.111 | E30: 0.119 | F30: 0.113 | G30: 0.123 | H30: 0.13 | I30: 0.108 | J30: 0.118 | K30: 0.114 | L30: 0.13 | M30: 0.123 | N30: 0.118 | O30: 0.119 | P30: 0.108 | Q30: 0.113 | R30: 0.12 | S30: 0.117 | T30: 0.12 | U30: 0.129 | V30: 0.12 | W30: 0.118 | X30: 0.12 | Y30: 0.129 | AA30: Training & Technical Support Services | AB30: 0.075222954 | AC30: 0.067412736 | AD30: 0.073694545 | AE30: 0.08007182 | AF30: 0.050398919 | AG30: 0.068120179 | AH30: 0.056498467 | AI30: 0.044114422 | AJ30: 0.061977315 | AK30: 0.10373157 | AL30: 0.095875927 | AM30: 0.061563006 | AN30: 0.081611101 | AO30: 0.088898607 | AP30: 0.067000652 | AQ30: 0.074997528 | AR30: 0.065701477 | AS30: 0.050512654 | AT30: 0.059375118 | AU30: 0.061369177 | AV30: 0.039495745 | AW30: 0.047621437 | AX30: 0.054888391 | AZ30: Training & Technical Support Services | BA30: CMI_Trend_46 | BB30: CMI_Trend_46 | BC30: CMI_Trend_46 | BD30: CMI_Trend_25 | BE30: CMI_Trend_25 | BF30: CMI_Trend_20 | BG30: CMI_Trend_20 | BH30: CMI_Trend_46 | BI30: CMI_Trend_25 | BJ30: CMI_Trend_60 | BK30: CMI_Trend_46 | BL30: CMI_Trend_20 | BM30: CMI_Trend_56 | BN30: CMI_Trend_38 | BO30: CMI_Trend_25 | BP30: CMI_Trend_25 | BQ30: CMI_Trend_60 | BR30: CMI_Trend_56 | BS30: CMI_Trend_52 | BT30: CMI_Trend_52 | BU30: CMI_Trend_46 | BV30: CMI_Trend_25 | BW30: CMI_Trend_20
B31: Consulting & Custom Solution Development | C31: 0.145 | D31: 0.153 | E31: 0.149 | F31: 0.141 | G31: 0.151 | H31: 0.145 | I31: 0.149 | J31: 0.145 | K31: 0.143 | L31: 0.145 | M31: 0.138 | N31: 0.147 | O31: 0.149 | P31: 0.149 | Q31: 0.155 | R31: 0.147 | S31: 0.143 | T31: 0.147 | U31: 0.143 | V31: 0.147 | W31: 0.145 | X31: 0.147 | Y31: 0.143 | AA31: Consulting & Custom Solution Development | AB31: 0.091222954 | AC31: 0.083412736 | AD31: 0.089694545 | AE31: 0.09607182 | AF31: 0.066398919 | AG31: 0.084120179 | AH31: 0.072498467 | AI31: 0.060114422 | AJ31: 0.077977315 | AK31: 0.11973157 | AL31: 0.11187593 | AM31: 0.077563006 | AN31: 0.097611101 | AO31: 0.10489861 | AP31: 0.083000652 | AQ31: 0.090997528 | AR31: 0.081701477 | AS31: 0.066512654 | AT31: 0.075375118 | AU31: 0.077369177 | AV31: 0.055495745 | AW31: 0.063621437 | AX31: 0.070888391 | AZ31: Consulting & Custom Solution Development | BA31: CMI_Trend_25 | BB31: CMI_Trend_46 | BC31: CMI_Trend_20 | BD31: CMI_Trend_20 | BE31: CMI_Trend_25 | BF31: CMI_Trend_38 | BG31: CMI_Trend_60 | BH31: CMI_Trend_60 | BI31: CMI_Trend_56 | BJ31: CMI_Trend_38 | BK31: CMI_Trend_38 | BL31: CMI_Trend_56 | BM31: CMI_Trend_38 | BN31: CMI_Trend_25 | BO31: CMI_Trend_38 | BP31: CMI_Trend_38 | BQ31: CMI_Trend_25 | BR31: CMI_Trend_46 | BS31: CMI_Trend_38 | BT31: CMI_Trend_46 | BU31: CMI_Trend_20 | BV31: CMI_Trend_56 | BW31: CMI_Trend_56
B33: By Technology | AA33: By Technology | AZ33: By Technology
B34: Imaging | C34: 0.368 | D34: 0.405 | E34: 0.372 | F34: 0.36 | G34: 0.367 | H34: 0.374 | I34: 0.38 | J34: 0.399 | K34: 0.371 | L34: 0.374 | M34: 0.406 | N34: 0.354 | O34: 0.355 | P34: 0.39 | Q34: 0.413 | R34: 0.401 | S34: 0.38 | T34: 0.404 | U34: 0.414 | V34: 0.422 | W34: 0.423 | X34: 0.386 | Y34: 0.423 | AA34: Imaging | AB34: 0.10047337 | AC34: 0.09177037 | AD34: 0.098910328 | AE34: 0.10526484 | AF34: 0.075188446 | AG34: 0.093101933 | AH34: 0.081044643 | AI34: 0.068491357 | AJ34: 0.087012189 | AK34: 0.12840572 | AL34: 0.11979772 | AM34: 0.086981167 | AN34: 0.10691396 | AO34: 0.11310172 | AP34: 0.091212282 | AQ34: 0.09892723 | AR34: 0.090304209 | AS34: 0.074466011 | AT34: 0.083011322 | AU34: 0.084966004 | AV34: 0.062968036 | AW34: 0.071917331 | AX34: 0.078330342 | AZ34: Imaging | BA34: CMI_Trend_52 | BB34: CMI_Trend_60 | BC34: CMI_Trend_25 | BD34: CMI_Trend_60 | BE34: CMI_Trend_25 | BF34: CMI_Trend_38 | BG34: CMI_Trend_60 | BH34: CMI_Trend_38 | BI34: CMI_Trend_60 | BJ34: CMI_Trend_46 | BK34: CMI_Trend_46 | BL34: CMI_Trend_52 | BM34: CMI_Trend_56 | BN34: CMI_Trend_56 | BO34: CMI_Trend_52 | BP34: CMI_Trend_56 | BQ34: CMI_Trend_56 | BR34: CMI_Trend_46 | BS34: CMI_Trend_46 | BT34: CMI_Trend_20 | BU34: CMI_Trend_60 | BV34: CMI_Trend_52 | BW34: CMI_Trend_25
B35: Non-Imaging | C35: =1-C34 -> 0.632 | D35: =1-D34 -> 0.595 | E35: =1-E34 -> 0.628 | F35: =1-F34 -> 0.64 | G35: =1-G34 -> 0.633 | H35: =1-H34 -> 0.626 | I35: =1-I34 -> 0.62 | J35: =1-J34 -> 0.601 | ... Y35: =1-Y34 -> 0.577 | AA35: Non-Imaging | AB35: 0.08147337 | AC35: 0.07277037 | AD35: 0.079910328 | AE35: 0.086264837 | AF35: 0.056188446 | AG35: 0.074101933 | AH35: 0.062044643 | AI35: 0.049491357 | AJ35: 0.068012189 | AK35: 0.10940572 | AL35: 0.10079772 | AM35: 0.067981167 | AN35: 0.087913962 | AO35: 0.094101717 | AP35: 0.072212282 | AQ35: 0.07992723 | AR35: 0.071304209 | AS35: 0.055466011 | AT35: 0.064011322 | AU35: 0.065966004 | AV35: 0.043968036 | AW35: 0.052917331 | AX35: 0.059330342 | AZ35: Non-Imaging | BA35: CMI_Trend_52 | BB35: CMI_Trend_52 | BC35: CMI_Trend_20 | BD35: CMI_Trend_56 | BE35: CMI_Trend_52 | BF35: CMI_Trend_52 | BG35: CMI_Trend_20 | BH35: CMI_Trend_20 | BI35: CMI_Trend_56 | BJ35: CMI_Trend_52 | BK35: CMI_Trend_20 | BL35: CMI_Trend_38 | BM35: CMI_Trend_52 | BN35: CMI_Trend_20 | BO35: CMI_Trend_25 | BP35: CMI_Trend_56 | BQ35: CMI_Trend_56 | BR35: CMI_Trend_52 | BS35: CMI_Trend_46 | BT35: CMI_Trend_38 | BU35: CMI_Trend_52 | BV35: CMI_Trend_52 | BW35: CMI_Trend_25
B37: By Spectral Range | AA37: By Spectral Range | AZ37: By Spectral Range
B38: Ultraviolet (UV) | C38: 0.066 | D38: 0.063 | E38: 0.069 | F38: 0.066 | G38: 0.061 | H38: 0.064 | I38: 0.063 | J38: 0.05 | K38: 0.069 | L38: 0.058 | M38: 0.055 | N38: 0.07 | O38: 0.064 | P38: 0.056 | Q38: 0.06 | R38: 0.054 | S38: 0.058 | T38: 0.059 | U38: 0.053 | V38: 0.053 | W38: 0.052 | X38: 0.056 | Y38: 0.054 | AA38: Ultraviolet (UV) | AB38: 0.069087412 | AC38: 0.060817443 | AD38: 0.06772307 | AE38: 0.073576968 | AF38: 0.043295801 | AG38: 0.061679966 | AH38: 0.049501741 | AI38: 0.03732034 | AJ38: 0.055655223 | AK38: 0.09659058 | AL38: 0.08846258 | AM38: 0.055299104 | AN38: 0.075114914 | AO38: 0.081412591 | AP38: 0.06036306 | AQ38: 0.06739777 | AR38: 0.058886053 | AS38: 0.043252148 | AT38: 0.051799006 | AU38: 0.053784616 | AV38: 0.031726553 | AW38: 0.04013889 | AX38: 0.047219553 | AZ38: Ultraviolet (UV) | BA38: CMI_Trend_56 | BB38: CMI_Trend_52 | BC38: CMI_Trend_38 | BD38: CMI_Trend_46 | BE38: CMI_Trend_20 | BF38: CMI_Trend_46 | BG38: CMI_Trend_20 | BH38: CMI_Trend_52 | BI38: CMI_Trend_46 | BJ38: CMI_Trend_52 | BK38: CMI_Trend_20 | BL38: CMI_Trend_38 | BM38: CMI_Trend_52 | BN38: CMI_Trend_25 | BO38: CMI_Trend_52 | BP38: CMI_Trend_20 | BQ38: CMI_Trend_46 | BR38: CMI_Trend_60 | BS38: CMI_Trend_52 | BT38: CMI_Trend_56 | BU38: CMI_Trend_38 | BV38: CMI_Trend_20 | BW38: CMI_Trend_52
B39: Visible (VIS) | C39: 0.172 | D39: 0.183 | E39: 0.174 | F39: 0.171 | G39: 0.178 | H39: 0.175 | I39: 0.18 | J39: 0.153 | K39: 0.178 | L39: 0.173 | M39: 0.179 | N39: 0.175 | O39: 0.168 | P39: 0.179 | Q39: 0.176 | R39: 0.178 | S39: 0.16 | T39: 0.18 | U39: 0.175 | V39: 0.185 | W39: 0.185 | X39: 0.177 | Y39: 0.182 | AA39: Visible (VIS) | AB39: 0.073662584 | AC39: 0.065392615 | AD39: 0.072298242 | AE39: 0.07815214 | AF39: 0.047870974 | AG39: 0.066255138 | AH39: 0.054076913 | AI39: 0.041895512 | AJ39: 0.060230395 | AK39: 0.10116575 | AL39: 0.093037752 | AM39: 0.059874277 | AN39: 0.079690086 | AO39: 0.085987763 | AP39: 0.064938232 | AQ39: 0.071972942 | AR39: 0.063461226 | AS39: 0.047827321 | AT39: 0.056374178 | AU39: 0.058359789 | AV39: 0.036301725 | AW39: 0.044714063 | AX39: 0.051794725 | AZ39: Visible (VIS) | BA39: CMI_Trend_56 | BB39: CMI_Trend_52 | BC39: CMI_Trend_56 | BD39: CMI_Trend_46 | BE39: CMI_Trend_52 | BF39: CMI_Trend_46 | BG39: CMI_Trend_38 | BH39: CMI_Trend_46 | BI39: CMI_Trend_46 | BJ39: CMI_Trend_20 | BK39: CMI_Trend_52 | BL39: CMI_Trend_38 | BM39: CMI_Trend_60 | BN39: CMI_Trend_46 | BO39: CMI_Trend_25 | BP39: CMI_Trend_60 | BQ39: CMI_Trend_52 | BR39: CMI_Trend_25 | BS39: CMI_Trend_52 | BT39: CMI_Trend_52 | BU39: CMI_Trend_60 | BV39: CMI_Trend_46 | BW39: CMI_Trend_46
B40: Near-Infrared (NIR) | C40: 0.318 | D40: 0.341 | E40: 0.315 | F40: 0.327 | G40: 0.346 | H40: 0.327 | I40: 0.345 | J40: 0.305 | K40: 0.329 | L40: 0.343 | M40: 0.353 | N40: 0.327 | O40: 0.323 | P40: 0.357 | Q40: 0.335 | R40: 0.357 | S40: 0.316 | T40: 0.349 | U40: 0.349 | V40: 0.365 | W40: 0.369 | X40: 0.356 | Y40: 0.36 | AA40: Near-Infrared (NIR) | AB40: 0.10053188 | AC40: 0.092261915 | AD40: 0.099167542 | AE40: 0.10502144 | AF40: 0.074740274 | AG40: 0.093124438 | AH40: 0.080946213 | AI40: 0.068764812 | AJ40: 0.087099695 | AK40: 0.12803505 | AL40: 0.11990705 | AM40: 0.086743577 | AN40: 0.10655939 | AO40: 0.11285706 | AP40: 0.091807532 | AQ40: 0.098842242 | AR40: 0.090330526 | AS40: 0.074696621 | AT40: 0.083243478 | AU40: 0.085229089 | AV40: 0.063171025 | AW40: 0.071583363 | AX40: 0.078664025 | AZ40: Near-Infrared (NIR) | BA40: CMI_Trend_56 | BB40: CMI_Trend_38 | BC40: CMI_Trend_60 | BD40: CMI_Trend_20 | BE40: CMI_Trend_38 | BF40: CMI_Trend_25 | BG40: CMI_Trend_38 | BH40: CMI_Trend_56 | BI40: CMI_Trend_52 | BJ40: CMI_Trend_56 | BK40: CMI_Trend_20 | BL40: CMI_Trend_38 | BM40: CMI_Trend_52 | BN40: CMI_Trend_38 | BO40: CMI_Trend_56 | BP40: CMI_Trend_52 | BQ40: CMI_Trend_25 | BR40: CMI_Trend_56 | BS40: CMI_Trend_25 | BT40: CMI_Trend_25 | BU40: CMI_Trend_46 | BV40: CMI_Trend_46 | BW40: CMI_Trend_20
B41: Short-Wave Infrared (SWIR) | C41: 0.227 | D41: 0.221 | E41: 0.225 | F41: 0.227 | G41: 0.226 | H41: 0.226 | I41: 0.223 | J41: 0.244 | K41: 0.222 | L41: 0.229 | M41: 0.226 | N41: 0.224 | O41: 0.23 | P41: 0.226 | Q41: 0.226 | R41: 0.227 | S41: 0.235 | T41: 0.224 | U41: 0.229 | V41: 0.223 | W41: 0.223 | X41: 0.227 | Y41: 0.225 | AA41: Short-Wave Infrared (SWIR) | AB41: 0.093889228 | AC41: 0.085619259 | AD41: 0.092524886 | AE41: 0.098378785 | AF41: 0.068097618 | AG41: 0.086481782 | AH41: 0.074303558 | AI41: 0.062122157 | AJ41: 0.080457039 | AK41: 0.1213924 | AL41: 0.1132644 | AM41: 0.080100921 | AN41: 0.09991673 | AO41: 0.10621441 | AP41: 0.085164877 | AQ41: 0.092199587 | AR41: 0.08368787 | AS41: 0.068053965 | AT41: 0.076600823 | AU41: 0.078586433 | AV41: 0.05652837 | AW41: 0.064940707 | AX41: 0.07202137 | AZ41: Short-Wave Infrared (SWIR) | BA41: CMI_Trend_20 | BB41: CMI_Trend_20 | BC41: CMI_Trend_56 | BD41: CMI_Trend_56 | BE41: CMI_Trend_38 | BF41: CMI_Trend_20 | BG41: CMI_Trend_56 | BH41: CMI_Trend_38 | BI41: CMI_Trend_25 | BJ41: CMI_Trend_25 | BK41: CMI_Trend_46 | BL41: CMI_Trend_60 | BM41: CMI_Trend_56 | BN41: CMI_Trend_56 | BO41: CMI_Trend_52 | BP41: CMI_Trend_56 | BQ41: CMI_Trend_56 | BR41: CMI_Trend_56 | BS41: CMI_Trend_25 | BT41: CMI_Trend_46 | BU41: CMI_Trend_20 | BV41: CMI_Trend_56 | BW41: CMI_Trend_20
B42: Mid-Wave Infrared (MWIR) | C42: 0.076 | D42: 0.065 | E42: 0.078 | F42: 0.07 | G42: 0.064 | H42: 0.073 | I42: 0.063 | J42: 0.091 | K42: 0.068 | L42: 0.065 | M42: 0.061 | N42: 0.069 | O42: 0.072 | P42: 0.058 | Q42: 0.068 | R42: 0.059 | S42: 0.079 | T42: 0.061 | U42: 0.064 | V42: 0.056 | W42: 0.054 | X42: 0.059 | Y42: 0.058 | AA42: Mid-Wave Infrared (MWIR) | AB42: 0.086662584 | AC42: 0.078392615 | AD42: 0.085298242 | AE42: 0.09115214 | AF42: 0.060870974 | AG42: 0.079255138 | AH42: 0.067076913 | AI42: 0.054895512 | AJ42: 0.073230395 | AK42: 0.11416575 | AL42: 0.10603775 | AM42: 0.072874277 | AN42: 0.092690086 | AO42: 0.098987763 | AP42: 0.077938232 | AQ42: 0.084972942 | AR42: 0.076461226 | AS42: 0.060827321 | AT42: 0.069374178 | AU42: 0.071359789 | AV42: 0.049301725 | AW42: 0.057714063 | AX42: 0.064794725 | AZ42: Mid-Wave Infrared (MWIR) | BA42: CMI_Trend_38 | BB42: CMI_Trend_25 | BC42: CMI_Trend_46 | BD42: CMI_Trend_56 | BE42: CMI_Trend_56 | BF42: CMI_Trend_52 | BG42: CMI_Trend_52 | BH42: CMI_Trend_52 | BI42: CMI_Trend_38 | BJ42: CMI_Trend_25 | BK42: CMI_Trend_25 | BL42: CMI_Trend_38 | BM42: CMI_Trend_38 | BN42: CMI_Trend_38 | BO42: CMI_Trend_46 | BP42: CMI_Trend_52 | BQ42: CMI_Trend_38 | BR42: CMI_Trend_60 | BS42: CMI_Trend_52 | BT42: CMI_Trend_46 | BU42: CMI_Trend_56 | BV42: CMI_Trend_56 | BW42: CMI_Trend_20
B43: Long-Wave Infrared (LWIR) | C43: =1-SUM(C38:C42) -> 0.141 | D43: =1-SUM(D38:D42) -> 0.127 | E43: =1-SUM(E38:E42) -> 0.139 | F43: =1-SUM(F38:F42) -> 0.139 | G43: =1-SUM(G38:G42) -> 0.125 | H43: =1-SUM(H38:H42) -> 0.135 | I43: =1-SUM(I38:I42) -> 0.126 | J43: =1-SUM(J38:J42) -> 0.157 | ... Y43: =1-SUM(Y38:Y42) -> 0.121 | AA43: Long-Wave Infrared (LWIR) | AB43: 0.080619051 | AC43: 0.072349082 | AD43: 0.079254709 | AE43: 0.085108607 | AF43: 0.054827441 | AG43: 0.073211605 | AH43: 0.06103338 | AI43: 0.048851979 | AJ43: 0.067186862 | AK43: 0.10812222 | AL43: 0.099994219 | AM43: 0.066830744 | AN43: 0.086646553 | AO43: 0.09294423 | AP43: 0.071894699 | AQ43: 0.078929409 | AR43: 0.070417693 | AS43: 0.054783788 | AT43: 0.063330645 | AU43: 0.065316255 | AV43: 0.043258192 | AW43: 0.05167053 | AX43: 0.058751192 | AZ43: Long-Wave Infrared (LWIR) | BA43: CMI_Trend_20 | BB43: CMI_Trend_56 | BC43: CMI_Trend_56 | BD43: CMI_Trend_56 | BE43: CMI_Trend_46 | BF43: CMI_Trend_20 | BG43: CMI_Trend_46 | BH43: CMI_Trend_20 | BI43: CMI_Trend_60 | BJ43: CMI_Trend_25 | BK43: CMI_Trend_25 | BL43: CMI_Trend_25 | BM43: CMI_Trend_52 | BN43: CMI_Trend_38 | BO43: CMI_Trend_20 | BP43: CMI_Trend_60 | BQ43: CMI_Trend_56 | BR43: CMI_Trend_46 | BS43: CMI_Trend_60 | BT43: CMI_Trend_46 | BU43: CMI_Trend_52 | BV43: CMI_Trend_56 | BW43: CMI_Trend_56
...

Sheet Market Value
B3: Region | C3: Share | D3: CAGR | E3: Value
B4: North America | C4: 0.315 | D4: 0.087463494 | E4: =C4*$E$9 -> 2057.4712
B5: Europe | C5: 0.274 | D5: 0.079473867 | E5: =C5*$E$9 -> 1789.6734
B6: Asia Pacific | C6: 0.302 | D6: 0.099669244 | E6: =C6*$E$9 -> 1972.5597
B7: Middle East & Africa | C7: 0.046 | D7: 0.073165836 | E7: =C7*$E$9 -> 300.45611
B8: Latin America | C8: =1-SUM(C4:C7) -> 0.063 | D8: 0.066784445 | E8: =C8*$E$9 -> 411.49424
B9: Total | C9: =SUM(C4:C8) -> 1 | D9: =SUMPRODUCT(D4:D8,C4:C8) -> 0.087 | E9: 6531.6546
