Workbook

Sheet Data
B1: Market Name | C1: Construction Safety Net Market | AN1: 0.99 | AO1: 0.99 | BP1: 0.99
C2: Market Share | AM2: =VLOOKUP(AM3,$B$120:$D$159,3,0) -> 0.12254789 | AN2: =VLOOKUP(AN3,$B$120:$D$159,3,0) -> 0.1143096 | AO2: =VLOOKUP(AO3,$B$120:$D$159,3,0) -> 0.15483646 | AP2: =VLOOKUP(AP3,$B$120:$D$159,3,0) -> 0.16341377 | AQ2: =VLOOKUP(AQ3,$B$120:$D$159,3,0) -> 0.097694978 | AR2: =VLOOKUP(AR3,$B$120:$D$159,3,0) -> 0.14806968 | AS2: =VLOOKUP(AS3,$B$120:$D$159,3,0) -> 0.11581248 | AT2: =VLOOKUP(AT3,$B$120:$D$159,3,0) -> 0.077070547 | ... BT2: =VLOOKUP(BT3,$B$120:$D$159,3,0) -> 0.14310259
A3: Segment Name in B Column Only | B3: Segment | C3: U.S. | D3: Canada | E3: U.K. | F3: Germany | G3: Italy | H3: France | I3: Spain | J3: Russia | K3: Netherlands | L3: Ireland | M3: Sweden | N3: Poland | O3: Hungary | P3: Slovakia | Q3: Turkey | R3: Rest of Europe | S3: China | T3: Japan | U3: India | V3: South Korea | W3: Singapore | X3: Malaysia | Y3: Thailand | Z3: Indonesia | AA3: Rest of ASEAN | AB3: Australia | AC3: Rest of Asia Pacific | AD3: Brazil | AE3: Argentina | AF3: Mexico | AG3: Rest of Latin America | AH3: GCC | AI3: South Africa | AJ3: Rest of Middle East & Africa | AM3: =C3 -> U.S. | AN3: =D3 -> Canada | AO3: =E3 -> U.K. | AP3: =F3 -> Germany | AQ3: =G3 -> Italy | AR3: =H3 -> France | AS3: =I3 -> Spain | AT3: =J3 -> Russia | ... BT3: =AJ3 -> Rest of Middle East & Africa | BW3: =AM3 -> U.S. | BX3: =AN3 -> Canada | BY3: =AO3 -> U.K. | BZ3: =AP3 -> Germany | CA3: =AQ3 -> Italy | CB3: =AR3 -> France | CC3: =AS3 -> Spain | CD3: =AT3 -> Russia | ... DD3: =BT3 -> Rest of Middle East & Africa
B4: By Component | AL4: By Component | AM4: =AM5*C5+AM17*C17+AM23*C23 -> 0.12254789 | AN4: =AN5*D5+AN17*D17+AN23*D23 -> 0.11173341 | AO4: =AO5*E5+AO17*E17+AO23*E23 -> 0.12917937 | AP4: =AP5*F5+AP17*F17+AP23*F23 -> 0.12403877 | AQ4: =AQ5*G5+AQ17*G17+AQ23*G23 -> 0.11825065 | AR4: =AR5*H5+AR17*H17+AR23*H23 -> 0.12734857 | AS4: =AS5*I5+AS17*I17+AS23*I23 -> 0.12162104 | AT4: =AT5*J5+AT17*J17+AT23*J23 -> 0.077668255 | ... BT4: =BT5*AJ5+BT17*AJ17+BT23*AJ23 -> 0.12900923 | BV4: By Component
B5: Hardware | C5: =1-SUM(C17,C23) -> 0.50201611 | D5: =1-SUM(D17,D23) -> 0.51108623 | E5: =1-SUM(E17,E23) -> 0.52036581 | F5: =1-SUM(F17,F23) -> 0.47232041 | G5: =1-SUM(G17,G23) -> 0.49468867 | H5: =1-SUM(H17,H23) -> 0.51170775 | I5: =1-SUM(I17,I23) -> 0.48019089 | J5: =1-SUM(J17,J23) -> 0.50811648 | ... AJ5: =1-SUM(AJ17,AJ23) -> 0.48160036 | AL5: Hardware | AM5: =AM6*C6+SUMPRODUCT(AM10:AM16,C10:C16) -> 0.1112195 | AN5: =AN6*D6+SUMPRODUCT(AN10:AN16,D10:D16) -> 0.10896507 | AO5: =AO6*E6+SUMPRODUCT(AO10:AO16,E10:E16) -> 0.12151639 | AP5: =AP6*F6+SUMPRODUCT(AP10:AP16,F10:F16) -> 0.11976997 | AQ5: =AQ6*G6+SUMPRODUCT(AQ10:AQ16,G10:G16) -> 0.10316261 | AR5: =AR6*H6+SUMPRODUCT(AR10:AR16,H10:H16) -> 0.11798566 | AS5: =AS6*I6+SUMPRODUCT(AS10:AS16,I10:I16) -> 0.11070606 | AT5: =AT6*J6+SUMPRODUCT(AT10:AT16,J10:J16) -> 0.054672083 | ... BT5: =BT6*AJ6+SUMPRODUCT(BT10:BT16,AJ10:AJ16) -> 0.11650164 | BV5: Hardware | BW5: CMI_Trend_52 | BX5: CMI_Trend_25 | BY5: CMI_Trend_60 | BZ5: CMI_Trend_25 | CA5: CMI_Trend_60 | CB5: CMI_Trend_20 | CC5: CMI_Trend_38 | CD5: CMI_Trend_25 | CE5: CMI_Trend_52 | CF5: CMI_Trend_20 | CG5: CMI_Trend_46 | CH5: CMI_Trend_25 | CI5: CMI_Trend_52 | CJ5: CMI_Trend_52 | CK5: CMI_Trend_56 | CL5: CMI_Trend_25 | CM5: CMI_Trend_46 | CN5: CMI_Trend_60 | CO5: CMI_Trend_25 | CP5: CMI_Trend_25 | CQ5: CMI_Trend_38 | CR5: CMI_Trend_38 | CS5: CMI_Trend_52 | CT5: CMI_Trend_52 | CU5: CMI_Trend_56 | CV5: CMI_Trend_25 | CW5: CMI_Trend_56 | CX5: CMI_Trend_56 | CY5: CMI_Trend_56 | CZ5: CMI_Trend_38 | DA5: CMI_Trend_52 | DB5: CMI_Trend_20 | DC5: CMI_Trend_56 | DD5: CMI_Trend_60
B6: Kiosk Scanner Devices | C6: =1-SUM(C10:C16) -> 0.21041163 | D6: =1-SUM(D10:D16) -> 0.17891163 | E6: =1-SUM(E10:E16) -> 0.21171163 | F6: =1-SUM(F10:F16) -> 0.23071163 | G6: =1-SUM(G10:G16) -> 0.24591163 | H6: =1-SUM(H10:H16) -> 0.24771163 | I6: =1-SUM(I10:I16) -> 0.18281163 | J6: =1-SUM(J10:J16) -> 0.16791163 | ... AJ6: =1-SUM(AJ10:AJ16) -> 0.18281163 | AL6: Kiosk Scanner Devices | AM6: =SUMPRODUCT(AM7:AM9,C7:C9) -> 0.10029207 | AN6: =SUMPRODUCT(AN7:AN9,D7:D9) -> 0.097049339 | AO6: =SUMPRODUCT(AO7:AO9,E7:E9) -> 0.11209756 | AP6: =SUMPRODUCT(AP7:AP9,F7:F9) -> 0.11192878 | AQ6: =SUMPRODUCT(AQ7:AQ9,G7:G9) -> 0.091847156 | AR6: =SUMPRODUCT(AR7:AR9,H7:H9) -> 0.10812436 | AS6: =SUMPRODUCT(AS7:AS9,I7:I9) -> 0.098955534 | AT6: =SUMPRODUCT(AT7:AT9,J7:J9) -> 0.03955753 | ... BT6: =SUMPRODUCT(BT7:BT9,AJ7:AJ9) -> 0.1068153 | BV6: Kiosk Scanner Devices | BW6: CMI_Trend_46 | BX6: CMI_Trend_60 | BY6: CMI_Trend_56 | BZ6: CMI_Trend_52 | CA6: CMI_Trend_25 | CB6: CMI_Trend_60 | CC6: CMI_Trend_60 | CD6: CMI_Trend_52 | CE6: CMI_Trend_52 | CF6: CMI_Trend_60 | CG6: CMI_Trend_25 | CH6: CMI_Trend_25 | CI6: CMI_Trend_60 | CJ6: CMI_Trend_56 | CK6: CMI_Trend_60 | CL6: CMI_Trend_25 | CM6: CMI_Trend_60 | CN6: CMI_Trend_60 | CO6: CMI_Trend_25 | CP6: CMI_Trend_52 | CQ6: CMI_Trend_25 | CR6: CMI_Trend_56 | CS6: CMI_Trend_46 | CT6: CMI_Trend_52 | CU6: CMI_Trend_46 | CV6: CMI_Trend_60 | CW6: CMI_Trend_20 | CX6: CMI_Trend_25 | CY6: CMI_Trend_20 | CZ6: CMI_Trend_38 | DA6: CMI_Trend_52 | DB6: CMI_Trend_52 | DC6: CMI_Trend_25 | DD6: CMI_Trend_46
B7: Single-plane Kiosk Scanners | C7: =1-SUM(C8:C9) -> 0.253469 | D7: =1-SUM(D8:D9) -> 0.233269 | E7: =1-SUM(E8:E9) -> 0.235869 | F7: =1-SUM(F8:F9) -> 0.249169 | G7: =1-SUM(G8:G9) -> 0.231169 | H7: =1-SUM(H8:H9) -> 0.249669 | I7: =1-SUM(I8:I9) -> 0.247469 | J7: =1-SUM(J8:J9) -> 0.236169 | ... AJ7: =1-SUM(AJ8:AJ9) -> 0.226069 | AL7: Single-plane Kiosk Scanners | AM7: 0.093614017 | AN7: 0.089828082 | AO7: 0.10626791 | AP7: 0.10655046 | AQ7: 0.083474925 | AR7: 0.10242372 | AS7: 0.09170323 | AT7: 0.030911608 | AU7: 0.10121616 | AV7: 0.097108627 | AW7: 0.096156347 | AX7: 0.087348652 | AY7: 0.050180968 | AZ7: 0.037528662 | BA7: 0.08763256 | BB7: 0.093167265 | BC7: 0.10834423 | BD7: 0.10552378 | BE7: 0.10168965 | BF7: 0.1067819 | BG7: 0.10760695 | BH7: 0.10352669 | BI7: 0.10733928 | BJ7: 0.10081315 | BK7: 0.096667973 | BL7: 0.09765665 | BM7: 0.095495981 | BN7: 0.10352088 | BO7: 0.09329762 | BP7: 0.10081061 | BQ7: 0.095975852 | BR7: 0.10639825 | BS7: 0.097905393 | BT7: 0.10061837 | BV7: Single-plane Kiosk Scanners | BW7: CMI_Trend_20 | BX7: CMI_Trend_46 | BY7: CMI_Trend_60 | BZ7: CMI_Trend_20 | CA7: CMI_Trend_25 | CB7: CMI_Trend_20 | CC7: CMI_Trend_60 | CD7: CMI_Trend_60 | CE7: CMI_Trend_20 | CF7: CMI_Trend_60 | CG7: CMI_Trend_60 | CH7: CMI_Trend_38 | CI7: CMI_Trend_25 | CJ7: CMI_Trend_38 | CK7: CMI_Trend_46 | CL7: CMI_Trend_52 | CM7: CMI_Trend_46 | CN7: CMI_Trend_20 | CO7: CMI_Trend_20 | CP7: CMI_Trend_20 | CQ7: CMI_Trend_46 | CR7: CMI_Trend_60 | CS7: CMI_Trend_52 | CT7: CMI_Trend_46 | CU7: CMI_Trend_20 | CV7: CMI_Trend_60 | CW7: CMI_Trend_56 | CX7: CMI_Trend_56 | CY7: CMI_Trend_20 | CZ7: CMI_Trend_56 | DA7: CMI_Trend_52 | DB7: CMI_Trend_46 | DC7: CMI_Trend_52 | DD7: CMI_Trend_46
B8: Multi-plane (Bioptic) Kiosk Scanners | C8: 0.66682665 | D8: 0.68392665 | E8: 0.67372665 | F8: 0.66402665 | G8: 0.68242665 | H8: 0.67942665 | I8: 0.66162665 | J8: 0.67912665 | K8: 0.65812665 | L8: 0.67132665 | M8: 0.68082665 | N8: 0.67442665 | O8: 0.67232665 | P8: 0.67182665 | Q8: 0.66312665 | R8: 0.67362665 | S8: 0.66232665 | T8: 0.66922665 | U8: 0.66732665 | V8: 0.66542665 | W8: 0.67782665 | X8: 0.66522665 | Y8: 0.68152665 | Z8: 0.65662665 | AA8: 0.68002665 | AB8: 0.67942665 | AC8: 0.67342665 | AD8: 0.66642665 | AE8: 0.65202665 | AF8: 0.65742665 | AG8: 0.66282665 | AH8: 0.66912665 | AI8: 0.65422665 | AJ8: 0.68382665 | AL8: Multi-plane (Bioptic) Kiosk Scanners | AM8: 0.10158705 | AN8: 0.098212011 | AO8: 0.11298872 | AP8: 0.11287797 | AQ8: 0.093125536 | AR8: 0.10928099 | AS8: 0.10017184 | AT8: 0.040958092 | AU8: 0.10835472 | AV8: 0.10439213 | AW8: 0.10381521 | AX8: 0.096618991 | AY8: 0.060431436 | AZ8: 0.048526247 | BA8: 0.09644856 | BB8: 0.1011403 | BC8: 0.11460847 | BD8: 0.11231248 | BE8: 0.10904672 | BF8: 0.11336897 | BG8: 0.11406293 | BH8: 0.11045323 | BI8: 0.11412798 | BJ8: 0.10795171 | BK8: 0.10409936 | BL8: 0.10531551 | BM8: 0.1036309 | BN8: 0.11051738 | BO8: 0.10127065 | BP8: 0.10809411 | BQ8: 0.10340724 | BR8: 0.11325552 | BS8: 0.10541184 | BT8: 0.10768555 | BV8: Multi-plane (Bioptic) Kiosk Scanners | BW8: CMI_Trend_60 | BX8: CMI_Trend_52 | BY8: CMI_Trend_52 | BZ8: CMI_Trend_46 | CA8: CMI_Trend_60 | CB8: CMI_Trend_20 | CC8: CMI_Trend_20 | CD8: CMI_Trend_56 | CE8: CMI_Trend_56 | CF8: CMI_Trend_56 | CG8: CMI_Trend_25 | CH8: CMI_Trend_25 | CI8: CMI_Trend_52 | CJ8: CMI_Trend_38 | CK8: CMI_Trend_56 | CL8: CMI_Trend_38 | CM8: CMI_Trend_38 | CN8: CMI_Trend_60 | CO8: CMI_Trend_20 | CP8: CMI_Trend_56 | CQ8: CMI_Trend_20 | CR8: CMI_Trend_20 | CS8: CMI_Trend_38 | CT8: CMI_Trend_38 | CU8: CMI_Trend_38 | CV8: CMI_Trend_60 | CW8: CMI_Trend_38 | CX8: CMI_Trend_46 | CY8: CMI_Trend_38 | CZ8: CMI_Trend_46 | DA8: CMI_Trend_20 | DB8: CMI_Trend_38 | DC8: CMI_Trend_52 | DD8: CMI_Trend_20
A9: 0.001 | B9: Presentation Kiosk Scanners | C9: 0.079704348 | D9: 0.082804348 | E9: 0.090404348 | F9: 0.086804348 | G9: 0.086404348 | H9: 0.070904348 | I9: 0.090904348 | J9: 0.084704348 | K9: 0.090604348 | L9: 0.074304348 | M9: 0.069904348 | N9: 0.069404348 | O9: 0.088704348 | P9: 0.091904348 | Q9: 0.082304348 | R9: 0.083704348 | S9: 0.075604348 | T9: 0.071404348 | U9: 0.080104348 | V9: 0.074404348 | W9: 0.091304348 | X9: 0.085704348 | Y9: 0.085104348 | Z9: 0.089504348 | AA9: 0.070104348 | AB9: 0.074104348 | AC9: 0.069304348 | AD9: 0.082104348 | AE9: 0.085004348 | AF9: 0.088104348 | AG9: 0.091304348 | AH9: 0.068204348 | AI9: 0.081704348 | AJ9: 0.090104348 | AL9: Presentation Kiosk Scanners | AM9: 0.11069493 | AN9: 0.10778927 | AO9: 0.12066615 | AP9: 0.12010611 | AQ9: 0.10414978 | AR9: 0.1171143 | AS9: 0.10984585 | AT9: 0.05243455 | AU9: 0.11650936 | AV9: 0.11271234 | AW9: 0.1125642 | AX9: 0.10720883 | AY9: 0.072140912 | AZ9: 0.061089182 | BA9: 0.10651939 | BB9: 0.11024818 | BC9: 0.12176433 | BD9: 0.12006745 | BE9: 0.11745097 | BF9: 0.12089362 | BG9: 0.12143784 | BH9: 0.11836566 | BI9: 0.12188296 | BJ9: 0.11610635 | BK9: 0.1125885 | BL9: 0.11406451 | BM9: 0.11292371 | BN9: 0.11850974 | BO9: 0.11037853 | BP9: 0.11641432 | BQ9: 0.11189638 | BR9: 0.12108883 | BS9: 0.11398673 | BT9: 0.11575864 | BV9: Presentation Kiosk Scanners | BW9: CMI_Trend_52 | BX9: CMI_Trend_60 | BY9: CMI_Trend_20 | BZ9: CMI_Trend_60 | CA9: CMI_Trend_25 | CB9: CMI_Trend_20 | CC9: CMI_Trend_46 | CD9: CMI_Trend_20 | CE9: CMI_Trend_20 | CF9: CMI_Trend_52 | CG9: CMI_Trend_56 | CH9: CMI_Trend_25 | CI9: CMI_Trend_25 | CJ9: CMI_Trend_52 | CK9: CMI_Trend_46 | CL9: CMI_Trend_46 | CM9: CMI_Trend_20 | CN9: CMI_Trend_60 | CO9: CMI_Trend_20 | CP9: CMI_Trend_25 | CQ9: CMI_Trend_60 | CR9: CMI_Trend_56 | CS9: CMI_Trend_60 | CT9: CMI_Trend_52 | CU9: CMI_Trend_25 | CV9: CMI_Trend_56 | CW9: CMI_Trend_25 | CX9: CMI_Trend_60 | CY9: CMI_Trend_38 | CZ9: CMI_Trend_60 | DA9: CMI_Trend_52 | DB9: CMI_Trend_46 | DC9: CMI_Trend_38 | DD9: CMI_Trend_25
B10: Dedicated / Retailer-Supplied Mobile Devices | C10: 0.093461817 | D10: 0.10436182 | E10: 0.098761817 | F10: 0.079961817 | G10: 0.10046182 | H10: 0.089661817 | I10: 0.11056182 | J10: 0.10566182 | K10: 0.087361817 | L10: 0.10236182 | M10: 0.090461817 | N10: 0.082761817 | O10: 0.088561817 | P10: 0.082061817 | Q10: 0.094261817 | R10: 0.098161817 | S10: 0.090761817 | T10: 0.083061817 | U10: 0.088561817 | V10: 0.10126182 | W10: 0.087061817 | X10: 0.079961817 | Y10: 0.085661817 | Z10: 0.10266182 | AA10: 0.10996182 | AB10: 0.077961817 | AC10: 0.095461817 | AD10: 0.10686182 | AE10: 0.088461817 | AF10: 0.082661817 | AG10: 0.10126182 | AH10: 0.079761817 | AI10: 0.089261817 | AJ10: 0.093761817 | AL10: Dedicated / Retailer-Supplied Mobile Devices | AM10: 0.1352375 | AN10: 0.13359666 | AO10: 0.14135413 | AP10: 0.13958344 | AQ10: 0.13385626 | AR10: 0.13822234 | AS10: 0.13591391 | AT10: 0.083359604 | AU10: 0.13848325 | AV10: 0.13513239 | AW10: 0.13613969 | AX10: 0.13574476 | AY10: 0.10369387 | AZ10: 0.094941914 | BA10: 0.13365678 | BB10: 0.13479074 | BC10: 0.14104689 | BD10: 0.14096441 | BE10: 0.14009749 | BF10: 0.14116991 | BG10: 0.14131064 | BH10: 0.13968691 | BI10: 0.14277991 | BJ10: 0.13808024 | BK10: 0.13546378 | BL10: 0.13764 | BM10: 0.13796458 | BN10: 0.14004636 | BO10: 0.1349211 | BP10: 0.13883438 | BQ10: 0.13477165 | BR10: 0.14219687 | BS10: 0.13709307 | BT10: 0.1375128 | BV10: Dedicated / Retailer-Supplied Mobile Devices | BW10: CMI_Trend_56 | BX10: CMI_Trend_38 | BY10: CMI_Trend_52 | BZ10: CMI_Trend_56 | CA10: CMI_Trend_56 | CB10: CMI_Trend_46 | CC10: CMI_Trend_60 | CD10: CMI_Trend_38 | CE10: CMI_Trend_46 | CF10: CMI_Trend_46 | CG10: CMI_Trend_52 | CH10: CMI_Trend_56 | CI10: CMI_Trend_20 | CJ10: CMI_Trend_52 | CK10: CMI_Trend_52 | CL10: CMI_Trend_60 | CM10: CMI_Trend_60 | CN10: CMI_Trend_60 | CO10: CMI_Trend_52 | CP10: CMI_Trend_60 | CQ10: CMI_Trend_60 | CR10: CMI_Trend_38 | CS10: CMI_Trend_56 | CT10: CMI_Trend_38 | CU10: CMI_Trend_46 | CV10: CMI_Trend_60 | CW10: CMI_Trend_56 | CX10: CMI_Trend_38 | CY10: CMI_Trend_56 | CZ10: CMI_Trend_38 | DA10: CMI_Trend_46 | DB10: CMI_Trend_60 | DC10: CMI_Trend_38 | DD10: CMI_Trend_38
B11: Smart-Cart Units | C11: 0.053710556 | D11: 0.069410556 | E11: 0.059010556 | F11: 0.043710556 | G11: 0.037510556 | H11: 0.057510556 | I11: 0.053610556 | J11: 0.066810556 | K11: 0.041310556 | L11: 0.044910556 | M11: 0.038510556 | N11: 0.058210556 | O11: 0.051510556 | P11: 0.052710556 | Q11: 0.065510556 | R11: 0.063010556 | S11: 0.064710556 | T11: 0.061110556 | U11: 0.037510556 | V11: 0.069310556 | W11: 0.043810556 | X11: 0.057510556 | Y11: 0.048210556 | Z11: 0.044410556 | AA11: 0.061810556 | AB11: 0.062610556 | AC11: 0.040810556 | AD11: 0.053810556 | AE11: 0.058010556 | AF11: 0.051310556 | AG11: 0.053910556 | AH11: 0.041810556 | AI11: 0.062510556 | AJ11: 0.065310556 | AL11: Smart-Cart Units | AM11: 0.1429911 | AN11: 0.14174985 | AO11: 0.14788998 | AP11: 0.14573682 | AQ11: 0.14324128 | AR11: 0.14489089 | AS11: 0.14414946 | AT11: 0.093129599 | AU11: 0.14542535 | AV11: 0.14221545 | AW11: 0.14358778 | AX11: 0.14475997 | AY11: 0.11366224 | AZ11: 0.10563683 | BA11: 0.14223015 | BB11: 0.14254435 | BC11: 0.14713873 | BD11: 0.14756628 | BE11: 0.14725209 | BF11: 0.1475757 | BG11: 0.14758895 | BH11: 0.14642283 | BI11: 0.14938178 | BJ11: 0.14502235 | BK11: 0.14269064 | BL11: 0.14508808 | BM11: 0.14587562 | BN11: 0.14685031 | BO11: 0.14267471 | BP11: 0.14591743 | BQ11: 0.14199852 | BR11: 0.14886542 | BS11: 0.14439294 | BT11: 0.14438548 | BV11: Smart-Cart Units | BW11: CMI_Trend_25 | BX11: CMI_Trend_20 | BY11: CMI_Trend_46 | BZ11: CMI_Trend_25 | CA11: CMI_Trend_60 | CB11: CMI_Trend_25 | CC11: CMI_Trend_25 | CD11: CMI_Trend_60 | CE11: CMI_Trend_20 | CF11: CMI_Trend_38 | CG11: CMI_Trend_25 | CH11: CMI_Trend_60 | CI11: CMI_Trend_38 | CJ11: CMI_Trend_56 | CK11: CMI_Trend_60 | CL11: CMI_Trend_38 | CM11: CMI_Trend_46 | CN11: CMI_Trend_56 | CO11: CMI_Trend_56 | CP11: CMI_Trend_20 | CQ11: CMI_Trend_25 | CR11: CMI_Trend_25 | CS11: CMI_Trend_46 | CT11: CMI_Trend_46 | CU11: CMI_Trend_52 | CV11: CMI_Trend_25 | CW11: CMI_Trend_56 | CX11: CMI_Trend_38 | CY11: CMI_Trend_20 | CZ11: CMI_Trend_56 | DA11: CMI_Trend_25 | DB11: CMI_Trend_38 | DC11: CMI_Trend_56 | DD11: CMI_Trend_60
B12: Kiosk Terminals / Display + Controller | C12: 0.22919987 | D12: 0.21569987 | E12: 0.22589987 | F12: 0.23809987 | G12: 0.21479987 | H12: 0.24079987 | I12: 0.23639987 | J12: 0.21609987 | K12: 0.22259987 | L12: 0.23669987 | M12: 0.24539987 | N12: 0.23399987 | O12: 0.23099987 | P12: 0.22869987 | Q12: 0.22529987 | R12: 0.21749987 | S12: 0.22789987 | T12: 0.22009987 | U12: 0.21509987 | V12: 0.22829987 | W12: 0.23459987 | X12: 0.23229987 | Y12: 0.24539987 | Z12: 0.24569987 | AA12: 0.22359987 | AB12: 0.22589987 | AC12: 0.21819987 | AD12: 0.24439987 | AE12: 0.23839987 | AF12: 0.23529987 | AG12: 0.22289987 | AH12: 0.23009987 | AI12: 0.22769987 | AJ12: 0.22379987 | AL12: Kiosk Terminals / Display + Controller | AM12: 0.12656345 | AN12: 0.12447559 | AO12: 0.13404241 | AP12: 0.1326996 | AQ12: 0.12335714 | AR12: 0.13076215 | AS12: 0.12670071 | AT12: 0.072429807 | AU12: 0.13071705 | AV12: 0.1272085 | AW12: 0.12780744 | AX12: 0.12565935 | AY12: 0.092542154 | AZ12: 0.082977392 | BA12: 0.12406565 | BB12: 0.1261167 | BC12: 0.13423188 | BD12: 0.13357883 | BE12: 0.13209356 | BF12: 0.13400369 | BG12: 0.13428702 | BH12: 0.13215137 | BI12: 0.13539433 | BJ12: 0.13031404 | BK12: 0.127379 | BL12: 0.12930775 | BM12: 0.12911442 | BN12: 0.1324347 | BO12: 0.12624705 | BP12: 0.13091049 | BQ12: 0.12668688 | BR12: 0.13473669 | BS12: 0.12892663 | BT12: 0.12982425 | BV12: Kiosk Terminals / Display + Controller | BW12: CMI_Trend_52 | BX12: CMI_Trend_52 | BY12: CMI_Trend_60 | BZ12: CMI_Trend_46 | CA12: CMI_Trend_56 | CB12: CMI_Trend_52 | CC12: CMI_Trend_25 | CD12: CMI_Trend_52 | CE12: CMI_Trend_20 | CF12: CMI_Trend_56 | CG12: CMI_Trend_46 | CH12: CMI_Trend_60 | CI12: CMI_Trend_46 | CJ12: CMI_Trend_60 | CK12: CMI_Trend_52 | CL12: CMI_Trend_46 | CM12: CMI_Trend_46 | CN12: CMI_Trend_56 | CO12: CMI_Trend_52 | CP12: CMI_Trend_52 | CQ12: CMI_Trend_38 | CR12: CMI_Trend_20 | CS12: CMI_Trend_25 | CT12: CMI_Trend_46 | CU12: CMI_Trend_20 | CV12: CMI_Trend_46 | CW12: CMI_Trend_52 | CX12: CMI_Trend_38 | CY12: CMI_Trend_38 | CZ12: CMI_Trend_56 | DA12: CMI_Trend_52 | DB12: CMI_Trend_52 | DC12: CMI_Trend_46 | DD12: CMI_Trend_56
B13: Payment Units | C13: 0.051866343 | D13: 0.053666343 | E13: 0.046666343 | F13: 0.051466343 | G13: 0.036366343 | H13: 0.041966343 | I13: 0.042166343 | J13: 0.060466343 | K13: 0.057366343 | L13: 0.050866343 | M13: 0.067366343 | N13: 0.049866343 | O13: 0.066166343 | P13: 0.037866343 | Q13: 0.053766343 | R13: 0.036566343 | S13: 0.046866343 | T13: 0.066366343 | U13: 0.039266343 | V13: 0.067766343 | W13: 0.060766343 | X13: 0.065166343 | Y13: 0.045266343 | Z13: 0.048866343 | AA13: 0.040366343 | AB13: 0.041866343 | AC13: 0.051666343 | AD13: 0.063666343 | AE13: 0.062766343 | AF13: 0.056666343 | AG13: 0.068166343 | AH13: 0.055066343 | AI13: 0.044666343 | AJ13: 0.056766343 | AL13: Payment Units | AM13: 0.10752989 | AN13: 0.10446112 | AO13: 0.1179982 | AP13: 0.11759429 | AQ13: 0.10031879 | AR13: 0.11439218 | AS13: 0.10648408 | AT13: 0.048446419 | AU13: 0.11367558 | AV13: 0.10982102 | AW13: 0.10952388 | AX13: 0.10352881 | AY13: 0.068071807 | AZ13: 0.056723495 | BA13: 0.10301972 | BB13: 0.10708314 | BC13: 0.11927763 | BD13: 0.11737256 | BE13: 0.11453045 | BF13: 0.11827876 | BG13: 0.11887502 | BH13: 0.11561605 | BI13: 0.11918806 | BJ13: 0.11327257 | BK13: 0.10963848 | BL13: 0.11102419 | BM13: 0.10969441 | BN13: 0.11573235 | BO13: 0.1072135 | BP13: 0.113523 | BQ13: 0.10894636 | BR13: 0.11836671 | BS13: 0.11100691 | BT13: 0.1129532 | BV13: Payment Units | BW13: CMI_Trend_60 | BX13: CMI_Trend_38 | BY13: CMI_Trend_46 | BZ13: CMI_Trend_25 | CA13: CMI_Trend_20 | CB13: CMI_Trend_56 | CC13: CMI_Trend_52 | CD13: CMI_Trend_56 | CE13: CMI_Trend_56 | CF13: CMI_Trend_56 | CG13: CMI_Trend_52 | CH13: CMI_Trend_56 | CI13: CMI_Trend_60 | CJ13: CMI_Trend_56 | CK13: CMI_Trend_60 | CL13: CMI_Trend_20 | CM13: CMI_Trend_56 | CN13: CMI_Trend_38 | CO13: CMI_Trend_38 | CP13: CMI_Trend_46 | CQ13: CMI_Trend_56 | CR13: CMI_Trend_20 | CS13: CMI_Trend_60 | CT13: CMI_Trend_56 | CU13: CMI_Trend_20 | CV13: CMI_Trend_56 | CW13: CMI_Trend_20 | CX13: CMI_Trend_20 | CY13: CMI_Trend_46 | CZ13: CMI_Trend_20 | DA13: CMI_Trend_46 | DB13: CMI_Trend_52 | DC13: CMI_Trend_20 | DD13: CMI_Trend_60
B14: Kiosk Cabinet / Enclosure | C14: 0.1929895 | D14: 0.1923895 | E14: 0.1776895 | F14: 0.2047895 | G14: 0.2060895 | H14: 0.1792895 | I14: 0.2028895 | J14: 0.2023895 | K14: 0.1803895 | L14: 0.1838895 | M14: 0.1841895 | N14: 0.1911895 | O14: 0.1995895 | P14: 0.2010895 | Q14: 0.1771895 | R14: 0.1895895 | S14: 0.1893895 | T14: 0.2018895 | U14: 0.1939895 | V14: 0.2089895 | W14: 0.1915895 | X14: 0.1933895 | Y14: 0.1860895 | Z14: 0.1955895 | AA14: 0.1904895 | AB14: 0.1777895 | AC14: 0.1910895 | AD14: 0.1931895 | AE14: 0.1870895 | AF14: 0.1835895 | AG14: 0.1871895 | AH14: 0.1985895 | AI14: 0.1912895 | AJ14: 0.1919895 | AL14: Kiosk Cabinet / Enclosure | AM14: 0.091631135 | AN14: 0.08774301 | AO14: 0.10459645 | AP14: 0.10497681 | AQ14: 0.08107483 | AR14: 0.10071832 | AS14: 0.089597097 | AT14: 0.028413062 | AU14: 0.099440811 | AV14: 0.09529723 | AW14: 0.094251598 | AX14: 0.085043131 | AY14: 0.047631691 | AZ14: 0.034793578 | BA14: 0.085440032 | BB14: 0.091184383 | BC14: 0.10678632 | BD14: 0.10383544 | BE14: 0.099859951 | BF14: 0.10514371 | BG14: 0.10600135 | BH14: 0.10180407 | BI14: 0.10565094 | BJ14: 0.099037801 | BK14: 0.094819797 | BL14: 0.095751901 | BM14: 0.093472838 | BN14: 0.10178086 | BO14: 0.091314737 | BP14: 0.098999213 | BQ14: 0.094127676 | BR14: 0.10469285 | BS14: 0.096038548 | BT14: 0.098860777 | BV14: Kiosk Cabinet / Enclosure | BW14: CMI_Trend_52 | BX14: CMI_Trend_46 | BY14: CMI_Trend_38 | BZ14: CMI_Trend_38 | CA14: CMI_Trend_46 | CB14: CMI_Trend_20 | CC14: CMI_Trend_20 | CD14: CMI_Trend_20 | CE14: CMI_Trend_46 | CF14: CMI_Trend_20 | CG14: CMI_Trend_38 | CH14: CMI_Trend_20 | CI14: CMI_Trend_20 | CJ14: CMI_Trend_56 | CK14: CMI_Trend_60 | CL14: CMI_Trend_60 | CM14: CMI_Trend_20 | CN14: CMI_Trend_25 | CO14: CMI_Trend_25 | CP14: CMI_Trend_56 | CQ14: CMI_Trend_25 | CR14: CMI_Trend_38 | CS14: CMI_Trend_38 | CT14: CMI_Trend_20 | CU14: CMI_Trend_52 | CV14: CMI_Trend_60 | CW14: CMI_Trend_46 | CX14: CMI_Trend_60 | CY14: CMI_Trend_60 | CZ14: CMI_Trend_38 | DA14: CMI_Trend_56 | DB14: CMI_Trend_46 | DC14: CMI_Trend_46 | DD14: CMI_Trend_56
B15: Receipt Printer | C15: 0.06503502 | D15: 0.07803502 | E15: 0.07053502 | F15: 0.06233502 | G15: 0.07033502 | H15: 0.04903502 | I15: 0.07723502 | J15: 0.06103502 | K15: 0.08133502 | L15: 0.05273502 | M15: 0.04923502 | N15: 0.06183502 | O15: 0.07643502 | P15: 0.07163502 | Q15: 0.05153502 | R15: 0.06733502 | S15: 0.08063502 | T15: 0.08133502 | U15: 0.06753502 | V15: 0.06343502 | W15: 0.06753502 | X15: 0.08183502 | Y15: 0.05183502 | Z15: 0.07073502 | AA15: 0.06643502 | AB15: 0.07673502 | AC15: 0.07693502 | AD15: 0.06763502 | AE15: 0.07173502 | AF15: 0.05763502 | AG15: 0.08193502 | AH15: 0.06443502 | AI15: 0.07363502 | AJ15: 0.07793502 | AL15: Receipt Printer | AM15: 0.082793053 | AN15: 0.078449452 | AO15: 0.097146447 | AP15: 0.097962784 | AQ15: 0.070377157 | AR15: 0.093117057 | AS15: 0.080209664 | AT15: 0.022377581 | AU15: 0.091527738 | AV15: 0.087223489 | AW15: 0.085761772 | AX15: 0.074766989 | AY15: 0.036269079 | AZ15: 0.02260279 | BA15: 0.075667523 | BB15: 0.082346301 | BC15: 0.099842436 | BD15: 0.096310183 | BE15: 0.091704658 | BF15: 0.097841959 | BG15: 0.09884491 | BH15: 0.094126023 | BI15: 0.098125685 | BJ15: 0.091124729 | BK15: 0.086582127 | BL15: 0.087262075 | BM15: 0.084455307 | BN15: 0.094025255 | BO15: 0.082476655 | BP15: 0.090925473 | BQ15: 0.085890006 | BR15: 0.097091588 | BS15: 0.08771767 | BT15: 0.091026835 | BV15: Receipt Printer | BW15: CMI_Trend_46 | BX15: CMI_Trend_20 | BY15: CMI_Trend_60 | BZ15: CMI_Trend_25 | CA15: CMI_Trend_20 | CB15: CMI_Trend_56 | CC15: CMI_Trend_60 | CD15: CMI_Trend_56 | CE15: CMI_Trend_46 | CF15: CMI_Trend_56 | CG15: CMI_Trend_60 | CH15: CMI_Trend_20 | CI15: CMI_Trend_46 | CJ15: CMI_Trend_52 | CK15: CMI_Trend_25 | CL15: CMI_Trend_38 | CM15: CMI_Trend_20 | CN15: CMI_Trend_56 | CO15: CMI_Trend_60 | CP15: CMI_Trend_52 | CQ15: CMI_Trend_25 | CR15: CMI_Trend_46 | CS15: CMI_Trend_60 | CT15: CMI_Trend_52 | CU15: CMI_Trend_38 | CV15: CMI_Trend_20 | CW15: CMI_Trend_20 | CX15: CMI_Trend_60 | CY15: CMI_Trend_25 | CZ15: CMI_Trend_60 | DA15: CMI_Trend_56 | DB15: CMI_Trend_20 | DC15: CMI_Trend_25 | DD15: CMI_Trend_38
B16: Others (Scale / Bagging Hardware, Power & Internal Electronics, Mounting / Wiring / Minor Internal Hardware, Embedded Scan Modules, Network & Accessories) | C16: 0.10332527 | D16: 0.10752527 | E16: 0.10972527 | F16: 0.088925265 | G16: 0.088525265 | H16: 0.094025265 | I16: 0.094325265 | J16: 0.11962527 | K16: 0.10132527 | L16: 0.10122527 | M16: 0.099625265 | N16: 0.097525265 | O16: 0.11882527 | P16: 0.096225265 | Q16: 0.089425265 | R16: 0.10452527 | S16: 0.10302527 | T16: 0.11382527 | U16: 0.11862527 | V16: 0.099125265 | W16: 0.11202527 | X16: 0.11732527 | Y16: 0.098225265 | Z16: 0.096825265 | AA16: 0.10352527 | AB16: 0.10782527 | AC16: 0.089825265 | AD16: 0.10282527 | AE16: 0.099225265 | AF16: 0.10552527 | AG16: 0.090825265 | AH16: 0.094425265 | AI16: 0.093625265 | AJ16: 0.10762527 | AL16: Others (Scale / Bagging Hardware, Power & Internal Electronics, Mounting / Wiring / Minor Internal Hardware, Embedded Scan Modules, Network & Accessories) | AM16: 0.11752599 | AN16: 0.11497238 | AO16: 0.12642434 | AP16: 0.12552734 | AQ16: 0.11241814 | AR16: 0.12298941 | AS16: 0.11710151 | AT16: 0.061042081 | AU16: 0.12262547 | AV16: 0.11895263 | AW16: 0.11912609 | AX16: 0.11515139 | AY16: 0.080923212 | AZ16: 0.07051159 | BA16: 0.11407268 | BB16: 0.11707924 | BC16: 0.12713135 | BD16: 0.12588381 | BE16: 0.12375429 | BF16: 0.12653722 | BG16: 0.12696914 | BH16: 0.12430012 | BI16: 0.12769931 | BJ16: 0.12222246 | BK16: 0.1189555 | BL16: 0.1206264 | BM16: 0.11989346 | BN16: 0.12450414 | BO16: 0.11720959 | BP16: 0.12265461 | BQ16: 0.11826337 | BR16: 0.12696394 | BS16: 0.12041804 | BT16: 0.12181359 | BV16: Others (Scale / Bagging Hardware, Power & Internal Electronics, Mounting / Wiring / Minor Internal Hardware, Embedded Scan Modules, Network & Accessories) | BW16: CMI_Trend_38 | BX16: CMI_Trend_60 | BY16: CMI_Trend_46 | BZ16: CMI_Trend_38 | CA16: CMI_Trend_60 | CB16: CMI_Trend_56 | CC16: CMI_Trend_52 | CD16: CMI_Trend_46 | CE16: CMI_Trend_38 | CF16: CMI_Trend_60 | CG16: CMI_Trend_60 | CH16: CMI_Trend_25 | CI16: CMI_Trend_38 | CJ16: CMI_Trend_52 | CK16: CMI_Trend_46 | CL16: CMI_Trend_60 | CM16: CMI_Trend_25 | CN16: CMI_Trend_52 | CO16: CMI_Trend_46 | CP16: CMI_Trend_38 | CQ16: CMI_Trend_56 | CR16: CMI_Trend_38 | CS16: CMI_Trend_46 | CT16: CMI_Trend_60 | CU16: CMI_Trend_38 | CV16: CMI_Trend_52 | CW16: CMI_Trend_38 | CX16: CMI_Trend_38 | CY16: CMI_Trend_56 | CZ16: CMI_Trend_60 | DA16: CMI_Trend_46 | DB16: CMI_Trend_56 | DC16: CMI_Trend_38 | DD16: CMI_Trend_52
B17: Software | C17: 0.17226105 | D17: 0.17346105 | E17: 0.16956105 | F17: 0.18166105 | G17: 0.16406105 | H17: 0.17076105 | I17: 0.18516105 | J17: 0.16726105 | K17: 0.16986105 | L17: 0.18606105 | M17: 0.16886105 | N17: 0.18166105 | O17: 0.17006105 | P17: 0.17606105 | Q17: 0.18506105 | R17: 0.17106105 | S17: 0.17786105 | T17: 0.17626105 | U17: 0.16096105 | V17: 0.17396105 | W17: 0.16536105 | X17: 0.17986105 | Y17: 0.17166105 | Z17: 0.15496105 | AA17: 0.18276105 | AB17: 0.15786105 | AC17: 0.16236105 | AD17: 0.16246105 | AE17: 0.18386105 | AF17: 0.18616105 | AG17: 0.18676105 | AH17: 0.16956105 | AI17: 0.16226105 | AJ17: 0.17886105 | AL17: Software | AM17: =SUMPRODUCT(AM18:AM22,C18:C22) -> 0.12570371 | AN17: =((((((((((((((SUMPRODUCT(AN18:AN22,D18:D22))*0.99)*0.99)*0.99)*0.99)*0.99)*0.99)*0.99)*0.99)*0.99)*0.99)*0.99)*0.99)*0.99)*0.99 -> 0.10716311 | AO17: =((((((((((SUMPRODUCT(AO18:AO22,E18:E22))*0.99)*0.99)*0.99)*0.99)*0.99)*0.99)/0.99)/0.99)/0.99)/0.99 -> 0.13057581 | AP17: =((((((((((((((((SUMPRODUCT(AP18:AP22,F18:F22))*0.99)*0.99)*0.99)*0.99)*0.99)*0.99)*0.99)*0.99)*0.99)/0.99)/0.99)/0.99)/0.99)*0.99)*0.99)*0.99 -> 0.12179527 | AQ17: =SUMPRODUCT(AQ18:AQ22,G18:G22) -> 0.12315277 | AR17: =SUMPRODUCT(AR18:AR22,H18:H22) -> 0.12991999 | AS17: =((((((((SUMPRODUCT(AS18:AS22,I18:I22))*0.99)*0.99)*0.99)*0.99)/0.99)/0.99)/0.99)*0.99 -> 0.12341688 | AT17: =(((((((((((((((((((((SUMPRODUCT(AT18:AT22,J18:J22))/0.99)/0.99)/0.99)/0.99)/0.99)/0.99)/0.99)/0.99)/0.99)/0.99)/0.99)/0.99)/0.99)/0.99)/0.99)/0.99)/0.99)/0.99)/0.99)/0.99)/0.99 -> 0.089175119 | AU17: =((((SUMPRODUCT(AU18:AU22,K18:K22))/0.99)/0.99)/0.99)/0.99 -> 0.13565184 | AV17: =((((((SUMPRODUCT(AV18:AV22,L18:L22))/0.99)/0.99)/0.99)/0.99)/0.99)/0.99 -> 0.13359597 | AW17: =(((((((((((SUMPRODUCT(AW18:AW22,M18:M22))/0.99)/0.99)/0.99)/0.99)/0.99)/0.99)/0.99)/0.99)/0.99)/0.99)/0.99 -> 0.1420517 | AX17: =((((((((((((((SUMPRODUCT(AX18:AX22,N18:N22))*0.99)*0.99)*0.99)*0.99)*0.99)*0.99)*0.99)*0.99)/0.99)/0.99)/0.99)/0.99)/0.99)*0.99 -> 0.11961424 | AY17: =((((((((((SUMPRODUCT(AY18:AY22,O18:O22))/0.99)/0.99)/0.99)/0.99)/0.99)/0.99)/0.99)/0.99)*0.99)*0.99 -> 0.097095423 | AZ17: =(((((((((((((SUMPRODUCT(AZ18:AZ22,P18:P22))/0.99)/0.99)/0.99)/0.99)/0.99)/0.99)/0.99)/0.99)/0.99)/0.99)/0.99)/0.99)/0.99 -> 0.092920255 | BA17: =(((((((((SUMPRODUCT(BA18:BA22,Q18:Q22))*0.99)*0.99)*0.99)*0.99)*0.99)*0.99)*0.99)*0.99)*0.99 -> 0.11302043 | BB17: =SUMPRODUCT(BB18:BB22,R18:R22) -> 0.1248944 | BC17: =(((((((((((((((((SUMPRODUCT(BC18:BC22,S18:S22))*0.99)*0.99)*0.99)*0.99)*0.99)*0.99)*0.99)*0.99)*0.99)*0.99)/0.99)/0.99)/0.99)/0.99)/0.99)/0.99)/0.99 -> 0.13003987 | BD17: =(((((((((SUMPRODUCT(BD18:BD22,T18:T22))*0.99)/0.99)/0.99)/0.99)/0.99)/0.99)/0.99)/0.99)*0.99 -> 0.13948824 | BE17: =(((((((SUMPRODUCT(BE18:BE22,U18:U22))/0.99)/0.99)/0.99)/0.99)/0.99)/0.99)/0.99 -> 0.1412229 | BF17: =(((((((((SUMPRODUCT(BF18:BF22,V18:V22))/0.99)/0.99)/0.99)/0.99)/0.99)/0.99)*0.99)*0.99)*0.99 -> 0.13761875 | BG17: =(((SUMPRODUCT(BG18:BG22,W18:W22))/0.99)/0.99)*0.99 -> 0.13458588 | BH17: =(((((SUMPRODUCT(BH18:BH22,X18:X22))/0.99)/0.99)/0.99)*0.99)*0.99 -> 0.13262755 | BI17: =(((((SUMPRODUCT(BI18:BI22,Y18:Y22))/0.99)/0.99)/0.99)/0.99)/0.99 -> 0.14184823 | BJ17: =(((((((((((SUMPRODUCT(BJ18:BJ22,Z18:Z22))*0.99)*0.99)*0.99)*0.99)*0.99)*0.99)*0.99)*0.99)*0.99)*0.99)*0.99 -> 0.11602706 | BK17: =((((((((SUMPRODUCT(BK18:BK22,AA18:AA22))/0.99)/0.99)/0.99)/0.99)/0.99)/0.99)/0.99)/0.99 -> 0.13721227 | BL17: =(((((((((((SUMPRODUCT(BL18:BL22,AB18:AB22))/0.99)/0.99)/0.99)/0.99)/0.99)/0.99)/0.99)/0.99)/0.99)/0.99)/0.99 -> 0.14327007 | BM17: =((SUMPRODUCT(BM18:BM22,AC18:AC22))/0.99)/0.99 -> 0.13069206 | BN17: =((SUMPRODUCT(BN18:BN22,AD18:AD22))/0.99)/0.99 -> 0.13455162 | BO17: =SUMPRODUCT(BO18:BO22,AE18:AE22) -> 0.12593747 | BP17: =((((((((((((SUMPRODUCT(BP18:BP22,AF18:AF22))/0.99)/0.99)/0.99)/0.99)/0.99)/0.99)/0.99)/0.99)/0.99)*0.99)*0.99)*0.99 -> 0.13777641 | BQ17: =((((((((SUMPRODUCT(BQ18:BQ22,AG18:AG22))/0.99)/0.99)/0.99)/0.99)/0.99)/0.99)/0.99)/0.99 -> 0.13661523 | BR17: =SUMPRODUCT(BR18:BR22,AH18:AH22) -> 0.13412823 | BS17: =(((((((((SUMPRODUCT(BS18:BS22,AI18:AI22))/0.99)/0.99)/0.99)/0.99)/0.99)/0.99)/0.99)/0.99)/0.99 -> 0.14092927 | BT17: =(((SUMPRODUCT(BT18:BT22,AJ18:AJ22))/0.99)/0.99)/0.99 -> 0.13308135 | BV17: Software | BW17: CMI_Trend_60 | BX17: CMI_Trend_25 | BY17: CMI_Trend_25 | BZ17: CMI_Trend_52 | CA17: CMI_Trend_38 | CB17: CMI_Trend_56 | CC17: CMI_Trend_52 | CD17: CMI_Trend_52 | CE17: CMI_Trend_56 | CF17: CMI_Trend_20 | CG17: CMI_Trend_46 | CH17: CMI_Trend_52 | CI17: CMI_Trend_46 | CJ17: CMI_Trend_52 | CK17: CMI_Trend_20 | CL17: CMI_Trend_56 | CM17: CMI_Trend_20 | CN17: CMI_Trend_56 | CO17: CMI_Trend_25 | CP17: CMI_Trend_38 | CQ17: CMI_Trend_56 | CR17: CMI_Trend_56 | CS17: CMI_Trend_46 | CT17: CMI_Trend_56 | CU17: CMI_Trend_25 | CV17: CMI_Trend_25 | CW17: CMI_Trend_56 | CX17: CMI_Trend_56 | CY17: CMI_Trend_38 | CZ17: CMI_Trend_56 | DA17: CMI_Trend_60 | DB17: CMI_Trend_52 | DC17: CMI_Trend_25 | DD17: CMI_Trend_20
B18: Scanning & Decoding software | C18: =1-SUM(C19:C22) -> 0.31824149 | D18: =1-SUM(D19:D22) -> 0.32424149 | E18: =1-SUM(E19:E22) -> 0.31814149 | F18: =1-SUM(F19:F22) -> 0.30774149 | G18: =1-SUM(G19:G22) -> 0.28364149 | H18: =1-SUM(H19:H22) -> 0.32704149 | I18: =1-SUM(I19:I22) -> 0.32214149 | J18: =1-SUM(J19:J22) -> 0.28574149 | ... AJ18: =1-SUM(AJ19:AJ22) -> 0.31774149 | AL18: Scanning & Decoding software | AM18: 0.11230834 | AN18: 0.10948583 | AO18: 0.12202616 | AP18: 0.12138654 | AQ18: 0.10610266 | AR18: 0.11850193 | AS18: 0.11155954 | AT18: 0.054467539 | AU18: 0.1179539 | AV18: 0.11418621 | AW18: 0.11411404 | AX18: 0.10908476 | AY18: 0.07421518 | AZ18: 0.063314635 | BA18: 0.10830338 | BB18: 0.11186159 | BC18: 0.12303195 | BD18: 0.1214412 | BE18: 0.11893973 | BF18: 0.12222656 | BG18: 0.12274426 | BH18: 0.11976731 | BI18: 0.12325671 | BJ18: 0.11755089 | BK18: 0.1140923 | BL18: 0.11561434 | BM18: 0.11456987 | BN18: 0.11992554 | BO18: 0.11199194 | BP18: 0.1178882 | BQ18: 0.11340018 | BR18: 0.12247646 | BS18: 0.11550573 | BT18: 0.11718874 | BV18: Scanning & Decoding software | BW18: CMI_Trend_56 | BX18: CMI_Trend_38 | BY18: CMI_Trend_38 | BZ18: CMI_Trend_52 | CA18: CMI_Trend_60 | CB18: CMI_Trend_46 | CC18: CMI_Trend_38 | CD18: CMI_Trend_46 | CE18: CMI_Trend_52 | CF18: CMI_Trend_38 | CG18: CMI_Trend_20 | CH18: CMI_Trend_38 | CI18: CMI_Trend_38 | CJ18: CMI_Trend_20 | CK18: CMI_Trend_56 | CL18: CMI_Trend_46 | CM18: CMI_Trend_20 | CN18: CMI_Trend_46 | CO18: CMI_Trend_52 | CP18: CMI_Trend_60 | CQ18: CMI_Trend_46 | CR18: CMI_Trend_20 | CS18: CMI_Trend_52 | CT18: CMI_Trend_52 | CU18: CMI_Trend_20 | CV18: CMI_Trend_60 | CW18: CMI_Trend_20 | CX18: CMI_Trend_25 | CY18: CMI_Trend_46 | CZ18: CMI_Trend_60 | DA18: CMI_Trend_46 | DB18: CMI_Trend_25 | DC18: CMI_Trend_38 | DD18: CMI_Trend_60
B19: Computer Vision Software | C19: 0.081608 | D19: 0.072408 | E19: 0.076608 | F19: 0.070208 | G19: 0.091908 | H19: 0.081308 | I19: 0.093308 | J19: 0.089208 | K19: 0.092708 | L19: 0.076008 | M19: 0.085908 | N19: 0.075608 | O19: 0.092508 | P19: 0.073708 | Q19: 0.093008 | R19: 0.073308 | S19: 0.092608 | T19: 0.071108 | U19: 0.092008 | V19: 0.086308 | W19: 0.078908 | X19: 0.072308 | Y19: 0.086608 | Z19: 0.090808 | AA19: 0.089608 | AB19: 0.073708 | AC19: 0.071008 | AD19: 0.085608 | AE19: 0.088308 | AF19: 0.084808 | AG19: 0.082308 | AH19: 0.086308 | AI19: 0.089708 | AJ19: 0.083508 | AL19: Computer Vision Software | AM19: 0.14496433 | AN19: 0.14382477 | AO19: 0.1495533 | AP19: 0.1473028 | AQ19: 0.14562969 | AR19: 0.14658798 | AS19: 0.14624534 | AT19: 0.09561598 | AU19: 0.14719206 | AV19: 0.14401802 | AW19: 0.14548325 | AX19: 0.14705427 | AY19: 0.1161991 | AZ19: 0.1083586 | BA19: 0.14441201 | BB19: 0.14451758 | BC19: 0.14868905 | BD19: 0.1492464 | BE19: 0.14907287 | BF19: 0.14920592 | BG19: 0.14918673 | BH19: 0.14813706 | BI19: 0.1510619 | BJ19: 0.14678905 | BK19: 0.14452982 | BL19: 0.14698356 | BM19: 0.14788891 | BN19: 0.14858186 | BO19: 0.14464793 | BP19: 0.14772001 | BQ19: 0.1438377 | BR19: 0.15056252 | BS19: 0.14625069 | BT19: 0.14613451 | BV19: Computer Vision Software | BW19: CMI_Trend_56 | BX19: CMI_Trend_20 | BY19: CMI_Trend_25 | BZ19: CMI_Trend_25 | CA19: CMI_Trend_52 | CB19: CMI_Trend_52 | CC19: CMI_Trend_60 | CD19: CMI_Trend_56 | CE19: CMI_Trend_25 | CF19: CMI_Trend_56 | CG19: CMI_Trend_25 | CH19: CMI_Trend_25 | CI19: CMI_Trend_38 | CJ19: CMI_Trend_38 | CK19: CMI_Trend_25 | CL19: CMI_Trend_56 | CM19: CMI_Trend_25 | CN19: CMI_Trend_56 | CO19: CMI_Trend_46 | CP19: CMI_Trend_38 | CQ19: CMI_Trend_25 | CR19: CMI_Trend_60 | CS19: CMI_Trend_25 | CT19: CMI_Trend_46 | CU19: CMI_Trend_25 | CV19: CMI_Trend_46 | CW19: CMI_Trend_52 | CX19: CMI_Trend_56 | CY19: CMI_Trend_60 | CZ19: CMI_Trend_56 | DA19: CMI_Trend_56 | DB19: CMI_Trend_46 | DC19: CMI_Trend_56 | DD19: CMI_Trend_52
B20: POS & Payment Integration Software | C20: 0.27722772 | D20: 0.28582772 | E20: 0.28112772 | F20: 0.29432772 | G20: 0.28732772 | H20: 0.26172772 | I20: 0.27132772 | J20: 0.28042772 | K20: 0.28392772 | L20: 0.26252772 | M20: 0.26772772 | N20: 0.28372772 | O20: 0.28152772 | P20: 0.29192772 | Q20: 0.27582772 | R20: 0.28782772 | S20: 0.28662772 | T20: 0.27572772 | U20: 0.28932772 | V20: 0.27752772 | W20: 0.27652772 | X20: 0.28212772 | Y20: 0.28232772 | Z20: 0.27652772 | AA20: 0.26212772 | AB20: 0.26672772 | AC20: 0.27532772 | AD20: 0.28482772 | AE20: 0.27832772 | AF20: 0.26382772 | AG20: 0.28062772 | AH20: 0.29332772 | AI20: 0.29342772 | AJ20: 0.26662772 | AL20: POS & Payment Integration Software | AM20: 0.12923915 | AN20: 0.12728918 | AO20: 0.13629787 | AP20: 0.13482307 | AQ20: 0.12659582 | AR20: 0.13306341 | AS20: 0.12954272 | AT20: 0.075801339 | AU20: 0.1331127 | AV20: 0.1296528 | AW20: 0.13037771 | AX20: 0.12877041 | AY20: 0.095982143 | AZ20: 0.086668108 | BA20: 0.12702424 | BB20: 0.1287924 | BC20: 0.13633412 | BD20: 0.13585707 | BE20: 0.13456255 | BF20: 0.13621427 | BG20: 0.13645361 | BH20: 0.13447587 | BI20: 0.13767257 | BJ20: 0.1327097 | BK20: 0.12987292 | BL20: 0.13187801 | BM20: 0.13184445 | BN20: 0.13478268 | BO20: 0.12892275 | BP20: 0.13335478 | BQ20: 0.1291808 | BR20: 0.13703794 | BS20: 0.13144575 | BT20: 0.13219595 | BV20: POS & Payment Integration Software | BW20: CMI_Trend_20 | BX20: CMI_Trend_56 | BY20: CMI_Trend_60 | BZ20: CMI_Trend_56 | CA20: CMI_Trend_20 | CB20: CMI_Trend_38 | CC20: CMI_Trend_56 | CD20: CMI_Trend_56 | CE20: CMI_Trend_56 | CF20: CMI_Trend_38 | CG20: CMI_Trend_38 | CH20: CMI_Trend_20 | CI20: CMI_Trend_46 | CJ20: CMI_Trend_52 | CK20: CMI_Trend_52 | CL20: CMI_Trend_60 | CM20: CMI_Trend_38 | CN20: CMI_Trend_38 | CO20: CMI_Trend_20 | CP20: CMI_Trend_20 | CQ20: CMI_Trend_52 | CR20: CMI_Trend_38 | CS20: CMI_Trend_60 | CT20: CMI_Trend_56 | CU20: CMI_Trend_46 | CV20: CMI_Trend_56 | CW20: CMI_Trend_38 | CX20: CMI_Trend_56 | CY20: CMI_Trend_52 | CZ20: CMI_Trend_38 | DA20: CMI_Trend_20 | DB20: CMI_Trend_20 | DC20: CMI_Trend_56 | DD20: CMI_Trend_52
B21: Store Operations & Workflow Software | C21: 0.21782178 | D21: 0.21702178 | E21: 0.21672178 | F21: 0.21882178 | G21: 0.22262178 | H21: 0.22382178 | I21: 0.21282178 | J21: 0.23102178 | K21: 0.21792178 | L21: 0.20472178 | M21: 0.22862178 | N21: 0.21212178 | O21: 0.20252178 | P21: 0.21102178 | Q21: 0.22712178 | R21: 0.20742178 | S21: 0.22482178 | T21: 0.22092178 | U21: 0.21362178 | V21: 0.22612178 | W21: 0.20412178 | X21: 0.22202178 | Y21: 0.21962178 | Z21: 0.20352178 | AA21: 0.21452178 | AB21: 0.22582178 | AC21: 0.23192178 | AD21: 0.21412178 | AE21: 0.22712178 | AF21: 0.20672178 | AG21: 0.22232178 | AH21: 0.20422178 | AI21: 0.21932178 | AJ21: 0.22522178 | AL21: Store Operations & Workflow Software | AM21: 0.13658156 | AN21: 0.13500999 | AO21: 0.1424871 | AP21: 0.14065011 | AQ21: 0.13548312 | AR21: 0.13937831 | AS21: 0.13734152 | AT21: 0.085053201 | AU21: 0.13968664 | AV21: 0.13636022 | AW21: 0.1374308 | AX21: 0.13730752 | AY21: 0.10542185 | AZ21: 0.096795844 | BA21: 0.13514295 | BB21: 0.13613481 | BC21: 0.14210289 | BD21: 0.14210882 | BE21: 0.14133772 | BF21: 0.14228034 | BG21: 0.14239896 | BH21: 0.14085456 | BI21: 0.14392433 | BJ21: 0.13928364 | BK21: 0.13671653 | BL21: 0.1389311 | BM21: 0.13933594 | BN21: 0.1412258 | BO21: 0.13626516 | BP21: 0.1400622 | BQ21: 0.13602441 | BR21: 0.14335284 | BS21: 0.13835848 | BT21: 0.13870415 | BV21: Store Operations & Workflow Software | BW21: CMI_Trend_38 | BX21: CMI_Trend_52 | BY21: CMI_Trend_20 | BZ21: CMI_Trend_60 | CA21: CMI_Trend_25 | CB21: CMI_Trend_25 | CC21: CMI_Trend_46 | CD21: CMI_Trend_60 | CE21: CMI_Trend_52 | CF21: CMI_Trend_56 | CG21: CMI_Trend_56 | CH21: CMI_Trend_20 | CI21: CMI_Trend_38 | CJ21: CMI_Trend_60 | CK21: CMI_Trend_56 | CL21: CMI_Trend_52 | CM21: CMI_Trend_25 | CN21: CMI_Trend_25 | CO21: CMI_Trend_25 | CP21: CMI_Trend_25 | CQ21: CMI_Trend_38 | CR21: CMI_Trend_60 | CS21: CMI_Trend_20 | CT21: CMI_Trend_25 | CU21: CMI_Trend_60 | CV21: CMI_Trend_20 | CW21: CMI_Trend_60 | CX21: CMI_Trend_56 | CY21: CMI_Trend_20 | CZ21: CMI_Trend_56 | DA21: CMI_Trend_52 | DB21: CMI_Trend_52 | DC21: CMI_Trend_52 | DD21: CMI_Trend_60
B22: Others (Analytics & Dashboard Software, etc.) | C22: 0.10510101 | D22: 0.10050101 | E22: 0.10740101 | F22: 0.10890101 | G22: 0.11450101 | H22: 0.10610101 | I22: 0.10040101 | J22: 0.11360101 | K22: 0.094301005 | L22: 0.11120101 | M22: 0.10080101 | N22: 0.11980101 | O22: 0.094501005 | P22: 0.10390101 | Q22: 0.10130101 | R22: 0.10250101 | S22: 0.091401005 | T22: 0.11410101 | U22: 0.093001005 | V22: 0.095001005 | W22: 0.10500101 | X22: 0.10510101 | Y22: 0.10250101 | Z22: 0.12050101 | AA22: 0.12070101 | AB22: 0.10880101 | AC22: 0.090101005 | AD22: 0.11230101 | AE22: 0.11730101 | AF22: 0.096901005 | AG22: 0.10490101 | AH22: 0.11300101 | AI22: 0.11740101 | AJ22: 0.10690101 | AL22: Others (Analytics & Dashboard Software, etc.) | AM22: 0.11943911 | AN22: 0.11698409 | AO22: 0.128037 | AP22: 0.12704562 | AQ22: 0.11473379 | AR22: 0.12463481 | AS22: 0.11913355 | AT22: 0.063452728 | AU22: 0.12433836 | AV22: 0.1207003 | AW22: 0.12096383 | AX22: 0.1173758 | AY22: 0.083382804 | AZ22: 0.073150452 | BA22: 0.11618808 | BB22: 0.11899236 | BC22: 0.12863445 | BD22: 0.12751276 | BE22: 0.12551962 | BF22: 0.12811779 | BG22: 0.12851825 | BH22: 0.12596214 | BI22: 0.12932826 | BJ22: 0.12393535 | BK22: 0.12073865 | BL22: 0.12246414 | BM22: 0.12184543 | BN22: 0.12618294 | BO22: 0.11912272 | BP22: 0.12440228 | BQ22: 0.12004653 | BR22: 0.12860934 | BS22: 0.12221921 | BT22: 0.12350935 | BV22: Others (Analytics & Dashboard Software, etc.) | BW22: CMI_Trend_46 | BX22: CMI_Trend_60 | BY22: CMI_Trend_60 | BZ22: CMI_Trend_38 | CA22: CMI_Trend_25 | CB22: CMI_Trend_52 | CC22: CMI_Trend_46 | CD22: CMI_Trend_25 | CE22: CMI_Trend_25 | CF22: CMI_Trend_52 | CG22: CMI_Trend_56 | CH22: CMI_Trend_25 | CI22: CMI_Trend_38 | CJ22: CMI_Trend_20 | CK22: CMI_Trend_56 | CL22: CMI_Trend_46 | CM22: CMI_Trend_60 | CN22: CMI_Trend_25 | CO22: CMI_Trend_56 | CP22: CMI_Trend_60 | CQ22: CMI_Trend_56 | CR22: CMI_Trend_60 | CS22: CMI_Trend_46 | CT22: CMI_Trend_60 | CU22: CMI_Trend_20 | CV22: CMI_Trend_56 | CW22: CMI_Trend_52 | CX22: CMI_Trend_56 | CY22: CMI_Trend_38 | CZ22: CMI_Trend_52 | DA22: CMI_Trend_46 | DB22: CMI_Trend_20 | DC22: CMI_Trend_25 | DD22: CMI_Trend_60
A23: 0.99 | B23: Services | C23: 0.32572284 | D23: 0.31545272 | E23: 0.31007314 | F23: 0.34601855 | G23: 0.34125028 | H23: 0.3175312 | I23: 0.33464806 | J23: 0.32462247 | K23: 0.33159148 | L23: 0.32474473 | M23: 0.30457129 | N23: 0.31007314 | O23: 0.32975753 | P23: 0.33880501 | Q23: 0.33635975 | R23: 0.31912062 | S23: 0.32437794 | T23: 0.30481582 | U23: 0.30689429 | V23: 0.31312972 | W23: 0.30750561 | X23: 0.32792358 | Y23: 0.33330317 | Z23: 0.32205494 | AA23: 0.33868275 | AB23: 0.31374104 | AC23: 0.30065886 | AD23: 0.31679762 | AE23: 0.34076123 | AF23: 0.30836145 | AG23: 0.31679762 | AH23: 0.30713882 | AI23: 0.32144363 | AJ23: 0.33953859 | AL23: Services | AM23: =SUMPRODUCT(AM24:AM25,C24:C25) -> 0.13833864 | AN23: =((((((((((((((SUMPRODUCT(AN24:AN25,D24:D25))*0.99)*0.99)*0.99)*0.99)*0.99)*0.99)*0.99)*0.99)*0.99)*0.99)*0.99)*0.99)*0.99)*0.99 -> 0.11873169 | AO23: =((((((((((SUMPRODUCT(AO24:AO25,E24:E25))*0.99)*0.99)*0.99)*0.99)*0.99)*0.99)/0.99)/0.99)/0.99)/0.99 -> 0.14127576 | AP23: =((((((((((((((((SUMPRODUCT(AP24:AP25,F24:F25))*0.99)*0.99)*0.99)*0.99)*0.99)*0.99)*0.99)*0.99)*0.99)/0.99)/0.99)/0.99)/0.99)*0.99)*0.99)*0.99 -> 0.13104359 | AQ23: =SUMPRODUCT(AQ24:AQ25,G24:G25) -> 0.13776606 | AR23: =SUMPRODUCT(AR24:AR25,H24:H25) -> 0.14105422 | AS23: =((((((((SUMPRODUCT(AS24:AS25,I24:I25))*0.99)*0.99)*0.99)*0.99)/0.99)/0.99)/0.99)*0.99 -> 0.13628944 | AT23: =(((((((((((((((((((((SUMPRODUCT(AT24:AT25,J24:J25))/0.99)/0.99)/0.99)/0.99)/0.99)/0.99)/0.99)/0.99)/0.99)/0.99)/0.99)/0.99)/0.99)/0.99)/0.99)/0.99)/0.99)/0.99)/0.99)/0.99)/0.99 -> 0.10773421 | AU23: =((((SUMPRODUCT(AU24:AU25,K24:K25))/0.99)/0.99)/0.99)/0.99 -> 0.14701345 | AV23: =((((((SUMPRODUCT(AV24:AV25,L24:L25))/0.99)/0.99)/0.99)/0.99)/0.99)/0.99 -> 0.14668027 | AW23: =(((((((((((SUMPRODUCT(AW24:AW25,M24:M25))/0.99)/0.99)/0.99)/0.99)/0.99)/0.99)/0.99)/0.99)/0.99)/0.99)/0.99 -> 0.15561511 | AX23: =((((((((((((((SUMPRODUCT(AX24:AX25,N24:N25))*0.99)*0.99)*0.99)*0.99)*0.99)*0.99)*0.99)*0.99)/0.99)/0.99)/0.99)/0.99)/0.99)*0.99 -> 0.13366049 | AY23: =((((((((((SUMPRODUCT(AY24:AY25,O24:O25))/0.99)/0.99)/0.99)/0.99)/0.99)/0.99)/0.99)/0.99)*0.99)*0.99 -> 0.11459374 | AZ23: =(((((((((((((SUMPRODUCT(AZ24:AZ25,P24:P25))/0.99)/0.99)/0.99)/0.99)/0.99)/0.99)/0.99)/0.99)/0.99)/0.99)/0.99)/0.99)/0.99 -> 0.11327906 | BA23: =(((((((((SUMPRODUCT(BA24:BA25,Q24:Q25))*0.99)*0.99)*0.99)*0.99)*0.99)*0.99)*0.99)*0.99)*0.99 -> 0.12528264 | BB23: =SUMPRODUCT(BB24:BB25,R24:R25) -> 0.13806213 | BC23: =(((((((((((((((((SUMPRODUCT(BC24:BC25,S24:S25))*0.99)*0.99)*0.99)*0.99)*0.99)*0.99)*0.99)*0.99)*0.99)*0.99)/0.99)/0.99)/0.99)/0.99)/0.99)/0.99)/0.99 -> 0.13926438 | BD23: =(((((((((SUMPRODUCT(BD24:BD25,T24:T25))*0.99)/0.99)/0.99)/0.99)/0.99)/0.99)/0.99)/0.99)*0.99 -> 0.15097116 | BE23: =(((((((SUMPRODUCT(BE24:BE25,U24:U25))/0.99)/0.99)/0.99)/0.99)/0.99)/0.99)/0.99 -> 0.15339328 | BF23: =(((((((((SUMPRODUCT(BF24:BF25,V24:V25))/0.99)/0.99)/0.99)/0.99)/0.99)/0.99)*0.99)*0.99)*0.99 -> 0.14813844 | BG23: =(((SUMPRODUCT(BG24:BG25,W24:W25))/0.99)/0.99)*0.99 -> 0.14535714 | BH23: =(((((SUMPRODUCT(BH24:BH25,X24:X25))/0.99)/0.99)/0.99)*0.99)*0.99 -> 0.1436885 | BI23: =(((((SUMPRODUCT(BI24:BI25,Y24:Y25))/0.99)/0.99)/0.99)/0.99)/0.99 -> 0.15273971 | BJ23: =(((((((((((SUMPRODUCT(BJ24:BJ25,Z24:Z25))*0.99)*0.99)*0.99)*0.99)*0.99)*0.99)*0.99)*0.99)*0.99)*0.99)*0.99 -> 0.12626269 | BK23: =((((((((SUMPRODUCT(BK24:BK25,AA24:AA25))/0.99)/0.99)/0.99)/0.99)/0.99)/0.99)/0.99)/0.99 -> 0.14986922 | BL23: =(((((((((((SUMPRODUCT(BL24:BL25,AB24:AB25))/0.99)/0.99)/0.99)/0.99)/0.99)/0.99)/0.99)/0.99)/0.99)/0.99)/0.99 -> 0.15704252 | BM23: =((SUMPRODUCT(BM24:BM25,AC24:AC25))/0.99)/0.99 -> 0.14399834 | BN23: =((SUMPRODUCT(BN24:BN25,AD24:AD25))/0.99)/0.99 -> 0.14577837 | BO23: =SUMPRODUCT(BO24:BO25,AE24:AE25) -> 0.13781477 | BP23: =((((((((((((SUMPRODUCT(BP24:BP25,AF24:AF25))/0.99)/0.99)/0.99)/0.99)/0.99)/0.99)/0.99)/0.99)/0.99)*0.99)*0.99)*0.99 -> 0.15031813 | BQ23: =((((((((SUMPRODUCT(BQ24:BQ25,AG24:AG25))/0.99)/0.99)/0.99)/0.99)/0.99)/0.99)/0.99)/0.99 -> 0.14939186 | BR23: =SUMPRODUCT(BR24:BR25,AH24:AH25) -> 0.1447405 | BS23: =(((((((((SUMPRODUCT(BS24:BS25,AI24:AI25))/0.99)/0.99)/0.99)/0.99)/0.99)/0.99)/0.99)/0.99)/0.99 -> 0.15316907 | BT23: =(((SUMPRODUCT(BT24:BT25,AJ24:AJ25))/0.99)/0.99)/0.99 -> 0.14460485 | BV23: Services | BW23: CMI_Trend_38 | BX23: CMI_Trend_52 | BY23: CMI_Trend_38 | BZ23: CMI_Trend_20 | CA23: CMI_Trend_20 | CB23: CMI_Trend_20 | CC23: CMI_Trend_46 | CD23: CMI_Trend_52 | CE23: CMI_Trend_56 | CF23: CMI_Trend_25 | CG23: CMI_Trend_46 | CH23: CMI_Trend_46 | CI23: CMI_Trend_20 | CJ23: CMI_Trend_38 | CK23: CMI_Trend_52 | CL23: CMI_Trend_52 | CM23: CMI_Trend_38 | CN23: CMI_Trend_38 | CO23: CMI_Trend_52 | CP23: CMI_Trend_38 | CQ23: CMI_Trend_52 | CR23: CMI_Trend_25 | CS23: CMI_Trend_46 | CT23: CMI_Trend_60 | CU23: CMI_Trend_60 | CV23: CMI_Trend_38 | CW23: CMI_Trend_60 | CX23: CMI_Trend_20 | CY23: CMI_Trend_46 | CZ23: CMI_Trend_25 | DA23: CMI_Trend_25 | DB23: CMI_Trend_56 | DC23: CMI_Trend_38 | DD23: CMI_Trend_52
B24: Managed Services | C24: 0.57425743 | D24: 0.56085743 | E24: 0.58995743 | F24: 0.57145743 | G24: 0.58395743 | H24: 0.58865743 | I24: 0.56355743 | J24: 0.57235743 | K24: 0.57095743 | L24: 0.58505743 | M24: 0.59065743 | N24: 0.56085743 | O24: 0.58635743 | P24: 0.58435743 | Q24: 0.57815743 | R24: 0.58705743 | S24: 0.57845743 | T24: 0.57135743 | U24: 0.57535743 | V24: 0.57485743 | W24: 0.58185743 | X24: 0.56305743 | Y24: 0.55955743 | Z24: 0.58815743 | AA24: 0.56915743 | AB24: 0.57325743 | AC24: 0.57455743 | AD24: 0.58365743 | AE24: 0.55865743 | AF24: 0.56225743 | AG24: 0.58945743 | AH24: 0.56345743 | AI24: 0.56705743 | AJ24: 0.57835743 | AL24: Managed Services | AM24: 0.14400086 | AN24: 0.14281164 | AO24: 0.14874115 | AP24: 0.14653817 | AQ24: 0.14446349 | AR24: 0.14575934 | AS24: 0.14522198 | AT24: 0.094401949 | AU24: 0.14632943 | AV24: 0.14313788 | AW24: 0.14455775 | AX24: 0.14593403 | AY24: 0.11496042 | AZ24: 0.10702964 | BA24: 0.14334667 | BB24: 0.14355411 | BC24: 0.14793207 | BD24: 0.14842604 | BE24: 0.14818384 | BF24: 0.14840993 | BG24: 0.14840658 | BH24: 0.14730005 | BI24: 0.15024155 | BJ24: 0.14592642 | BK24: 0.1436318 | BL24: 0.14605805 | BM24: 0.14690588 | BN24: 0.14773639 | BO24: 0.14368446 | BP24: 0.14683986 | BQ24: 0.14293968 | BR24: 0.14973387 | BS24: 0.1453436 | BT24: 0.14528051 | BV24: Managed Services | BW24: CMI_Trend_60 | BX24: CMI_Trend_52 | BY24: CMI_Trend_46 | BZ24: CMI_Trend_60 | CA24: CMI_Trend_46 | CB24: CMI_Trend_56 | CC24: CMI_Trend_60 | CD24: CMI_Trend_60 | CE24: CMI_Trend_56 | CF24: CMI_Trend_25 | CG24: CMI_Trend_60 | CH24: CMI_Trend_60 | CI24: CMI_Trend_25 | CJ24: CMI_Trend_38 | CK24: CMI_Trend_46 | CL24: CMI_Trend_38 | CM24: CMI_Trend_46 | CN24: CMI_Trend_25 | CO24: CMI_Trend_52 | CP24: CMI_Trend_60 | CQ24: CMI_Trend_60 | CR24: CMI_Trend_60 | CS24: CMI_Trend_25 | CT24: CMI_Trend_52 | CU24: CMI_Trend_20 | CV24: CMI_Trend_60 | CW24: CMI_Trend_38 | CX24: CMI_Trend_60 | CY24: CMI_Trend_20 | CZ24: CMI_Trend_56 | DA24: CMI_Trend_20 | DB24: CMI_Trend_52 | DC24: CMI_Trend_60 | DD24: CMI_Trend_25
B25: Professional Services | C25: =1-C24 -> 0.42574257 | D25: =1-D24 -> 0.43914257 | E25: =1-E24 -> 0.41004257 | F25: =1-F24 -> 0.42854257 | G25: =1-G24 -> 0.41604257 | H25: =1-H24 -> 0.41134257 | I25: =1-I24 -> 0.43644257 | J25: =1-J24 -> 0.42764257 | ... AJ25: =1-AJ24 -> 0.42164257 | AL25: Professional Services | AM25: 0.13070124 | AN25: 0.12882662 | AO25: 0.13753033 | AP25: 0.1359834 | AQ25: 0.12836554 | AR25: 0.13432089 | AS25: 0.13109569 | AT25: 0.077643657 | AU25: 0.13442177 | AV25: 0.13098844 | AW25: 0.13178218 | AX25: 0.1304704 | AY25: 0.097861866 | AZ25: 0.088684838 | BA25: 0.12864091 | BB25: 0.13025449 | BC25: 0.13748285 | BD25: 0.13710198 | BE25: 0.13591168 | BF25: 0.1374222 | BG25: 0.1376375 | BH25: 0.13574606 | BI25: 0.13891748 | BJ25: 0.13401876 | BK25: 0.13123569 | BL25: 0.13328249 | BM25: 0.13333622 | BN25: 0.13606569 | BO25: 0.13038484 | BP25: 0.13469043 | BQ25: 0.13054357 | BR25: 0.13829542 | BS25: 0.13282228 | BT25: 0.13349193 | BV25: Professional Services | BW25: CMI_Trend_38 | BX25: CMI_Trend_56 | BY25: CMI_Trend_38 | BZ25: CMI_Trend_52 | CA25: CMI_Trend_38 | CB25: CMI_Trend_60 | CC25: CMI_Trend_46 | CD25: CMI_Trend_25 | CE25: CMI_Trend_60 | CF25: CMI_Trend_38 | CG25: CMI_Trend_56 | CH25: CMI_Trend_52 | CI25: CMI_Trend_20 | CJ25: CMI_Trend_60 | CK25: CMI_Trend_52 | CL25: CMI_Trend_60 | CM25: CMI_Trend_46 | CN25: CMI_Trend_52 | CO25: CMI_Trend_46 | CP25: CMI_Trend_60 | CQ25: CMI_Trend_46 | CR25: CMI_Trend_56 | CS25: CMI_Trend_20 | CT25: CMI_Trend_46 | CU25: CMI_Trend_52 | CV25: CMI_Trend_25 | CW25: CMI_Trend_46 | CX25: CMI_Trend_60 | CY25: CMI_Trend_25 | CZ25: CMI_Trend_52 | DA25: CMI_Trend_52 | DB25: CMI_Trend_60 | DC25: CMI_Trend_46 | DD25: CMI_Trend_60
AY26: =AY4-AY2 -> 2.8928821e-05 | AZ26: =AZ4-AZ2 -> -1.5372824e-05
B27: By Product Type | AL27: By Product Type | BV27: By Product Type
B28: Fixed-Position Self-Scanning Kiosks | C28: =C55 -> 0.8676332 | D28: =D55 -> 0.8811332 | E28: =E55 -> 0.8727332 | F28: =F55 -> 0.8764332 | G28: =G55 -> 0.8517332 | H28: =H55 -> 0.8803332 | I28: =I55 -> 0.8671332 | J28: =J55 -> 0.8523332 | ... AJ28: =AJ55 -> 0.8774332 | AL28: Fixed-Position Self-Scanning Kiosks | AM28: =SUMPRODUCT(AM29:AM31,C29:C31) -> 0.11499798 | AN28: =SUMPRODUCT(AN29:AN31,D29:D31) -> 0.10754378 | AO28: =SUMPRODUCT(AO29:AO31,E29:E31) -> 0.14755071 | AP28: =SUMPRODUCT(AP29:AP31,F29:F31) -> 0.15643188 | AQ28: =SUMPRODUCT(AQ29:AQ31,G29:G31) -> 0.089225007 | AR28: =SUMPRODUCT(AR29:AR31,H29:H31) -> 0.1412737 | AS28: =SUMPRODUCT(AS29:AS31,I29:I31) -> 0.10818509 | AT28: =SUMPRODUCT(AT29:AT31,J29:J31) -> 0.068624908 | ... BT28: =SUMPRODUCT(BT29:BT31,AJ29:AJ31) -> 0.13614676 | BV28: Fixed-Position Self-Scanning Kiosks | BW28: CMI_Trend_52 | BX28: CMI_Trend_52 | BY28: CMI_Trend_56 | BZ28: CMI_Trend_56 | CA28: CMI_Trend_20 | CB28: CMI_Trend_46 | CC28: CMI_Trend_20 | CD28: CMI_Trend_52 | CE28: CMI_Trend_52 | CF28: CMI_Trend_56 | CG28: CMI_Trend_56 | CH28: CMI_Trend_56 | CI28: CMI_Trend_25 | CJ28: CMI_Trend_38 | CK28: CMI_Trend_46 | CL28: CMI_Trend_20 | CM28: CMI_Trend_56 | CN28: CMI_Trend_52 | CO28: CMI_Trend_25 | CP28: CMI_Trend_52 | CQ28: CMI_Trend_25 | CR28: CMI_Trend_20 | CS28: CMI_Trend_46 | CT28: CMI_Trend_20 | CU28: CMI_Trend_38 | CV28: CMI_Trend_38 | CW28: CMI_Trend_52 | CX28: CMI_Trend_25 | CY28: CMI_Trend_38 | CZ28: CMI_Trend_60 | DA28: CMI_Trend_20 | DB28: CMI_Trend_25 | DC28: CMI_Trend_38 | DD28: CMI_Trend_25
B29: Single-Plane Self-Scanning Kiosks | C29: 0.37799855 | D29: 0.36609855 | E29: 0.36199855 | F29: 0.38649855 | G29: 0.36679855 | H29: 0.37899855 | I29: 0.38259855 | J29: 0.36959855 | K29: 0.39509855 | L29: 0.39329855 | M29: 0.37209855 | N29: 0.37969855 | O29: 0.38099855 | P29: 0.36589855 | Q29: 0.37049855 | R29: 0.37189855 | S29: 0.36239855 | T29: 0.38409855 | U29: 0.37239855 | V29: 0.36289855 | W29: 0.37399855 | X29: 0.37499855 | Y29: 0.38049855 | Z29: 0.37649855 | AA29: 0.36769855 | AB29: 0.38049855 | AC29: 0.36809855 | AD29: 0.37019855 | AE29: 0.36419855 | AF29: 0.39009855 | AG29: 0.37399855 | AH29: 0.38859855 | AI29: 0.37639855 | AJ29: 0.39249855 | AL29: Single-Plane Self-Scanning Kiosks | AM29: 0.10635961 | AN29: 0.098786495 | AO29: 0.13873346 | AP29: 0.14798896 | AQ29: 0.080544311 | AR29: 0.13258846 | AS29: 0.099703867 | AT29: 0.060003192 | AU29: 0.12592559 | AV29: 0.12032184 | AW29: 0.11294171 | AX29: 0.087029482 | AY29: 0.074651209 | AZ29: 0.067457257 | BA29: 0.092631885 | BB29: 0.10500642 | BC29: 0.1509951 | BD29: 0.13588581 | BE29: 0.12077089 | BF29: 0.14233556 | BG29: 0.14549158 | BH29: 0.13087737 | BI29: 0.13837216 | BJ29: 0.125084 | BK29: 0.11794724 | BL29: 0.11443059 | BM29: 0.1040472 | BN29: 0.13065751 | BO29: 0.10650458 | BP29: 0.12228706 | BQ29: 0.11656502 | BR29: 0.13465397 | BS29: 0.11649277 | BT29: 0.12762544 | BV29: Single-Plane Self-Scanning Kiosks | BW29: CMI_Trend_38 | BX29: CMI_Trend_20 | BY29: CMI_Trend_38 | BZ29: CMI_Trend_52 | CA29: CMI_Trend_60 | CB29: CMI_Trend_20 | CC29: CMI_Trend_38 | CD29: CMI_Trend_60 | CE29: CMI_Trend_25 | CF29: CMI_Trend_56 | CG29: CMI_Trend_56 | CH29: CMI_Trend_56 | CI29: CMI_Trend_38 | CJ29: CMI_Trend_52 | CK29: CMI_Trend_46 | CL29: CMI_Trend_46 | CM29: CMI_Trend_52 | CN29: CMI_Trend_60 | CO29: CMI_Trend_25 | CP29: CMI_Trend_60 | CQ29: CMI_Trend_46 | CR29: CMI_Trend_52 | CS29: CMI_Trend_60 | CT29: CMI_Trend_20 | CU29: CMI_Trend_20 | CV29: CMI_Trend_46 | CW29: CMI_Trend_52 | CX29: CMI_Trend_25 | CY29: CMI_Trend_25 | CZ29: CMI_Trend_46 | DA29: CMI_Trend_25 | DB29: CMI_Trend_60 | DC29: CMI_Trend_25 | DD29: CMI_Trend_20
B30: Multi-Plane Self-Scanning Kiosks | C30: 0.44083482 | D30: 0.44323482 | E30: 0.44653482 | F30: 0.42473482 | G30: 0.43403482 | H30: 0.44803482 | I30: 0.42543482 | J30: 0.42943482 | K30: 0.44533482 | L30: 0.43563482 | M30: 0.43693482 | N30: 0.44813482 | O30: 0.43643482 | P30: 0.42693482 | Q30: 0.44803482 | R30: 0.45133482 | S30: 0.45593482 | T30: 0.42573482 | U30: 0.45803482 | V30: 0.44123482 | W30: 0.42783482 | X30: 0.44843482 | Y30: 0.43083482 | Z30: 0.45183482 | AA30: 0.43173482 | AB30: 0.42543482 | AC30: 0.45713482 | AD30: 0.44473482 | AE30: 0.45653482 | AF30: 0.44933482 | AG30: 0.42663482 | AH30: 0.45083482 | AI30: 0.44093482 | AJ30: 0.44153482 | AL30: Multi-Plane Self-Scanning Kiosks | AM30: 0.12248521 | AN30: 0.1149121 | AO30: 0.15485906 | AP30: 0.16411457 | AQ30: 0.096669917 | AR30: 0.14871406 | AS30: 0.11582947 | AT30: 0.076128798 | AU30: 0.1420512 | AV30: 0.13644745 | AW30: 0.12906731 | AX30: 0.10315509 | AY30: 0.090776816 | AZ30: 0.083582863 | BA30: 0.10875749 | BB30: 0.12113203 | BC30: 0.16712071 | BD30: 0.15201141 | BE30: 0.13689649 | BF30: 0.15846116 | BG30: 0.16161718 | BH30: 0.14700298 | BI30: 0.15449776 | BJ30: 0.14120961 | BK30: 0.13407285 | BL30: 0.1305562 | BM30: 0.12017281 | BN30: 0.14678312 | BO30: 0.12263019 | BP30: 0.13841267 | BQ30: 0.13269063 | BR30: 0.15077957 | BS30: 0.13261838 | BT30: 0.14375105 | BV30: Multi-Plane Self-Scanning Kiosks | BW30: CMI_Trend_52 | BX30: CMI_Trend_20 | BY30: CMI_Trend_38 | BZ30: CMI_Trend_52 | CA30: CMI_Trend_38 | CB30: CMI_Trend_20 | CC30: CMI_Trend_60 | CD30: CMI_Trend_52 | CE30: CMI_Trend_38 | CF30: CMI_Trend_56 | CG30: CMI_Trend_60 | CH30: CMI_Trend_60 | CI30: CMI_Trend_46 | CJ30: CMI_Trend_52 | CK30: CMI_Trend_60 | CL30: CMI_Trend_20 | CM30: CMI_Trend_56 | CN30: CMI_Trend_25 | CO30: CMI_Trend_38 | CP30: CMI_Trend_60 | CQ30: CMI_Trend_60 | CR30: CMI_Trend_38 | CS30: CMI_Trend_52 | CT30: CMI_Trend_56 | CU30: CMI_Trend_38 | CV30: CMI_Trend_20 | CW30: CMI_Trend_56 | CX30: CMI_Trend_20 | CY30: CMI_Trend_38 | CZ30: CMI_Trend_46 | DA30: CMI_Trend_56 | DB30: CMI_Trend_56 | DC30: CMI_Trend_46 | DD30: CMI_Trend_60
B31: Presentation Self-Scanning Kiosks | C31: =1-SUM(C29:C30) -> 0.18116663 | D31: =1-SUM(D29:D30) -> 0.19066663 | E31: =1-SUM(E29:E30) -> 0.19146663 | F31: =1-SUM(F29:F30) -> 0.18876663 | G31: =1-SUM(G29:G30) -> 0.19916663 | H31: =1-SUM(H29:H30) -> 0.17296663 | I31: =1-SUM(I29:I30) -> 0.19196663 | J31: =1-SUM(J29:J30) -> 0.20096663 | ... AJ31: =1-SUM(AJ29:AJ30) -> 0.16596663 | AL31: Presentation Self-Scanning Kiosks | AM31: 0.1148029 | AN31: 0.10722978 | AO31: 0.14717675 | AP31: 0.15643225 | AQ31: 0.088987601 | AR31: 0.14103174 | AS31: 0.10814716 | AT31: 0.068446482 | AU31: 0.13436888 | AV31: 0.12876513 | AW31: 0.121385 | AX31: 0.095472772 | AY31: 0.083094499 | AZ31: 0.075900547 | BA31: 0.10107517 | BB31: 0.11344971 | BC31: 0.15943839 | BD31: 0.14432909 | BE31: 0.12921418 | BF31: 0.15077885 | BG31: 0.15393486 | BH31: 0.13932066 | BI31: 0.14681545 | BJ31: 0.13352729 | BK31: 0.12639053 | BL31: 0.12287388 | BM31: 0.11249049 | BN31: 0.1391008 | BO31: 0.11494787 | BP31: 0.13073035 | BQ31: 0.12500831 | BR31: 0.14309726 | BS31: 0.12493606 | BT31: 0.13606873 | BV31: Presentation Self-Scanning Kiosks | BW31: CMI_Trend_38 | BX31: CMI_Trend_20 | BY31: CMI_Trend_56 | BZ31: CMI_Trend_46 | CA31: CMI_Trend_56 | CB31: CMI_Trend_52 | CC31: CMI_Trend_38 | CD31: CMI_Trend_52 | CE31: CMI_Trend_46 | CF31: CMI_Trend_20 | CG31: CMI_Trend_46 | CH31: CMI_Trend_25 | CI31: CMI_Trend_46 | CJ31: CMI_Trend_20 | CK31: CMI_Trend_38 | CL31: CMI_Trend_52 | CM31: CMI_Trend_38 | CN31: CMI_Trend_60 | CO31: CMI_Trend_60 | CP31: CMI_Trend_20 | CQ31: CMI_Trend_56 | CR31: CMI_Trend_25 | CS31: CMI_Trend_20 | CT31: CMI_Trend_25 | CU31: CMI_Trend_20 | CV31: CMI_Trend_52 | CW31: CMI_Trend_38 | CX31: CMI_Trend_52 | CY31: CMI_Trend_46 | CZ31: CMI_Trend_20 | DA31: CMI_Trend_25 | DB31: CMI_Trend_25 | DC31: CMI_Trend_20 | DD31: CMI_Trend_25
B32: Mobile Self-Scanning Solutions | C32: =C62 -> 0.1323668 | D32: =D62 -> 0.1188668 | E32: =E62 -> 0.1272668 | F32: =F62 -> 0.1235668 | G32: =G62 -> 0.1482668 | H32: =H62 -> 0.1196668 | I32: =I62 -> 0.1328668 | J32: =J62 -> 0.1476668 | ... AJ32: =AJ62 -> 0.1225668 | AL32: Mobile Self-Scanning Solutions | AM32: =SUMPRODUCT(AM33:AM35,C33:C35) -> 0.17203577 | AN32: =SUMPRODUCT(AN33:AN35,D33:D35) -> 0.16446311 | AO32: =SUMPRODUCT(AO33:AO35,E33:E35) -> 0.2047986 | AP32: =SUMPRODUCT(AP33:AP35,F33:F35) -> 0.21293484 | AQ32: =SUMPRODUCT(AQ33:AQ35,G33:G35) -> 0.14635156 | AR32: =SUMPRODUCT(AR33:AR35,H33:H35) -> 0.19806459 | AS32: =SUMPRODUCT(AS33:AS35,I33:I35) -> 0.16559138 | AT32: =SUMPRODUCT(AT33:AT35,J33:J35) -> 0.1258188 | ... BT32: =SUMPRODUCT(BT33:BT35,AJ33:AJ35) -> 0.19289804 | BV32: Mobile Self-Scanning Solutions | BW32: CMI_Trend_46 | BX32: CMI_Trend_52 | BY32: CMI_Trend_46 | BZ32: CMI_Trend_56 | CA32: CMI_Trend_60 | CB32: CMI_Trend_60 | CC32: CMI_Trend_60 | CD32: CMI_Trend_20 | CE32: CMI_Trend_56 | CF32: CMI_Trend_46 | CG32: CMI_Trend_60 | CH32: CMI_Trend_46 | CI32: CMI_Trend_25 | CJ32: CMI_Trend_38 | CK32: CMI_Trend_38 | CL32: CMI_Trend_20 | CM32: CMI_Trend_20 | CN32: CMI_Trend_46 | CO32: CMI_Trend_38 | CP32: CMI_Trend_38 | CQ32: CMI_Trend_46 | CR32: CMI_Trend_56 | CS32: CMI_Trend_56 | CT32: CMI_Trend_46 | CU32: CMI_Trend_60 | CV32: CMI_Trend_52 | CW32: CMI_Trend_25 | CX32: CMI_Trend_56 | CY32: CMI_Trend_60 | CZ32: CMI_Trend_38 | DA32: CMI_Trend_52 | DB32: CMI_Trend_52 | DC32: CMI_Trend_25 | DD32: CMI_Trend_56
