Workbook

Sheet Data
B1: Market Name | C1: Adhesive & Bonding Market
C3: U.S. | D3: Canada | E3: Germany | F3: U.K. | G3: France | H3: Italy | I3: Spain | J3: Russia | K3: Rest of Europe | L3: China | M3: India | N3: Japan | O3: South Korea | P3: ASEAN | Q3: Australia | R3: Rest of Asia Pacific | S3: Brazil | T3: Mexico | U3: Argentina | V3: Rest of Latin America | W3: Israel | X3: GCC | Y3: Rest of Middle East | Z3: North Africa | AA3: Central Africa | AB3: South Africa | AE3: U.S. | AF3: Canada | AG3: Germany | AH3: U.K. | AI3: France | AJ3: Italy | AK3: Spain | AL3: Russia | AM3: Rest of Europe | AN3: China | AO3: India | AP3: Japan | AQ3: South Korea | AR3: ASEAN | AS3: Australia | AT3: Rest of Asia Pacific | AU3: Brazil | AV3: Mexico | AW3: Argentina | AX3: Rest of Latin America | AY3: Israel | AZ3: GCC | BA3: Rest of Middle East | BB3: North Africa | BC3: Central Africa | BD3: South Africa | BG3: U.S. | BH3: Canada | BI3: Germany | BJ3: U.K. | BK3: France | BL3: Italy | BM3: Spain | BN3: Russia | BO3: Rest of Europe | BP3: China | BQ3: India | BR3: Japan | BS3: South Korea | BT3: ASEAN | BU3: Australia | BV3: Rest of Asia Pacific | BW3: Brazil | BX3: Mexico | BY3: Argentina | BZ3: Rest of Latin America | CA3: Israel | CB3: GCC | CC3: Rest of Middle East | CD3: North Africa | CE3: Central Africa | CF3: South Africa
B4: By Resin / Chemistry Type | AD4: By Resin / Chemistry Type | BF4: By Resin / Chemistry Type
B5: Acrylic Adhesives | C5: 0.1744 | D5: 0.1634 | E5: 0.1918 | F5: 0.1743 | G5: 0.167 | H5: 0.1577 | I5: 0.1661 | J5: 0.1701 | K5: 0.188 | L5: 0.159 | M5: 0.1909 | N5: 0.1722 | O5: 0.1731 | P5: 0.1851 | Q5: 0.1684 | R5: 0.1894 | S5: 0.1679 | T5: 0.1856 | U5: 0.1815 | V5: 0.1853 | W5: 0.1715 | X5: 0.1772 | Y5: 0.1811 | Z5: 0.1584 | AA5: 0.1639 | AB5: 0.1706 | AD5: Acrylic Adhesives | AE5: 0.063279557 | AF5: 0.054070821 | AG5: 0.061900465 | AH5: 0.056174979 | AI5: 0.051560374 | AJ5: 0.046957918 | AK5: 0.041192438 | AL5: 0.029657602 | AM5: 0.034102058 | AN5: 0.082483545 | AO5: 0.095068407 | AP5: 0.066322413 | AQ5: 0.073392174 | AR5: 0.087387129 | AS5: 0.055924192 | AT5: 0.059173724 | AU5: 0.074382845 | AV5: 0.0668494 | AW5: 0.059544124 | AX5: 0.053378589 | AY5: 0.061862162 | AZ5: 0.077551894 | BA5: 0.069064252 | BB5: 0.063767299 | BC5: 0.054577947 | BD5: 0.050623724 | BF5: Acrylic Adhesives | BG5: CMI_Trend_46 | BH5: CMI_Trend_25 | BI5: CMI_Trend_25 | BJ5: CMI_Trend_46 | BK5: CMI_Trend_20 | BL5: CMI_Trend_56 | BM5: CMI_Trend_25 | BN5: CMI_Trend_56 | BO5: CMI_Trend_52 | BP5: CMI_Trend_38 | BQ5: CMI_Trend_52 | BR5: CMI_Trend_56 | BS5: CMI_Trend_25 | BT5: CMI_Trend_56 | BU5: CMI_Trend_52 | BV5: CMI_Trend_38 | BW5: CMI_Trend_20 | BX5: CMI_Trend_46 | BY5: CMI_Trend_25 | BZ5: CMI_Trend_38 | CA5: CMI_Trend_38 | CB5: CMI_Trend_52 | CC5: CMI_Trend_20 | CD5: CMI_Trend_38 | CE5: CMI_Trend_25 | CF5: CMI_Trend_25
B6: Epoxy Adhesives | C6: 0.1687 | D6: 0.1781 | E6: 0.1865 | F6: 0.1754 | G6: 0.1707 | H6: 0.1726 | I6: 0.1741 | J6: 0.1982 | K6: 0.1706 | L6: 0.1764 | M6: 0.1839 | N6: 0.1682 | O6: 0.1768 | P6: 0.1867 | Q6: 0.183 | R6: 0.1798 | S6: 0.1665 | T6: 0.1793 | U6: 0.1972 | V6: 0.186 | W6: 0.1964 | X6: 0.1789 | Y6: 0.1828 | Z6: 0.1753 | AA6: 0.2 | AB6: 0.1769 | AD6: Epoxy Adhesives | AE6: 0.069220151 | AF6: 0.060011415 | AG6: 0.067841059 | AH6: 0.062115573 | AI6: 0.057500968 | AJ6: 0.052898512 | AK6: 0.047133032 | AL6: 0.032568824 | AM6: 0.038751001 | AN6: 0.088424139 | AO6: 0.101009 | AP6: 0.072263007 | AQ6: 0.079332768 | AR6: 0.093327723 | AS6: 0.061864786 | AT6: 0.065114318 | AU6: 0.080323439 | AV6: 0.072789994 | AW6: 0.065484718 | AX6: 0.059319183 | AY6: 0.067802756 | AZ6: 0.083492488 | BA6: 0.075004846 | BB6: 0.069707893 | BC6: 0.060518541 | BD6: 0.056564318 | BF6: Epoxy Adhesives | BG6: CMI_Trend_60 | BH6: CMI_Trend_60 | BI6: CMI_Trend_38 | BJ6: CMI_Trend_52 | BK6: CMI_Trend_56 | BL6: CMI_Trend_20 | BM6: CMI_Trend_46 | BN6: CMI_Trend_46 | BO6: CMI_Trend_25 | BP6: CMI_Trend_56 | BQ6: CMI_Trend_52 | BR6: CMI_Trend_60 | BS6: CMI_Trend_38 | BT6: CMI_Trend_56 | BU6: CMI_Trend_38 | BV6: CMI_Trend_20 | BW6: CMI_Trend_20 | BX6: CMI_Trend_25 | BY6: CMI_Trend_25 | BZ6: CMI_Trend_20 | CA6: CMI_Trend_25 | CB6: CMI_Trend_38 | CC6: CMI_Trend_38 | CD6: CMI_Trend_46 | CE6: CMI_Trend_38 | CF6: CMI_Trend_38
B7: Polyurethane Adhesives | C7: 0.1985 | D7: 0.1694 | E7: 0.1834 | F7: 0.1767 | G7: 0.1807 | H7: 0.1803 | I7: 0.1677 | J7: 0.1678 | K7: 0.1945 | L7: 0.1758 | M7: 0.17 | N7: 0.179 | O7: 0.1678 | P7: 0.1742 | Q7: 0.1989 | R7: 0.1963 | S7: 0.1711 | T7: 0.1784 | U7: 0.1917 | V7: 0.196 | W7: 0.1777 | X7: 0.1829 | Y7: 0.19 | Z7: 0.1998 | AA7: 0.1806 | AB7: 0.1686 | AD7: Polyurethane Adhesives | AE7: 0.056950469 | AF7: 0.047741734 | AG7: 0.055571378 | AH7: 0.049845891 | AI7: 0.045231287 | AJ7: 0.040628831 | AK7: 0.03486335 | AL7: 0.026095085 | AM7: 0.02889417 | AN7: 0.076154458 | AO7: 0.08873932 | AP7: 0.059993326 | AQ7: 0.067063086 | AR7: 0.081058042 | AS7: 0.049595105 | AT7: 0.052844637 | AU7: 0.068053758 | AV7: 0.060520313 | AW7: 0.053215037 | AX7: 0.047049502 | AY7: 0.055533074 | AZ7: 0.071222807 | BA7: 0.062735165 | BB7: 0.057438212 | BC7: 0.04824886 | BD7: 0.044294637 | BF7: Polyurethane Adhesives | BG7: CMI_Trend_25 | BH7: CMI_Trend_20 | BI7: CMI_Trend_56 | BJ7: CMI_Trend_56 | BK7: CMI_Trend_20 | BL7: CMI_Trend_46 | BM7: CMI_Trend_25 | BN7: CMI_Trend_52 | BO7: CMI_Trend_25 | BP7: CMI_Trend_38 | BQ7: CMI_Trend_38 | BR7: CMI_Trend_56 | BS7: CMI_Trend_38 | BT7: CMI_Trend_20 | BU7: CMI_Trend_20 | BV7: CMI_Trend_38 | BW7: CMI_Trend_52 | BX7: CMI_Trend_38 | BY7: CMI_Trend_60 | BZ7: CMI_Trend_52 | CA7: CMI_Trend_46 | CB7: CMI_Trend_20 | CC7: CMI_Trend_38 | CD7: CMI_Trend_56 | CE7: CMI_Trend_20 | CF7: CMI_Trend_56
B8: Silicone Adhesives | C8: 0.1168 | D8: 0.1275 | E8: 0.1464 | F8: 0.1438 | G8: 0.148 | H8: 0.1346 | I8: 0.1467 | J8: 0.1238 | K8: 0.1349 | L8: 0.1485 | M8: 0.1242 | N8: 0.1391 | O8: 0.1255 | P8: 0.1272 | Q8: 0.1485 | R8: 0.1408 | S8: 0.1322 | T8: 0.1395 | U8: 0.1372 | V8: 0.1287 | W8: 0.1331 | X8: 0.1198 | Y8: 0.1261 | Z8: 0.1479 | AA8: 0.1241 | AB8: 0.1272 | AD8: Silicone Adhesives | AE8: 0.04448697 | AF8: 0.035278235 | AG8: 0.043107879 | AH8: 0.037382392 | AI8: 0.032767788 | AJ8: 0.028165332 | AK8: 0.022399852 | AL8: 0.019252163 | AM8: 0.019831056 | AN8: 0.063690959 | AO8: 0.076275821 | AP8: 0.047529827 | AQ8: 0.054599587 | AR8: 0.068594543 | AS8: 0.037131606 | AT8: 0.040381138 | AU8: 0.055590259 | AV8: 0.048056814 | AW8: 0.040751538 | AX8: 0.034586003 | AY8: 0.043069576 | AZ8: 0.058759308 | BA8: 0.050271666 | BB8: 0.044974713 | BC8: 0.035785361 | BD8: 0.031831138 | BF8: Silicone Adhesives | BG8: CMI_Trend_25 | BH8: CMI_Trend_46 | BI8: CMI_Trend_46 | BJ8: CMI_Trend_46 | BK8: CMI_Trend_38 | BL8: CMI_Trend_46 | BM8: CMI_Trend_46 | BN8: CMI_Trend_20 | BO8: CMI_Trend_38 | BP8: CMI_Trend_52 | BQ8: CMI_Trend_56 | BR8: CMI_Trend_38 | BS8: CMI_Trend_20 | BT8: CMI_Trend_56 | BU8: CMI_Trend_52 | BV8: CMI_Trend_20 | BW8: CMI_Trend_56 | BX8: CMI_Trend_20 | BY8: CMI_Trend_56 | BZ8: CMI_Trend_25 | CA8: CMI_Trend_56 | CB8: CMI_Trend_52 | CC8: CMI_Trend_52 | CD8: CMI_Trend_46 | CE8: CMI_Trend_25 | CF8: CMI_Trend_20
B9: Cyanoacrylate Adhesives | C9: 0.1325 | D9: 0.125 | E9: 0.1048 | F9: 0.1164 | G9: 0.1182 | H9: 0.1221 | I9: 0.1301 | J9: 0.1256 | K9: 0.129 | L9: 0.1067 | M9: 0.1202 | N9: 0.1161 | O9: 0.1296 | P9: 0.1132 | Q9: 0.1154 | R9: 0.1087 | S9: 0.13 | T9: 0.1047 | U9: 0.1059 | V9: 0.1147 | W9: 0.1001 | X9: 0.1214 | Y9: 0.1025 | Z9: 0.1037 | AA9: 0.1259 | AB9: 0.1051 | AD9: Cyanoacrylate Adhesives | AE9: 0.074950469 | AF9: 0.065741734 | AG9: 0.073571378 | AH9: 0.067845891 | AI9: 0.063231287 | AJ9: 0.058628831 | AK9: 0.05286335 | AL9: 0.037153297 | AM9: 0.043235378 | AN9: 0.094154458 | AO9: 0.10673932 | AP9: 0.077993326 | AQ9: 0.085063086 | AR9: 0.099058042 | AS9: 0.067595105 | AT9: 0.070844637 | AU9: 0.086053758 | AV9: 0.078520313 | AW9: 0.071215037 | AX9: 0.065049502 | AY9: 0.073533074 | AZ9: 0.089222807 | BA9: 0.080735165 | BB9: 0.075438212 | BC9: 0.06624886 | BD9: 0.062294637 | BF9: Cyanoacrylate Adhesives | BG9: CMI_Trend_52 | BH9: CMI_Trend_60 | BI9: CMI_Trend_46 | BJ9: CMI_Trend_52 | BK9: CMI_Trend_52 | BL9: CMI_Trend_46 | BM9: CMI_Trend_52 | BN9: CMI_Trend_56 | BO9: CMI_Trend_52 | BP9: CMI_Trend_20 | BQ9: CMI_Trend_20 | BR9: CMI_Trend_38 | BS9: CMI_Trend_52 | BT9: CMI_Trend_60 | BU9: CMI_Trend_56 | BV9: CMI_Trend_52 | BW9: CMI_Trend_38 | BX9: CMI_Trend_52 | BY9: CMI_Trend_25 | BZ9: CMI_Trend_20 | CA9: CMI_Trend_56 | CB9: CMI_Trend_25 | CC9: CMI_Trend_60 | CD9: CMI_Trend_60 | CE9: CMI_Trend_56 | CF9: CMI_Trend_38
B10: Ethylene Vinyl Acetate Adhesives | C10: 0.0587 | D10: 0.0498 | E10: 0.0541 | F10: 0.0584 | G10: 0.0589 | H10: 0.0556 | I10: 0.0511 | J10: 0.0583 | K10: 0.0533 | L10: 0.0491 | M10: 0.0533 | N10: 0.0484 | O10: 0.0588 | P10: 0.0564 | Q10: 0.0518 | R10: 0.0591 | S10: 0.0497 | T10: 0.0579 | U10: 0.0484 | V10: 0.0526 | W10: 0.057 | X10: 0.0491 | Y10: 0.0566 | Z10: 0.0506 | AA10: 0.0483 | AB10: 0.0558 | AD10: Ethylene Vinyl Acetate Adhesives | AE10: 0.050408269 | AF10: 0.041199534 | AG10: 0.049029178 | AH10: 0.043303691 | AI10: 0.038689087 | AJ10: 0.034086631 | AK10: 0.02832115 | AL10: 0.022436948 | AM10: 0.023877128 | AN10: 0.069612258 | AO10: 0.08219712 | AP10: 0.053451126 | AQ10: 0.060520886 | AR10: 0.074515842 | AS10: 0.043052905 | AT10: 0.046302437 | AU10: 0.061511558 | AV10: 0.053978113 | AW10: 0.046672837 | AX10: 0.040507302 | AY10: 0.048990874 | AZ10: 0.064680607 | BA10: 0.056192965 | BB10: 0.050896012 | BC10: 0.04170666 | BD10: 0.037752437 | BF10: Ethylene Vinyl Acetate Adhesives | BG10: CMI_Trend_25 | BH10: CMI_Trend_56 | BI10: CMI_Trend_38 | BJ10: CMI_Trend_60 | BK10: CMI_Trend_25 | BL10: CMI_Trend_56 | BM10: CMI_Trend_38 | BN10: CMI_Trend_56 | BO10: CMI_Trend_20 | BP10: CMI_Trend_52 | BQ10: CMI_Trend_60 | BR10: CMI_Trend_25 | BS10: CMI_Trend_25 | BT10: CMI_Trend_60 | BU10: CMI_Trend_25 | BV10: CMI_Trend_56 | BW10: CMI_Trend_20 | BX10: CMI_Trend_38 | BY10: CMI_Trend_52 | BZ10: CMI_Trend_20 | CA10: CMI_Trend_25 | CB10: CMI_Trend_25 | CC10: CMI_Trend_52 | CD10: CMI_Trend_56 | CE10: CMI_Trend_52 | CF10: CMI_Trend_25
B11: Others (Polyvinyl Acetate, Rubber-based, Phenolic, etc.) | C11: =1-SUM(C5:C10) -> 0.1504 | D11: =1-SUM(D5:D10) -> 0.1868 | E11: =1-SUM(E5:E10) -> 0.133 | F11: =1-SUM(F5:F10) -> 0.155 | G11: =1-SUM(G5:G10) -> 0.1565 | H11: =1-SUM(H5:H10) -> 0.1771 | I11: =1-SUM(I5:I10) -> 0.1642 | J11: =1-SUM(J5:J10) -> 0.1562 | ... AB11: =1-SUM(AB5:AB10) -> 0.1958 | AD11: Others (Polyvinyl Acetate, Rubber-based, Phenolic, etc.) | AE11: 0.039729432 | AF11: 0.030520697 | AG11: 0.038350341 | AH11: 0.032624855 | AI11: 0.02801025 | AJ11: 0.023407794 | AK11: 0.017642314 | AL11: 0.016745445 | AM11: 0.017232449 | AN11: 0.058933421 | AO11: 0.071518283 | AP11: 0.042772289 | AQ11: 0.049842049 | AR11: 0.063837005 | AS11: 0.032374068 | AT11: 0.0356236 | AU11: 0.050832721 | AV11: 0.043299276 | AW11: 0.035994 | AX11: 0.029828465 | AY11: 0.038312038 | AZ11: 0.05400177 | BA11: 0.045514128 | BB11: 0.040217175 | BC11: 0.031027823 | BD11: 0.0270736 | BF11: Others (Polyvinyl Acetate, Rubber-based, Phenolic, etc.) | BG11: CMI_Trend_25 | BH11: CMI_Trend_52 | BI11: CMI_Trend_25 | BJ11: CMI_Trend_46 | BK11: CMI_Trend_20 | BL11: CMI_Trend_25 | BM11: CMI_Trend_46 | BN11: CMI_Trend_20 | BO11: CMI_Trend_56 | BP11: CMI_Trend_60 | BQ11: CMI_Trend_38 | BR11: CMI_Trend_38 | BS11: CMI_Trend_56 | BT11: CMI_Trend_46 | BU11: CMI_Trend_20 | BV11: CMI_Trend_20 | BW11: CMI_Trend_52 | BX11: CMI_Trend_60 | BY11: CMI_Trend_46 | BZ11: CMI_Trend_56 | CA11: CMI_Trend_38 | CB11: CMI_Trend_52 | CC11: CMI_Trend_20 | CD11: CMI_Trend_25 | CE11: CMI_Trend_56 | CF11: CMI_Trend_25
B13: By Formulation | AD13: By Formulation | BF13: By Formulation
B14: Water Based Adhesives | C14: =1-SUM(C15:C20) -> 0.3476 | D14: =1-SUM(D15:D20) -> 0.3327 | E14: =1-SUM(E15:E20) -> 0.2969 | F14: =1-SUM(F15:F20) -> 0.3242 | G14: =1-SUM(G15:G20) -> 0.3538 | H14: =1-SUM(H15:H20) -> 0.2947 | I14: =1-SUM(I15:I20) -> 0.3478 | J14: =1-SUM(J15:J20) -> 0.3249 | ... AB14: =1-SUM(AB15:AB20) -> 0.3201 | AD14: Water Based Adhesives | AE14: 0.051028904 | AF14: 0.041134669 | AG14: 0.048827015 | AH14: 0.043207012 | AI14: 0.038657783 | AJ14: 0.033200388 | AK14: 0.028649792 | AL14: 0.021964644 | AM14: 0.022862402 | AN14: 0.068303283 | AO14: 0.083021227 | AP14: 0.05261729 | AQ14: 0.060404916 | AR14: 0.074888352 | AS14: 0.042585817 | AT14: 0.04634057 | AU14: 0.060987755 | AV14: 0.053407033 | AW14: 0.046541145 | AX14: 0.040817656 | AY14: 0.048514123 | AZ14: 0.065212267 | BA14: 0.056727765 | BB14: 0.050164064 | BC14: 0.04249493 | BD14: 0.037376252 | BF14: Water Based Adhesives | BG14: CMI_Trend_38 | BH14: CMI_Trend_46 | BI14: CMI_Trend_56 | BJ14: CMI_Trend_38 | BK14: CMI_Trend_20 | BL14: CMI_Trend_56 | BM14: CMI_Trend_60 | BN14: CMI_Trend_56 | BO14: CMI_Trend_60 | BP14: CMI_Trend_25 | BQ14: CMI_Trend_38 | BR14: CMI_Trend_52 | BS14: CMI_Trend_60 | BT14: CMI_Trend_52 | BU14: CMI_Trend_38 | BV14: CMI_Trend_60 | BW14: CMI_Trend_60 | BX14: CMI_Trend_46 | BY14: CMI_Trend_20 | BZ14: CMI_Trend_52 | CA14: CMI_Trend_46 | CB14: CMI_Trend_56 | CC14: CMI_Trend_46 | CD14: CMI_Trend_56 | CE14: CMI_Trend_25 | CF14: CMI_Trend_38
B15: Solvent Based Adhesives | C15: 0.2271 | D15: 0.2391 | E15: 0.2372 | F15: 0.2301 | G15: 0.2265 | H15: 0.2366 | I15: 0.2368 | J15: 0.2442 | K15: 0.2299 | L15: 0.244 | M15: 0.2435 | N15: 0.2381 | O15: 0.2211 | P15: 0.2177 | Q15: 0.2226 | R15: 0.2316 | S15: 0.243 | T15: 0.2475 | U15: 0.245 | V15: 0.2509 | W15: 0.2479 | X15: 0.2487 | Y15: 0.2529 | Z15: 0.2271 | AA15: 0.2443 | AB15: 0.2476 | AD15: Solvent Based Adhesives | AE15: 0.044028904 | AF15: 0.034134669 | AG15: 0.041827015 | AH15: 0.036207012 | AI15: 0.031657783 | AJ15: 0.026200388 | AK15: 0.021649792 | AL15: 0.017270914 | AM15: 0.017176709 | AN15: 0.061303283 | AO15: 0.076021227 | AP15: 0.04561729 | AQ15: 0.053404916 | AR15: 0.067888352 | AS15: 0.035585817 | AT15: 0.03934057 | AU15: 0.053987755 | AV15: 0.046407033 | AW15: 0.039541145 | AX15: 0.033817656 | AY15: 0.041514123 | AZ15: 0.058212267 | BA15: 0.049727765 | BB15: 0.043164064 | BC15: 0.03549493 | BD15: 0.030376252 | BF15: Solvent Based Adhesives | BG15: CMI_Trend_52 | BH15: CMI_Trend_25 | BI15: CMI_Trend_52 | BJ15: CMI_Trend_38 | BK15: CMI_Trend_56 | BL15: CMI_Trend_56 | BM15: CMI_Trend_46 | BN15: CMI_Trend_56 | BO15: CMI_Trend_20 | BP15: CMI_Trend_25 | BQ15: CMI_Trend_46 | BR15: CMI_Trend_60 | BS15: CMI_Trend_20 | BT15: CMI_Trend_56 | BU15: CMI_Trend_46 | BV15: CMI_Trend_56 | BW15: CMI_Trend_52 | BX15: CMI_Trend_52 | BY15: CMI_Trend_20 | BZ15: CMI_Trend_52 | CA15: CMI_Trend_46 | CB15: CMI_Trend_20 | CC15: CMI_Trend_46 | CD15: CMI_Trend_46 | CE15: CMI_Trend_56 | CF15: CMI_Trend_52
B16: Hot Melt Adhesives | C16: 0.1729 | D16: 0.1738 | E16: 0.1855 | F16: 0.155 | G16: 0.164 | H16: 0.1841 | I16: 0.1531 | J16: 0.1788 | K16: 0.1707 | L16: 0.1769 | M16: 0.1557 | N16: 0.1815 | O16: 0.163 | P16: 0.1543 | Q16: 0.1853 | R16: 0.1826 | S16: 0.1769 | T16: 0.1848 | U16: 0.1813 | V16: 0.1839 | W16: 0.1772 | X16: 0.1525 | Y16: 0.1572 | Z16: 0.1561 | AA16: 0.1699 | AB16: 0.1582 | AD16: Hot Melt Adhesives | AE16: 0.077196016 | AF16: 0.067301782 | AG16: 0.074994128 | AH16: 0.069374125 | AI16: 0.064824896 | AJ16: 0.059367501 | AK16: 0.054816905 | AL16: 0.040039946 | AM16: 0.049029515 | AN16: 0.094470395 | AO16: 0.10918834 | AP16: 0.078784402 | AQ16: 0.086572028 | AR16: 0.10105546 | AS16: 0.06875293 | AT16: 0.072507683 | AU16: 0.087154868 | AV16: 0.079574146 | AW16: 0.072708258 | AX16: 0.066984769 | AY16: 0.074681236 | AZ16: 0.091379379 | BA16: 0.082894878 | BB16: 0.076331177 | BC16: 0.068662043 | BD16: 0.063543365 | BF16: Hot Melt Adhesives | BG16: CMI_Trend_60 | BH16: CMI_Trend_25 | BI16: CMI_Trend_60 | BJ16: CMI_Trend_46 | BK16: CMI_Trend_46 | BL16: CMI_Trend_20 | BM16: CMI_Trend_52 | BN16: CMI_Trend_46 | BO16: CMI_Trend_52 | BP16: CMI_Trend_52 | BQ16: CMI_Trend_20 | BR16: CMI_Trend_60 | BS16: CMI_Trend_38 | BT16: CMI_Trend_52 | BU16: CMI_Trend_20 | BV16: CMI_Trend_56 | BW16: CMI_Trend_20 | BX16: CMI_Trend_20 | BY16: CMI_Trend_25 | BZ16: CMI_Trend_25 | CA16: CMI_Trend_52 | CB16: CMI_Trend_52 | CC16: CMI_Trend_46 | CD16: CMI_Trend_46 | CE16: CMI_Trend_38 | CF16: CMI_Trend_52
B17: Reactive Adhesives | C17: 0.1026 | D17: 0.0987 | E17: 0.1219 | F17: 0.1275 | G17: 0.097 | H17: 0.1232 | I17: 0.103 | J17: 0.0993 | K17: 0.1083 | L17: 0.114 | M17: 0.1257 | N17: 0.1088 | O17: 0.1258 | P17: 0.1138 | Q17: 0.1284 | R17: 0.1093 | S17: 0.1269 | T17: 0.1129 | U17: 0.1281 | V17: 0.1174 | W17: 0.1226 | X17: 0.1229 | Y17: 0.1018 | Z17: 0.1261 | AA17: 0.1008 | AB17: 0.1187 | AD17: Reactive Adhesives | AE17: 0.06505004 | AF17: 0.055155805 | AG17: 0.062848151 | AH17: 0.057228148 | AI17: 0.052678919 | AJ17: 0.047221524 | AK17: 0.042670928 | AL17: 0.030124692 | AM17: 0.036883538 | AN17: 0.082324419 | AO17: 0.097042363 | AP17: 0.066638426 | AQ17: 0.074426052 | AR17: 0.088909488 | AS17: 0.056606953 | AT17: 0.060361706 | AU17: 0.075008891 | AV17: 0.067428169 | AW17: 0.060562281 | AX17: 0.054838792 | AY17: 0.062535259 | AZ17: 0.079233403 | BA17: 0.070748901 | BB17: 0.0641852 | BC17: 0.056516066 | BD17: 0.051397388 | BF17: Reactive Adhesives | BG17: CMI_Trend_60 | BH17: CMI_Trend_56 | BI17: CMI_Trend_38 | BJ17: CMI_Trend_56 | BK17: CMI_Trend_25 | BL17: CMI_Trend_20 | BM17: CMI_Trend_60 | BN17: CMI_Trend_60 | BO17: CMI_Trend_60 | BP17: CMI_Trend_38 | BQ17: CMI_Trend_60 | BR17: CMI_Trend_56 | BS17: CMI_Trend_52 | BT17: CMI_Trend_25 | BU17: CMI_Trend_56 | BV17: CMI_Trend_38 | BW17: CMI_Trend_52 | BX17: CMI_Trend_38 | BY17: CMI_Trend_20 | BZ17: CMI_Trend_20 | CA17: CMI_Trend_25 | CB17: CMI_Trend_60 | CC17: CMI_Trend_25 | CD17: CMI_Trend_38 | CE17: CMI_Trend_38 | CF17: CMI_Trend_25
B18: UV Cured / Light Cured Adhesives | C18: 0.0371 | D18: 0.0405 | E18: 0.0399 | F18: 0.0461 | G18: 0.0461 | H18: 0.0372 | I18: 0.0478 | J18: 0.0392 | K18: 0.0441 | L18: 0.0472 | M18: 0.0374 | N18: 0.0423 | O18: 0.0476 | P18: 0.0449 | Q18: 0.0403 | R18: 0.0446 | S18: 0.037 | T18: 0.048 | U18: 0.0477 | V18: 0.0382 | W18: 0.0466 | X18: 0.0393 | Y18: 0.0442 | Z18: 0.0477 | AA18: 0.047 | AB18: 0.038 | AD18: UV Cured / Light Cured Adhesives | AE18: 0.083028904 | AF18: 0.073134669 | AG18: 0.080827015 | AH18: 0.075207012 | AI18: 0.070657783 | AJ18: 0.065200388 | AK18: 0.060649792 | AL18: 0.044952686 | AM18: 0.054862402 | AN18: 0.10030328 | AO18: 0.11502123 | AP18: 0.08461729 | AQ18: 0.092404916 | AR18: 0.10688835 | AS18: 0.074585817 | AT18: 0.07834057 | AU18: 0.092987755 | AV18: 0.085407033 | AW18: 0.078541145 | AX18: 0.072817656 | AY18: 0.080514123 | AZ18: 0.097212267 | BA18: 0.088727765 | BB18: 0.082164064 | BC18: 0.07449493 | BD18: 0.069376252 | BF18: UV Cured / Light Cured Adhesives | BG18: CMI_Trend_25 | BH18: CMI_Trend_46 | BI18: CMI_Trend_52 | BJ18: CMI_Trend_56 | BK18: CMI_Trend_56 | BL18: CMI_Trend_60 | BM18: CMI_Trend_52 | BN18: CMI_Trend_25 | BO18: CMI_Trend_25 | BP18: CMI_Trend_46 | BQ18: CMI_Trend_25 | BR18: CMI_Trend_56 | BS18: CMI_Trend_20 | BT18: CMI_Trend_25 | BU18: CMI_Trend_56 | BV18: CMI_Trend_60 | BW18: CMI_Trend_56 | BX18: CMI_Trend_56 | BY18: CMI_Trend_38 | BZ18: CMI_Trend_52 | CA18: CMI_Trend_38 | CB18: CMI_Trend_52 | CC18: CMI_Trend_25 | CD18: CMI_Trend_46 | CE18: CMI_Trend_38 | CF18: CMI_Trend_20
B19: Pressure Sensitive Adhesives | C19: 0.0593 | D19: 0.0709 | E19: 0.0689 | F19: 0.0702 | G19: 0.0672 | H19: 0.0708 | I19: 0.0621 | J19: 0.062 | K19: 0.0704 | L19: 0.0651 | M19: 0.0599 | N19: 0.0679 | O19: 0.0717 | P19: 0.0635 | Q19: 0.0632 | R19: 0.0707 | S19: 0.0597 | T19: 0.0647 | U19: 0.0708 | V19: 0.0712 | W19: 0.0608 | X19: 0.0708 | Y19: 0.066 | Z19: 0.0611 | AA19: 0.0588 | AB19: 0.0696 | AD19: Pressure Sensitive Adhesives | AE19: 0.058146673 | AF19: 0.048252439 | AG19: 0.055944785 | AH19: 0.050324782 | AI19: 0.045775552 | AJ19: 0.040318158 | AK19: 0.035767561 | AL19: 0.026282092 | AM19: 0.029980172 | AN19: 0.075421052 | AO19: 0.090138996 | AP19: 0.059735059 | AQ19: 0.067522685 | AR19: 0.082006122 | AS19: 0.049703587 | AT19: 0.053458339 | AU19: 0.068105525 | AV19: 0.060524803 | AW19: 0.053658914 | AX19: 0.047935426 | AY19: 0.055631892 | AZ19: 0.072330036 | BA19: 0.063845535 | BB19: 0.057281833 | BC19: 0.0496127 | BD19: 0.044494022 | BF19: Pressure Sensitive Adhesives | BG19: CMI_Trend_38 | BH19: CMI_Trend_46 | BI19: CMI_Trend_38 | BJ19: CMI_Trend_56 | BK19: CMI_Trend_38 | BL19: CMI_Trend_56 | BM19: CMI_Trend_25 | BN19: CMI_Trend_25 | BO19: CMI_Trend_20 | BP19: CMI_Trend_20 | BQ19: CMI_Trend_25 | BR19: CMI_Trend_60 | BS19: CMI_Trend_25 | BT19: CMI_Trend_60 | BU19: CMI_Trend_25 | BV19: CMI_Trend_46 | BW19: CMI_Trend_38 | BX19: CMI_Trend_52 | BY19: CMI_Trend_52 | BZ19: CMI_Trend_25 | CA19: CMI_Trend_46 | CB19: CMI_Trend_20 | CC19: CMI_Trend_46 | CD19: CMI_Trend_46 | CE19: CMI_Trend_20 | CF19: CMI_Trend_25
B20: Adhesive Films and Tapes | C20: 0.0534 | D20: 0.0443 | E20: 0.0497 | F20: 0.0469 | G20: 0.0454 | H20: 0.0534 | I20: 0.0494 | J20: 0.0516 | K20: 0.052 | L20: 0.055 | M20: 0.0491 | N20: 0.0538 | O20: 0.0446 | P20: 0.0505 | Q20: 0.0535 | R20: 0.0468 | S20: 0.0539 | T20: 0.0455 | U20: 0.0444 | V20: 0.0509 | W20: 0.0456 | X20: 0.0512 | Y20: 0.0437 | Z20: 0.0533 | AA20: 0.0435 | AB20: 0.0478 | AD20: Adhesive Films and Tapes | AE20: 0.071028904 | AF20: 0.061134669 | AG20: 0.068827015 | AH20: 0.063207012 | AI20: 0.058657783 | AJ20: 0.053200388 | AK20: 0.048649792 | AL20: 0.034973264 | AM20: 0.042862402 | AN20: 0.088303283 | AO20: 0.10302123 | AP20: 0.07261729 | AQ20: 0.080404916 | AR20: 0.094888352 | AS20: 0.062585817 | AT20: 0.06634057 | AU20: 0.080987755 | AV20: 0.073407033 | AW20: 0.066541145 | AX20: 0.060817656 | AY20: 0.068514123 | AZ20: 0.085212267 | BA20: 0.076727765 | BB20: 0.070164064 | BC20: 0.06249493 | BD20: 0.057376252 | BF20: Adhesive Films and Tapes | BG20: CMI_Trend_20 | BH20: CMI_Trend_56 | BI20: CMI_Trend_52 | BJ20: CMI_Trend_60 | BK20: CMI_Trend_38 | BL20: CMI_Trend_52 | BM20: CMI_Trend_38 | BN20: CMI_Trend_38 | BO20: CMI_Trend_56 | BP20: CMI_Trend_38 | BQ20: CMI_Trend_20 | BR20: CMI_Trend_46 | BS20: CMI_Trend_46 | BT20: CMI_Trend_46 | BU20: CMI_Trend_46 | BV20: CMI_Trend_25 | BW20: CMI_Trend_25 | BX20: CMI_Trend_52 | BY20: CMI_Trend_46 | BZ20: CMI_Trend_52 | CA20: CMI_Trend_25 | CB20: CMI_Trend_60 | CC20: CMI_Trend_38 | CD20: CMI_Trend_56 | CE20: CMI_Trend_46 | CF20: CMI_Trend_25
B22: By Bonding Type | AD22: By Bonding Type | BF22: By Bonding Type
B23: Structural Bonding | C23: =1-SUM(C24:C29) -> 0.2149 | D23: =1-SUM(D24:D29) -> 0.2359 | E23: =1-SUM(E24:E29) -> 0.2544 | F23: =1-SUM(F24:F29) -> 0.2439 | G23: =1-SUM(G24:G29) -> 0.2469 | H23: =1-SUM(H24:H29) -> 0.2447 | I23: =1-SUM(I24:I29) -> 0.2084 | J23: =1-SUM(J24:J29) -> 0.227 | ... AB23: =1-SUM(AB24:AB29) -> 0.2256 | AD23: Structural Bonding | AE23: 0.069041072 | AF23: 0.058621684 | AG23: 0.067230166 | AH23: 0.060782864 | AI23: 0.056047397 | AJ23: 0.051650096 | AK23: 0.046424157 | AL23: 0.034118932 | AM23: 0.037423011 | AN23: 0.086243544 | AO23: 0.10014828 | AP23: 0.071060921 | AQ23: 0.079024448 | AR23: 0.092750338 | AS23: 0.060668542 | AT23: 0.064436002 | AU23: 0.079125349 | AV23: 0.071484635 | AW23: 0.065105955 | AX23: 0.058856978 | AY23: 0.066537339 | AZ23: 0.082834401 | BA23: 0.073075122 | BB23: 0.067779151 | BC23: 0.060232214 | BD23: 0.05485777 | BF23: Structural Bonding | BG23: CMI_Trend_25 | BH23: CMI_Trend_60 | BI23: CMI_Trend_56 | BJ23: CMI_Trend_60 | BK23: CMI_Trend_25 | BL23: CMI_Trend_60 | BM23: CMI_Trend_38 | BN23: CMI_Trend_46 | BO23: CMI_Trend_38 | BP23: CMI_Trend_46 | BQ23: CMI_Trend_46 | BR23: CMI_Trend_52 | BS23: CMI_Trend_46 | BT23: CMI_Trend_20 | BU23: CMI_Trend_52 | BV23: CMI_Trend_52 | BW23: CMI_Trend_20 | BX23: CMI_Trend_38 | BY23: CMI_Trend_46 | BZ23: CMI_Trend_25 | CA23: CMI_Trend_46 | CB23: CMI_Trend_56 | CC23: CMI_Trend_25 | CD23: CMI_Trend_38 | CE23: CMI_Trend_52 | CF23: CMI_Trend_56
B24: Non-Structural Bonding | C24: 0.191 | D24: 0.1715 | E24: 0.1725 | F24: 0.1757 | G24: 0.1643 | H24: 0.1957 | I24: 0.1798 | J24: 0.1948 | K24: 0.1688 | L24: 0.1754 | M24: 0.1717 | N24: 0.1931 | O24: 0.1919 | P24: 0.1647 | Q24: 0.1666 | R24: 0.1818 | S24: 0.1862 | T24: 0.1788 | U24: 0.1923 | V24: 0.1704 | W24: 0.1775 | X24: 0.1886 | Y24: 0.162 | Z24: 0.1765 | AA24: 0.1864 | AB24: 0.1756 | AD24: Non-Structural Bonding | AE24: 0.044974202 | AF24: 0.034554814 | AG24: 0.043163296 | AH24: 0.036715994 | AI24: 0.031980527 | AJ24: 0.027583226 | AK24: 0.022357286 | AL24: 0.018744846 | AM24: 0.022048924 | AN24: 0.062176674 | AO24: 0.076081415 | AP24: 0.046994051 | AQ24: 0.054957578 | AR24: 0.068683468 | AS24: 0.036601672 | AT24: 0.040369132 | AU24: 0.055058479 | AV24: 0.047417765 | AW24: 0.041039085 | AX24: 0.034790108 | AY24: 0.042470469 | AZ24: 0.058767531 | BA24: 0.049008252 | BB24: 0.043712281 | BC24: 0.036165344 | BD24: 0.0307909 | BF24: Non-Structural Bonding | BG24: CMI_Trend_20 | BH24: CMI_Trend_60 | BI24: CMI_Trend_52 | BJ24: CMI_Trend_52 | BK24: CMI_Trend_60 | BL24: CMI_Trend_46 | BM24: CMI_Trend_60 | BN24: CMI_Trend_56 | BO24: CMI_Trend_46 | BP24: CMI_Trend_25 | BQ24: CMI_Trend_52 | BR24: CMI_Trend_52 | BS24: CMI_Trend_52 | BT24: CMI_Trend_52 | BU24: CMI_Trend_38 | BV24: CMI_Trend_38 | BW24: CMI_Trend_46 | BX24: CMI_Trend_52 | BY24: CMI_Trend_20 | BZ24: CMI_Trend_46 | CA24: CMI_Trend_60 | CB24: CMI_Trend_52 | CC24: CMI_Trend_60 | CD24: CMI_Trend_20 | CE24: CMI_Trend_20 | CF24: CMI_Trend_20
B25: Flexible / Elastic Bonding | C25: 0.1282 | D25: 0.1439 | E25: 0.1584 | F25: 0.1345 | G25: 0.1404 | H25: 0.159 | I25: 0.1598 | J25: 0.1315 | K25: 0.148 | L25: 0.136 | M25: 0.1319 | N25: 0.1324 | O25: 0.1579 | P25: 0.1561 | Q25: 0.1514 | R25: 0.1596 | S25: 0.1275 | T25: 0.1415 | U25: 0.1357 | V25: 0.1456 | W25: 0.1405 | X25: 0.1377 | Y25: 0.1482 | Z25: 0.1566 | AA25: 0.1396 | AB25: 0.1344 | AD25: Flexible / Elastic Bonding | AE25: 0.057509466 | AF25: 0.047090078 | AG25: 0.05569856 | AH25: 0.049251258 | AI25: 0.044515791 | AJ25: 0.04011849 | AK25: 0.034892551 | AL25: 0.026025952 | AM25: 0.02933003 | AN25: 0.074711939 | AO25: 0.088616679 | AP25: 0.059529315 | AQ25: 0.067492842 | AR25: 0.081218733 | AS25: 0.049136936 | AT25: 0.052904396 | AU25: 0.067593743 | AV25: 0.059953029 | AW25: 0.053574349 | AX25: 0.047325372 | AY25: 0.055005733 | AZ25: 0.071302795 | BA25: 0.061543516 | BB25: 0.056247545 | BC25: 0.048700608 | BD25: 0.043326164 | BF25: Flexible / Elastic Bonding | BG25: CMI_Trend_56 | BH25: CMI_Trend_25 | BI25: CMI_Trend_20 | BJ25: CMI_Trend_25 | BK25: CMI_Trend_52 | BL25: CMI_Trend_38 | BM25: CMI_Trend_52 | BN25: CMI_Trend_20 | BO25: CMI_Trend_52 | BP25: CMI_Trend_56 | BQ25: CMI_Trend_25 | BR25: CMI_Trend_38 | BS25: CMI_Trend_20 | BT25: CMI_Trend_52 | BU25: CMI_Trend_56 | BV25: CMI_Trend_20 | BW25: CMI_Trend_20 | BX25: CMI_Trend_38 | BY25: CMI_Trend_20 | BZ25: CMI_Trend_38 | CA25: CMI_Trend_25 | CB25: CMI_Trend_20 | CC25: CMI_Trend_38 | CD25: CMI_Trend_56 | CE25: CMI_Trend_52 | CF25: CMI_Trend_25
B26: Surface Lamination Bonding | C26: 0.1787 | D26: 0.1624 | E26: 0.1699 | F26: 0.1644 | G26: 0.1687 | H26: 0.1522 | I26: 0.1743 | J26: 0.1709 | K26: 0.1713 | L26: 0.1686 | M26: 0.1646 | N26: 0.1625 | O26: 0.1809 | P26: 0.1795 | Q26: 0.1555 | R26: 0.1474 | S26: 0.1721 | T26: 0.1566 | U26: 0.1663 | V26: 0.1782 | W26: 0.1671 | X26: 0.1538 | Y26: 0.1523 | Z26: 0.1468 | AA26: 0.1559 | AB26: 0.1804 | AD26: Surface Lamination Bonding | AE26: 0.051041072 | AF26: 0.040621684 | AG26: 0.049230166 | AH26: 0.042782864 | AI26: 0.038047397 | AJ26: 0.033650096 | AK26: 0.028424157 | AL26: 0.021930139 | AM26: 0.025234218 | AN26: 0.068243544 | AO26: 0.082148285 | AP26: 0.053060921 | AQ26: 0.061024448 | AR26: 0.074750338 | AS26: 0.042668542 | AT26: 0.046436002 | AU26: 0.061125349 | AV26: 0.053484635 | AW26: 0.047105955 | AX26: 0.040856978 | AY26: 0.048537339 | AZ26: 0.064834401 | BA26: 0.055075122 | BB26: 0.049779151 | BC26: 0.042232214 | BD26: 0.03685777 | BF26: Surface Lamination Bonding | BG26: CMI_Trend_60 | BH26: CMI_Trend_38 | BI26: CMI_Trend_20 | BJ26: CMI_Trend_60 | BK26: CMI_Trend_56 | BL26: CMI_Trend_56 | BM26: CMI_Trend_46 | BN26: CMI_Trend_46 | BO26: CMI_Trend_38 | BP26: CMI_Trend_20 | BQ26: CMI_Trend_20 | BR26: CMI_Trend_46 | BS26: CMI_Trend_20 | BT26: CMI_Trend_56 | BU26: CMI_Trend_25 | BV26: CMI_Trend_56 | BW26: CMI_Trend_20 | BX26: CMI_Trend_25 | BY26: CMI_Trend_20 | BZ26: CMI_Trend_56 | CA26: CMI_Trend_52 | CB26: CMI_Trend_38 | CC26: CMI_Trend_46 | CD26: CMI_Trend_38 | CE26: CMI_Trend_46 | CF26: CMI_Trend_38
B27: Assembly Bonding | C27: 0.1785 | D27: 0.1725 | E27: 0.1471 | F27: 0.1814 | G27: 0.1815 | H27: 0.1471 | I27: 0.1689 | J27: 0.1811 | K27: 0.1637 | L27: 0.1529 | M27: 0.1651 | N27: 0.1499 | O27: 0.1506 | P27: 0.1667 | Q27: 0.1678 | R27: 0.153 | S27: 0.1676 | T27: 0.1636 | U27: 0.1654 | V27: 0.1669 | W27: 0.1468 | X27: 0.1796 | Y27: 0.1491 | Z27: 0.1683 | AA27: 0.1691 | AB27: 0.174 | AD27: Assembly Bonding | AE27: 0.063417309 | AF27: 0.052997922 | AG27: 0.061606404 | AH27: 0.055159102 | AI27: 0.050423634 | AJ27: 0.046026333 | AK27: 0.040800394 | AL27: 0.03019797 | AM27: 0.033502048 | AN27: 0.080619782 | AO27: 0.094524522 | AP27: 0.065437158 | AQ27: 0.073400685 | AR27: 0.087126576 | AS27: 0.05504478 | AT27: 0.058812239 | AU27: 0.073501586 | AV27: 0.065860873 | AW27: 0.059482193 | AX27: 0.053233215 | AY27: 0.060913576 | AZ27: 0.077210639 | BA27: 0.06745136 | BB27: 0.062155389 | BC27: 0.054608452 | BD27: 0.049234007 | BF27: Assembly Bonding | BG27: CMI_Trend_52 | BH27: CMI_Trend_52 | BI27: CMI_Trend_25 | BJ27: CMI_Trend_52 | BK27: CMI_Trend_25 | BL27: CMI_Trend_46 | BM27: CMI_Trend_56 | BN27: CMI_Trend_25 | BO27: CMI_Trend_38 | BP27: CMI_Trend_56 | BQ27: CMI_Trend_25 | BR27: CMI_Trend_38 | BS27: CMI_Trend_52 | BT27: CMI_Trend_25 | BU27: CMI_Trend_52 | BV27: CMI_Trend_20 | BW27: CMI_Trend_38 | BX27: CMI_Trend_46 | BY27: CMI_Trend_60 | BZ27: CMI_Trend_46 | CA27: CMI_Trend_56 | CB27: CMI_Trend_60 | CC27: CMI_Trend_25 | CD27: CMI_Trend_46 | CE27: CMI_Trend_60 | CF27: CMI_Trend_56
B28: Temporary / Removable Bonding | C28: 0.0388 | D28: 0.0451 | E28: 0.0424 | F28: 0.0373 | G28: 0.0413 | H28: 0.038 | I28: 0.0415 | J28: 0.0379 | K28: 0.0463 | L28: 0.0385 | M28: 0.0434 | N28: 0.0463 | O28: 0.0387 | P28: 0.0466 | Q28: 0.0372 | R28: 0.0434 | S28: 0.0384 | T28: 0.0432 | U28: 0.0377 | V28: 0.0376 | W28: 0.0444 | X28: 0.0469 | Y28: 0.0375 | Z28: 0.0372 | AA28: 0.0455 | AB28: 0.0411 | AD28: Temporary / Removable Bonding | AE28: 0.039261268 | AF28: 0.02884188 | AG28: 0.037450362 | AH28: 0.03100306 | AI28: 0.026267593 | AJ28: 0.021870292 | AK28: 0.017493382 | AL28: 0.015490863 | AM28: 0.018794942 | AN28: 0.056463741 | AO28: 0.070368481 | AP28: 0.041281117 | AQ28: 0.049244644 | AR28: 0.062970535 | AS28: 0.030888738 | AT28: 0.034656198 | AU28: 0.049345545 | AV28: 0.041704831 | AW28: 0.035326151 | AX28: 0.029077174 | AY28: 0.036757535 | AZ28: 0.053054597 | BA28: 0.043295318 | BB28: 0.037999347 | BC28: 0.03045241 | BD28: 0.025077966 | BF28: Temporary / Removable Bonding | BG28: CMI_Trend_60 | BH28: CMI_Trend_56 | BI28: CMI_Trend_25 | BJ28: CMI_Trend_56 | BK28: CMI_Trend_20 | BL28: CMI_Trend_38 | BM28: CMI_Trend_56 | BN28: CMI_Trend_20 | BO28: CMI_Trend_52 | BP28: CMI_Trend_38 | BQ28: CMI_Trend_20 | BR28: CMI_Trend_52 | BS28: CMI_Trend_38 | BT28: CMI_Trend_20 | BU28: CMI_Trend_52 | BV28: CMI_Trend_56 | BW28: CMI_Trend_38 | BX28: CMI_Trend_60 | BY28: CMI_Trend_38 | BZ28: CMI_Trend_20 | CA28: CMI_Trend_20 | CB28: CMI_Trend_38 | CC28: CMI_Trend_25 | CD28: CMI_Trend_60 | CE28: CMI_Trend_60 | CF28: CMI_Trend_56
B29: Hybrid Bonding | C29: 0.0699 | D29: 0.0687 | E29: 0.0553 | F29: 0.0628 | G29: 0.0569 | H29: 0.0633 | I29: 0.0673 | J29: 0.0568 | K29: 0.062 | L29: 0.0691 | M29: 0.0639 | N29: 0.0569 | O29: 0.0689 | P29: 0.0666 | Q29: 0.0605 | R29: 0.0689 | S29: 0.056 | T29: 0.0679 | U29: 0.0597 | V29: 0.0651 | W29: 0.0687 | X29: 0.0626 | Y29: 0.0694 | Z29: 0.0608 | AA29: 0.0589 | AB29: 0.0689 | AD29: Hybrid Bonding | AE29: 0.076041072 | AF29: 0.065621684 | AG29: 0.074230166 | AH29: 0.067782864 | AI29: 0.063047397 | AJ29: 0.058650096 | AK29: 0.053424157 | AL29: 0.036583219 | AM29: 0.039887298 | AN29: 0.093243544 | AO29: 0.10714828 | AP29: 0.078060921 | AQ29: 0.086024448 | AR29: 0.099750338 | AS29: 0.067668542 | AT29: 0.071436002 | AU29: 0.086125349 | AV29: 0.078484635 | AW29: 0.072105955 | AX29: 0.065856978 | AY29: 0.073537339 | AZ29: 0.089834401 | BA29: 0.080075122 | BB29: 0.074779151 | BC29: 0.067232214 | BD29: 0.06185777 | BF29: Hybrid Bonding | BG29: CMI_Trend_38 | BH29: CMI_Trend_38 | BI29: CMI_Trend_52 | BJ29: CMI_Trend_60 | BK29: CMI_Trend_25 | BL29: CMI_Trend_52 | BM29: CMI_Trend_56 | BN29: CMI_Trend_20 | BO29: CMI_Trend_20 | BP29: CMI_Trend_38 | BQ29: CMI_Trend_46 | BR29: CMI_Trend_52 | BS29: CMI_Trend_25 | BT29: CMI_Trend_60 | BU29: CMI_Trend_56 | BV29: CMI_Trend_20 | BW29: CMI_Trend_52 | BX29: CMI_Trend_25 | BY29: CMI_Trend_20 | BZ29: CMI_Trend_20 | CA29: CMI_Trend_25 | CB29: CMI_Trend_20 | CC29: CMI_Trend_20 | CD29: CMI_Trend_60 | CE29: CMI_Trend_38 | CF29: CMI_Trend_25
B31: By Substrate | AD31: By Substrate | BF31: By Substrate
B32: Metal | C32: 0.1834 | D32: 0.1834 | E32: 0.1834 | F32: 0.1834 | G32: 0.1834 | H32: 0.1834 | I32: 0.1834 | J32: 0.1834 | K32: 0.1834 | L32: 0.1834 | M32: 0.1834 | N32: 0.1834 | O32: 0.1834 | P32: 0.1834 | Q32: 0.1834 | R32: 0.1834 | S32: 0.1834 | T32: 0.1834 | U32: 0.1834 | V32: 0.1834 | W32: 0.1834 | X32: 0.1834 | Y32: 0.1834 | Z32: 0.1834 | AA32: 0.1834 | AB32: 0.1834 | AD32: Metal | AE32: 0.061461955 | AF32: 0.050655905 | AG32: 0.058815117 | AH32: 0.053663584 | AI32: 0.048273752 | AJ32: 0.043631462 | AK32: 0.038639642 | AL32: 0.028869734 | AM32: 0.032503429 | AN32: 0.078487133 | AO32: 0.092500505 | AP32: 0.062619308 | AQ32: 0.070384424 | AR32: 0.084568501 | AS32: 0.0531567 | AT32: 0.056646756 | AU32: 0.070997298 | AV32: 0.064105328 | AW32: 0.057615103 | AX32: 0.05162396 | AY32: 0.059700299 | AZ32: 0.074926633 | BA32: 0.0657718 | BB32: 0.060221849 | BC32: 0.052358395 | BD32: 0.047133402 | BF32: Metal | BG32: CMI_Trend_60 | BH32: CMI_Trend_60 | BI32: CMI_Trend_25 | BJ32: CMI_Trend_20 | BK32: CMI_Trend_56 | BL32: CMI_Trend_46 | BM32: CMI_Trend_25 | BN32: CMI_Trend_52 | BO32: CMI_Trend_46 | BP32: CMI_Trend_25 | BQ32: CMI_Trend_20 | BR32: CMI_Trend_38 | BS32: CMI_Trend_56 | BT32: CMI_Trend_56 | BU32: CMI_Trend_60 | BV32: CMI_Trend_52 | BW32: CMI_Trend_25 | BX32: CMI_Trend_56 | BY32: CMI_Trend_56 | BZ32: CMI_Trend_38 | CA32: CMI_Trend_52 | CB32: CMI_Trend_25 | CC32: CMI_Trend_46 | CD32: CMI_Trend_38 | CE32: CMI_Trend_60 | CF32: CMI_Trend_20
B33: Plastic | C33: =1-C32-SUM(C34:C38) -> 0.2232 | D33: =1-D32-SUM(D34:D38) -> 0.2659 | E33: =1-E32-SUM(E34:E38) -> 0.2768 | F33: =1-F32-SUM(F34:F38) -> 0.2339 | G33: =1-G32-SUM(G34:G38) -> 0.2541 | H33: =1-H32-SUM(H34:H38) -> 0.2696 | I33: =1-I32-SUM(I34:I38) -> 0.249 | J33: =1-J32-SUM(J34:J38) -> 0.2527 | ... AB33: =1-AB32-SUM(AB34:AB38) -> 0.2445 | AD33: Plastic | AE33: 0.069367015 | AF33: 0.058560966 | AG33: 0.066720177 | AH33: 0.061568644 | AI33: 0.056178813 | AJ33: 0.051536523 | AK33: 0.046544703 | AL33: 0.031662368 | AM33: 0.035296063 | AN33: 0.086392194 | AO33: 0.10040556 | AP33: 0.070524368 | AQ33: 0.078289484 | AR33: 0.092473561 | AS33: 0.06106176 | AT33: 0.064551816 | AU33: 0.078902359 | AV33: 0.072010388 | AW33: 0.065520164 | AX33: 0.05952902 | AY33: 0.067605359 | AZ33: 0.082831693 | BA33: 0.07367686 | BB33: 0.068126909 | BC33: 0.060263455 | BD33: 0.055038462 | BF33: Plastic | BG33: CMI_Trend_38 | BH33: CMI_Trend_20 | BI33: CMI_Trend_46 | BJ33: CMI_Trend_56 | BK33: CMI_Trend_46 | BL33: CMI_Trend_52 | BM33: CMI_Trend_25 | BN33: CMI_Trend_56 | BO33: CMI_Trend_52 | BP33: CMI_Trend_46 | BQ33: CMI_Trend_56 | BR33: CMI_Trend_60 | BS33: CMI_Trend_46 | BT33: CMI_Trend_25 | BU33: CMI_Trend_52 | BV33: CMI_Trend_25 | BW33: CMI_Trend_60 | BX33: CMI_Trend_46 | BY33: CMI_Trend_56 | BZ33: CMI_Trend_52 | CA33: CMI_Trend_25 | CB33: CMI_Trend_60 | CC33: CMI_Trend_56 | CD33: CMI_Trend_52 | CE33: CMI_Trend_52 | CF33: CMI_Trend_52
B34: Composite | C34: 0.0787 | D34: 0.0675 | E34: 0.071 | F34: 0.0694 | G34: 0.0737 | H34: 0.0653 | I34: 0.064 | J34: 0.0787 | K34: 0.0668 | L34: 0.0729 | M34: 0.0797 | N34: 0.074 | O34: 0.0793 | P34: 0.0717 | Q34: 0.0656 | R34: 0.0798 | S34: 0.0671 | T34: 0.0707 | U34: 0.0647 | V34: 0.0733 | W34: 0.0781 | X34: 0.0749 | Y34: 0.075 | Z34: 0.0786 | AA34: 0.0722 | AB34: 0.0697 | AD34: Composite | AE34: 0.076461955 | AF34: 0.065655905 | AG34: 0.073815117 | AH34: 0.068663584 | AI34: 0.063273752 | AJ34: 0.058631462 | AK34: 0.053639642 | AL34: 0.035027147 | AM34: 0.038660842 | AN34: 0.093487133 | AO34: 0.1075005 | AP34: 0.077619308 | AQ34: 0.085384424 | AR34: 0.099568501 | AS34: 0.0681567 | AT34: 0.071646756 | AU34: 0.085997298 | AV34: 0.079105328 | AW34: 0.072615103 | AX34: 0.06662396 | AY34: 0.074700299 | AZ34: 0.089926633 | BA34: 0.0807718 | BB34: 0.075221849 | BC34: 0.067358395 | BD34: 0.062133402 | BF34: Composite | BG34: CMI_Trend_60 | BH34: CMI_Trend_52 | BI34: CMI_Trend_38 | BJ34: CMI_Trend_56 | BK34: CMI_Trend_60 | BL34: CMI_Trend_52 | BM34: CMI_Trend_20 | BN34: CMI_Trend_38 | BO34: CMI_Trend_52 | BP34: CMI_Trend_25 | BQ34: CMI_Trend_60 | BR34: CMI_Trend_52 | BS34: CMI_Trend_25 | BT34: CMI_Trend_56 | BU34: CMI_Trend_38 | BV34: CMI_Trend_56 | BW34: CMI_Trend_46 | BX34: CMI_Trend_38 | BY34: CMI_Trend_60 | BZ34: CMI_Trend_46 | CA34: CMI_Trend_52 | CB34: CMI_Trend_38 | CC34: CMI_Trend_25 | CD34: CMI_Trend_20 | CE34: CMI_Trend_20 | CF34: CMI_Trend_25
B35: Glass | C35: 0.0576 | D35: 0.057 | E35: 0.0611 | F35: 0.0621 | G35: 0.0572 | H35: 0.0676 | I35: 0.0588 | J35: 0.058 | K35: 0.0635 | L35: 0.0649 | M35: 0.0683 | N35: 0.0616 | O35: 0.0575 | P35: 0.0689 | Q35: 0.0633 | R35: 0.0655 | S35: 0.0607 | T35: 0.0587 | U35: 0.0667 | V35: 0.0573 | W35: 0.0683 | X35: 0.0612 | Y35: 0.0603 | Z35: 0.0658 | AA35: 0.0643 | AB35: 0.0694 | AD35: Glass | AE35: 0.044863436 | AF35: 0.034057386 | AG35: 0.042216598 | AH35: 0.037065065 | AI35: 0.031675233 | AJ35: 0.027032943 | AK35: 0.022041123 | AL35: 0.018855542 | AM35: 0.022489238 | AN35: 0.061888614 | AO35: 0.075901985 | AP35: 0.046020789 | AQ35: 0.053785904 | AR35: 0.067969982 | AS35: 0.036558181 | AT35: 0.040048237 | AU35: 0.054398779 | AV35: 0.047506809 | AW35: 0.041016584 | AX35: 0.03502544 | AY35: 0.043101779 | AZ35: 0.058328113 | BA35: 0.04917328 | BB35: 0.043623329 | BC35: 0.035759876 | BD35: 0.030534882 | BF35: Glass | BG35: CMI_Trend_56 | BH35: CMI_Trend_56 | BI35: CMI_Trend_46 | BJ35: CMI_Trend_52 | BK35: CMI_Trend_20 | BL35: CMI_Trend_46 | BM35: CMI_Trend_56 | BN35: CMI_Trend_38 | BO35: CMI_Trend_25 | BP35: CMI_Trend_46 | BQ35: CMI_Trend_52 | BR35: CMI_Trend_56 | BS35: CMI_Trend_46 | BT35: CMI_Trend_38 | BU35: CMI_Trend_46 | BV35: CMI_Trend_56 | BW35: CMI_Trend_20 | BX35: CMI_Trend_56 | BY35: CMI_Trend_25 | BZ35: CMI_Trend_60 | CA35: CMI_Trend_52 | CB35: CMI_Trend_20 | CC35: CMI_Trend_25 | CD35: CMI_Trend_20 | CE35: CMI_Trend_20 | CF35: CMI_Trend_25
B36: Paper & Paperboard | C36: 0.2248 | D36: 0.2168 | E36: 0.2114 | F36: 0.2366 | G36: 0.232 | H36: 0.2105 | I36: 0.2166 | J36: 0.2356 | K36: 0.2393 | L36: 0.2169 | M36: 0.2288 | N36: 0.2294 | O36: 0.2262 | P36: 0.2263 | Q36: 0.2381 | R36: 0.2367 | S36: 0.2104 | T36: 0.2233 | U36: 0.2231 | V36: 0.2453 | W36: 0.2378 | X36: 0.2359 | Y36: 0.2357 | Z36: 0.2107 | AA36: 0.2347 | AB36: 0.2342 | AD36: Paper & Paperboard | AE36: 0.055081756 | AF36: 0.044275706 | AG36: 0.052434918 | AH36: 0.047283385 | AI36: 0.041893553 | AJ36: 0.037251263 | AK36: 0.032259443 | AL36: 0.025314122 | AM36: 0.028947818 | AN36: 0.072106934 | AO36: 0.086120306 | AP36: 0.056239109 | AQ36: 0.064004225 | AR36: 0.078188302 | AS36: 0.046776501 | AT36: 0.050266557 | AU36: 0.064617099 | AV36: 0.057725129 | AW36: 0.051234904 | AX36: 0.045243761 | AY36: 0.0533201 | AZ36: 0.068546434 | BA36: 0.059391601 | BB36: 0.05384165 | BC36: 0.045978196 | BD36: 0.040753203 | BF36: Paper & Paperboard | BG36: CMI_Trend_38 | BH36: CMI_Trend_60 | BI36: CMI_Trend_60 | BJ36: CMI_Trend_56 | BK36: CMI_Trend_60 | BL36: CMI_Trend_56 | BM36: CMI_Trend_25 | BN36: CMI_Trend_56 | BO36: CMI_Trend_20 | BP36: CMI_Trend_25 | BQ36: CMI_Trend_38 | BR36: CMI_Trend_56 | BS36: CMI_Trend_20 | BT36: CMI_Trend_60 | BU36: CMI_Trend_60 | BV36: CMI_Trend_20 | BW36: CMI_Trend_25 | BX36: CMI_Trend_60 | BY36: CMI_Trend_46 | BZ36: CMI_Trend_56 | CA36: CMI_Trend_60 | CB36: CMI_Trend_60 | CC36: CMI_Trend_56 | CD36: CMI_Trend_46 | CE36: CMI_Trend_25 | CF36: CMI_Trend_38
B37: Wood | C37: 0.1264 | D37: 0.0968 | E37: 0.0965 | F37: 0.1189 | G37: 0.1077 | H37: 0.1085 | I37: 0.1187 | J37: 0.0911 | K37: 0.0976 | L37: 0.0931 | M37: 0.1008 | N37: 0.0949 | O37: 0.0919 | P37: 0.0965 | Q37: 0.0987 | R37: 0.1026 | S37: 0.1031 | T37: 0.1175 | U37: 0.1165 | V37: 0.1076 | W37: 0.1244 | X37: 0.1118 | Y37: 0.1015 | Z37: 0.1085 | AA37: 0.1012 | AB37: 0.1065 | AD37: Wood | AE37: 0.039529429 | AF37: 0.028723379 | AG37: 0.036882591 | AH37: 0.031731058 | AI37: 0.026341226 | AJ37: 0.021698936 | AK37: 0.017213358 | AL37: 0.015022404 | AM37: 0.018656099 | AN37: 0.056554607 | AO37: 0.070567978 | AP37: 0.040686782 | AQ37: 0.048451897 | AR37: 0.062635975 | AS37: 0.031224174 | AT37: 0.03471423 | AU37: 0.049064772 | AV37: 0.042172802 | AW37: 0.035682577 | AX37: 0.029691433 | AY37: 0.037767772 | AZ37: 0.052994106 | BA37: 0.043839273 | BB37: 0.038289322 | BC37: 0.030425869 | BD37: 0.025200875 | BF37: Wood | BG37: CMI_Trend_38 | BH37: CMI_Trend_38 | BI37: CMI_Trend_25 | BJ37: CMI_Trend_20 | BK37: CMI_Trend_60 | BL37: CMI_Trend_25 | BM37: CMI_Trend_46 | BN37: CMI_Trend_46 | BO37: CMI_Trend_56 | BP37: CMI_Trend_38 | BQ37: CMI_Trend_46 | BR37: CMI_Trend_38 | BS37: CMI_Trend_38 | BT37: CMI_Trend_60 | BU37: CMI_Trend_60 | BV37: CMI_Trend_20 | BW37: CMI_Trend_52 | BX37: CMI_Trend_38 | BY37: CMI_Trend_60 | BZ37: CMI_Trend_38 | CA37: CMI_Trend_20 | CB37: CMI_Trend_52 | CC37: CMI_Trend_46 | CD37: CMI_Trend_25 | CE37: CMI_Trend_38 | CF37: CMI_Trend_56
B38: Others (Rubber, Textile, etc.) | C38: 0.1059 | D38: 0.1126 | E38: 0.0998 | F38: 0.0957 | G38: 0.0919 | H38: 0.0951 | I38: 0.1095 | J38: 0.1005 | K38: 0.0902 | L38: 0.1109 | M38: 0.0959 | N38: 0.0975 | O38: 0.1168 | P38: 0.0971 | Q38: 0.0896 | R38: 0.0912 | S38: 0.1046 | T38: 0.102 | U38: 0.103 | V38: 0.1171 | W38: 0.1035 | X38: 0.0919 | Y38: 0.0862 | Z38: 0.1016 | AA38: 0.1027 | AB38: 0.0923 | AD38: Others (Rubber, Textile, etc.) | AE38: 0.050461955 | AF38: 0.039655905 | AG38: 0.047815117 | AH38: 0.042663584 | AI38: 0.037273752 | AJ38: 0.032631462 | AK38: 0.027639642 | AL38: 0.022109993 | AM38: 0.025743689 | AN38: 0.067487133 | AO38: 0.081500505 | AP38: 0.051619308 | AQ38: 0.059384424 | AR38: 0.073568501 | AS38: 0.0421567 | AT38: 0.045646756 | AU38: 0.059997298 | AV38: 0.053105328 | AW38: 0.046615103 | AX38: 0.04062396 | AY38: 0.048700299 | AZ38: 0.063926633 | BA38: 0.0547718 | BB38: 0.049221849 | BC38: 0.041358395 | BD38: 0.036133402 | BF38: Others (Rubber, Textile, etc.) | BG38: CMI_Trend_52 | BH38: CMI_Trend_46 | BI38: CMI_Trend_20 | BJ38: CMI_Trend_20 | BK38: CMI_Trend_46 | BL38: CMI_Trend_52 | BM38: CMI_Trend_46 | BN38: CMI_Trend_60 | BO38: CMI_Trend_60 | BP38: CMI_Trend_46 | BQ38: CMI_Trend_52 | BR38: CMI_Trend_46 | BS38: CMI_Trend_38 | BT38: CMI_Trend_38 | BU38: CMI_Trend_60 | BV38: CMI_Trend_38 | BW38: CMI_Trend_20 | BX38: CMI_Trend_25 | BY38: CMI_Trend_25 | BZ38: CMI_Trend_38 | CA38: CMI_Trend_46 | CB38: CMI_Trend_38 | CC38: CMI_Trend_46 | CD38: CMI_Trend_38 | CE38: CMI_Trend_25 | CF38: CMI_Trend_38
B40: By End Use | AD40: By End Use | BF40: By End Use
B41: Automotive | C41: 0.1681 | D41: 0.1636 | E41: 0.1578 | F41: 0.1735 | G41: 0.146 | H41: 0.1784 | I41: 0.173 | J41: 0.1691 | K41: 0.155 | L41: 0.1786 | M41: 0.1752 | N41: 0.1512 | O41: 0.1794 | P41: 0.1502 | Q41: 0.1462 | R41: 0.1534 | S41: 0.1555 | T41: 0.1544 | U41: 0.1518 | V41: 0.1614 | W41: 0.1734 | X41: 0.1645 | Y41: 0.1774 | Z41: 0.1657 | AA41: 0.1579 | AB41: 0.158 | AD41: Automotive | AE41: 0.062617733 | AF41: 0.053085064 | AG41: 0.061481521 | AH41: 0.055563945 | AI41: 0.050597434 | AJ41: 0.045568742 | AK41: 0.040452708 | AL41: 0.030222433 | AM41: 0.033283436 | AN41: 0.080467065 | AO41: 0.094788107 | AP41: 0.064983694 | AQ41: 0.072487379 | AR41: 0.086767836 | AS41: 0.055289953 | AT41: 0.058853058 | AU41: 0.073444214 | AV41: 0.065879996 | AW41: 0.059321426 | AX41: 0.053503627 | AY41: 0.0608199 | AZ41: 0.076740038 | BA41: 0.067840763 | BB41: 0.062784432 | BC41: 0.05462146 | BD41: 0.048671955 | BF41: Automotive | BG41: CMI_Trend_46 | BH41: CMI_Trend_60 | BI41: CMI_Trend_56 | BJ41: CMI_Trend_46 | BK41: CMI_Trend_46 | BL41: CMI_Trend_60 | BM41: CMI_Trend_52 | BN41: CMI_Trend_52 | BO41: CMI_Trend_38 | BP41: CMI_Trend_60 | BQ41: CMI_Trend_25 | BR41: CMI_Trend_20 | BS41: CMI_Trend_20 | BT41: CMI_Trend_20 | BU41: CMI_Trend_56 | BV41: CMI_Trend_20 | BW41: CMI_Trend_38 | BX41: CMI_Trend_56 | BY41: CMI_Trend_46 | BZ41: CMI_Trend_56 | CA41: CMI_Trend_46 | CB41: CMI_Trend_60 | CC41: CMI_Trend_60 | CD41: CMI_Trend_56 | CE41: CMI_Trend_25 | CF41: CMI_Trend_46
B42: Consumer Electronics | C42: 0.1005 | D42: 0.097 | E42: 0.1088 | F42: 0.0914 | G42: 0.0994 | H42: 0.119 | I42: 0.0897 | J42: 0.0955 | K42: 0.1146 | L42: 0.1107 | M42: 0.0937 | N42: 0.106 | O42: 0.1035 | P42: 0.1189 | Q42: 0.1203 | R42: 0.0937 | S42: 0.1216 | T42: 0.105 | U42: 0.1106 | V42: 0.111 | W42: 0.0978 | X42: 0.0881 | Y42: 0.0989 | Z42: 0.089 | AA42: 0.0942 | AB42: 0.1185 | AD42: Consumer Electronics | AE42: 0.067571588 | AF42: 0.058038918 | AG42: 0.066435375 | AH42: 0.060517799 | AI42: 0.055551288 | AJ42: 0.050522596 | AK42: 0.045406562 | AL42: 0.035393732 | AM42: 0.038454736 | AN42: 0.085420919 | AO42: 0.099741961 | AP42: 0.069937548 | AQ42: 0.077441233 | AR42: 0.09172169 | AS42: 0.060243807 | AT42: 0.063806912 | AU42: 0.078398068 | AV42: 0.07083385 | AW42: 0.06427528 | AX42: 0.058457481 | AY42: 0.065773754 | AZ42: 0.081693892 | BA42: 0.072794617 | BB42: 0.067738286 | BC42: 0.059575314 | BD42: 0.053625809 | BF42: Consumer Electronics | BG42: CMI_Trend_20 | BH42: CMI_Trend_46 | BI42: CMI_Trend_25 | BJ42: CMI_Trend_38 | BK42: CMI_Trend_56 | BL42: CMI_Trend_38 | BM42: CMI_Trend_20 | BN42: CMI_Trend_60 | BO42: CMI_Trend_52 | BP42: CMI_Trend_60 | BQ42: CMI_Trend_46 | BR42: CMI_Trend_46 | BS42: CMI_Trend_60 | BT42: CMI_Trend_25 | BU42: CMI_Trend_52 | BV42: CMI_Trend_60 | BW42: CMI_Trend_38 | BX42: CMI_Trend_46 | BY42: CMI_Trend_56 | BZ42: CMI_Trend_25 | CA42: CMI_Trend_56 | CB42: CMI_Trend_38 | CC42: CMI_Trend_52 | CD42: CMI_Trend_52 | CE42: CMI_Trend_25 | CF42: CMI_Trend_38
B43: Aerospace | C43: 0.048 | D43: 0.0371 | E43: 0.0408 | F43: 0.0387 | G43: 0.0427 | H43: 0.0467 | I43: 0.0382 | J43: 0.0413 | K43: 0.0401 | L43: 0.0361 | M43: 0.0438 | N43: 0.0474 | O43: 0.0455 | P43: 0.0457 | Q43: 0.0467 | R43: 0.0387 | S43: 0.0421 | T43: 0.0462 | U43: 0.0413 | V43: 0.0371 | W43: 0.0461 | X43: 0.047 | Y43: 0.0416 | Z43: 0.0366 | AA43: 0.043 | AB43: 0.0384 | AD43: Aerospace | AE43: 0.073617733 | AF43: 0.064085064 | AG43: 0.072481521 | AH43: 0.066563945 | AI43: 0.061597434 | AJ43: 0.056568742 | AK43: 0.051452708 | AL43: 0.038921251 | AM43: 0.041982255 | AN43: 0.091467065 | AO43: 0.10578811 | AP43: 0.075983694 | AQ43: 0.083487379 | AR43: 0.097767836 | AS43: 0.066289953 | AT43: 0.069853058 | AU43: 0.084444214 | AV43: 0.076879996 | AW43: 0.070321426 | AX43: 0.064503627 | AY43: 0.0718199 | AZ43: 0.087740038 | BA43: 0.078840763 | BB43: 0.073784432 | BC43: 0.06562146 | BD43: 0.059671955 | BF43: Aerospace | BG43: CMI_Trend_25 | BH43: CMI_Trend_25 | BI43: CMI_Trend_56 | BJ43: CMI_Trend_56 | BK43: CMI_Trend_25 | BL43: CMI_Trend_38 | BM43: CMI_Trend_46 | BN43: CMI_Trend_46 | BO43: CMI_Trend_56 | BP43: CMI_Trend_56 | BQ43: CMI_Trend_20 | BR43: CMI_Trend_38 | BS43: CMI_Trend_38 | BT43: CMI_Trend_56 | BU43: CMI_Trend_20 | BV43: CMI_Trend_52 | BW43: CMI_Trend_38 | BX43: CMI_Trend_38 | BY43: CMI_Trend_20 | BZ43: CMI_Trend_46 | CA43: CMI_Trend_25 | CB43: CMI_Trend_38 | CC43: CMI_Trend_20 | CD43: CMI_Trend_60 | CE43: CMI_Trend_56 | CF43: CMI_Trend_38
B44: Packaging | C44: =1-SUM(C41:C43,C45:C48) -> 0.2652 | D44: =1-SUM(D41:D43,D45:D48) -> 0.2914 | E44: =1-SUM(E41:E43,E45:E48) -> 0.2654 | F44: =1-SUM(F41:F43,F45:F48) -> 0.2335 | G44: =1-SUM(G41:G43,G45:G48) -> 0.3054 | H44: =1-SUM(H41:H43,H45:H48) -> 0.2188 | I44: =1-SUM(I41:I43,I45:I48) -> 0.248 | J44: =1-SUM(J41:J43,J45:J48) -> 0.2739 | ... AB44: =1-SUM(AB41:AB43,AB45:AB48) -> 0.2754 | AD44: Packaging | AE44: 0.056608606 | AF44: 0.047075937 | AG44: 0.055472394 | AH44: 0.049554818 | AI44: 0.044588307 | AJ44: 0.039559614 | AK44: 0.034443581 | AL44: 0.026569747 | AM44: 0.02963075 | AN44: 0.074457937 | AO44: 0.088778979 | AP44: 0.058974567 | AQ44: 0.066478251 | AR44: 0.080758709 | AS44: 0.049280826 | AT44: 0.05284393 | AU44: 0.067435087 | AV44: 0.059870869 | AW44: 0.053312299 | AX44: 0.0474945 | AY44: 0.054810773 | AZ44: 0.07073091 | BA44: 0.061831636 | BB44: 0.056775304 | BC44: 0.048612333 | BD44: 0.042662827 | BF44: Packaging | BG44: CMI_Trend_38 | BH44: CMI_Trend_20 | BI44: CMI_Trend_20 | BJ44: CMI_Trend_56 | BK44: CMI_Trend_25 | BL44: CMI_Trend_46 | BM44: CMI_Trend_25 | BN44: CMI_Trend_20 | BO44: CMI_Trend_25 | BP44: CMI_Trend_56 | BQ44: CMI_Trend_46 | BR44: CMI_Trend_60 | BS44: CMI_Trend_38 | BT44: CMI_Trend_46 | BU44: CMI_Trend_52 | BV44: CMI_Trend_52 | BW44: CMI_Trend_56 | BX44: CMI_Trend_56 | BY44: CMI_Trend_25 | BZ44: CMI_Trend_46 | CA44: CMI_Trend_60 | CB44: CMI_Trend_38 | CC44: CMI_Trend_46 | CD44: CMI_Trend_25 | CE44: CMI_Trend_20 | CF44: CMI_Trend_60
B45: Building & Construction | C45: 0.1694 | D45: 0.1673 | E45: 0.1926 | F45: 0.1875 | G45: 0.1704 | H45: 0.1666 | I45: 0.1952 | J45: 0.1772 | K45: 0.1802 | L45: 0.196 | M45: 0.1915 | N45: 0.1923 | O45: 0.1968 | P45: 0.1993 | Q45: 0.1892 | R45: 0.1785 | S45: 0.1777 | T45: 0.1913 | U45: 0.1803 | V45: 0.1918 | W45: 0.1985 | X45: 0.1706 | Y45: 0.1745 | Z45: 0.1882 | AA45: 0.1799 | AB45: 0.1741 | AD45: Building & Construction | AE45: 0.051617733 | AF45: 0.042085064 | AG45: 0.050481521 | AH45: 0.044563945 | AI45: 0.039597434 | AJ45: 0.034568742 | AK45: 0.029452708 | AL45: 0.021612757 | AM45: 0.024673761 | AN45: 0.069467065 | AO45: 0.083788107 | AP45: 0.053983694 | AQ45: 0.061487379 | AR45: 0.075767836 | AS45: 0.044289953 | AT45: 0.047853058 | AU45: 0.062444214 | AV45: 0.054879996 | AW45: 0.048321426 | AX45: 0.042503627 | AY45: 0.0498199 | AZ45: 0.065740038 | BA45: 0.056840763 | BB45: 0.051784432 | BC45: 0.04362146 | BD45: 0.037671955 | BF45: Building & Construction | BG45: CMI_Trend_20 | BH45: CMI_Trend_38 | BI45: CMI_Trend_60 | BJ45: CMI_Trend_60 | BK45: CMI_Trend_56 | BL45: CMI_Trend_25 | BM45: CMI_Trend_20 | BN45: CMI_Trend_20 | BO45: CMI_Trend_60 | BP45: CMI_Trend_20 | BQ45: CMI_Trend_20 | BR45: CMI_Trend_52 | BS45: CMI_Trend_25 | BT45: CMI_Trend_60 | BU45: CMI_Trend_25 | BV45: CMI_Trend_52 | BW45: CMI_Trend_56 | BX45: CMI_Trend_46 | BY45: CMI_Trend_56 | BZ45: CMI_Trend_60 | CA45: CMI_Trend_60 | CB45: CMI_Trend_56 | CC45: CMI_Trend_52 | CD45: CMI_Trend_38 | CE45: CMI_Trend_56 | CF45: CMI_Trend_38
...

Sheet ASP
B1: 79.4
B2: =B40 -> 23544.448 | C2: =C40 -> 5963.0835 | D2: =D40 -> 851.31706 | E2: =E40 -> 1254.0478 | F2: =F40 -> 831.74077 | G2: =G40 -> 634.17993 | H2: =H40 -> 506.02611 | I2: =I40 -> 344.11902 | ... AB2: =AB40 -> 170.19326
C3: U.S. | D3: Canada | E3: Germany | F3: U.K. | G3: France | H3: Italy | I3: Spain | J3: Russia | K3: Rest of Europe | L3: China | M3: India | N3: Japan | O3: South Korea | P3: ASEAN | Q3: Australia | R3: Rest of Asia Pacific | S3: Brazil | T3: Mexico | U3: Argentina | V3: Rest of Latin America | W3: Israel | X3: GCC | Y3: Rest of Middle East | Z3: North Africa | AA3: Central Africa | AB3: South Africa | AE3: U.S. | AF3: Canada | AG3: Germany | AH3: U.K. | AI3: France | AJ3: Italy | AK3: Spain | AL3: Russia | AM3: Rest of Europe | AN3: China | AO3: India | AP3: Japan | AQ3: South Korea | AR3: ASEAN | AS3: Australia | AT3: Rest of Asia Pacific | AU3: Brazil | AV3: Mexico | AW3: Argentina | AX3: Rest of Latin America | AY3: Israel | AZ3: GCC | BA3: Rest of Middle East | BB3: North Africa | BC3: Central Africa | BD3: South Africa
B4: By Product | AD4: By Product
B5: Acrylic Adhesives | C5: 2402.5564 | D5: 2400.1296 | E5: 2540.582 | F5: 2599.0154 | G5: 2515.1762 | H5: 2583.7719 | I5: 2565.9879 | J5: 2522.798 | K5: 2550.7444 | L5: 1794.8643 | M5: 1763.4673 | N5: 1747.7688 | O5: 1744.2802 | P5: 1794.8643 | Q5: 1796.6086 | R5: 1732.0702 | S5: 2021.7724 | T5: 2039.8599 | U5: 2023.7821 | V5: 2039.8599 | W5: 2150.2045 | X5: 2079.2958 | Y5: 2131.4346 | Z5: 2219.1036 | AA5: 2236.6981 | AB5: 2179.516 | AD5: Acrylic Adhesives | AE5: ASP2 | AF5: ASP2 | AG5: ASP8 | AH5: ASP9 | AI5: ASP8 | AJ5: ASP1 | AK5: ASP8 | AL5: ASP5 | AM5: ASP1 | AN5: ASP4 | AO5: ASP9 | AP5: ASP4 | AQ5: ASP6 | AR5: ASP6 | AS5: ASP8 | AT5: ASP3 | AU5: ASP6 | AV5: ASP6 | AW5: ASP4 | AX5: ASP7 | AY5: ASP9 | AZ5: ASP6 | BA5: ASP2 | BB5: ASP3 | BC5: ASP5 | BD5: ASP1
B6: Epoxy Adhesives | C6: 3088.1343 | D6: 3082.0673 | E6: 3172.4665 | F6: 3258.4671 | G6: 3156.5405 | H6: 3252.0967 | I6: 3159.7257 | J6: 3274.3931 | K6: 3217.0594 | L6: 2252.3966 | M6: 2291.0741 | N6: 2250.1215 | O6: 2302.4499 | P6: 2302.4499 | Q6: 2304.725 | R6: 2279.6984 | S6: 2288.799 | T6: 2313.8256 | U6: 2284.2487 | V6: 2252.3966 | W6: 2347.9528 | X6: 2318.3759 | Y6: 2272.8729 | Z6: 2256.9469 | AA6: 2281.9735 | AB6: 2291.0741 | AD6: Epoxy Adhesives | AE6: ASP2 | AF6: ASP6 | AG6: ASP4 | AH6: ASP9 | AI6: ASP8 | AJ6: ASP3 | AK6: ASP9 | AL6: ASP2 | AM6: ASP4 | AN6: ASP4 | AO6: ASP4 | AP6: ASP5 | AQ6: ASP6 | AR6: ASP9 | AS6: ASP9 | AT6: ASP7 | AU6: ASP2 | AV6: ASP4 | AW6: ASP5 | AX6: ASP6 | AY6: ASP4 | AZ6: ASP1 | BA6: ASP2 | BB6: ASP3 | BC6: ASP4 | BD6: ASP1
B7: Polyurethane Adhesives | C7: 4720.7806 | D7: 4800.7141 | E7: 4949.2055 | F7: 4880.1927 | G7: 4875.2632 | H7: 4885.1221 | I7: 4939.3465 | J7: 5003.4298 | K7: 5067.5132 | L7: 3544.3774 | M7: 3512.9803 | N7: 3502.5146 | O7: 3446.6977 | P7: 3443.2091 | Q7: 3544.3774 | R7: 3558.3316 | S7: 3509.4918 | T7: 3593.2172 | U7: 3509.4918 | V7: 3526.9346 | W7: 3547.8659 | X7: 3467.629 | Y7: 3526.9346 | Z7: 3600.1943 | AA7: 3460.6519 | AB7: 3523.446 | AD7: Polyurethane Adhesives | AE7: ASP5 | AF7: ASP9 | AG7: ASP6 | AH7: ASP1 | AI7: ASP9 | AJ7: ASP1 | AK7: ASP5 | AL7: ASP8 | AM7: ASP4 | AN7: ASP3 | AO7: ASP3 | AP7: ASP7 | AQ7: ASP8 | AR7: ASP8 | AS7: ASP4 | AT7: ASP8 | AU7: ASP8 | AV7: ASP9 | AW7: ASP9 | AX7: ASP2 | AY7: ASP2 | AZ7: ASP6 | BA7: ASP1 | BB7: ASP5 | BC7: ASP2 | BD7: ASP1
B8: Silicone Adhesives | C8: 5591.4039 | D8: 5433.0536 | E8: 5824.3791 | F8: 5716.3096 | G8: 5653.743 | H8: 5807.3155 | I8: 5733.3732 | J8: 5693.5581 | K8: 5665.1187 | L8: 4038.2362 | M8: 4018.5182 | N8: 3900.2105 | O8: 3994.8567 | P8: 3983.0259 | Q8: 4022.4618 | R8: 4006.6875 | S8: 3931.7593 | T8: 3959.3644 | U8: 3904.1541 | V8: 3986.9695 | W8: 3955.4208 | X8: 3923.8721 | Y8: 3986.9695 | Z8: 4061.8977 | AA8: 4010.6311 | AB8: 4057.9541 | AD8: Silicone Adhesives | AE8: ASP8 | AF8: ASP2 | AG8: ASP5 | AH8: ASP2 | AI8: ASP3 | AJ8: ASP7 | AK8: ASP4 | AL8: ASP6 | AM8: ASP5 | AN8: ASP9 | AO8: ASP2 | AP8: ASP9 | AQ8: ASP4 | AR8: ASP7 | AS8: ASP5 | AT8: ASP8 | AU8: ASP4 | AV8: ASP2 | AW8: ASP4 | AX8: ASP2 | AY8: ASP6 | AZ8: ASP4 | BA8: ASP7 | BB8: ASP3 | BC8: ASP9 | BD8: ASP9
B9: Cyanoacrylate Adhesives | C9: 2134.0889 | D9: 2191.4226 | E9: 2286.5238 | F9: 2345.6777 | G9: 2347.9528 | H9: 2343.4025 | I9: 2343.4025 | J9: 2256.9469 | K9: 2309.2753 | L9: 1536.4833 | M9: 1544.0672 | N9: 1541.0336 | O9: 1501.5977 | P9: 1498.5642 | Q9: 1503.1145 | R9: 1507.6648 | S9: 1525.866 | T9: 1510.6983 | U9: 1531.933 | V9: 1497.0474 | W9: 1538.0001 | X9: 1509.1816 | Y9: 1504.6313 | Z9: 1513.7319 | AA9: 1565.3019 | AB9: 1538.0001 | AD9: Cyanoacrylate Adhesives | AE9: ASP5 | AF9: ASP8 | AG9: ASP1 | AH9: ASP7 | AI9: ASP3 | AJ9: ASP2 | AK9: ASP1 | AL9: ASP1 | AM9: ASP9 | AN9: ASP3 | AO9: ASP2 | AP9: ASP2 | AQ9: ASP7 | AR9: ASP8 | AS9: ASP7 | AT9: ASP6 | AU9: ASP5 | AV9: ASP1 | AW9: ASP3 | AX9: ASP6 | AY9: ASP1 | AZ9: ASP7 | BA9: ASP3 | BB9: ASP1 | BC9: ASP1 | BD9: ASP2
B10: Ethylene Vinyl Acetate Adhesives | C10: 11688.782 | D10: 11794.297 | E10: 12593.089 | F10: 12868.211 | G10: 12493.045 | H10: 12868.211 | I10: 12543.067 | J10: 12355.484 | K10: 12568.078 | L10: 7761.2573 | M10: 7917.5767 | N10: 7987.9204 | O10: 8058.2641 | P10: 7894.1288 | Q10: 7948.8405 | R10: 7878.4968 | S10: 7909.7607 | T10: 7980.1044 | U10: 7941.0246 | V10: 7722.1774 | W10: 8019.1843 | X10: 8058.2641 | Y10: 7808.1531 | Z10: 7987.9204 | AA10: 7917.5767 | AB10: 7761.2573 | AD10: Ethylene Vinyl Acetate Adhesives | AE10: ASP6 | AF10: ASP7 | AG10: ASP4 | AH10: ASP7 | AI10: ASP7 | AJ10: ASP5 | AK10: ASP9 | AL10: ASP5 | AM10: ASP6 | AN10: ASP7 | AO10: ASP5 | AP10: ASP7 | AQ10: ASP6 | AR10: ASP7 | AS10: ASP4 | AT10: ASP4 | AU10: ASP4 | AV10: ASP2 | AW10: ASP7 | AX10: ASP8 | AY10: ASP3 | AZ10: ASP3 | BA10: ASP3 | BB10: ASP8 | BC10: ASP8 | BD10: ASP4
B11: Others (Polyvinyl Acetate, Rubber-based, Phenolic, etc.) | C11: 2369.7943 | D11: 2407.41 | E11: 2492.3489 | F11: 2499.6294 | G11: 2421.971 | H11: 2426.8246 | I11: 2407.41 | J11: 2429.2515 | K11: 2451.0929 | L11: 1656.7628 | M11: 1685.1264 | N11: 1655.0944 | O11: 1660.0997 | P11: 1708.4845 | Q11: 1725.169 | R11: 1655.0944 | S11: 1681.7895 | T11: 1666.7735 | U11: 1720.1636 | V11: 1650.0891 | W11: 1703.4792 | X11: 1675.1157 | Y11: 1700.1423 | Z11: 1711.8214 | AA11: 1691.8001 | AB11: 1696.8054 | AD11: Others (Polyvinyl Acetate, Rubber-based, Phenolic, etc.) | AE11: ASP3 | AF11: ASP8 | AG11: ASP6 | AH11: ASP6 | AI11: ASP1 | AJ11: ASP6 | AK11: ASP3 | AL11: ASP6 | AM11: ASP8 | AN11: ASP7 | AO11: ASP9 | AP11: ASP5 | AQ11: ASP5 | AR11: ASP3 | AS11: ASP2 | AT11: ASP7 | AU11: ASP4 | AV11: ASP8 | AW11: ASP8 | AX11: ASP5 | AY11: ASP7 | AZ11: ASP5 | BA11: ASP2 | BB11: ASP9 | BC11: ASP7 | BD11: ASP6
C15: U.S. | D15: Canada | E15: Germany | F15: U.K. | G15: France | H15: Italy | I15: Spain | J15: Russia | K15: Rest of Europe | L15: China | M15: India | N15: Japan | O15: South Korea | P15: ASEAN | Q15: Australia | R15: Rest of Asia Pacific | S15: Brazil | T15: Mexico | U15: Argentina | V15: Rest of Latin America | W15: Israel | X15: GCC | Y15: Rest of Middle East | Z15: North Africa | AA15: Central Africa | AB15: South Africa
B16: By Product
B17: Adhesives
B18: Acrylic Adhesives | C18: 0.1744 | D18: 0.1634 | E18: 0.1918 | F18: 0.1743 | G18: 0.167 | H18: 0.1577 | I18: 0.1661 | J18: 0.1701 | K18: 0.188 | L18: 0.159 | M18: 0.1909 | N18: 0.1722 | O18: 0.1731 | P18: 0.1851 | Q18: 0.1684 | R18: 0.1894 | S18: 0.1679 | T18: 0.1856 | U18: 0.1815 | V18: 0.1853 | W18: 0.1715 | X18: 0.1772 | Y18: 0.1811 | Z18: 0.1584 | AA18: 0.1639 | AB18: 0.1706
B19: Epoxy Adhesives | C19: 0.1687 | D19: 0.1781 | E19: 0.1865 | F19: 0.1754 | G19: 0.1707 | H19: 0.1726 | I19: 0.1741 | J19: 0.1982 | K19: 0.1706 | L19: 0.1764 | M19: 0.1839 | N19: 0.1682 | O19: 0.1768 | P19: 0.1867 | Q19: 0.183 | R19: 0.1798 | S19: 0.1665 | T19: 0.1793 | U19: 0.1972 | V19: 0.186 | W19: 0.1964 | X19: 0.1789 | Y19: 0.1828 | Z19: 0.1753 | AA19: 0.2 | AB19: 0.1769
B20: Polyurethane Adhesives | C20: 0.1985 | D20: 0.1694 | E20: 0.1834 | F20: 0.1767 | G20: 0.1807 | H20: 0.1803 | I20: 0.1677 | J20: 0.1678 | K20: 0.1945 | L20: 0.1758 | M20: 0.17 | N20: 0.179 | O20: 0.1678 | P20: 0.1742 | Q20: 0.1989 | R20: 0.1963 | S20: 0.1711 | T20: 0.1784 | U20: 0.1917 | V20: 0.196 | W20: 0.1777 | X20: 0.1829 | Y20: 0.19 | Z20: 0.1998 | AA20: 0.1806 | AB20: 0.1686
B21: Silicone Adhesives | C21: 0.1168 | D21: 0.1275 | E21: 0.1464 | F21: 0.1438 | G21: 0.148 | H21: 0.1346 | I21: 0.1467 | J21: 0.1238 | K21: 0.1349 | L21: 0.1485 | M21: 0.1242 | N21: 0.1391 | O21: 0.1255 | P21: 0.1272 | Q21: 0.1485 | R21: 0.1408 | S21: 0.1322 | T21: 0.1395 | U21: 0.1372 | V21: 0.1287 | W21: 0.1331 | X21: 0.1198 | Y21: 0.1261 | Z21: 0.1479 | AA21: 0.1241 | AB21: 0.1272
