Workbook

Sheet Data
B1: Market | C1: Global High Energy Laser Market | AE1: =VLOOKUP(AE3,$B$120:$D$151,3,0) -> 0.120736 | AF1: =VLOOKUP(AF3,$B$120:$D$151,3,0) -> 0.106736 | AG1: =VLOOKUP(AG3,$B$120:$D$151,3,0) -> 0.12416182 | AH1: =VLOOKUP(AH3,$B$120:$D$151,3,0) -> 0.10898555 | AI1: =VLOOKUP(AI3,$B$120:$D$151,3,0) -> 0.096482248 | AJ1: =VLOOKUP(AJ3,$B$120:$D$151,3,0) -> 0.11689586 | AK1: =VLOOKUP(AK3,$B$120:$D$151,3,0) -> 0.088281079 | AL1: =VLOOKUP(AL3,$B$120:$D$151,3,0) -> 0.080810923 | ... BD1: =VLOOKUP(BD3,$B$120:$D$151,3,0) -> 0.086528747
D2: 0.001
C3: U.S. | D3: Canada | E3: U.K. | F3: Germany | G3: Italy | H3: France | I3: Spain | J3: Russia | K3: Rest of Europe | L3: China | M3: India | N3: Japan | O3: South Korea | P3: ASEAN | Q3: Australia | R3: Rest of Asia Pacific | S3: Brazil | T3: Argentina | U3: Mexico | V3: Rest of Latin America | W3: GCC | X3: Israel | Y3: Rest of Middle East | Z3: South Africa | AA3: North Africa | AB3: Central Africa | AE3: U.S. | AF3: Canada | AG3: U.K. | AH3: Germany | AI3: Italy | AJ3: France | AK3: Spain | AL3: Russia | AM3: Rest of Europe | AN3: China | AO3: India | AP3: Japan | AQ3: South Korea | AR3: ASEAN | AS3: Australia | AT3: Rest of Asia Pacific | AU3: Brazil | AV3: Argentina | AW3: Mexico | AX3: Rest of Latin America | AY3: GCC | AZ3: Israel | BA3: Rest of Middle East | BB3: South Africa | BC3: North Africa | BD3: Central Africa | BG3: U.S. | BH3: Canada | BI3: U.K. | BJ3: Germany | BK3: Italy | BL3: France | BM3: Spain | BN3: Russia | BO3: Rest of Europe | BP3: China | BQ3: India | BR3: Japan | BS3: South Korea | BT3: ASEAN | BU3: Australia | BV3: Rest of Asia Pacific | BW3: Brazil | BX3: Argentina | BY3: Mexico | BZ3: Rest of Latin America | CA3: GCC | CB3: Israel | CC3: Rest of Middle East | CD3: South Africa | CE3: North Africa | CF3: Central Africa
B4: By Laser Type | AD4: By Laser Type | AE4: =AE5*C5+AE11*C11+AE16*C16+AE20*C20+AE21*C21 -> 0.120736 | AF4: =AF5*D5+AF11*D11+AF16*D16+AF20*D20+AF21*D21 -> 0.106736 | AG4: =AG5*E5+AG11*E11+AG16*E16+AG20*E20+AG21*E21 -> 0.12416182 | AH4: =AH5*F5+AH11*F11+AH16*F16+AH20*F20+AH21*F21 -> 0.10898555 | AI4: =AI5*G5+AI11*G11+AI16*G16+AI20*G20+AI21*G21 -> 0.096482248 | AJ4: =AJ5*H5+AJ11*H11+AJ16*H16+AJ20*H20+AJ21*H21 -> 0.11689586 | AK4: =AK5*I5+AK11*I11+AK16*I16+AK20*I20+AK21*I21 -> 0.088281079 | AL4: =AL5*J5+AL11*J11+AL16*J16+AL20*J20+AL21*J21 -> 0.080810923 | ... BD4: =BD5*AB5+BD11*AB11+BD16*AB16+BD20*AB20+BD21*AB21 -> 0.086528747 | BF4: By Laser Type
B5: Solid-State Lasers | C5: =1-C11-C16-C20-C21 -> 0.2671 | D5: =1-D11-D16-D20-D21 -> 0.2244 | E5: =1-E11-E16-E20-E21 -> 0.2077 | F5: =1-F11-F16-F20-F21 -> 0.2358 | G5: =1-G11-G16-G20-G21 -> 0.2949 | H5: =1-H11-H16-H20-H21 -> 0.266 | I5: =1-I11-I16-I20-I21 -> 0.2658 | J5: =1-J11-J16-J20-J21 -> 0.2594 | ... AB5: =1-AB11-AB16-AB20-AB21 -> 0.2503 | AD5: Solid-State Lasers | AE5: =SUMPRODUCT(AE6:AE10,C6:C10) -> 0.1120884 | AF5: =SUMPRODUCT(AF6:AF10,D6:D10) -> 0.098416933 | AG5: =SUMPRODUCT(AG6:AG10,E6:E10) -> 0.1155609 | AH5: =SUMPRODUCT(AH6:AH10,F6:F10) -> 0.10065615 | AI5: =SUMPRODUCT(AI6:AI10,G6:G10) -> 0.087554589 | AJ5: =SUMPRODUCT(AJ6:AJ10,H6:H10) -> 0.10813707 | AK5: =SUMPRODUCT(AK6:AK10,I6:I10) -> 0.080785268 | AL5: =SUMPRODUCT(AL6:AL10,J6:J10) -> 0.071945253 | ... BD5: =SUMPRODUCT(BD6:BD10,AB6:AB10) -> 0.07830623 | BF5: Solid-State Lasers | BG5: CMI_Trend_52 | BH5: CMI_Trend_38 | BI5: CMI_Trend_25 | BJ5: CMI_Trend_20 | BK5: CMI_Trend_60 | BL5: CMI_Trend_38 | BM5: CMI_Trend_46 | BN5: CMI_Trend_25 | BO5: CMI_Trend_60 | BP5: CMI_Trend_38 | BQ5: CMI_Trend_46 | BR5: CMI_Trend_38 | BS5: CMI_Trend_52 | BT5: CMI_Trend_46 | BU5: CMI_Trend_25 | BV5: CMI_Trend_56 | BW5: CMI_Trend_20 | BX5: CMI_Trend_52 | BY5: CMI_Trend_52 | BZ5: CMI_Trend_38 | CA5: CMI_Trend_52 | CB5: CMI_Trend_25 | CC5: CMI_Trend_20 | CD5: CMI_Trend_25 | CE5: CMI_Trend_38 | CF5: CMI_Trend_20
B6: Nd:YAG | C6: 0.3785 | D6: 0.3855 | E6: 0.3841 | F6: 0.3881 | G6: 0.4059 | H6: 0.395 | I6: 0.3956 | J6: 0.398 | K6: 0.3856 | L6: 0.3849 | M6: 0.385 | N6: 0.3792 | O6: 0.4049 | P6: 0.3774 | Q6: 0.3796 | R6: 0.3805 | S6: 0.3909 | T6: 0.3788 | U6: 0.391 | V6: 0.3974 | W6: 0.404 | X6: 0.3973 | Y6: 0.3813 | Z6: 0.3974 | AA6: 0.4053 | AB6: 0.3973 | AD6: Nd:YAG | AE6: 0.099480531 | AF6: 0.085697051 | AG6: 0.10308768 | AH6: 0.088370575 | AI6: 0.075624769 | AJ6: 0.096155453 | AK6: 0.068148962 | AL6: 0.059979635 | AM6: 0.081271568 | AN6: 0.12974774 | AO6: 0.13727009 | AP6: 0.095149165 | AQ6: 0.11203663 | AR6: 0.11960198 | AS6: 0.087495257 | AT6: 0.10224243 | AU6: 0.077810167 | AV6: 0.062200937 | AW6: 0.086280116 | AX6: 0.070858388 | AY6: 0.1047843 | AZ6: 0.11216487 | BA6: 0.093280184 | BB6: 0.08092379 | BC6: 0.073535446 | BD6: 0.066024134 | BF6: Nd:YAG | BG6: CMI_Trend_60 | BH6: CMI_Trend_56 | BI6: CMI_Trend_46 | BJ6: CMI_Trend_25 | BK6: CMI_Trend_38 | BL6: CMI_Trend_56 | BM6: CMI_Trend_46 | BN6: CMI_Trend_52 | BO6: CMI_Trend_46 | BP6: CMI_Trend_25 | BQ6: CMI_Trend_20 | BR6: CMI_Trend_56 | BS6: CMI_Trend_60 | BT6: CMI_Trend_60 | BU6: CMI_Trend_38 | BV6: CMI_Trend_20 | BW6: CMI_Trend_25 | BX6: CMI_Trend_46 | BY6: CMI_Trend_46 | BZ6: CMI_Trend_56 | CA6: CMI_Trend_25 | CB6: CMI_Trend_38 | CC6: CMI_Trend_60 | CD6: CMI_Trend_38 | CE6: CMI_Trend_20 | CF6: CMI_Trend_52
B7: Yb:YAG | C7: 0.2411 | D7: 0.2494 | E7: 0.2407 | F7: 0.2303 | G7: 0.2307 | H7: 0.2285 | I7: 0.255 | J7: 0.2297 | K7: 0.2541 | L7: 0.2336 | M7: 0.2327 | N7: 0.2471 | O7: 0.2343 | P7: 0.224 | Q7: 0.245 | R7: 0.2266 | S7: 0.232 | T7: 0.2557 | U7: 0.2381 | V7: 0.23 | W7: 0.2581 | X7: 0.2275 | Y7: 0.2412 | Z7: 0.2311 | AA7: 0.2256 | AB7: 0.2439 | AD7: Yb:YAG | AE7: 0.12975666 | AF7: 0.11597318 | AG7: 0.1333638 | AH7: 0.1186467 | AI7: 0.1059009 | AJ7: 0.12643158 | AK7: 0.098425089 | AL7: 0.090255761 | AM7: 0.11154769 | AN7: 0.16002387 | AO7: 0.16754622 | AP7: 0.12542529 | AQ7: 0.14231276 | AR7: 0.14987811 | AS7: 0.11777138 | AT7: 0.13251856 | AU7: 0.10808629 | AV7: 0.092477063 | AW7: 0.11655624 | AX7: 0.10113451 | AY7: 0.13506043 | AZ7: 0.14244099 | BA7: 0.12355631 | BB7: 0.11119992 | BC7: 0.10381157 | BD7: 0.09630026 | BF7: Yb:YAG | BG7: CMI_Trend_46 | BH7: CMI_Trend_60 | BI7: CMI_Trend_60 | BJ7: CMI_Trend_52 | BK7: CMI_Trend_46 | BL7: CMI_Trend_46 | BM7: CMI_Trend_20 | BN7: CMI_Trend_60 | BO7: CMI_Trend_56 | BP7: CMI_Trend_52 | BQ7: CMI_Trend_46 | BR7: CMI_Trend_20 | BS7: CMI_Trend_56 | BT7: CMI_Trend_60 | BU7: CMI_Trend_60 | BV7: CMI_Trend_60 | BW7: CMI_Trend_20 | BX7: CMI_Trend_25 | BY7: CMI_Trend_60 | BZ7: CMI_Trend_60 | CA7: CMI_Trend_56 | CB7: CMI_Trend_52 | CC7: CMI_Trend_46 | CD7: CMI_Trend_56 | CE7: CMI_Trend_25 | CF7: CMI_Trend_60
B8: Tm:YAG | C8: 0.0895 | D8: 0.1044 | E8: 0.0917 | F8: 0.0862 | G8: 0.0882 | H8: 0.0803 | I8: 0.0914 | J8: 0.0815 | K8: 0.0864 | L8: 0.0901 | M8: 0.1019 | N8: 0.0882 | O8: 0.1042 | P8: 0.0956 | Q8: 0.0857 | R8: 0.08 | S8: 0.0926 | T8: 0.1013 | U8: 0.1033 | V8: 0.0969 | W8: 0.0813 | X8: 0.0848 | Y8: 0.0899 | Z8: 0.092 | AA8: 0.0992 | AB8: 0.0888 | AD8: Tm:YAG | AE8: 0.12159586 | AF8: 0.10781238 | AG8: 0.125203 | AH8: 0.1104859 | AI8: 0.097740096 | AJ8: 0.11827078 | AK8: 0.090264289 | AL8: 0.082094961 | AM8: 0.10338689 | AN8: 0.15186307 | AO8: 0.15938542 | AP8: 0.11726449 | AQ8: 0.13415196 | AR8: 0.14171731 | AS8: 0.10961058 | AT8: 0.12435776 | AU8: 0.099925494 | AV8: 0.084316263 | AW8: 0.10839544 | AX8: 0.092973715 | AY8: 0.12689963 | AZ8: 0.13428019 | BA8: 0.11539551 | BB8: 0.10303912 | BC8: 0.095650772 | BD8: 0.08813946 | BF8: Tm:YAG | BG8: CMI_Trend_46 | BH8: CMI_Trend_46 | BI8: CMI_Trend_20 | BJ8: CMI_Trend_38 | BK8: CMI_Trend_20 | BL8: CMI_Trend_20 | BM8: CMI_Trend_25 | BN8: CMI_Trend_46 | BO8: CMI_Trend_20 | BP8: CMI_Trend_60 | BQ8: CMI_Trend_56 | BR8: CMI_Trend_46 | BS8: CMI_Trend_20 | BT8: CMI_Trend_25 | BU8: CMI_Trend_20 | BV8: CMI_Trend_46 | BW8: CMI_Trend_56 | BX8: CMI_Trend_46 | BY8: CMI_Trend_25 | BZ8: CMI_Trend_25 | CA8: CMI_Trend_52 | CB8: CMI_Trend_20 | CC8: CMI_Trend_56 | CD8: CMI_Trend_56 | CE8: CMI_Trend_38 | CF8: CMI_Trend_56
B9: Er:YAG | C9: 0.0985 | D9: 0.1058 | E9: 0.1083 | F9: 0.0963 | G9: 0.1152 | H9: 0.1148 | I9: 0.0956 | J9: 0.1154 | K9: 0.1074 | L9: 0.0997 | M9: 0.1106 | N9: 0.1165 | O9: 0.0991 | P9: 0.1077 | Q9: 0.1012 | R9: 0.0973 | S9: 0.1164 | T9: 0.1088 | U9: 0.1135 | V9: 0.1017 | W9: 0.1154 | X9: 0.1113 | Y9: 0.1071 | Z9: 0.0996 | AA9: 0.1111 | AB9: 0.1136 | AD9: Er:YAG | AE9: 0.10627495 | AF9: 0.092491471 | AG9: 0.10988209 | AH9: 0.095164994 | AI9: 0.082419189 | AJ9: 0.10294987 | AK9: 0.074943382 | AL9: 0.066774054 | AM9: 0.088065987 | AN9: 0.13654216 | AO9: 0.14406451 | AP9: 0.10194358 | AQ9: 0.11883105 | AR9: 0.1263964 | AS9: 0.094289676 | AT9: 0.10903685 | AU9: 0.084604587 | AV9: 0.068995357 | AW9: 0.093074535 | AX9: 0.077652808 | AY9: 0.11157872 | AZ9: 0.11895929 | BA9: 0.1000746 | BB9: 0.087718209 | BC9: 0.080329865 | BD9: 0.072818553 | BF9: Er:YAG | BG9: CMI_Trend_46 | BH9: CMI_Trend_20 | BI9: CMI_Trend_38 | BJ9: CMI_Trend_52 | BK9: CMI_Trend_46 | BL9: CMI_Trend_20 | BM9: CMI_Trend_52 | BN9: CMI_Trend_38 | BO9: CMI_Trend_56 | BP9: CMI_Trend_56 | BQ9: CMI_Trend_60 | BR9: CMI_Trend_60 | BS9: CMI_Trend_52 | BT9: CMI_Trend_25 | BU9: CMI_Trend_38 | BV9: CMI_Trend_52 | BW9: CMI_Trend_46 | BX9: CMI_Trend_38 | BY9: CMI_Trend_60 | BZ9: CMI_Trend_56 | CA9: CMI_Trend_56 | CB9: CMI_Trend_52 | CC9: CMI_Trend_25 | CD9: CMI_Trend_56 | CE9: CMI_Trend_25 | CF9: CMI_Trend_25
B10: Others (Ce:YAG, Ho:YAG, etc.) | C10: =1-SUM(C6:C9) -> 0.1924 | D10: =1-SUM(D6:D9) -> 0.1549 | E10: =1-SUM(E6:E9) -> 0.1752 | F10: =1-SUM(F6:F9) -> 0.1991 | G10: =1-SUM(G6:G9) -> 0.16 | H10: =1-SUM(H6:H9) -> 0.1814 | I10: =1-SUM(I6:I9) -> 0.1624 | J10: =1-SUM(J6:J9) -> 0.1754 | ... AB10: =1-SUM(AB6:AB9) -> 0.1564 | AD10: Others (Ce:YAG, Ho:YAG, etc.) | AE10: 0.11330446 | AF10: 0.099520978 | AG10: 0.1169116 | AH10: 0.1021945 | AI10: 0.089448696 | AJ10: 0.10997938 | AK10: 0.081972889 | AL10: 0.073803561 | AM10: 0.095095494 | AN10: 0.14357167 | AO10: 0.15109402 | AP10: 0.10897309 | AQ10: 0.12586056 | AR10: 0.13342591 | AS10: 0.10131918 | AT10: 0.11606636 | AU10: 0.091634094 | AV10: 0.076024863 | AW10: 0.10010404 | AX10: 0.084682315 | AY10: 0.11860823 | AZ10: 0.12598879 | BA10: 0.10710411 | BB10: 0.094747716 | BC10: 0.087359372 | BD10: 0.07984806 | BF10: Others (Ce:YAG, Ho:YAG, etc.) | BG10: CMI_Trend_56 | BH10: CMI_Trend_52 | BI10: CMI_Trend_25 | BJ10: CMI_Trend_52 | BK10: CMI_Trend_46 | BL10: CMI_Trend_38 | BM10: CMI_Trend_25 | BN10: CMI_Trend_20 | BO10: CMI_Trend_38 | BP10: CMI_Trend_56 | BQ10: CMI_Trend_46 | BR10: CMI_Trend_38 | BS10: CMI_Trend_60 | BT10: CMI_Trend_52 | BU10: CMI_Trend_25 | BV10: CMI_Trend_60 | BW10: CMI_Trend_20 | BX10: CMI_Trend_46 | BY10: CMI_Trend_20 | BZ10: CMI_Trend_56 | CA10: CMI_Trend_46 | CB10: CMI_Trend_20 | CC10: CMI_Trend_20 | CD10: CMI_Trend_20 | CE10: CMI_Trend_60 | CF10: CMI_Trend_52
B11: Fiber Lasers | C11: 0.3599 | D11: 0.3653 | E11: 0.3646 | F11: 0.3534 | G11: 0.3472 | H11: 0.3492 | I11: 0.3389 | J11: 0.3503 | K11: 0.345 | L11: 0.3546 | M11: 0.3655 | N11: 0.3314 | O11: 0.3456 | P11: 0.3352 | Q11: 0.3652 | R11: 0.3636 | S11: 0.3346 | T11: 0.3423 | U11: 0.3352 | V11: 0.345 | W11: 0.3476 | X11: 0.358 | Y11: 0.3397 | Z11: 0.3374 | AA11: 0.3448 | AB11: 0.3566 | AD11: Fiber Lasers | AE11: =SUMPRODUCT(AE12:AE15,C12:C15) -> 0.1380884 | AF11: =SUMPRODUCT(AF12:AF15,D12:D15) -> 0.12341442 | AG11: =SUMPRODUCT(AG12:AG15,E12:E15) -> 0.14103614 | AH11: =SUMPRODUCT(AH12:AH15,F12:F15) -> 0.12719744 | AI11: =SUMPRODUCT(AI12:AI15,G12:G15) -> 0.11373754 | AJ11: =SUMPRODUCT(AJ12:AJ15,H12:H15) -> 0.13366572 | AK11: =SUMPRODUCT(AK12:AK15,I12:I15) -> 0.10619553 | AL11: =SUMPRODUCT(AL12:AL15,J12:J15) -> 0.098591304 | ... BD11: =SUMPRODUCT(BD12:BD15,AB12:AB15) -> 0.1038188 | BF11: Fiber Lasers | BG11: CMI_Trend_46 | BH11: CMI_Trend_20 | BI11: CMI_Trend_25 | BJ11: CMI_Trend_46 | BK11: CMI_Trend_60 | BL11: CMI_Trend_38 | BM11: CMI_Trend_60 | BN11: CMI_Trend_38 | BO11: CMI_Trend_20 | BP11: CMI_Trend_60 | BQ11: CMI_Trend_20 | BR11: CMI_Trend_20 | BS11: CMI_Trend_56 | BT11: CMI_Trend_60 | BU11: CMI_Trend_25 | BV11: CMI_Trend_52 | BW11: CMI_Trend_56 | BX11: CMI_Trend_25 | BY11: CMI_Trend_38 | BZ11: CMI_Trend_52 | CA11: CMI_Trend_56 | CB11: CMI_Trend_38 | CC11: CMI_Trend_52 | CD11: CMI_Trend_46 | CE11: CMI_Trend_46 | CF11: CMI_Trend_56
B12: Continuous Wave Fiber Lasers | C12: 0.4769 | D12: 0.4691 | E12: 0.4918 | F12: 0.4713 | G12: 0.4686 | H12: 0.4775 | I12: 0.4844 | J12: 0.4652 | K12: 0.4852 | L12: 0.4672 | M12: 0.487 | N12: 0.4962 | O12: 0.4899 | P12: 0.4692 | Q12: 0.4786 | R12: 0.4905 | S12: 0.4723 | T12: 0.4715 | U12: 0.4691 | V12: 0.4976 | W12: 0.4905 | X12: 0.4672 | Y12: 0.4798 | Z12: 0.4866 | AA12: 0.4895 | AB12: 0.4745 | AD12: Continuous Wave Fiber Lasers | AE12: 0.1248808 | AF12: 0.11109732 | AG12: 0.12848794 | AH12: 0.11377084 | AI12: 0.10102504 | AJ12: 0.12155572 | AK12: 0.093549232 | AL12: 0.085379904 | AM12: 0.10667184 | AN12: 0.15514801 | AO12: 0.16267036 | AP12: 0.12054943 | AQ12: 0.1374369 | AR12: 0.14500225 | AS12: 0.11289553 | AT12: 0.1276427 | AU12: 0.10321044 | AV12: 0.087601207 | AW12: 0.11168039 | AX12: 0.096258658 | AY12: 0.13018457 | AZ12: 0.13756514 | BA12: 0.11868045 | BB12: 0.10632406 | BC12: 0.098935715 | BD12: 0.091424403 | BF12: Continuous Wave Fiber Lasers | BG12: CMI_Trend_46 | BH12: CMI_Trend_25 | BI12: CMI_Trend_25 | BJ12: CMI_Trend_60 | BK12: CMI_Trend_38 | BL12: CMI_Trend_38 | BM12: CMI_Trend_25 | BN12: CMI_Trend_46 | BO12: CMI_Trend_25 | BP12: CMI_Trend_25 | BQ12: CMI_Trend_20 | BR12: CMI_Trend_20 | BS12: CMI_Trend_25 | BT12: CMI_Trend_46 | BU12: CMI_Trend_46 | BV12: CMI_Trend_52 | BW12: CMI_Trend_46 | BX12: CMI_Trend_46 | BY12: CMI_Trend_60 | BZ12: CMI_Trend_20 | CA12: CMI_Trend_56 | CB12: CMI_Trend_38 | CC12: CMI_Trend_25 | CD12: CMI_Trend_25 | CE12: CMI_Trend_46 | CF12: CMI_Trend_46
B13: Pulsed Fiber Lasers | C13: 0.2331 | D13: 0.2592 | E13: 0.2354 | F13: 0.2289 | G13: 0.2481 | H13: 0.2357 | I13: 0.238 | J13: 0.2441 | K13: 0.2484 | L13: 0.2345 | M13: 0.2492 | N13: 0.2507 | O13: 0.2479 | P13: 0.2486 | Q13: 0.2476 | R13: 0.2264 | S13: 0.2342 | T13: 0.2446 | U13: 0.2436 | V13: 0.2255 | W13: 0.2381 | X13: 0.2543 | Y13: 0.2334 | Z13: 0.2441 | AA13: 0.2403 | AB13: 0.2261 | AD13: Pulsed Fiber Lasers | AE13: 0.1428808 | AF13: 0.12909732 | AG13: 0.14648794 | AH13: 0.13177084 | AI13: 0.11902504 | AJ13: 0.13955572 | AK13: 0.11154923 | AL13: 0.1033799 | AM13: 0.12467184 | AN13: 0.17314801 | AO13: 0.18067036 | AP13: 0.13854943 | AQ13: 0.1554369 | AR13: 0.16300225 | AS13: 0.13089553 | AT13: 0.1456427 | AU13: 0.12121044 | AV13: 0.10560121 | AW13: 0.12968039 | AX13: 0.11425866 | AY13: 0.14818457 | AZ13: 0.15556514 | BA13: 0.13668045 | BB13: 0.12432406 | BC13: 0.11693572 | BD13: 0.1094244 | BF13: Pulsed Fiber Lasers | BG13: CMI_Trend_56 | BH13: CMI_Trend_46 | BI13: CMI_Trend_38 | BJ13: CMI_Trend_56 | BK13: CMI_Trend_46 | BL13: CMI_Trend_20 | BM13: CMI_Trend_25 | BN13: CMI_Trend_60 | BO13: CMI_Trend_56 | BP13: CMI_Trend_25 | BQ13: CMI_Trend_52 | BR13: CMI_Trend_52 | BS13: CMI_Trend_38 | BT13: CMI_Trend_20 | BU13: CMI_Trend_25 | BV13: CMI_Trend_60 | BW13: CMI_Trend_20 | BX13: CMI_Trend_56 | BY13: CMI_Trend_56 | BZ13: CMI_Trend_20 | CA13: CMI_Trend_56 | CB13: CMI_Trend_52 | CC13: CMI_Trend_56 | CD13: CMI_Trend_60 | CE13: CMI_Trend_56 | CF13: CMI_Trend_56
B14: Raman Fiber Lasers | C14: 0.0662 | D14: 0.075 | E14: 0.065 | F14: 0.0686 | G14: 0.0738 | H14: 0.0826 | I14: 0.0677 | J14: 0.0699 | K14: 0.0791 | L14: 0.0833 | M14: 0.0791 | N14: 0.0658 | O14: 0.0752 | P14: 0.0838 | Q14: 0.0715 | R14: 0.0747 | S14: 0.0657 | T14: 0.0665 | U14: 0.0848 | V14: 0.0684 | W14: 0.0775 | X14: 0.0837 | Y14: 0.0785 | Z14: 0.074 | AA14: 0.0676 | AB14: 0.0844 | AD14: Raman Fiber Lasers | AE14: 0.1088808 | AF14: 0.095097321 | AG14: 0.11248794 | AH14: 0.097770844 | AI14: 0.085025039 | AJ14: 0.10555572 | AK14: 0.077549232 | AL14: 0.069379904 | AM14: 0.090671837 | AN14: 0.13914801 | AO14: 0.14667036 | AP14: 0.10454943 | AQ14: 0.1214369 | AR14: 0.12900225 | AS14: 0.096895526 | AT14: 0.1116427 | AU14: 0.087210437 | AV14: 0.071601207 | AW14: 0.095680385 | AX14: 0.080258658 | AY14: 0.11418457 | AZ14: 0.12156514 | BA14: 0.10268045 | BB14: 0.090324059 | BC14: 0.082935715 | BD14: 0.075424403 | BF14: Raman Fiber Lasers | BG14: CMI_Trend_25 | BH14: CMI_Trend_52 | BI14: CMI_Trend_38 | BJ14: CMI_Trend_20 | BK14: CMI_Trend_25 | BL14: CMI_Trend_60 | BM14: CMI_Trend_46 | BN14: CMI_Trend_38 | BO14: CMI_Trend_46 | BP14: CMI_Trend_56 | BQ14: CMI_Trend_56 | BR14: CMI_Trend_38 | BS14: CMI_Trend_60 | BT14: CMI_Trend_56 | BU14: CMI_Trend_56 | BV14: CMI_Trend_20 | BW14: CMI_Trend_25 | BX14: CMI_Trend_20 | BY14: CMI_Trend_25 | BZ14: CMI_Trend_52 | CA14: CMI_Trend_56 | CB14: CMI_Trend_56 | CC14: CMI_Trend_56 | CD14: CMI_Trend_25 | CE14: CMI_Trend_60 | CF14: CMI_Trend_25
B15: SBC Fiber Arrays | C15: =1-SUM(C12:C14) -> 0.2238 | D15: =1-SUM(D12:D14) -> 0.1967 | E15: =1-SUM(E12:E14) -> 0.2078 | F15: =1-SUM(F12:F14) -> 0.2312 | G15: =1-SUM(G12:G14) -> 0.2095 | H15: =1-SUM(H12:H14) -> 0.2042 | I15: =1-SUM(I12:I14) -> 0.2099 | J15: =1-SUM(J12:J14) -> 0.2208 | ... AB15: =1-SUM(AB12:AB14) -> 0.215 | AD15: SBC Fiber Arrays | AE15: 0.1698808 | AF15: 0.15609732 | AG15: 0.17348794 | AH15: 0.15877084 | AI15: 0.14602504 | AJ15: 0.16655572 | AK15: 0.13854923 | AL15: 0.1303799 | AM15: 0.15167184 | AN15: 0.20014801 | AO15: 0.20767036 | AP15: 0.16554943 | AQ15: 0.1824369 | AR15: 0.19000225 | AS15: 0.15789553 | AT15: 0.1726427 | AU15: 0.14821044 | AV15: 0.13260121 | AW15: 0.15668039 | AX15: 0.14125866 | AY15: 0.17518457 | AZ15: 0.18256514 | BA15: 0.16368045 | BB15: 0.15132406 | BC15: 0.14393572 | BD15: 0.1364244 | BF15: SBC Fiber Arrays | BG15: CMI_Trend_56 | BH15: CMI_Trend_38 | BI15: CMI_Trend_56 | BJ15: CMI_Trend_56 | BK15: CMI_Trend_38 | BL15: CMI_Trend_25 | BM15: CMI_Trend_25 | BN15: CMI_Trend_25 | BO15: CMI_Trend_52 | BP15: CMI_Trend_25 | BQ15: CMI_Trend_52 | BR15: CMI_Trend_56 | BS15: CMI_Trend_60 | BT15: CMI_Trend_56 | BU15: CMI_Trend_60 | BV15: CMI_Trend_25 | BW15: CMI_Trend_56 | BX15: CMI_Trend_56 | BY15: CMI_Trend_25 | BZ15: CMI_Trend_25 | CA15: CMI_Trend_20 | CB15: CMI_Trend_60 | CC15: CMI_Trend_52 | CD15: CMI_Trend_56 | CE15: CMI_Trend_52 | CF15: CMI_Trend_20
B16: Gas Lasers | C16: 0.0797 | D16: 0.0906 | E16: 0.0877 | F16: 0.0915 | G16: 0.0704 | H16: 0.0728 | I16: 0.0905 | J16: 0.0711 | K16: 0.0752 | L16: 0.0815 | M16: 0.0774 | N16: 0.0724 | O16: 0.0884 | P16: 0.0709 | Q16: 0.0784 | R16: 0.0712 | S16: 0.0827 | T16: 0.0756 | U16: 0.0738 | V16: 0.0888 | W16: 0.0865 | X16: 0.0781 | Y16: 0.0723 | Z16: 0.084 | AA16: 0.0899 | AB16: 0.0832 | AD16: Gas Lasers | AE16: =SUMPRODUCT(AE17:AE19,C17:C19) -> 0.0760884 | AF16: =SUMPRODUCT(AF17:AF19,D17:D19) -> 0.063576921 | AG16: =SUMPRODUCT(AG17:AG19,E17:E19) -> 0.080316445 | AH16: =SUMPRODUCT(AH17:AH19,F17:F19) -> 0.066299844 | AI16: =SUMPRODUCT(AI17:AI19,G17:G19) -> 0.053537539 | AJ16: =SUMPRODUCT(AJ17:AJ19,H17:H19) -> 0.073312823 | AK16: =SUMPRODUCT(AK17:AK19,I17:I19) -> 0.045679632 | AL16: =SUMPRODUCT(AL17:AL19,J17:J19) -> 0.036735004 | ... BD16: =SUMPRODUCT(BD17:BD19,AB17:AB19) -> 0.042589603 | BF16: Gas Lasers | BG16: CMI_Trend_60 | BH16: CMI_Trend_46 | BI16: CMI_Trend_25 | BJ16: CMI_Trend_25 | BK16: CMI_Trend_38 | BL16: CMI_Trend_25 | BM16: CMI_Trend_56 | BN16: CMI_Trend_52 | BO16: CMI_Trend_38 | BP16: CMI_Trend_60 | BQ16: CMI_Trend_46 | BR16: CMI_Trend_52 | BS16: CMI_Trend_52 | BT16: CMI_Trend_60 | BU16: CMI_Trend_52 | BV16: CMI_Trend_38 | BW16: CMI_Trend_56 | BX16: CMI_Trend_38 | BY16: CMI_Trend_52 | BZ16: CMI_Trend_46 | CA16: CMI_Trend_60 | CB16: CMI_Trend_38 | CC16: CMI_Trend_60 | CD16: CMI_Trend_25 | CE16: CMI_Trend_60 | CF16: CMI_Trend_20
B17: Chemical High-Energy Lasers | C17: 0.4482 | D17: 0.4653 | E17: 0.4697 | F17: 0.4601 | G17: 0.4715 | H17: 0.4589 | I17: 0.4464 | J17: 0.4445 | K17: 0.4511 | L17: 0.4513 | M17: 0.4385 | N17: 0.4646 | O17: 0.4464 | P17: 0.4483 | Q17: 0.4687 | R17: 0.445 | S17: 0.4413 | T17: 0.445 | U17: 0.465 | V17: 0.4645 | W17: 0.45 | X17: 0.4582 | Y17: 0.4533 | Z17: 0.4462 | AA17: 0.4387 | AB17: 0.4436 | AD17: Chemical High-Energy Lasers | AE17: 0.075526 | AF17: 0.061742521 | AG17: 0.079133145 | AH17: 0.064416044 | AI17: 0.051670239 | AJ17: 0.072200923 | AK17: 0.044194432 | AL17: 0.036025104 | AM17: 0.057317037 | AN17: 0.10579321 | AO17: 0.11331556 | AP17: 0.071194635 | AQ17: 0.088082101 | AR17: 0.095647454 | AS17: 0.063540726 | AT17: 0.078287904 | AU17: 0.053855637 | AV17: 0.038246407 | AW17: 0.062325585 | AX17: 0.046903858 | AY17: 0.08082977 | AZ17: 0.088210336 | BA17: 0.069325653 | BB17: 0.056969259 | BC17: 0.049580915 | BD17: 0.042069603 | BF17: Chemical High-Energy Lasers | BG17: CMI_Trend_25 | BH17: CMI_Trend_60 | BI17: CMI_Trend_60 | BJ17: CMI_Trend_38 | BK17: CMI_Trend_46 | BL17: CMI_Trend_46 | BM17: CMI_Trend_56 | BN17: CMI_Trend_25 | BO17: CMI_Trend_25 | BP17: CMI_Trend_46 | BQ17: CMI_Trend_46 | BR17: CMI_Trend_56 | BS17: CMI_Trend_38 | BT17: CMI_Trend_52 | BU17: CMI_Trend_46 | BV17: CMI_Trend_20 | BW17: CMI_Trend_25 | BX17: CMI_Trend_60 | BY17: CMI_Trend_52 | BZ17: CMI_Trend_52 | CA17: CMI_Trend_56 | CB17: CMI_Trend_38 | CC17: CMI_Trend_20 | CD17: CMI_Trend_56 | CE17: CMI_Trend_52 | CF17: CMI_Trend_20
B18: Excimer Lasers | C18: 0.2408 | D18: 0.2664 | E18: 0.2479 | F18: 0.2698 | G18: 0.2647 | H18: 0.2505 | I18: 0.2652 | J18: 0.2461 | K18: 0.2467 | L18: 0.2507 | M18: 0.249 | N18: 0.2749 | O18: 0.2418 | P18: 0.2482 | Q18: 0.249 | R18: 0.2548 | S18: 0.268 | T18: 0.2642 | U18: 0.2631 | V18: 0.2653 | W18: 0.2658 | X18: 0.2645 | Y18: 0.2572 | Z18: 0.2732 | AA18: 0.2582 | AB18: 0.2416 | AD18: Excimer Lasers | AE18: 0.098526 | AF18: 0.084742521 | AG18: 0.10213314 | AH18: 0.087416044 | AI18: 0.074670239 | AJ18: 0.095200923 | AK18: 0.067194432 | AL18: 0.059025104 | AM18: 0.080317037 | AN18: 0.12879321 | AO18: 0.13631556 | AP18: 0.094194635 | AQ18: 0.1110821 | AR18: 0.11864745 | AS18: 0.086540726 | AT18: 0.1012879 | AU18: 0.076855637 | AV18: 0.061246407 | AW18: 0.085325585 | AX18: 0.069903858 | AY18: 0.10382977 | AZ18: 0.11121034 | BA18: 0.092325653 | BB18: 0.079969259 | BC18: 0.072580915 | BD18: 0.065069603 | BF18: Excimer Lasers | BG18: CMI_Trend_46 | BH18: CMI_Trend_46 | BI18: CMI_Trend_52 | BJ18: CMI_Trend_52 | BK18: CMI_Trend_25 | BL18: CMI_Trend_20 | BM18: CMI_Trend_20 | BN18: CMI_Trend_52 | BO18: CMI_Trend_52 | BP18: CMI_Trend_56 | BQ18: CMI_Trend_38 | BR18: CMI_Trend_46 | BS18: CMI_Trend_60 | BT18: CMI_Trend_52 | BU18: CMI_Trend_52 | BV18: CMI_Trend_60 | BW18: CMI_Trend_60 | BX18: CMI_Trend_25 | BY18: CMI_Trend_20 | BZ18: CMI_Trend_52 | CA18: CMI_Trend_52 | CB18: CMI_Trend_60 | CC18: CMI_Trend_20 | CD18: CMI_Trend_25 | CE18: CMI_Trend_60 | CF18: CMI_Trend_56
B19: Industrial Gas Lasers (CO₂ etc.) | C19: =1-SUM(C17:C18) -> 0.311 | D19: =1-SUM(D17:D18) -> 0.2683 | E19: =1-SUM(E17:E18) -> 0.2824 | F19: =1-SUM(F17:F18) -> 0.2701 | G19: =1-SUM(G17:G18) -> 0.2638 | H19: =1-SUM(H17:H18) -> 0.2906 | I19: =1-SUM(I17:I18) -> 0.2884 | J19: =1-SUM(J17:J18) -> 0.3094 | ... AB19: =1-SUM(AB17:AB18) -> 0.3148 | AD19: Industrial Gas Lasers (CO₂ etc.) | AE19: 0.059526 | AF19: 0.045742521 | AG19: 0.063133145 | AH19: 0.048416044 | AI19: 0.035670239 | AJ19: 0.056200923 | AK19: 0.028194432 | AL19: 0.020025104 | AM19: 0.041317037 | AN19: 0.089793212 | AO19: 0.097315564 | AP19: 0.055194635 | AQ19: 0.072082101 | AR19: 0.079647454 | AS19: 0.047540726 | AT19: 0.062287904 | AU19: 0.037855637 | AV19: 0.022246407 | AW19: 0.046325585 | AX19: 0.030903858 | AY19: 0.06482977 | AZ19: 0.072210336 | BA19: 0.053325653 | BB19: 0.040969259 | BC19: 0.033580915 | BD19: 0.026069603 | BF19: Industrial Gas Lasers (CO₂ etc.) | BG19: CMI_Trend_25 | BH19: CMI_Trend_38 | BI19: CMI_Trend_56 | BJ19: CMI_Trend_60 | BK19: CMI_Trend_56 | BL19: CMI_Trend_25 | BM19: CMI_Trend_56 | BN19: CMI_Trend_25 | BO19: CMI_Trend_56 | BP19: CMI_Trend_20 | BQ19: CMI_Trend_60 | BR19: CMI_Trend_60 | BS19: CMI_Trend_38 | BT19: CMI_Trend_52 | BU19: CMI_Trend_20 | BV19: CMI_Trend_20 | BW19: CMI_Trend_60 | BX19: CMI_Trend_52 | BY19: CMI_Trend_38 | BZ19: CMI_Trend_60 | CA19: CMI_Trend_60 | CB19: CMI_Trend_56 | CC19: CMI_Trend_20 | CD19: CMI_Trend_52 | CE19: CMI_Trend_52 | CF19: CMI_Trend_46
B20: Semiconductor Lasers | C20: 0.1733 | D20: 0.1899 | E20: 0.1953 | F20: 0.1748 | G20: 0.1668 | H20: 0.18 | I20: 0.1734 | J20: 0.1686 | K20: 0.1974 | L20: 0.1947 | M20: 0.1708 | N20: 0.1923 | O20: 0.1836 | P20: 0.1787 | Q20: 0.1885 | R20: 0.1839 | S20: 0.1884 | T20: 0.164 | U20: 0.1679 | V20: 0.1961 | W20: 0.1771 | X20: 0.1827 | Y20: 0.1791 | Z20: 0.1748 | AA20: 0.1965 | AB20: 0.1721 | AD20: Semiconductor Lasers | AE20: 0.1300884 | AF20: 0.11630492 | AG20: 0.13369554 | AH20: 0.11897844 | AI20: 0.10623264 | AJ20: 0.12676332 | AK20: 0.098756832 | AL20: 0.090587504 | AM20: 0.11187944 | AN20: 0.16035561 | AO20: 0.16787796 | AP20: 0.12575703 | AQ20: 0.1426445 | AR20: 0.15020985 | AS20: 0.11810313 | AT20: 0.1328503 | AU20: 0.10841804 | AV20: 0.092808807 | AW20: 0.11688799 | AX20: 0.10146626 | AY20: 0.13539217 | AZ20: 0.14277274 | BA20: 0.12388805 | BB20: 0.11153166 | BC20: 0.10414332 | BD20: 0.096632003 | BF20: Semiconductor Lasers | BG20: CMI_Trend_52 | BH20: CMI_Trend_25 | BI20: CMI_Trend_52 | BJ20: CMI_Trend_60 | BK20: CMI_Trend_52 | BL20: CMI_Trend_25 | BM20: CMI_Trend_25 | BN20: CMI_Trend_56 | BO20: CMI_Trend_60 | BP20: CMI_Trend_52 | BQ20: CMI_Trend_46 | BR20: CMI_Trend_56 | BS20: CMI_Trend_25 | BT20: CMI_Trend_46 | BU20: CMI_Trend_52 | BV20: CMI_Trend_25 | BW20: CMI_Trend_46 | BX20: CMI_Trend_56 | BY20: CMI_Trend_25 | BZ20: CMI_Trend_46 | CA20: CMI_Trend_25 | CB20: CMI_Trend_25 | CC20: CMI_Trend_46 | CD20: CMI_Trend_25 | CE20: CMI_Trend_52 | CF20: CMI_Trend_25
B21: Other Laser Types | C21: 0.12 | D21: 0.1298 | E21: 0.1447 | F21: 0.1445 | G21: 0.1207 | H21: 0.132 | I21: 0.1314 | J21: 0.1506 | K21: 0.1272 | L21: 0.12 | M21: 0.1327 | N21: 0.1192 | O21: 0.1501 | P21: 0.1516 | Q21: 0.1239 | R21: 0.138 | S21: 0.1498 | T21: 0.1332 | U21: 0.1433 | V21: 0.1281 | W21: 0.1351 | X21: 0.1349 | Y21: 0.1191 | Z21: 0.1257 | AA21: 0.1261 | AB21: 0.1378 | AD21: Other Laser Types | AE21: 0.1040884 | AF21: 0.090304921 | AG21: 0.10769554 | AH21: 0.092978444 | AI21: 0.080232639 | AJ21: 0.10076332 | AK21: 0.072756832 | AL21: 0.064587504 | AM21: 0.085879437 | AN21: 0.13435561 | AO21: 0.14187796 | AP21: 0.099757035 | AQ21: 0.1166445 | AR21: 0.12420985 | AS21: 0.092103126 | AT21: 0.1068503 | AU21: 0.082418037 | AV21: 0.066808807 | AW21: 0.090887985 | AX21: 0.075466258 | AY21: 0.10939217 | AZ21: 0.11677274 | BA21: 0.097888053 | BB21: 0.085531659 | BC21: 0.078143315 | BD21: 0.070632003 | BF21: Other Laser Types | BG21: CMI_Trend_52 | BH21: CMI_Trend_60 | BI21: CMI_Trend_20 | BJ21: CMI_Trend_38 | BK21: CMI_Trend_52 | BL21: CMI_Trend_20 | BM21: CMI_Trend_60 | BN21: CMI_Trend_46 | BO21: CMI_Trend_20 | BP21: CMI_Trend_46 | BQ21: CMI_Trend_20 | BR21: CMI_Trend_52 | BS21: CMI_Trend_56 | BT21: CMI_Trend_20 | BU21: CMI_Trend_38 | BV21: CMI_Trend_52 | BW21: CMI_Trend_56 | BX21: CMI_Trend_52 | BY21: CMI_Trend_25 | BZ21: CMI_Trend_60 | CA21: CMI_Trend_38 | CB21: CMI_Trend_46 | CC21: CMI_Trend_52 | CD21: CMI_Trend_56 | CE21: CMI_Trend_52 | CF21: CMI_Trend_52
B23: By Beam Architecture | AD23: By Beam Architecture | BF23: By Beam Architecture
B24: Rod Geometry | C24: 0.1303 | D24: 0.1301 | E24: 0.1243 | F24: 0.1254 | G24: 0.131 | H24: 0.1376 | I24: 0.1431 | J24: 0.1267 | K24: 0.1496 | L24: 0.1183 | M24: 0.1193 | N24: 0.1467 | O24: 0.1348 | P24: 0.1197 | Q24: 0.1357 | R24: 0.1402 | S24: 0.1367 | T24: 0.1276 | U24: 0.1284 | V24: 0.1194 | W24: 0.1201 | X24: 0.1334 | Y24: 0.1488 | Z24: 0.1292 | AA24: 0.1211 | AB24: 0.1283 | AD24: Rod Geometry | AE24: 0.099562098 | AF24: 0.08561162 | AG24: 0.1020273 | AH24: 0.087901828 | AI24: 0.075873814 | AJ24: 0.095298897 | AK24: 0.067009617 | AL24: 0.059207528 | AM24: 0.081803899 | AN24: 0.12866686 | AO24: 0.13711834 | AP24: 0.095560298 | AQ24: 0.11142174 | AR24: 0.11818687 | AS24: 0.087184476 | AT24: 0.10324547 | AU24: 0.077689944 | AV24: 0.062483753 | AW24: 0.085295196 | AX24: 0.069247021 | AY24: 0.10296724 | AZ24: 0.11195334 | BA24: 0.093394552 | BB24: 0.079198256 | BC24: 0.071764544 | BD24: 0.066152656 | BF24: Rod Geometry | BG24: CMI_Trend_20 | BH24: CMI_Trend_52 | BI24: CMI_Trend_46 | BJ24: CMI_Trend_56 | BK24: CMI_Trend_38 | BL24: CMI_Trend_56 | BM24: CMI_Trend_25 | BN24: CMI_Trend_38 | BO24: CMI_Trend_46 | BP24: CMI_Trend_25 | BQ24: CMI_Trend_60 | BR24: CMI_Trend_56 | BS24: CMI_Trend_60 | BT24: CMI_Trend_20 | BU24: CMI_Trend_46 | BV24: CMI_Trend_20 | BW24: CMI_Trend_25 | BX24: CMI_Trend_25 | BY24: CMI_Trend_38 | BZ24: CMI_Trend_25 | CA24: CMI_Trend_52 | CB24: CMI_Trend_38 | CC24: CMI_Trend_46 | CD24: CMI_Trend_60 | CE24: CMI_Trend_56 | CF24: CMI_Trend_38
B25: Disk / Thin-Disk | C25: 0.1683 | D25: 0.1512 | E25: 0.1636 | F25: 0.1747 | G25: 0.1799 | H25: 0.1507 | I25: 0.1551 | J25: 0.1684 | K25: 0.1695 | L25: 0.1847 | M25: 0.1761 | N25: 0.175 | O25: 0.1821 | P25: 0.1783 | Q25: 0.1652 | R25: 0.1687 | S25: 0.1743 | T25: 0.1736 | U25: 0.1619 | V25: 0.1588 | W25: 0.1595 | X25: 0.156 | Y25: 0.1517 | Z25: 0.1589 | AA25: 0.1658 | AB25: 0.1851 | AD25: Disk / Thin-Disk | AE25: 0.12004879 | AF25: 0.10609831 | AG25: 0.12251399 | AH25: 0.10838852 | AI25: 0.096360501 | AJ25: 0.11578558 | AK25: 0.087496304 | AL25: 0.079694216 | AM25: 0.10229059 | AN25: 0.14915355 | AO25: 0.15760503 | AP25: 0.11604699 | AQ25: 0.13190843 | AR25: 0.13867356 | AS25: 0.10767116 | AT25: 0.12373216 | AU25: 0.098176631 | AV25: 0.082970441 | AW25: 0.10578188 | AX25: 0.089733709 | AY25: 0.12345393 | AZ25: 0.13244003 | BA25: 0.11388124 | BB25: 0.099684944 | BC25: 0.092251231 | BD25: 0.086639343 | BF25: Disk / Thin-Disk | BG25: CMI_Trend_56 | BH25: CMI_Trend_60 | BI25: CMI_Trend_60 | BJ25: CMI_Trend_56 | BK25: CMI_Trend_25 | BL25: CMI_Trend_56 | BM25: CMI_Trend_56 | BN25: CMI_Trend_20 | BO25: CMI_Trend_46 | BP25: CMI_Trend_38 | BQ25: CMI_Trend_56 | BR25: CMI_Trend_52 | BS25: CMI_Trend_20 | BT25: CMI_Trend_25 | BU25: CMI_Trend_46 | BV25: CMI_Trend_46 | BW25: CMI_Trend_56 | BX25: CMI_Trend_52 | BY25: CMI_Trend_56 | BZ25: CMI_Trend_25 | CA25: CMI_Trend_25 | CB25: CMI_Trend_56 | CC25: CMI_Trend_25 | CD25: CMI_Trend_52 | CE25: CMI_Trend_46 | CF25: CMI_Trend_56
B26: Slab | C26: 0.0788 | D26: 0.0882 | E26: 0.0742 | F26: 0.0819 | G26: 0.0903 | H26: 0.0817 | I26: 0.077 | J26: 0.0731 | K26: 0.0825 | L26: 0.0736 | M26: 0.09 | N26: 0.0754 | O26: 0.0902 | P26: 0.0782 | Q26: 0.0715 | R26: 0.0801 | S26: 0.0851 | T26: 0.0892 | U26: 0.0824 | V26: 0.0756 | W26: 0.0818 | X26: 0.0849 | Y26: 0.0897 | Z26: 0.0815 | AA26: 0.0743 | AB26: 0.0905 | AD26: Slab | AE26: 0.088358783 | AF26: 0.074408305 | AG26: 0.090823984 | AH26: 0.076698512 | AI26: 0.064670498 | AJ26: 0.084095581 | AK26: 0.055806301 | AL26: 0.048004213 | AM26: 0.070600584 | AN26: 0.11746355 | AO26: 0.12591503 | AP26: 0.084356982 | AQ26: 0.10021842 | AR26: 0.10698355 | AS26: 0.07598116 | AT26: 0.092042158 | AU26: 0.066486628 | AV26: 0.051280438 | AW26: 0.074091881 | AX26: 0.058043706 | AY26: 0.091763929 | AZ26: 0.10075002 | BA26: 0.082191237 | BB26: 0.067994941 | BC26: 0.060561228 | BD26: 0.05494934 | BF26: Slab | BG26: CMI_Trend_25 | BH26: CMI_Trend_20 | BI26: CMI_Trend_25 | BJ26: CMI_Trend_25 | BK26: CMI_Trend_38 | BL26: CMI_Trend_46 | BM26: CMI_Trend_38 | BN26: CMI_Trend_56 | BO26: CMI_Trend_56 | BP26: CMI_Trend_38 | BQ26: CMI_Trend_25 | BR26: CMI_Trend_52 | BS26: CMI_Trend_60 | BT26: CMI_Trend_60 | BU26: CMI_Trend_52 | BV26: CMI_Trend_25 | BW26: CMI_Trend_60 | BX26: CMI_Trend_46 | BY26: CMI_Trend_20 | BZ26: CMI_Trend_56 | CA26: CMI_Trend_56 | CB26: CMI_Trend_60 | CC26: CMI_Trend_20 | CD26: CMI_Trend_25 | CE26: CMI_Trend_46 | CF26: CMI_Trend_60
B27: Single-Mode | C27: 0.1597 | D27: 0.1703 | E27: 0.156 | F27: 0.174 | G27: 0.1773 | H27: 0.1709 | I27: 0.1648 | J27: 0.1822 | K27: 0.1614 | L27: 0.1653 | M27: 0.1573 | N27: 0.1623 | O27: 0.1583 | P27: 0.1901 | Q27: 0.1802 | R27: 0.184 | S27: 0.1754 | T27: 0.1715 | U27: 0.1592 | V27: 0.1839 | W27: 0.1873 | X27: 0.1622 | Y27: 0.1882 | Z27: 0.1771 | AA27: 0.1884 | AB27: 0.1895 | AD27: Single-Mode | AE27: 0.12958291 | AF27: 0.11563243 | AG27: 0.13204811 | AH27: 0.11792263 | AI27: 0.10589462 | AJ27: 0.1253197 | AK27: 0.097030424 | AL27: 0.089228335 | AM27: 0.11182471 | AN27: 0.15868767 | AO27: 0.16713915 | AP27: 0.1255811 | AQ27: 0.14144255 | AR27: 0.14820768 | AS27: 0.11720528 | AT27: 0.13326628 | AU27: 0.10771075 | AV27: 0.09250456 | AW27: 0.115316 | AX27: 0.099267828 | AY27: 0.13298805 | AZ27: 0.14197415 | BA27: 0.12341536 | BB27: 0.10921906 | BC27: 0.10178535 | BD27: 0.096173463 | BF27: Single-Mode | BG27: CMI_Trend_46 | BH27: CMI_Trend_60 | BI27: CMI_Trend_25 | BJ27: CMI_Trend_46 | BK27: CMI_Trend_56 | BL27: CMI_Trend_56 | BM27: CMI_Trend_60 | BN27: CMI_Trend_20 | BO27: CMI_Trend_60 | BP27: CMI_Trend_20 | BQ27: CMI_Trend_46 | BR27: CMI_Trend_20 | BS27: CMI_Trend_38 | BT27: CMI_Trend_38 | BU27: CMI_Trend_38 | BV27: CMI_Trend_52 | BW27: CMI_Trend_46 | BX27: CMI_Trend_46 | BY27: CMI_Trend_60 | BZ27: CMI_Trend_60 | CA27: CMI_Trend_52 | CB27: CMI_Trend_20 | CC27: CMI_Trend_38 | CD27: CMI_Trend_56 | CE27: CMI_Trend_56 | CF27: CMI_Trend_60
B28: Multi-Mode | C28: 0.1967 | D28: 0.1909 | E28: 0.1896 | F28: 0.1901 | G28: 0.1782 | H28: 0.1787 | I28: 0.1877 | J28: 0.1887 | K28: 0.1878 | L28: 0.1759 | M28: 0.198 | N28: 0.1978 | O28: 0.1826 | P28: 0.1753 | Q28: 0.1788 | R28: 0.1957 | S28: 0.1816 | T28: 0.1939 | U28: 0.1975 | V28: 0.183 | W28: 0.177 | X28: 0.1947 | Y28: 0.1686 | Z28: 0.1756 | AA28: 0.1755 | AB28: 0.179 | AD28: Multi-Mode | AE28: 0.10858291 | AF28: 0.094632427 | AG28: 0.11104811 | AH28: 0.096922635 | AI28: 0.084894621 | AJ28: 0.1043197 | AK28: 0.076030424 | AL28: 0.068228335 | AM28: 0.090824706 | AN28: 0.13768767 | AO28: 0.14613915 | AP28: 0.1045811 | AQ28: 0.12044255 | AR28: 0.12720768 | AS28: 0.096205283 | AT28: 0.11226628 | AU28: 0.086710751 | AV28: 0.07150456 | AW28: 0.094316003 | AX28: 0.078267828 | AY28: 0.11198805 | AZ28: 0.12097415 | BA28: 0.10241536 | BB28: 0.088219063 | BC28: 0.080785351 | BD28: 0.075173463 | BF28: Multi-Mode | BG28: CMI_Trend_25 | BH28: CMI_Trend_52 | BI28: CMI_Trend_25 | BJ28: CMI_Trend_25 | BK28: CMI_Trend_56 | BL28: CMI_Trend_60 | BM28: CMI_Trend_20 | BN28: CMI_Trend_25 | BO28: CMI_Trend_52 | BP28: CMI_Trend_60 | BQ28: CMI_Trend_20 | BR28: CMI_Trend_56 | BS28: CMI_Trend_20 | BT28: CMI_Trend_60 | BU28: CMI_Trend_52 | BV28: CMI_Trend_20 | BW28: CMI_Trend_20 | BX28: CMI_Trend_20 | BY28: CMI_Trend_20 | BZ28: CMI_Trend_46 | CA28: CMI_Trend_52 | CB28: CMI_Trend_46 | CC28: CMI_Trend_25 | CD28: CMI_Trend_46 | CE28: CMI_Trend_60 | CF28: CMI_Trend_38
B29: Beam Combined Arrays | C29: =1-SUM(C24:C28) -> 0.2662 | D29: =1-SUM(D24:D28) -> 0.2693 | E29: =1-SUM(E24:E28) -> 0.2923 | F29: =1-SUM(F24:F28) -> 0.2539 | G29: =1-SUM(G24:G28) -> 0.2433 | H29: =1-SUM(H24:H28) -> 0.2804 | I29: =1-SUM(I24:I28) -> 0.2723 | J29: =1-SUM(J24:J28) -> 0.2609 | ... AB29: =1-SUM(AB24:AB28) -> 0.2276 | AD29: Beam Combined Arrays | AE29: 0.14479162 | AF29: 0.13084114 | AG29: 0.14725682 | AH29: 0.13313135 | AI29: 0.12110333 | AJ29: 0.14052842 | AK29: 0.11223914 | AL29: 0.10443705 | AM29: 0.12703342 | AN29: 0.17389638 | AO29: 0.18234786 | AP29: 0.14078982 | AQ29: 0.15665126 | AR29: 0.16341639 | AS29: 0.13241399 | AT29: 0.14847499 | AU29: 0.12291946 | AV29: 0.10771327 | AW29: 0.13052472 | AX29: 0.11447654 | AY29: 0.14819676 | AZ29: 0.15718286 | BA29: 0.13862407 | BB29: 0.12442777 | BC29: 0.11699406 | BD29: 0.11138217 | BF29: Beam Combined Arrays | BG29: CMI_Trend_46 | BH29: CMI_Trend_60 | BI29: CMI_Trend_38 | BJ29: CMI_Trend_60 | BK29: CMI_Trend_60 | BL29: CMI_Trend_60 | BM29: CMI_Trend_60 | BN29: CMI_Trend_46 | BO29: CMI_Trend_52 | BP29: CMI_Trend_60 | BQ29: CMI_Trend_52 | BR29: CMI_Trend_25 | BS29: CMI_Trend_52 | BT29: CMI_Trend_52 | BU29: CMI_Trend_20 | BV29: CMI_Trend_46 | BW29: CMI_Trend_38 | BX29: CMI_Trend_60 | BY29: CMI_Trend_60 | BZ29: CMI_Trend_46 | CA29: CMI_Trend_52 | CB29: CMI_Trend_56 | CC29: CMI_Trend_38 | CD29: CMI_Trend_56 | CE29: CMI_Trend_38 | CF29: CMI_Trend_46
B31: By Power Output | AD31: By Power Output | BF31: By Power Output
B32: Below 1 kW | C32: 0.1264 | D32: 0.1435 | E32: 0.1246 | F32: 0.1475 | G32: 0.1194 | H32: 0.1255 | I32: 0.1346 | J32: 0.1485 | K32: 0.1505 | L32: 0.1168 | M32: 0.1435 | N32: 0.1308 | O32: 0.1476 | P32: 0.1368 | Q32: 0.1436 | R32: 0.147 | S32: 0.1363 | T32: 0.121 | U32: 0.1478 | V32: 0.1248 | W32: 0.1314 | X32: 0.1246 | Y32: 0.1257 | Z32: 0.1397 | AA32: 0.119 | AB32: 0.1251 | AD32: Below 1 kW | AE32: 0.09522189 | AF32: 0.082446059 | AG32: 0.098186467 | AH32: 0.084527733 | AI32: 0.070672448 | AJ32: 0.09184857 | AK32: 0.063678811 | AL32: 0.057260215 | AM32: 0.078572921 | AN32: 0.12472105 | AO32: 0.13309324 | AP32: 0.091241047 | AQ32: 0.10768085 | AR32: 0.11534726 | AS32: 0.085143688 | AT32: 0.099761086 | AU32: 0.073161106 | AV32: 0.057373209 | AW32: 0.08243588 | AX32: 0.065904252 | AY32: 0.09913048 | AZ32: 0.10773288 | BA32: 0.088513416 | BB32: 0.076526892 | BC32: 0.068716574 | BD32: 0.060784294 | BF32: Below 1 kW | BG32: CMI_Trend_38 | BH32: CMI_Trend_56 | BI32: CMI_Trend_38 | BJ32: CMI_Trend_20 | BK32: CMI_Trend_52 | BL32: CMI_Trend_20 | BM32: CMI_Trend_25 | BN32: CMI_Trend_46 | BO32: CMI_Trend_52 | BP32: CMI_Trend_52 | BQ32: CMI_Trend_38 | BR32: CMI_Trend_56 | BS32: CMI_Trend_38 | BT32: CMI_Trend_60 | BU32: CMI_Trend_52 | BV32: CMI_Trend_20 | BW32: CMI_Trend_46 | BX32: CMI_Trend_56 | BY32: CMI_Trend_52 | BZ32: CMI_Trend_25 | CA32: CMI_Trend_56 | CB32: CMI_Trend_60 | CC32: CMI_Trend_25 | CD32: CMI_Trend_38 | CE32: CMI_Trend_60 | CF32: CMI_Trend_38
B33: 1 kW to 20 kW | C33: 0.4211 | D33: 0.4219 | E33: 0.4096 | F33: 0.4201 | G33: 0.4273 | H33: 0.4307 | I33: 0.4334 | J33: 0.4358 | K33: 0.4348 | L33: 0.4215 | M33: 0.4056 | N33: 0.4335 | O33: 0.427 | P33: 0.4294 | Q33: 0.4365 | R33: 0.4326 | S33: 0.4185 | T33: 0.4226 | U33: 0.4257 | V33: 0.4252 | W33: 0.4109 | X33: 0.4218 | Y33: 0.4256 | Z33: 0.4343 | AA33: 0.4352 | AB33: 0.4119 | AD33: 1 kW to 20 kW | AE33: 0.1103865 | AF33: 0.097610666 | AG33: 0.11335107 | AH33: 0.09969234 | AI33: 0.085837054 | AJ33: 0.10701318 | AK33: 0.078843417 | AL33: 0.072424822 | AM33: 0.093737528 | AN33: 0.13988566 | AO33: 0.14825785 | AP33: 0.10640565 | AQ33: 0.12284546 | AR33: 0.13051186 | AS33: 0.10030829 | AT33: 0.11492569 | AU33: 0.088325713 | AV33: 0.072537815 | AW33: 0.097600486 | AX33: 0.081068859 | AY33: 0.11429509 | AZ33: 0.12289749 | BA33: 0.10367802 | BB33: 0.091691499 | BC33: 0.08388118 | BD33: 0.075948901 | BF33: 1 kW to 20 kW | BG33: CMI_Trend_60 | BH33: CMI_Trend_52 | BI33: CMI_Trend_56 | BJ33: CMI_Trend_60 | BK33: CMI_Trend_20 | BL33: CMI_Trend_25 | BM33: CMI_Trend_56 | BN33: CMI_Trend_25 | BO33: CMI_Trend_38 | BP33: CMI_Trend_46 | BQ33: CMI_Trend_56 | BR33: CMI_Trend_60 | BS33: CMI_Trend_52 | BT33: CMI_Trend_46 | BU33: CMI_Trend_25 | BV33: CMI_Trend_56 | BW33: CMI_Trend_20 | BX33: CMI_Trend_38 | BY33: CMI_Trend_20 | BZ33: CMI_Trend_46 | CA33: CMI_Trend_46 | CB33: CMI_Trend_25 | CC33: CMI_Trend_20 | CD33: CMI_Trend_25 | CE33: CMI_Trend_20 | CF33: CMI_Trend_25
B34: 21 kW to 100 kW | C34: 0.2845 | D34: 0.3024 | E34: 0.2884 | F34: 0.2835 | G34: 0.2748 | H34: 0.2939 | I34: 0.2857 | J34: 0.2997 | K34: 0.2932 | L34: 0.2715 | M34: 0.3048 | N34: 0.2918 | O34: 0.2796 | P34: 0.2884 | Q34: 0.2989 | R34: 0.297 | S34: 0.2768 | T34: 0.2925 | U34: 0.2944 | V34: 0.2779 | W34: 0.2735 | X34: 0.3048 | Y34: 0.2714 | Z34: 0.2751 | AA34: 0.29 | AB34: 0.2956 | AD34: 21 kW to 100 kW | AE34: 0.1313865 | AF34: 0.11861067 | AG34: 0.13435107 | AH34: 0.12069234 | AI34: 0.10683705 | AJ34: 0.12801318 | AK34: 0.099843417 | AL34: 0.093424822 | AM34: 0.11473753 | AN34: 0.16088566 | AO34: 0.16925785 | AP34: 0.12740565 | AQ34: 0.14384546 | AR34: 0.15151186 | AS34: 0.12130829 | AT34: 0.13592569 | AU34: 0.10932571 | AV34: 0.093537815 | AW34: 0.11860049 | AX34: 0.10206886 | AY34: 0.13529509 | AZ34: 0.14389749 | BA34: 0.12467802 | BB34: 0.1126915 | BC34: 0.10488118 | BD34: 0.096948901 | BF34: 21 kW to 100 kW | BG34: CMI_Trend_38 | BH34: CMI_Trend_52 | BI34: CMI_Trend_52 | BJ34: CMI_Trend_20 | BK34: CMI_Trend_46 | BL34: CMI_Trend_60 | BM34: CMI_Trend_20 | BN34: CMI_Trend_56 | BO34: CMI_Trend_52 | BP34: CMI_Trend_52 | BQ34: CMI_Trend_56 | BR34: CMI_Trend_46 | BS34: CMI_Trend_46 | BT34: CMI_Trend_60 | BU34: CMI_Trend_56 | BV34: CMI_Trend_60 | BW34: CMI_Trend_52 | BX34: CMI_Trend_25 | BY34: CMI_Trend_60 | BZ34: CMI_Trend_46 | CA34: CMI_Trend_38 | CB34: CMI_Trend_56 | CC34: CMI_Trend_56 | CD34: CMI_Trend_20 | CE34: CMI_Trend_25 | CF34: CMI_Trend_46
B35: Above 100 kW | C35: =1-SUM(C32:C34) -> 0.168 | D35: =1-SUM(D32:D34) -> 0.1322 | E35: =1-SUM(E32:E34) -> 0.1774 | F35: =1-SUM(F32:F34) -> 0.1489 | G35: =1-SUM(G32:G34) -> 0.1785 | H35: =1-SUM(H32:H34) -> 0.1499 | I35: =1-SUM(I32:I34) -> 0.1463 | J35: =1-SUM(J32:J34) -> 0.116 | ... AB35: =1-SUM(AB32:AB34) -> 0.1674 | AD35: Above 100 kW | AE35: 0.14783775 | AF35: 0.13506191 | AG35: 0.15080232 | AH35: 0.13714359 | AI35: 0.1232883 | AJ35: 0.14446443 | AK35: 0.11629467 | AL35: 0.10987607 | AM35: 0.13118878 | AN35: 0.1773369 | AO35: 0.1857091 | AP35: 0.1438569 | AQ35: 0.16029671 | AR35: 0.16796311 | AS35: 0.13775954 | AT35: 0.15237694 | AU35: 0.12577696 | AV35: 0.10998906 | AW35: 0.13505173 | AX35: 0.11852011 | AY35: 0.15174634 | AZ35: 0.16034874 | BA35: 0.14112927 | BB35: 0.12914275 | BC35: 0.12133243 | BD35: 0.11340015 | BF35: Above 100 kW | BG35: CMI_Trend_56 | BH35: CMI_Trend_25 | BI35: CMI_Trend_38 | BJ35: CMI_Trend_52 | BK35: CMI_Trend_46 | BL35: CMI_Trend_38 | BM35: CMI_Trend_56 | BN35: CMI_Trend_46 | BO35: CMI_Trend_60 | BP35: CMI_Trend_56 | BQ35: CMI_Trend_52 | BR35: CMI_Trend_25 | BS35: CMI_Trend_38 | BT35: CMI_Trend_56 | BU35: CMI_Trend_20 | BV35: CMI_Trend_20 | BW35: CMI_Trend_52 | BX35: CMI_Trend_38 | BY35: CMI_Trend_60 | BZ35: CMI_Trend_60 | CA35: CMI_Trend_25 | CB35: CMI_Trend_52 | CC35: CMI_Trend_20 | CD35: CMI_Trend_60 | CE35: CMI_Trend_38 | CF35: CMI_Trend_52
B37: By Mode of Operation | AD37: By Mode of Operation | BF37: By Mode of Operation
B38: Continuous Wave (CW) | C38: =1-SUM(C39:C40) -> 0.6047 | D38: =1-SUM(D39:D40) -> 0.5958 | E38: =1-SUM(E39:E40) -> 0.5541 | F38: =1-SUM(F39:F40) -> 0.5841 | G38: =1-SUM(G39:G40) -> 0.592 | H38: =1-SUM(H39:H40) -> 0.5584 | I38: =1-SUM(I39:I40) -> 0.5781 | J38: =1-SUM(J39:J40) -> 0.5649 | ... AB38: =1-SUM(AB39:AB40) -> 0.598 | AD38: Continuous Wave (CW) | AE38: 0.11429316 | AF38: 0.099912952 | AG38: 0.11659026 | AH38: 0.10221038 | AI38: 0.089742633 | AJ38: 0.10956973 | AK38: 0.081372496 | AL38: 0.073407718 | AM38: 0.095550581 | AN38: 0.14433371 | AO38: 0.15086327 | AP38: 0.10850066 | AQ38: 0.1253068 | AR38: 0.13299291 | AS38: 0.10150928 | AT38: 0.11665092 | AU38: 0.091990377 | AV38: 0.076339977 | AW38: 0.099107312 | AX38: 0.084230543 | AY38: 0.11761255 | AZ38: 0.12592712 | BA38: 0.10727017 | BB38: 0.093722062 | BC38: 0.087100887 | BD38: 0.07985279 | BF38: Continuous Wave (CW) | BG38: CMI_Trend_25 | BH38: CMI_Trend_46 | BI38: CMI_Trend_56 | BJ38: CMI_Trend_46 | BK38: CMI_Trend_52 | BL38: CMI_Trend_20 | BM38: CMI_Trend_56 | BN38: CMI_Trend_52 | BO38: CMI_Trend_38 | BP38: CMI_Trend_56 | BQ38: CMI_Trend_38 | BR38: CMI_Trend_38 | BS38: CMI_Trend_46 | BT38: CMI_Trend_60 | BU38: CMI_Trend_46 | BV38: CMI_Trend_20 | BW38: CMI_Trend_56 | BX38: CMI_Trend_38 | BY38: CMI_Trend_52 | BZ38: CMI_Trend_38 | CA38: CMI_Trend_25 | CB38: CMI_Trend_52 | CC38: CMI_Trend_46 | CD38: CMI_Trend_60 | CE38: CMI_Trend_56 | CF38: CMI_Trend_38
B39: Pulsed | C39: 0.2763 | D39: 0.2687 | E39: 0.2938 | F39: 0.2909 | G39: 0.2799 | H39: 0.3011 | I39: 0.293 | J39: 0.2858 | K39: 0.2685 | L39: 0.2853 | M39: 0.2798 | N39: 0.2824 | O39: 0.2756 | P39: 0.2941 | Q39: 0.2897 | R39: 0.2931 | S39: 0.2666 | T39: 0.2751 | U39: 0.2937 | V39: 0.2771 | W39: 0.2938 | X39: 0.2894 | Y39: 0.2736 | Z39: 0.2944 | AA39: 0.2938 | AB39: 0.2737 | AD39: Pulsed | AE39: 0.12546988 | AF39: 0.11108967 | AG39: 0.12776698 | AH39: 0.1133871 | AI39: 0.10091935 | AJ39: 0.12074645 | AK39: 0.092549216 | AL39: 0.084584438 | AM39: 0.1067273 | AN39: 0.15551042 | AO39: 0.16203999 | AP39: 0.11967738 | AQ39: 0.13648352 | AR39: 0.14416963 | AS39: 0.112686 | AT39: 0.12782764 | AU39: 0.1031671 | AV39: 0.087516696 | AW39: 0.11028403 | AX39: 0.095407262 | AY39: 0.12878927 | AZ39: 0.13710384 | BA39: 0.11844689 | BB39: 0.10489878 | BC39: 0.098277606 | BD39: 0.091029509 | BF39: Pulsed | BG39: CMI_Trend_56 | BH39: CMI_Trend_52 | BI39: CMI_Trend_25 | BJ39: CMI_Trend_20 | BK39: CMI_Trend_38 | BL39: CMI_Trend_38 | BM39: CMI_Trend_52 | BN39: CMI_Trend_25 | BO39: CMI_Trend_38 | BP39: CMI_Trend_25 | BQ39: CMI_Trend_60 | BR39: CMI_Trend_46 | BS39: CMI_Trend_25 | BT39: CMI_Trend_52 | BU39: CMI_Trend_52 | BV39: CMI_Trend_20 | BW39: CMI_Trend_38 | BX39: CMI_Trend_20 | BY39: CMI_Trend_38 | BZ39: CMI_Trend_25 | CA39: CMI_Trend_46 | CB39: CMI_Trend_52 | CC39: CMI_Trend_20 | CD39: CMI_Trend_38 | CE39: CMI_Trend_38 | CF39: CMI_Trend_60
B40: Ultrashort Pulse | C40: 0.119 | D40: 0.1355 | E40: 0.1521 | F40: 0.125 | G40: 0.1281 | H40: 0.1405 | I40: 0.1289 | J40: 0.1493 | K40: 0.1281 | L40: 0.1212 | M40: 0.1406 | N40: 0.1519 | O40: 0.126 | P40: 0.1298 | Q40: 0.1487 | R40: 0.1287 | S40: 0.1209 | T40: 0.1266 | U40: 0.1454 | V40: 0.1465 | W40: 0.1436 | X40: 0.1355 | Y40: 0.1342 | Z40: 0.1415 | AA40: 0.1283 | AB40: 0.1283 | AD40: Ultrashort Pulse | AE40: 0.14248403 | AF40: 0.12810383 | AG40: 0.14478114 | AH40: 0.13040126 | AI40: 0.11793351 | AJ40: 0.13776061 | AK40: 0.10956337 | AL40: 0.10159859 | AM40: 0.12374146 | AN40: 0.17252458 | AO40: 0.17905415 | AP40: 0.13669153 | AQ40: 0.15349768 | AR40: 0.16118378 | AS40: 0.12970015 | AT40: 0.14484179 | AU40: 0.12018125 | AV40: 0.10453085 | AW40: 0.12729819 | AX40: 0.11242142 | AY40: 0.14580342 | AZ40: 0.15411799 | BA40: 0.13546105 | BB40: 0.12191294 | BC40: 0.11529176 | BD40: 0.10804367 | BF40: Ultrashort Pulse | BG40: CMI_Trend_52 | BH40: CMI_Trend_20 | BI40: CMI_Trend_38 | BJ40: CMI_Trend_56 | BK40: CMI_Trend_52 | BL40: CMI_Trend_38 | BM40: CMI_Trend_20 | BN40: CMI_Trend_56 | BO40: CMI_Trend_52 | BP40: CMI_Trend_56 | BQ40: CMI_Trend_20 | BR40: CMI_Trend_20 | BS40: CMI_Trend_60 | BT40: CMI_Trend_38 | BU40: CMI_Trend_56 | BV40: CMI_Trend_46 | BW40: CMI_Trend_56 | BX40: CMI_Trend_60 | BY40: CMI_Trend_20 | BZ40: CMI_Trend_56 | CA40: CMI_Trend_25 | CB40: CMI_Trend_46 | CC40: CMI_Trend_46 | CD40: CMI_Trend_52 | CE40: CMI_Trend_38 | CF40: CMI_Trend_46
B42: By Mobility / Deployment Model | AD42: By Mobility / Deployment Model | BF42: By Mobility / Deployment Model
B43: Fixed / Stationary | C43: =1-C44 -> 0.6919 | D43: =1-D44 -> 0.6772 | E43: =1-E44 -> 0.7024 | F43: =1-F44 -> 0.7013 | G43: =1-G44 -> 0.6778 | H43: =1-H44 -> 0.6774 | I43: =1-I44 -> 0.6929 | J43: =1-J44 -> 0.7015 | ... AB43: =1-AB44 -> 0.7091 | AD43: Fixed / Stationary | AE43: 0.11583462 | AF43: 0.10160077 | AG43: 0.11942748 | AH43: 0.10423371 | AI43: 0.091356565 | AJ43: 0.11176381 | AK43: 0.083395612 | AL43: 0.076062268 | AM43: 0.09751594 | AN43: 0.14577211 | AO43: 0.15299551 | AP43: 0.11114437 | AQ43: 0.12682143 | AR43: 0.13487552 | AS43: 0.10424141 | AT43: 0.11876655 | AU43: 0.093381542 | AV43: 0.077929562 | AW43: 0.10173544 | AX43: 0.086430524 | AY43: 0.11998742 | AZ43: 0.12795924 | BA43: 0.10920519 | BB43: 0.096082622 | BC43: 0.088883767 | BD43: 0.081900996 | BF43: Fixed / Stationary | BG43: CMI_Trend_60 | BH43: CMI_Trend_52 | BI43: CMI_Trend_46 | BJ43: CMI_Trend_38 | BK43: CMI_Trend_25 | BL43: CMI_Trend_20 | BM43: CMI_Trend_52 | BN43: CMI_Trend_25 | BO43: CMI_Trend_46 | BP43: CMI_Trend_25 | BQ43: CMI_Trend_46 | BR43: CMI_Trend_20 | BS43: CMI_Trend_60 | BT43: CMI_Trend_56 | BU43: CMI_Trend_20 | BV43: CMI_Trend_25 | BW43: CMI_Trend_38 | BX43: CMI_Trend_20 | BY43: CMI_Trend_46 | BZ43: CMI_Trend_38 | CA43: CMI_Trend_25 | CB43: CMI_Trend_25 | CC43: CMI_Trend_52 | CD43: CMI_Trend_20 | CE43: CMI_Trend_46 | CF43: CMI_Trend_60
B44: Mobile | C44: 0.3081 | D44: 0.3228 | E44: 0.2976 | F44: 0.2987 | G44: 0.3222 | H44: 0.3226 | I44: 0.3071 | J44: 0.2985 | K44: 0.2921 | L44: 0.3248 | M44: 0.3117 | N44: 0.3014 | O44: 0.3217 | P44: 0.3183 | Q44: 0.2953 | R44: 0.301 | S44: 0.3141 | T44: 0.3177 | U44: 0.2988 | V44: 0.316 | W44: 0.3116 | X44: 0.3157 | Y44: 0.3084 | Z44: 0.3092 | AA44: 0.3217 | AB44: 0.2909 | AD44: Mobile | AE44: 0.13174302 | AF44: 0.11750916 | AG44: 0.13533587 | AH44: 0.12014211 | AI44: 0.10726496 | AJ44: 0.1276722 | AK44: 0.099304003 | AL44: 0.091970659 | AM44: 0.11342433 | AN44: 0.1616805 | AO44: 0.1689039 | AP44: 0.12705276 | AQ44: 0.14272982 | AR44: 0.15078391 | AS44: 0.1201498 | AT44: 0.13467495 | AU44: 0.10928993 | AV44: 0.093837953 | AW44: 0.11764383 | AX44: 0.10233891 | AY44: 0.13589581 | AZ44: 0.14386763 | BA44: 0.12511358 | BB44: 0.11199101 | BC44: 0.10479216 | BD44: 0.097809387 | BF44: Mobile | BG44: CMI_Trend_38 | BH44: CMI_Trend_20 | BI44: CMI_Trend_20 | BJ44: CMI_Trend_56 | BK44: CMI_Trend_56 | BL44: CMI_Trend_56 | BM44: CMI_Trend_20 | BN44: CMI_Trend_46 | BO44: CMI_Trend_25 | BP44: CMI_Trend_56 | BQ44: CMI_Trend_52 | BR44: CMI_Trend_60 | BS44: CMI_Trend_56 | BT44: CMI_Trend_60 | BU44: CMI_Trend_46 | BV44: CMI_Trend_46 | BW44: CMI_Trend_56 | BX44: CMI_Trend_56 | BY44: CMI_Trend_46 | BZ44: CMI_Trend_46 | CA44: CMI_Trend_52 | CB44: CMI_Trend_56 | CC44: CMI_Trend_52 | CD44: CMI_Trend_52 | CE44: CMI_Trend_25 | CF44: CMI_Trend_52
...

Sheet ASP
B1: 121
B2: =B70 -> 121144 | C2: =C70 -> 26369 | D2: =D70 -> 4069 | E2: =E70 -> 3937 | F2: =F70 -> 6571 | G2: =G70 -> 2464 | H2: =H70 -> 3415 | I2: =I70 -> 2098 | ... AB2: =AB70 -> 1518
B3: Segment | C3: U.S. | D3: Canada | E3: U.K. | F3: Germany | G3: Italy | H3: France | I3: Spain | J3: Russia | K3: Rest of Europe | L3: China | M3: India | N3: Japan | O3: South Korea | P3: ASEAN | Q3: Australia | R3: Rest of Asia Pacific | S3: Brazil | T3: Argentina | U3: Mexico | V3: Rest of Latin America | W3: GCC | X3: Israel | Y3: Rest of Middle East | Z3: South Africa | AA3: North Africa | AB3: Central Africa | AE3: U.S. | AF3: Canada | AG3: U.K. | AH3: Germany | AI3: Italy | AJ3: France | AK3: Spain | AL3: Russia | AM3: Rest of Europe | AN3: China | AO3: India | AP3: Japan | AQ3: South Korea | AR3: ASEAN | AS3: Australia | AT3: Rest of Asia Pacific | AU3: Brazil | AV3: Argentina | AW3: Mexico | AX3: Rest of Latin America | AY3: GCC | AZ3: Israel | BA3: Rest of Middle East | BB3: South Africa | BC3: North Africa | BD3: Central Africa
B4: By Laser Type | AD4: By Laser Type
B5: Solid-State Lasers | AD5: Solid-State Lasers | AE5: ASP5 | AF5: ASP5 | AG5: ASP5 | AH5: ASP7 | AI5: ASP7 | AJ5: ASP7 | AK5: ASP2 | AL5: ASP7 | AM5: ASP4 | AN5: ASP5 | AO5: ASP5 | AP5: ASP3 | AQ5: ASP5 | AR5: ASP2 | AS5: ASP5 | AT5: ASP7 | AU5: ASP8 | AV5: ASP8 | AW5: ASP9 | AX5: ASP1 | AY5: ASP6 | AZ5: ASP2 | BA5: ASP6 | BB5: ASP3 | BC5: ASP3 | BD5: ASP5
B6: Nd:YAG | C6: 249258.56 | D6: 233052.9 | E6: 240866.34 | F6: 245882.38 | G6: 224564.22 | H6: 237586.62 | I6: 217908.32 | J6: 210866.57 | K6: 229097.94 | L6: 207008.08 | M6: 198037.09 | N6: 239419.41 | O6: 230255.49 | P6: 211638.27 | Q6: 228519.17 | R6: 214725.06 | S6: 213953.36 | T6: 202281.43 | U6: 218390.63 | V6: 205946.99 | W6: 225335.91 | X6: 237104.31 | Y6: 216750.77 | Z6: 210191.33 | AA6: 199484.02 | AB6: 191381.19 | AD6: Nd:YAG | AE6: ASP8 | AF6: ASP8 | AG6: ASP5 | AH6: ASP4 | AI6: ASP6 | AJ6: ASP8 | AK6: ASP5 | AL6: ASP4 | AM6: ASP9 | AN6: ASP6 | AO6: ASP3 | AP6: ASP4 | AQ6: ASP1 | AR6: ASP3 | AS6: ASP1 | AT6: ASP8 | AU6: ASP2 | AV6: ASP7 | AW6: ASP2 | AX6: ASP9 | AY6: ASP1 | AZ6: ASP4 | BA6: ASP4 | BB6: ASP9 | BC6: ASP3 | BD6: ASP8
B7: Yb:YAG | C7: 320833.58 | D7: 298454.33 | E7: 310415.66 | F7: 316589.24 | G7: 286975.32 | H7: 303470.37 | I7: 279065.41 | J7: 267007.62 | K7: 292184.28 | L7: 267104.09 | M7: 254853.38 | N7: 307135.94 | O7: 294017.07 | P7: 271637.81 | Q7: 290544.42 | R7: 277329.09 | S7: 276171.54 | T7: 261798.66 | U7: 283406.21 | V7: 269033.33 | W7: 291701.97 | X7: 305013.77 | Y7: 279451.26 | Z7: 269708.57 | AA7: 256493.23 | AB7: 243760.21 | AD7: Yb:YAG | AE7: ASP6 | AF7: ASP2 | AG7: ASP4 | AH7: ASP8 | AI7: ASP6 | AJ7: ASP5 | AK7: ASP9 | AL7: ASP7 | AM7: ASP1 | AN7: ASP3 | AO7: ASP4 | AP7: ASP2 | AQ7: ASP5 | AR7: ASP6 | AS7: ASP4 | AT7: ASP9 | AU7: ASP2 | AV7: ASP6 | AW7: ASP3 | AX7: ASP6 | AY7: ASP8 | AZ7: ASP5 | BA7: ASP7 | BB7: ASP1 | BC7: ASP3 | BD7: ASP1
B8: Tm:YAG | C8: 285721.31 | D8: 265078.38 | E8: 273856.45 | F8: 279258.33 | G8: 256010.92 | H8: 269708.57 | I8: 249547.95 | J8: 239515.87 | K8: 260255.26 | L8: 239033.56 | M8: 228133.32 | N8: 279354.8 | O8: 267489.94 | P8: 246654.08 | Q8: 261798.66 | R8: 250609.03 | S8: 249065.64 | T8: 236043.23 | U8: 256879.08 | V8: 242699.13 | W8: 261219.89 | X8: 274435.22 | Y8: 250994.88 | Z8: 242795.59 | AA8: 231316.58 | AB8: 219548.18 | AD8: Tm:YAG | AE8: ASP5 | AF8: ASP9 | AG8: ASP2 | AH8: ASP9 | AI8: ASP4 | AJ8: ASP7 | AK8: ASP4 | AL8: ASP8 | AM8: ASP3 | AN8: ASP5 | AO8: ASP5 | AP8: ASP1 | AQ8: ASP5 | AR8: ASP6 | AS8: ASP3 | AT8: ASP6 | AU8: ASP9 | AV8: ASP6 | AW8: ASP5 | AX8: ASP8 | AY8: ASP2 | AZ8: ASP2 | BA8: ASP6 | BB8: ASP3 | BC8: ASP7 | BD8: ASP8
B9: Er:YAG | C9: 239901.72 | D9: 223696.05 | E9: 231316.58 | F9: 235560.92 | G9: 213760.44 | H9: 227072.24 | I9: 209226.71 | J9: 201123.88 | K9: 218680.02 | L9: 201027.42 | M9: 191863.5 | N9: 234499.83 | O9: 224467.75 | P9: 207972.7 | Q9: 220705.72 | R9: 211541.81 | S9: 210963.03 | T9: 200062.79 | U9: 216172 | V9: 203824.82 | W9: 219837.56 | X9: 230930.73 | Y9: 212795.82 | Z9: 205657.61 | AA9: 194950.29 | AB9: 184725.29 | AD9: Er:YAG | AE9: ASP4 | AF9: ASP7 | AG9: ASP8 | AH9: ASP3 | AI9: ASP4 | AJ9: ASP7 | AK9: ASP6 | AL9: ASP9 | AM9: ASP4 | AN9: ASP9 | AO9: ASP5 | AP9: ASP8 | AQ9: ASP6 | AR9: ASP6 | AS9: ASP9 | AT9: ASP3 | AU9: ASP1 | AV9: ASP1 | AW9: ASP7 | AX9: ASP8 | AY9: ASP9 | AZ9: ASP4 | BA9: ASP7 | BB9: ASP3 | BC9: ASP6 | BD9: ASP8
B10: Others (Ce:YAG, Ho:YAG, etc.) | C10: 452311.69 | D10: 427038.57 | E10: 437745.88 | F10: 444884.09 | G10: 406685.02 | H10: 430125.36 | I10: 395302.47 | J10: 378518.03 | K10: 415366.63 | L10: 378807.42 | M10: 361347.75 | N10: 436298.95 | O10: 418453.42 | P10: 387392.56 | Q10: 410639.98 | R10: 394723.7 | S10: 394144.92 | T10: 373212.61 | U10: 405913.32 | V10: 383437.61 | W10: 413437.38 | X10: 432826.3 | Y10: 397810.49 | Z10: 387585.49 | AA10: 368196.57 | AB10: 350061.66 | AD10: Others (Ce:YAG, Ho:YAG, etc.) | AE10: ASP4 | AF10: ASP1 | AG10: ASP6 | AH10: ASP8 | AI10: ASP6 | AJ10: ASP8 | AK10: ASP7 | AL10: ASP4 | AM10: ASP6 | AN10: ASP5 | AO10: ASP7 | AP10: ASP7 | AQ10: ASP7 | AR10: ASP1 | AS10: ASP5 | AT10: ASP8 | AU10: ASP7 | AV10: ASP1 | AW10: ASP7 | AX10: ASP9 | AY10: ASP4 | AZ10: ASP9 | BA10: ASP1 | BB10: ASP5 | BC10: ASP6 | BD10: ASP8
B11: Fiber Lasers | C11: 0 | D11: 0 | E11: 0 | F11: 0 | G11: 0 | H11: 0 | I11: 0 | J11: 0 | K11: 0 | L11: 0 | M11: 0 | N11: 0 | O11: 0 | P11: 0 | Q11: 0 | R11: 0 | S11: 0 | T11: 0 | U11: 0 | V11: 0 | W11: 0 | X11: 0 | Y11: 0 | Z11: 0 | AA11: 0 | AB11: 0 | AD11: Fiber Lasers | AE11: ASP6 | AF11: ASP8 | AG11: ASP8 | AH11: ASP9 | AI11: ASP7 | AJ11: ASP6 | AK11: ASP8 | AL11: ASP2 | AM11: ASP3 | AN11: ASP4 | AO11: ASP9 | AP11: ASP4 | AQ11: ASP8 | AR11: ASP9 | AS11: ASP3 | AT11: ASP8 | AU11: ASP6 | AV11: ASP8 | AW11: ASP7 | AX11: ASP1 | AY11: ASP4 | AZ11: ASP6 | BA11: ASP9 | BB11: ASP7 | BC11: ASP8 | BD11: ASP2
B12: Continuous Wave Fiber Lasers | C12: 185979.3 | D12: 172571.04 | E12: 179902.17 | F12: 183664.2 | G12: 166204.53 | H12: 176718.92 | I12: 161863.73 | J12: 155014.9 | K12: 169387.78 | L12: 152989.19 | M12: 144500.51 | N12: 176911.84 | O12: 169966.56 | P12: 156172.45 | Q12: 167458.54 | R12: 159934.48 | S12: 158873.39 | T12: 150288.25 | U12: 163214.2 | V12: 154725.52 | W12: 165722.22 | X12: 174500.29 | Y12: 160416.79 | Z12: 155497.21 | AA12: 147008.53 | AB12: 140449.1 | AD12: Continuous Wave Fiber Lasers | AE12: ASP7 | AF12: ASP1 | AG12: ASP9 | AH12: ASP3 | AI12: ASP2 | AJ12: ASP5 | AK12: ASP4 | AL12: ASP6 | AM12: ASP5 | AN12: ASP9 | AO12: ASP2 | AP12: ASP9 | AQ12: ASP4 | AR12: ASP9 | AS12: ASP6 | AT12: ASP6 | AU12: ASP7 | AV12: ASP2 | AW12: ASP5 | AX12: ASP4 | AY12: ASP4 | AZ12: ASP1 | BA12: ASP7 | BB12: ASP1 | BC12: ASP6 | BD12: ASP4
B13: Pulsed Fiber Lasers | C13: 249258.56 | D13: 231220.11 | E13: 240094.64 | F13: 245593 | G13: 223599.59 | H13: 235560.92 | I13: 216943.69 | J13: 206718.69 | K13: 228326.24 | L13: 213856.9 | M13: 202860.2 | N13: 238068.94 | O13: 229001.48 | P13: 216172 | Q13: 227458.08 | R13: 220126.95 | S13: 219065.86 | T13: 207201 | U13: 223406.67 | V13: 212120.58 | W13: 225432.38 | X13: 236911.39 | Y13: 219837.56 | Z13: 213567.51 | AA13: 202184.96 | AB13: 192249.35 | AD13: Pulsed Fiber Lasers | AE13: ASP4 | AF13: ASP3 | AG13: ASP1 | AH13: ASP4 | AI13: ASP7 | AJ13: ASP5 | AK13: ASP8 | AL13: ASP1 | AM13: ASP1 | AN13: ASP3 | AO13: ASP1 | AP13: ASP9 | AQ13: ASP9 | AR13: ASP7 | AS13: ASP4 | AT13: ASP9 | AU13: ASP4 | AV13: ASP9 | AW13: ASP8 | AX13: ASP8 | AY13: ASP7 | AZ13: ASP6 | BA13: ASP8 | BB13: ASP3 | BC13: ASP9 | BD13: ASP4
B14: Raman Fiber Lasers | C14: 509899.67 | D14: 479224.67 | E14: 494562.17 | F14: 502954.39 | G14: 454916.17 | H14: 481250.37 | I14: 443051.31 | J14: 427038.57 | K14: 461861.45 | L14: 427135.03 | M14: 406685.02 | N14: 490896.6 | O14: 470060.75 | P14: 438614.04 | Q14: 459932.21 | R14: 444884.09 | S14: 443533.62 | T14: 422022.53 | U14: 451636.45 | V14: 431089.98 | W14: 461379.14 | X14: 483469.01 | Y14: 449224.89 | Z14: 437552.96 | AA14: 414594.93 | AB14: 394723.7 | AD14: Raman Fiber Lasers | AE14: ASP3 | AF14: ASP2 | AG14: ASP8 | AH14: ASP2 | AI14: ASP3 | AJ14: ASP3 | AK14: ASP4 | AL14: ASP2 | AM14: ASP7 | AN14: ASP2 | AO14: ASP1 | AP14: ASP7 | AQ14: ASP7 | AR14: ASP8 | AS14: ASP6 | AT14: ASP2 | AU14: ASP9 | AV14: ASP1 | AW14: ASP9 | AX14: ASP8 | AY14: ASP2 | AZ14: ASP4 | BA14: ASP7 | BB14: ASP5 | BC14: ASP1 | BD14: ASP8
B15: SBC Fiber Arrays | C15: 317264.48 | D15: 295849.85 | E15: 306171.31 | F15: 313116.6 | G15: 285335.46 | H15: 300480.04 | I15: 277039.7 | J15: 265850.08 | K15: 290255.04 | L15: 268551.02 | M15: 256300.31 | N15: 301541.12 | O15: 287843.48 | P15: 271927.2 | Q15: 285142.53 | R15: 276171.54 | S15: 275110.46 | T15: 261219.89 | U15: 281091.12 | V15: 267104.09 | W15: 284370.84 | X15: 298743.72 | Y15: 278390.17 | Z15: 269612.11 | AA15: 256396.77 | AB15: 243470.82 | AD15: SBC Fiber Arrays | AE15: ASP3 | AF15: ASP1 | AG15: ASP6 | AH15: ASP2 | AI15: ASP3 | AJ15: ASP3 | AK15: ASP6 | AL15: ASP6 | AM15: ASP2 | AN15: ASP7 | AO15: ASP1 | AP15: ASP2 | AQ15: ASP5 | AR15: ASP8 | AS15: ASP6 | AT15: ASP9 | AU15: ASP1 | AV15: ASP8 | AW15: ASP1 | AX15: ASP8 | AY15: ASP6 | AZ15: ASP8 | BA15: ASP8 | BB15: ASP6 | BC15: ASP7 | BD15: ASP6
B16: Gas Lasers | C16: 0 | D16: 0 | E16: 0 | F16: 0 | G16: 0 | H16: 0 | I16: 0 | J16: 0 | K16: 0 | L16: 0 | M16: 0 | N16: 0 | O16: 0 | P16: 0 | Q16: 0 | R16: 0 | S16: 0 | T16: 0 | U16: 0 | V16: 0 | W16: 0 | X16: 0 | Y16: 0 | Z16: 0 | AA16: 0 | AB16: 0 | AD16: Gas Lasers | AE16: ASP9 | AF16: ASP8 | AG16: ASP1 | AH16: ASP3 | AI16: ASP2 | AJ16: ASP4 | AK16: ASP5 | AL16: ASP6 | AM16: ASP6 | AN16: ASP8 | AO16: ASP1 | AP16: ASP8 | AQ16: ASP5 | AR16: ASP9 | AS16: ASP6 | AT16: ASP9 | AU16: ASP1 | AV16: ASP4 | AW16: ASP8 | AX16: ASP2 | AY16: ASP6 | AZ16: ASP5 | BA16: ASP7 | BB16: ASP7 | BC16: ASP3 | BD16: ASP5
B17: Chemical High-Energy Lasers | C17: 13311796 | D17: 12250711 | E17: 12154249 | F17: 12347173 | G17: 11575475 | H17: 12057786 | I17: 11382550 | J17: 10128541 | K17: 10803777 | L17: 9839153.8 | M17: 8874530.9 | N17: 12347173 | O17: 11575475 | P17: 9163917.7 | Q17: 11768400 | R17: 9453304.6 | S17: 9646229.2 | T17: 8874530.9 | U17: 9839153.8 | V17: 9163917.7 | W17: 12057786 | X17: 13022409 | Y17: 10128541 | Z17: 9453304.6 | AA17: 8874530.9 | AB17: 8199294.8 | AD17: Chemical High-Energy Lasers | AE17: ASP4 | AF17: ASP3 | AG17: ASP1 | AH17: ASP4 | AI17: ASP1 | AJ17: ASP5 | AK17: ASP4 | AL17: ASP3 | AM17: ASP6 | AN17: ASP6 | AO17: ASP5 | AP17: ASP2 | AQ17: ASP2 | AR17: ASP9 | AS17: ASP3 | AT17: ASP8 | AU17: ASP3 | AV17: ASP6 | AW17: ASP3 | AX17: ASP8 | AY17: ASP1 | AZ17: ASP5 | BA17: ASP9 | BB17: ASP5 | BC17: ASP5 | BD17: ASP8
