Workbook

Sheet Sheet1
E1: 0.5
B2: Population | C2: Per Capita Consumption | D2: Total Consumption (Units) | E2: Pricing (US$) | F2: Pizza Market Size | G2: Pricing Share (Pizza Base) | H2: Total Size (USD Million)
B3: 349035000 | C3: 48 | D3: 16753680000 | E3: 6.75 | F3: =D3*E3/10^6 -> 113087.34 | G3: =E3*8% -> 0.54 | H3: =D3*G3/10^6 -> 9046.9872
B4: 40467700 | C4: 44.5 | D4: 1800812650 | E4: 6.25 | F4: =D4*E4/10^6 -> 11255.079 | G4: =E4*8% -> 0.5 | H4: =D4*G4/10^6 -> 900.40633
C5: 0 | D5: 0 | E5: 0 | F5: =D5*E5/10^6 -> 0 | G5: =E5*8% -> 0 | H5: =D5*G5/10^6 -> 0
B6: 5652990 | C6: 57 | D6: 322220430 | E6: 9 | F6: =D6*E6/10^6 -> 2899.9839 | G6: =E6*8% -> 0.72 | H6: =D6*G6/10^6 -> 231.99871
B7: 58926200 | C7: 38 | D7: 2239195600 | E7: 5 | F7: =D7*E7/10^6 -> 11195.978 | G7: =E7*8% -> 0.4 | H7: =D7*G7/10^6 -> 895.67824
B8: 9007800 | C8: 37.5 | D8: 337792500 | E8: 10.5 | F8: =D8*E8/10^6 -> 3546.8212 | G8: =E8*8% -> 0.84 | H8: =D8*G8/10^6 -> 283.7457
B9: 10701000 | C9: 36 | D9: 385236000 | E9: 5.75 | F9: =D9*E9/10^6 -> 2215.107 | G9: =E9*8% -> 0.46 | H9: =D9*G9/10^6 -> 177.20856
B10: 66746400 | C10: 34 | D10: 2269377600 | E10: 6.25 | F10: =D10*E10/10^6 -> 14183.61 | G10: =E10*8% -> 0.5 | H10: =D10*G10/10^6 -> 1134.6888
B11: 5621740 | C11: 33.5 | D11: 188328290 | E11: 6.75 | F11: =D11*E11/10^6 -> 1271.216 | G11: =E11*8% -> 0.54 | H11: =D11*G11/10^6 -> 101.69728
B12: 69931500 | C12: 31.5 | D12: 2202842250 | E12: 7.5 | F12: =D12*E12/10^6 -> 16521.317 | G12: =E12*8% -> 0.6 | H12: =D12*G12/10^6 -> 1321.7053
B13: 83644300 | C13: 31 | D13: 2592973300 | E13: 6.25 | F13: =D13*E13/10^6 -> 16206.083 | G13: =E13*8% -> 0.5 | H13: =D13*G13/10^6 -> 1296.4867
B14: 47850800 | C14: 29.5 | D14: 1411598600 | E14: 5.5 | F14: =D14*E14/10^6 -> 7763.7923 | G14: =E14*8% -> 0.44 | H14: =D14*G14/10^6 -> 621.10338
B15: 143394000 | C15: 27 | D15: 3871638000 | E15: 3.75 | F15: =D15*E15/10^6 -> 14518.642 | G15: =E15*8% -> 0.3 | H15: =D15*G15/10^6 -> 1161.4914
B16: 11774600 | C16: 26.5 | D16: 312026900 | E16: 6.75 | F16: =D16*E16/10^6 -> 2106.1816 | G16: =E16*8% -> 0.54 | H16: =D16*G16/10^6 -> 168.49453
B17: 6023520 | C17: 25.5 | D17: 153599760 | E17: 7.5 | F17: =D17*E17/10^6 -> 1151.9982 | G17: =E17*8% -> 0.6 | H17: =D17*G17/10^6 -> 92.159856
... B34: 1331060 | C34: 12.5 | D34: 16638250 | E34: 5 | F34: =D34*E34/10^6 -> 83.19125 | G34: =E34*8% -> 0.4 | H34: =D34*G34/10^6 -> 6.6553
C35: 0 | D35: 0 | E35: 0 | F35: =D35*E35/10^6 -> 0 | G35: =E35*8% -> 0 | H35: =D35*G35/10^6 -> 0
B36: 132998000 | C36: 21.5 | D36: 2859457000 | E36: 4.5 | F36: =D36*E36/10^6 -> 12867.557 | G36: =E36*8% -> 0.36 | H36: =D36*G36/10^6 -> 1029.4045
B37: 46003700 | C37: 21 | D37: 966077700 | E37: 4.25 | F37: =D37*E37/10^6 -> 4105.8302 | G37: =E37*8% -> 0.34 | H37: =D37*G37/10^6 -> 328.46642
B38: 213563000 | C38: 29 | D38: 6193327000 | E38: 3.75 | F38: =D38*E38/10^6 -> 23224.976 | G38: =E38*8% -> 0.3 | H38: =D38*G38/10^6 -> 1857.9981
B39: 122428000 | C39: 28 | D39: 3427984000 | E39: 5.5 | F39: =D39*E39/10^6 -> 18853.912 | G39: =E39*8% -> 0.44 | H39: =D39*G39/10^6 -> 1508.313
C40: 0 | D40: 0 | E40: 0 | F40: =D40*E40/10^6 -> 0 | G40: =E40*8% -> 0 | H40: =D40*G40/10^6 -> 0 | L40: 50
B41: 27227100 | C41: 43 | D41: 1170765300 | E41: 6.5 | F41: =D41*E41/10^6 -> 7609.9744 | G41: =E41*8% -> 0.52 | H41: =D41*G41/10^6 -> 608.79796 | L41: =L40/5% -> 1000
B42: 5287480 | C42: 19.5 | D42: 103105860 | E42: 6.25 | F42: =D42*E42/10^6 -> 644.41162 | G42: =E42*8% -> 0.5 | H42: =D42*G42/10^6 -> 51.55293
B43: 51600400 | C43: 19 | D43: 980407600 | E43: 5.25 | F43: =D43*E43/10^6 -> 5147.1399 | G43: =E43*8% -> 0.42 | H43: =D43*G43/10^6 -> 411.77119
B44: 1476630000 | C44: 6.5 | D44: 9598095000 | E44: 2.5 | F44: =D44*E44/10^6 -> 23995.237 | G44: =E44*8% -> 0.2 | H44: =D44*G44/10^6 -> 1919.619
F45: =SUM(F3:F44) -> 398290.3 | G45: Global Pizza Base Market Size (USD Million) | H45: =SUM(H3:H44) -> 31863.224
F46: =F45*40% -> 159316.12 | H46: =H45/F46 -> 0.2

Sheet Input Sheet
A1: Segment | B1: Market Share | C1: CAGR
A2: By Pizza Base Type | B2: 1 | C2: =C3*B3+B34*C34 -> 0.09142706 | D2: 0.0942 | F2: North America | G2: =SUM(G3:G4) -> 9947.3935 | H2: =SUM(H3:H4) -> 1 | I2: =SUMPRODUCT(I3:I4,H3:H4) -> 0.085387898 | J2: =I2-M3 -> 0 | K2: Region | L2: Adjusted Market Share | M2: =SUMPRODUCT(M3:M8,L3:L8) -> 0.09142706 | N2: =M2-C2 -> 0
A3: Ready to Eat Bases | B3: 0.55 | C3: =C4*B4+C9*B9+C14*B14+B19*C19+B24*C24+C29*B29 -> 0.095736771 | F3: U.S. | G3: 9046.9872 | H3: =G3/G2 -> 0.90948319 | I3: 0.086347376 | K3: North America | L3: =G2/L10 -> 0.28443905 | M3: 0.085387898
A4: Quick Service Restaurants (QSR) | B4: 0.12 | C4: =SUMPRODUCT(C5:C8,B5:B8) -> 0.10539979 | D4: 0.10539979 | E4: 3 | F4: Canada | G4: 900.40633 | H4: =G4/G2 -> 0.09051681 | I4: 0.075747376 | K4: Europe | L4: =G5/L10 -> 0.26506825 | M4: 0.089887898
A5: Traditional Round Pizza | B5: 0.58 | C5: 0.097794792 | D5: =C4-D4 -> 0 | F5: Europe | G5: =SUM(G6:G17) -> 9269.9584 | H5: =SUM(H6:H17) -> 1 | I5: =SUMPRODUCT(I6:I17,H6:H17) -> 0.089887898 | J5: =I5-M4 -> 0 | K5: Asia Pacific | L5: =G18/L10 -> 0.28153455 | M5: 0.1017879
A6: Pizza Romana | B6: 0.15 | C6: 0.11869479 | D6: 2 | F6: Norway | G6: 180.44344 | H6: =G6/$G$5 -> 0.019465399 | I6: 0.077834416 | K6: LATAM | L6: =G27/L10 -> 0.10499092 | M6: 0.094287898
A7: Pinsa | B7: 0.12 | C7: 0.13779479 | D7: 1 | F7: UK | G7: 1321.7053 | H7: =G7/$G$5 -> 0.14257943 | I7: 0.091134416 | K7: Middle East | L7: =G32/L10 -> 0.035643404 | M7: 0.079587898
A8: Other Regional / Specialty Pizza Styles | B8: =1-SUM(B5:B7) -> 0.15 | C8: 0.095594792 | D8: 4 | F8: Germany | G8: 1296.4867 | H8: =G8/$G$5 -> 0.13985895 | I8: 0.085434416 | K8: Africa | L8: =1-SUM(L3:L7) -> 0.028323828 | M8: 0.067787898
A9: Full-Service Restaurants (FSR) | B9: 0.08 | C9: =SUMPRODUCT(C10:C13,B10:B13) -> 0.097673675 | D9: 0.097673675 | E9: 4 | F9: Romania | G9: 108.29146 | H9: =G9/$G$5 -> 0.011681979 | I9: 0.096834416
A10: Traditional Round Pizza | B10: 0.5 | C10: 0.089433675 | D10: =C9-D9 -> 0 | F10: Italy | G10: 895.67824 | H10: =G10/$G$5 -> 0.096621603 | I10: 0.086834416 | K10: Global Size (USD Million) | L10: =SUM(G2,G5,G18,G27,G32,G35) -> 34971.968
A11: Pizza Romana | B11: 0.18 | C11: 0.11543367 | D11: 2 | F11: France | G11: 1134.6888 | H11: =G11/$G$5 -> 0.12240495 | I11: 0.081134416
A12: Pinsa | B12: 0.12 | C12: 0.13593367 | D12: 1 | F12: Spain | G12: 621.10338 | H12: =G12/$G$5 -> 0.067001745 | I12: 0.10113442
A13: Other Regional / Specialty Pizza Styles | B13: =1-SUM(B10:B12) -> 0.2 | C13: 0.079333675 | D13: 4 | F13: Russia | G13: 1161.4914 | H13: =G13/$G$5 -> 0.12529629 | I13: 0.10683442
A14: Bars/Hotels | B14: 0.07 | C14: =SUMPRODUCT(C15:C18,B15:B18) -> 0.11207305 | D14: 0.11207305 | E14: 2 | F14: Switzerland | G14: 189.1638 | H14: =G14/$G$5 -> 0.020406111 | I14: 0.080034416
A15: Traditional Round Pizza | B15: 0.46 | C15: 0.10363805 | D15: =C14-D14 -> 0 | F15: Sweden | G15: 177.20856 | H15: =G15/$G$5 -> 0.019116435 | I15: 0.074334416
A16: Pizza Romana | B16: 0.17 | C16: 0.13093805 | D16: 2 | F16: Finland | G16: 101.69728 | H16: =G16/$G$5 -> 0.010970629 | I16: 0.067634416
A17: Pinsa | B17: 0.13 | C17: 0.14943805 | D17: 1 | F17: Rest of Europe | G17: 2082 | H17: =G17/$G$5 -> 0.22459648 | I17: 0.089134416
A18: Other Regional / Specialty Pizza Styles | B18: =1-SUM(B15:B17) -> 0.24 | C18: 0.094638052 | D18: 4 | F18: Asia Pacific | G18: =SUM(G19:G26) -> 9845.8172 | H18: =SUM(H19:H26) -> 1 | I18: =SUMPRODUCT(I19:I26,H19:H26) -> 0.1017879 | J18: =I18-M5 -> 0
A19: Pizzeria | B19: 0.08 | C19: =SUMPRODUCT(C20:C23,B20:B23) -> 0.12029382 | D19: 0.12029382 | E19: 1 | F19: China | G19: 4973.4432 | H19: =G19/$G$18 -> 0.50513259 | I19: 0.10224588
A20: Traditional Round Pizza | B20: 0.45 | C20: 0.11298682 | D20: =C19-D19 -> 0 | F20: India | G20: 1919.619 | H20: =G20/$G$18 -> 0.19496797 | I20: 0.11664588
A21: Pizza Romana | B21: 0.19 | C21: 0.13628682 | D21: 2 | F21: Japan | G21: 1508.313 | H21: =G21/$G$18 -> 0.15319327 | I21: 0.094545883
A22: Pinsa | B22: 0.18 | C22: 0.14208682 | D22: 1 | F22: South Korea | G22: 411.77119 | H22: =G22/$G$18 -> 0.041821941 | I22: 0.085645883
A23: Other Regional / Specialty Pizza Styles | B23: =1-SUM(B20:B22) -> 0.18 | C23: 0.099886824 | D23: 4 | F23: ASEAN | G23: 342.1 | H23: =G23/$G$18 -> 0.034745719 | I23: 0.080145883
A24: Retail | B24: 0.6 | C24: =SUMPRODUCT(C25:C28,B25:B28) -> 0.089585471 | D24: 0.089585471 | E24: 5 | F24: Australia | G24: 608.79796 | H24: =G24/$G$18 -> 0.061833156 | I24: 0.092345883
A25: Traditional Round Pizza | B25: 0.53 | C25: 0.089701471 | D25: =C24-D24 -> 0 | F25: New Zealand | G25: 51.55293 | H25: =G25/$G$18 -> 0.0052360235 | I25: 0.10564588
A26: Pizza Romana | B26: 0.16 | C26: 0.098701471 | D26: 2 | F26: Rest of Asia Pacific | G26: 30.22 | H26: =G26/$G$18 -> 0.0030693237 | I26: 0.092645883
A27: Pinsa | B27: 0.12 | C27: 0.10840147 | D27: 1 | F27: Latin America | G27: =SUM(G28:G31) -> 3671.739 | H27: =SUM(H28:H31) -> 1 | I27: =SUMPRODUCT(I28:I31,H28:H31) -> 0.094287898 | J27: =I27-M6 -> 0
A28: Other Regional / Specialty Pizza Styles | B28: =1-SUM(B25:B27) -> 0.19 | C28: 0.069701471 | D28: 4 | F28: Brazil | G28: 1857.9981 | H28: =G28/$G$27 -> 0.50602673 | I28: 0.10726119
A29: Others ( (Institutional Food Service, etc.) | B29: =1-SUM(B4,B9,B14,B19,B24) -> 0.05 | C29: =SUMPRODUCT(C30:C33,B30:B33) -> 0.0811 | D29: 0.0811 | E29: 6 | F29: Argentina | G29: 328.46642 | H29: =G29/$G$27 -> 0.089457996 | I29: 0.096261191
A30: Traditional Round Pizza | B30: 0.67 | C30: 0.084604 | D30: =C29-D29 -> 0 | F30: Mexico | G30: 1029.4045 | H30: =G30/$G$27 -> 0.28035885 | I30: 0.080661191
A31: Pizza Romana | B31: 0.1 | C31: 0.092504 | D31: 2 | F31: Rest of Latin America | G31: 455.87 | H31: =G31/$G$27 -> 0.12415643 | I31: 0.070761191
A32: Pinsa | B32: 0.06 | C32: 0.100304 | D32: 1 | F32: Middle East | G32: =SUM(G33:G34) -> 1246.52 | H32: =SUM(H33:H34) -> 1 | I32: =SUMPRODUCT(I33:I34,H33:H34) -> 0.079587898 | J32: =I32-M7 -> 0
A33: Other Regional / Specialty Pizza Styles | B33: =1-SUM(B30:B32) -> 0.17 | C33: 0.053804 | D33: 4 | F33: GCC Countries | G33: 790.87 | H33: =G33/$G$32 -> 0.63446234 | I33: 0.084047457
A34: Made From Scratch | B34: =1-SUM(B3) -> 0.45 | C34: =C35*B35+C40*B40+C45*B45+B50*C50+B55*C55+C60*B60 -> 0.086159634 | F34: Rest of Middle East | G34: 455.65 | H34: =G34/$G$32 -> 0.36553766 | I34: 0.071847457
A35: Quick Service Restaurants (QSR) | B35: 0.14 | C35: =SUMPRODUCT(C36:C39,B36:B39) -> 0.088422704 | D35: 0.088422704 | E35: 3 | F35: Africa | G35: =SUM(G36:G38) -> 990.54 | H35: =SUM(H36:H38) -> 1 | I35: =SUMPRODUCT(I36:I38,H36:H38) -> 0.067787898 | J35: =I35-M8 -> 0
A36: Traditional Round Pizza | B36: 0.58 | C36: 0.086926704 | D36: =C35-D35 -> 0 | F36: North Africa | G36: 566.77 | H36: =G36/$G$35 -> 0.57218285 | I36: 0.072640886
A37: Pizza Romana | B37: 0.16 | C37: 0.099226704 | D37: 2 | F37: South Africa | G37: 312.9 | H37: =G37/$G$35 -> 0.3158883 | I37: 0.062840886
A38: Pinsa | B38: 0.07 | C38: 0.1130267 | D38: 1 | F38: Central Africa | G38: 110.87 | H38: =G38/$G$35 -> 0.11192885 | I38: 0.056940886
A39: Other Regional / Specialty Pizza Styles | B39: =1-SUM(B36:B38) -> 0.19 | C39: 0.074826704 | D39: 4
A40: Full-Service Restaurants (FSR) | B40: 0.12 | C40: =SUMPRODUCT(C41:C44,B41:B44) -> 0.084131169 | D40: 0.084131169 | E40: 4
...

Sheet ASP
C1: U.S. | D1: Canada | E1: Norway | F1: UK | G1: Germany | H1: Romania | I1: Italy | J1: France | K1: Spain | L1: Russia | M1: Switzerland | N1: Sweden | O1: Finland | P1: Rest of Europe | Q1: China | R1: India | S1: Japan | T1: South Korea | U1: ASEAN | V1: Australia | W1: New Zealand | X1: Rest of Asia Pacific | Y1: Brazil | Z1: Argentina | AA1: Mexico | AB1: Rest of Latin America | AC1: GCC Countries | AD1: Rest of Middle East | AE1: North Africa | AF1: South Africa | AG1: Central Africa
B2: Pizza Type
A3: 1.11 | B3: Traditional Round Pizza | C3: =$A3*C8 -> 1.11 | D3: =$A3*D8 -> 1.33977 | E3: =$A3*E8 -> 1.31091 | F3: =$A3*F8 -> 1.49628 | G3: =$A3*G8 -> 1.47186 | H3: =$A3*H8 -> 1.50294 | I3: =$A3*I8 -> 1.45632 | J3: =$A3*J8 -> 1.50516 | ... AG3: =$A3*AG8 -> 1.0878
A4: 1.2 | B4: Pizza Romana | C4: =$A4*C9 -> 1.2 | D4: =$A4*D9 -> 1.476 | E4: =$A4*E9 -> 1.4028 | F4: =$A4*F9 -> 1.6356 | G4: =$A4*G9 -> 1.5972 | H4: =$A4*H9 -> 1.5948 | I4: =$A4*I9 -> 1.62 | J4: =$A4*J9 -> 1.5696 | ... AG4: =$A4*AG9 -> 1.1724
A5: 1.3 | B5: Pinsa | C5: =$A5*C10 -> 1.3 | D5: =$A5*D10 -> 1.5275 | E5: =$A5*E10 -> 1.5808 | F5: =$A5*F10 -> 1.7056 | G5: =$A5*G10 -> 1.7641 | H5: =$A5*H10 -> 1.7498 | I5: =$A5*I10 -> 1.7485 | J5: =$A5*J10 -> 1.7667 | ... AG5: =$A5*AG10 -> 1.1843
A6: 1.15 | B6: Other Regional / Specialty Pizza Styles | C6: =$A6*C11 -> 1.15 | D6: =$A6*D11 -> 1.3455 | E6: =$A6*E11 -> 1.34435 | F6: =$A6*F11 -> 1.56515 | G6: =$A6*G11 -> 1.5525 | H6: =$A6*H11 -> 1.55135 | I6: =$A6*I11 -> 1.5226 | J6: =$A6*J11 -> 1.50995 | ... AG6: =$A6*AG11 -> 1.13275
B8: Traditional Round Pizza | C8: 1 | D8: 1.207 | E8: 1.181 | F8: 1.348 | G8: 1.326 | H8: 1.354 | I8: 1.312 | J8: 1.356 | K8: 1.35 | L8: 1.323 | M8: 1.346 | N8: 1.305 | O8: 1.328 | P8: 1.322 | Q8: 0.887 | R8: 0.886 | S8: 0.886 | T8: 0.882 | U8: 0.885 | V8: 0.883 | W8: 0.884 | X8: 0.877 | Y8: 1.06 | Z8: 1.098 | AA8: 1.089 | AB8: 1.067 | AC8: =RANDBETWEEN(910,990)/1000 -> 0.912 | AD8: =RANDBETWEEN(910,990)/1000 -> 0.951 | AE8: =RANDBETWEEN(910,990)/1000 -> 0.928 | AF8: =RANDBETWEEN(910,990)/1000 -> 0.954 | AG8: =RANDBETWEEN(910,990)/1000 -> 0.98
B9: Pizza Romana | C9: 1 | D9: 1.23 | E9: 1.169 | F9: 1.363 | G9: 1.331 | H9: 1.329 | I9: 1.35 | J9: 1.308 | K9: 1.327 | L9: 1.348 | M9: 1.327 | N9: 1.327 | O9: 1.345 | P9: 1.356 | Q9: 0.88 | R9: 0.882 | S9: 0.887 | T9: 0.886 | U9: 0.883 | V9: 0.881 | W9: 0.878 | X9: 0.885 | Y9: 1.044 | Z9: 1.096 | AA9: 1.07 | AB9: 1.057 | AC9: =RANDBETWEEN(910,990)/1000 -> 0.97 | AD9: =RANDBETWEEN(910,990)/1000 -> 0.942 | AE9: =RANDBETWEEN(910,990)/1000 -> 0.949 | AF9: =RANDBETWEEN(910,990)/1000 -> 0.914 | AG9: =RANDBETWEEN(910,990)/1000 -> 0.977
B10: Pinsa | C10: 1 | D10: 1.175 | E10: 1.216 | F10: 1.312 | G10: 1.357 | H10: 1.346 | I10: 1.345 | J10: 1.359 | K10: 1.306 | L10: 1.353 | M10: 1.348 | N10: 1.346 | O10: 1.348 | P10: 1.343 | Q10: 0.885 | R10: 0.889 | S10: 0.889 | T10: 0.881 | U10: 0.884 | V10: 0.888 | W10: 0.885 | X10: 0.888 | Y10: 1.057 | Z10: 1.069 | AA10: 1.099 | AB10: 1.098 | AC10: =RANDBETWEEN(910,990)/1000 -> 0.944 | AD10: =RANDBETWEEN(910,990)/1000 -> 0.947 | AE10: =RANDBETWEEN(910,990)/1000 -> 0.916 | AF10: =RANDBETWEEN(910,990)/1000 -> 0.92 | AG10: =RANDBETWEEN(910,990)/1000 -> 0.911
B11: Other Regional / Specialty Pizza Styles | C11: 1 | D11: 1.17 | E11: 1.169 | F11: 1.361 | G11: 1.35 | H11: 1.349 | I11: 1.324 | J11: 1.313 | K11: 1.338 | L11: 1.328 | M11: 1.313 | N11: 1.341 | O11: 1.355 | P11: 1.35 | Q11: 0.884 | R11: 0.885 | S11: 0.881 | T11: 0.889 | U11: 0.889 | V11: 0.877 | W11: 0.882 | X11: 0.878 | Y11: 1.048 | Z11: 1.075 | AA11: 1.061 | AB11: 1.076 | AC11: =RANDBETWEEN(910,990)/1000 -> 0.957 | AD11: =RANDBETWEEN(910,990)/1000 -> 0.943 | AE11: =RANDBETWEEN(910,990)/1000 -> 0.94 | AF11: =RANDBETWEEN(910,990)/1000 -> 0.943 | AG11: =RANDBETWEEN(910,990)/1000 -> 0.985

Sheet Republic of Ireland

Sheet Sheet2
A1: Segment | B1: Market Share | C1: CAGR | G1: Finalised Country Data | I1: Market Share | O1: Region Name | P1: Market Volume | Q1: CAGR
A2: Product Type | B2: 1 | C2: 0.045 | G2: Region / Country | H2: Domestic Production / Consumption Data in ’000 Tons, 2024 | J2: CAGR | O2: North America | P2: 10956 | Q2: 0.0414
A3: Polyurethane (PU) Foams | B3: 0.47 | C3: 0.046 | G3: North America | H3: 10956 | I3: =SUM(I4:I5) -> 1 | J3: 0.0414 | O3: Europe | P3: 4000 | Q3: 0.0313
A4: Flexible PU | B4: 0.55 | C4: 0.039 | G4: U.S. | H4: 9860 | I4: =H4/$H$3 -> 0.89996349 | J4: 0.042 | O4: Asia Pacific | P4: 9900 | Q4: 0.0521
A5: Rigid PU | B5: 0.25 | C5: 0.052 | G5: Canada | H5: 1096 | I5: =H5/$H$3 -> 0.10003651 | J5: 0.036 | O5: Latin America | P5: 979 | Q5: 0.0454
A6: Semi-Rigid PU | B6: 0.07 | C6: 0.043 | G6: Europe | H6: 4000 | I6: =SUM(I7:I13) -> 1 | J6: 0.0313 | O6: Middle East | P6: 1300 | Q6: 0.0496
A7: Integral Skin PU | B7: 0.05 | C7: 0.041 | G7: Germany | H7: 656 | I7: =H7/$H$6 -> 0.164 | J7: 0.031 | O7: Africa | P7: 1900 | Q7: 0.0511
A8: Microcellular PU | B8: =1-SUM(B4:B7) -> 0.08 | C8: 0.057 | G8: UK | H8: 265 | I8: =H8/$H$6 -> 0.06625 | J8: 0.034
A9: Polystyrene (PS) Foams | B9: 0.23 | C9: 0.038 | G9: France | H9: 335 | I9: =H9/$H$6 -> 0.08375 | J9: 0.032
A10: Expanded Polystyrene (EPS) | B10: 0.72 | C10: 0.036 | G10: Italy | H10: 221 | I10: =H10/$H$6 -> 0.05525 | J10: 0.029
A11: Extruded Polystyrene (XPS) | B11: =1-SUM(B10) -> 0.28 | C11: 0.044 | G11: Spain | H11: 185 | I11: =H11/$H$6 -> 0.04625 | J11: 0.035
A12: Polyolefin Foams | B12: 0.09 | C12: 0.05 | G12: Russia | H12: 919 | I12: =H12/$H$6 -> 0.22975 | J12: 0.026
A13: Polyethylene (PE) Foams | B13: 0.62 | C13: 0.046 | G13: Rest of Europe | H13: 1419 | I13: =H13/$H$6 -> 0.35475 | J13: 0.034
A14: Polypropylene (PP) Foams | B14: =1-SUM(B13) -> 0.38 | C14: 0.057 | G14: Asia Pacific | H14: 9900 | I14: =SUM(I15:I21) -> 1 | J14: 0.0521
A15: PVC Foams | B15: 0.04 | C15: 0.038 | G15: China | H15: 5700 | I15: =H15/$H$14 -> 0.57575758 | J15: 0.05
A16: Rigid PVC Foam | B16: 0.48 | C16: 0.036 | G16: India | H16: 920 | I16: =H16/$H$14 -> 0.092929293 | J16: 0.07
A17: Semi-Rigid PVC Foam | B17: 0.22 | C17: 0.034 | G17: Japan | H17: 813 | I17: =H17/$H$14 -> 0.082121212 | J17: 0.03
A18: Closed-Cell PVC Structural Foam | B18: =1-SUM(B16:B17) -> 0.3 | C18: 0.043 | G18: South Korea | H18: 520 | I18: =H18/$H$14 -> 0.052525253 | J18: 0.043
A19: High-Performance Engineering Polymer Foams | B19: 0.05 | C19: 0.061 | G19: ASEAN | H19: 1430 | I19: =H19/$H$14 -> 0.14444444 | J19: 0.065
A20: Polyimide (PI) Foams | B20: 0.3 | C20: 0.058 | G20: Australia | H20: 119 | I20: =H20/$H$14 -> 0.012020202 | J20: 0.036
A21: Phenolic Foams | B21: 0.35 | C21: 0.051 | G21: Rest of Asia Pacific | H21: 398 | I21: =H21/$H$14 -> 0.04020202 | J21: 0.057
A22: Advanced Thermoplastic Foams | B22: =1-SUM(B20:B21) -> 0.35 | C22: 0.07 | G22: Latin America | H22: 979 | I22: =SUM(I23:I26) -> 1 | J22: 0.0454
A23: Melamine Foams | B23: 0.015 | C23: 0.043 | G23: Brazil | H23: 170 | I23: =H23/$H$22 -> 0.17364658 | J23: 0.044
A24: Elastomeric & Specialty Foams | B24: 0.06 | C24: 0.05 | G24: Mexico | H24: 491 | I24: =H24/$H$22 -> 0.50153218 | J24: 0.052
A25: Bio-Based & Sustainable Foams | B25: =1-SUM(B3,B9,B12,B15,B19,B23,B24) -> 0.045 | C25: 0.08 | G25: Argentina | H25: 138 | I25: =H25/$H$22 -> 0.14096016 | J25: 0.031
G26: Rest of Latin America | H26: 180 | I26: =H26/$H$22 -> 0.18386108 | J26: 0.04
A27: Density | B27: 1 | C27: 0.045 | G27: Middle East | H27: 1300 | I27: =SUM(I28:I30) -> 1 | J27: 0.0496
A28: Ultra-Low Density: < 15 | B28: 0.14 | C28: 0.037 | G28: Israel | H28: 40 | I28: =H28/$H$27 -> 0.030769231 | J28: 0.043
A29: Low Density: 15 – 30 | B29: 0.28 | C29: 0.04 | G29: GCC | H29: 384 | I29: =H29/$H$27 -> 0.29538462 | J29: 0.054
A30: Medium Density: 30 – 80 | B30: 0.33 | C30: 0.045 | G30: Rest of Middle East | H30: 876 | I30: =H30/$H$27 -> 0.67384615 | J30: 0.048
A31: High Density: 80 – 250 | B31: 0.18 | C31: 0.055 | G31: Africa | H31: 1900 | I31: =SUM(I32:I34) -> 1 | J31: 0.0511
A32: Ultra-High Density / Structural: > 250 | B32: =1-SUM(B28:B31) -> 0.07 | C32: 0.063 | G32: North Africa | H32: 600 | I32: =H32/$H$31 -> 0.31578947 | J32: 0.052
G33: Central Africa | H33: 950 | I33: =H33/$H$31 -> 0.5 | J33: 0.055
A34: Form | B34: 1 | C34: 0.045 | G34: South Africa | H34: 350 | I34: =H34/$H$31 -> 0.18421053 | J34: 0.039
A35: Sheets & Boards | B35: 0.35 | C35: 0.047 | G35: Global Total | H35: =SUM(H3,H6,H14,H22,H27,H31) -> 29035
A36: Rolls | B36: 0.1 | C36: 0.04 | G36: ASP | H36: 2000
A37: Blocks / Buns | B37: 0.24 | C37: 0.036 | G37: Total Value (USD Bn) | H37: =((H35/1000)*H36)/1000 -> 58.07
A38: Molded & Fabricated Parts | B38: 0.21 | C38: 0.054
A39: Laminated / Composite Foam Structures | B39: =1-SUM(B35:B38) -> 0.1 | C39: 0.063
A41: End-Use | B41: 1 | C41: 0.045
...

Sheet Data
AE2: =VLOOKUP(AE3,$B$76:$D$107,3,0) -> 0.040821165 | AF2: =VLOOKUP(AF3,$B$76:$D$107,3,0) -> 0.028020179 | AG2: =VLOOKUP(AG3,$B$76:$D$107,3,0) -> 0.031131217 | AH2: =VLOOKUP(AH3,$B$76:$D$107,3,0) -> 0.040314901 | AI2: =VLOOKUP(AI3,$B$76:$D$107,3,0) -> 0.034437446 | AJ2: =VLOOKUP(AJ3,$B$76:$D$107,3,0) -> 0.028167766 | AK2: =VLOOKUP(AK3,$B$76:$D$107,3,0) -> 0.043853148 | AL2: =VLOOKUP(AL3,$B$76:$D$107,3,0) -> 0.025284187 | ... BD2: =VLOOKUP(BD3,$B$76:$D$107,3,0) -> 0.040414009
C3: U.S. | D3: Canada | E3: Germany | F3: UK | G3: France | H3: Italy | I3: Spain | J3: Russia | K3: Rest of Europe | L3: China | M3: India | N3: Japan | O3: South Korea | P3: ASEAN | Q3: Australia | R3: Rest of Asia Pacific | S3: Brazil | T3: Mexico | U3: Argentina | V3: Rest of Latin America | W3: Israel | X3: GCC | Y3: Rest of Middle East | Z3: North Africa | AA3: Central Africa | AB3: South Africa | AE3: U.S. | AF3: Canada | AG3: Germany | AH3: UK | AI3: France | AJ3: Italy | AK3: Spain | AL3: Russia | AM3: Rest of Europe | AN3: China | AO3: India | AP3: Japan | AQ3: South Korea | AR3: ASEAN | AS3: Australia | AT3: Rest of Asia Pacific | AU3: Brazil | AV3: Mexico | AW3: Argentina | AX3: Rest of Latin America | AY3: Israel | AZ3: GCC | BA3: Rest of Middle East | BB3: North Africa | BC3: Central Africa | BD3: South Africa | BG3: U.S. | BH3: Canada | BI3: Germany | BJ3: UK | BK3: France | BL3: Italy | BM3: Spain | BN3: Russia | BO3: Rest of Europe | BP3: China | BQ3: India | BR3: Japan | BS3: South Korea | BT3: ASEAN | BU3: Australia | BV3: Rest of Asia Pacific | BW3: Brazil | BX3: Mexico | BY3: Argentina | BZ3: Rest of Latin America | CA3: Israel | CB3: GCC | CC3: Rest of Middle East | CD3: North Africa | CE3: Central Africa | CF3: South Africa
B4: By Product Type | AD4: By Product Type | AE4: =AE5*C5+AE11*C11+AE14*C14+AE17*C17+AE21*C21+AE25*C25+AE26*C26+AE27*C27 -> 0.040843165 | AF4: =AF5*D5+AF11*D11+AF14*D14+AF17*D17+AF21*D21+AF25*D25+AF26*D26+AF27*D27 -> 0.02813629 | AG4: =AG5*E5+AG11*E11+AG14*E14+AG17*E17+AG21*E21+AG25*E25+AG26*E26+AG27*E27 -> 0.031160542 | AH4: =AH5*F5+AH11*F11+AH14*F14+AH17*F17+AH21*F21+AH25*F25+AH26*F26+AH27*F27 -> 0.040335301 | AI4: =AI5*G5+AI11*G11+AI14*G14+AI17*G17+AI21*G21+AI25*G25+AI26*G26+AI27*G27 -> 0.034454246 | AJ4: =AJ5*H5+AJ11*H11+AJ14*H14+AJ17*H17+AJ21*H21+AJ25*H25+AJ26*H26+AJ27*H27 -> 0.028231039 | AK4: =AK5*I5+AK11*I11+AK14*I14+AK17*I17+AK21*I21+AK25*I25+AK26*I26+AK27*I27 -> 0.043871848 | AL4: =AL5*J5+AL11*J11+AL14*J14+AL17*J17+AL21*J21+AL25*J25+AL26*J26+AL27*J27 -> 0.025313569 | ... BD4: =BD5*AB5+BD11*AB11+BD14*AB14+BD17*AB17+BD21*AB21+BD25*AB25+BD26*AB26+BD27*AB27 -> 0.040430109 | BF4: By Product Type
B5: Polyurethane (PU) Foams | C5: =1-SUM(C11,C14,C17,C21,C25:C27) -> 0.4216 | D5: =1-SUM(D11,D14,D17,D21,D25:D27) -> 0.4571 | E5: =1-SUM(E11,E14,E17,E21,E25:E27) -> 0.4646 | F5: =1-SUM(F11,F14,F17,F21,F25:F27) -> 0.4524 | G5: =1-SUM(G11,G14,G17,G21,G25:G27) -> 0.497 | H5: =1-SUM(H11,H14,H17,H21,H25:H27) -> 0.4702 | I5: =1-SUM(I11,I14,I17,I21,I25:I27) -> 0.4301 | J5: =1-SUM(J11,J14,J17,J21,J25:J27) -> 0.467 | ... AB5: =1-SUM(AB11,AB14,AB17,AB21,AB25:AB27) -> 0.4293 | AD5: Polyurethane (PU) Foams | AE5: =SUMPRODUCT(AE6:AE10,C6:C10) -> 0.039469784 | AF5: =SUMPRODUCT(AF6:AF10,D6:D10) -> 0.027491435 | AG5: =SUMPRODUCT(AG6:AG10,E6:E10) -> 0.031128023 | AH5: =SUMPRODUCT(AH6:AH10,F6:F10) -> 0.039387881 | AI5: =SUMPRODUCT(AI6:AI10,G6:G10) -> 0.034040588 | AJ5: =SUMPRODUCT(AJ6:AJ10,H6:H10) -> 0.026968037 | AK5: =SUMPRODUCT(AK6:AK10,I6:I10) -> 0.042951447 | AL5: =SUMPRODUCT(AL6:AL10,J6:J10) -> 0.024242403 | ... BD5: =SUMPRODUCT(BD6:BD10,AB6:AB10) -> 0.039619547 | BF5: Polyurethane (PU) Foams | BG5: CMI_Trend_60 | BH5: CMI_Trend_20 | BI5: CMI_Trend_56 | BJ5: CMI_Trend_46 | BK5: CMI_Trend_52 | BL5: CMI_Trend_20 | BM5: CMI_Trend_20 | BN5: CMI_Trend_38 | BO5: CMI_Trend_38 | BP5: CMI_Trend_60 | BQ5: CMI_Trend_20 | BR5: CMI_Trend_20 | BS5: CMI_Trend_46 | BT5: CMI_Trend_46 | BU5: CMI_Trend_52 | BV5: CMI_Trend_46 | BW5: CMI_Trend_60 | BX5: CMI_Trend_56 | BY5: CMI_Trend_56 | BZ5: CMI_Trend_20 | CA5: CMI_Trend_38 | CB5: CMI_Trend_60 | CC5: CMI_Trend_56 | CD5: CMI_Trend_56 | CE5: CMI_Trend_56 | CF5: CMI_Trend_20
B6: Flexible PU | C6: =1-SUM(C7:C10) -> 0.5811 | D6: =1-SUM(D7:D10) -> 0.5537 | E6: =1-SUM(E7:E10) -> 0.523 | F6: =1-SUM(F7:F10) -> 0.5549 | G6: =1-SUM(G7:G10) -> 0.5414 | H6: =1-SUM(H7:H10) -> 0.5685 | I6: =1-SUM(I7:I10) -> 0.5307 | J6: =1-SUM(J7:J10) -> 0.5389 | ... AB6: =1-SUM(AB7:AB10) -> 0.5185 | AD6: Flexible PU | AE6: 0.033092986 | AF6: 0.020912576 | AG6: 0.023882608 | AH6: 0.032752591 | AI6: 0.027169916 | AJ6: 0.020439168 | AK6: 0.035816249 | AL6: 0.01730997 | AM6: 0.030585265 | AN6: 0.046044396 | AO6: 0.076299164 | AP6: 0.027754242 | AQ6: 0.041436918 | AR6: 0.061056366 | AS6: 0.035405811 | AT6: 0.055558108 | AU6: 0.034396773 | AV6: 0.041344439 | AW6: 0.022178763 | AX6: 0.029045271 | AY6: 0.032562842 | AZ6: 0.044126562 | BA6: 0.038425964 | BB6: 0.041972517 | BC6: 0.049098778 | BD6: 0.032300376 | BF6: Flexible PU | BG6: CMI_Trend_20 | BH6: CMI_Trend_38 | BI6: CMI_Trend_52 | BJ6: CMI_Trend_38 | BK6: CMI_Trend_52 | BL6: CMI_Trend_52 | BM6: CMI_Trend_25 | BN6: CMI_Trend_25 | BO6: CMI_Trend_60 | BP6: CMI_Trend_38 | BQ6: CMI_Trend_52 | BR6: CMI_Trend_60 | BS6: CMI_Trend_56 | BT6: CMI_Trend_46 | BU6: CMI_Trend_60 | BV6: CMI_Trend_52 | BW6: CMI_Trend_52 | BX6: CMI_Trend_52 | BY6: CMI_Trend_20 | BZ6: CMI_Trend_38 | CA6: CMI_Trend_38 | CB6: CMI_Trend_52 | CC6: CMI_Trend_56 | CD6: CMI_Trend_20 | CE6: CMI_Trend_56 | CF6: CMI_Trend_20
B7: Rigid PU | C7: 0.2368 | D7: 0.2397 | E7: 0.2654 | F7: 0.2481 | G7: 0.2552 | H7: 0.2364 | I7: 0.2558 | J7: 0.2493 | K7: 0.2423 | L7: 0.2345 | M7: 0.254 | N7: 0.247 | O7: 0.2541 | P7: 0.2602 | Q7: 0.2566 | R7: 0.2389 | S7: 0.2488 | T7: 0.2417 | U7: 0.2402 | V7: 0.2673 | W7: 0.2341 | X7: 0.238 | Y7: 0.2663 | Z7: 0.2646 | AA7: 0.2608 | AB7: 0.2677 | AD7: Rigid PU | AE7: 0.049337297 | AF7: 0.037156887 | AG7: 0.040126919 | AH7: 0.048996903 | AI7: 0.043414228 | AJ7: 0.036683479 | AK7: 0.05206056 | AL7: 0.033554281 | AM7: 0.046829576 | AN7: 0.062288707 | AO7: 0.092543475 | AP7: 0.043998554 | AQ7: 0.057681229 | AR7: 0.077300678 | AS7: 0.051650122 | AT7: 0.071802419 | AU7: 0.050641084 | AV7: 0.05758875 | AW7: 0.038423074 | AX7: 0.045289582 | AY7: 0.048807154 | AZ7: 0.060370874 | BA7: 0.054670275 | BB7: 0.058216829 | BC7: 0.06534309 | BD7: 0.048544687 | BF7: Rigid PU | BG7: CMI_Trend_56 | BH7: CMI_Trend_60 | BI7: CMI_Trend_60 | BJ7: CMI_Trend_56 | BK7: CMI_Trend_20 | BL7: CMI_Trend_60 | BM7: CMI_Trend_38 | BN7: CMI_Trend_52 | BO7: CMI_Trend_25 | BP7: CMI_Trend_38 | BQ7: CMI_Trend_60 | BR7: CMI_Trend_20 | BS7: CMI_Trend_52 | BT7: CMI_Trend_46 | BU7: CMI_Trend_38 | BV7: CMI_Trend_38 | BW7: CMI_Trend_52 | BX7: CMI_Trend_46 | BY7: CMI_Trend_46 | BZ7: CMI_Trend_38 | CA7: CMI_Trend_56 | CB7: CMI_Trend_60 | CC7: CMI_Trend_38 | CD7: CMI_Trend_20 | CE7: CMI_Trend_52 | CF7: CMI_Trend_46
B8: Semi-Rigid PU | C8: 0.0608 | D8: 0.0679 | E8: 0.0792 | F8: 0.0753 | G8: 0.0651 | H8: 0.0636 | I8: 0.0602 | J8: 0.073 | K8: 0.0638 | L8: 0.0658 | M8: 0.0701 | N8: 0.071 | O8: 0.0663 | P8: 0.0643 | Q8: 0.0714 | R8: 0.0655 | S8: 0.0649 | T8: 0.0636 | U8: 0.0665 | V8: 0.0787 | W8: 0.068 | X8: 0.0751 | Y8: 0.0706 | Z8: 0.0756 | AA8: 0.079 | AB8: 0.0685 | AD8: Semi-Rigid PU | AE8: 0.043191832 | AF8: 0.031011422 | AG8: 0.033981454 | AH8: 0.042851438 | AI8: 0.037268763 | AJ8: 0.030538014 | AK8: 0.045915095 | AL8: 0.027408816 | AM8: 0.040684111 | AN8: 0.056143242 | AO8: 0.08639801 | AP8: 0.037853089 | AQ8: 0.051535764 | AR8: 0.071155213 | AS8: 0.045504657 | AT8: 0.065656954 | AU8: 0.044495619 | AV8: 0.051443285 | AW8: 0.032277609 | AX8: 0.039144117 | AY8: 0.042661689 | AZ8: 0.054225409 | BA8: 0.04852481 | BB8: 0.052071364 | BC8: 0.059197625 | BD8: 0.042399222 | BF8: Semi-Rigid PU | BG8: CMI_Trend_52 | BH8: CMI_Trend_60 | BI8: CMI_Trend_46 | BJ8: CMI_Trend_52 | BK8: CMI_Trend_25 | BL8: CMI_Trend_38 | BM8: CMI_Trend_25 | BN8: CMI_Trend_60 | BO8: CMI_Trend_20 | BP8: CMI_Trend_38 | BQ8: CMI_Trend_46 | BR8: CMI_Trend_46 | BS8: CMI_Trend_25 | BT8: CMI_Trend_20 | BU8: CMI_Trend_60 | BV8: CMI_Trend_52 | BW8: CMI_Trend_60 | BX8: CMI_Trend_46 | BY8: CMI_Trend_46 | BZ8: CMI_Trend_60 | CA8: CMI_Trend_20 | CB8: CMI_Trend_20 | CC8: CMI_Trend_20 | CD8: CMI_Trend_56 | CE8: CMI_Trend_60 | CF8: CMI_Trend_46
B9: Integral Skin PU | C9: 0.0413 | D9: 0.0592 | E9: 0.0424 | F9: 0.0463 | G9: 0.0544 | H9: 0.0467 | I9: 0.0553 | J9: 0.0502 | K9: 0.0428 | L9: 0.0581 | M9: 0.0591 | N9: 0.0402 | O9: 0.0416 | P9: 0.0538 | Q9: 0.0425 | R9: 0.0578 | S9: 0.0428 | T9: 0.0469 | U9: 0.045 | V9: 0.0406 | W9: 0.0536 | X9: 0.0494 | Y9: 0.0575 | Z9: 0.0418 | AA9: 0.0581 | AB9: 0.0505 | AD9: Integral Skin PU | AE9: 0.038337297 | AF9: 0.026156887 | AG9: 0.029126919 | AH9: 0.037996903 | AI9: 0.032414228 | AJ9: 0.025683479 | AK9: 0.04106056 | AL9: 0.022554281 | AM9: 0.035829576 | AN9: 0.051288707 | AO9: 0.081543475 | AP9: 0.032998554 | AQ9: 0.046681229 | AR9: 0.066300678 | AS9: 0.040650122 | AT9: 0.060802419 | AU9: 0.039641084 | AV9: 0.04658875 | AW9: 0.027423074 | AX9: 0.034289582 | AY9: 0.037807154 | AZ9: 0.049370874 | BA9: 0.043670275 | BB9: 0.047216829 | BC9: 0.05434309 | BD9: 0.037544687 | BF9: Integral Skin PU | BG9: CMI_Trend_20 | BH9: CMI_Trend_60 | BI9: CMI_Trend_52 | BJ9: CMI_Trend_20 | BK9: CMI_Trend_25 | BL9: CMI_Trend_60 | BM9: CMI_Trend_25 | BN9: CMI_Trend_56 | BO9: CMI_Trend_38 | BP9: CMI_Trend_38 | BQ9: CMI_Trend_25 | BR9: CMI_Trend_52 | BS9: CMI_Trend_20 | BT9: CMI_Trend_56 | BU9: CMI_Trend_52 | BV9: CMI_Trend_56 | BW9: CMI_Trend_25 | BX9: CMI_Trend_46 | BY9: CMI_Trend_38 | BZ9: CMI_Trend_20 | CA9: CMI_Trend_38 | CB9: CMI_Trend_25 | CC9: CMI_Trend_60 | CD9: CMI_Trend_52 | CE9: CMI_Trend_38 | CF9: CMI_Trend_20
B10: Microcellular PU | C10: 0.08 | D10: 0.0795 | E10: 0.09 | F10: 0.0754 | G10: 0.0839 | H10: 0.0848 | I10: 0.098 | J10: 0.0886 | K10: 0.0882 | L10: 0.0797 | M10: 0.0902 | N10: 0.0701 | O10: 0.0639 | P10: 0.0877 | Q10: 0.0897 | R10: 0.0765 | S10: 0.083 | T10: 0.0731 | U10: 0.0688 | V10: 0.0662 | W10: 0.095 | X10: 0.0843 | Y10: 0.0795 | Z10: 0.0954 | AA10: 0.0706 | AB10: 0.0948 | AD10: Microcellular PU | AE10: 0.054337297 | AF10: 0.042156887 | AG10: 0.045126919 | AH10: 0.053996903 | AI10: 0.048414228 | AJ10: 0.041683479 | AK10: 0.05706056 | AL10: 0.038554281 | AM10: 0.051829576 | AN10: 0.067288707 | AO10: 0.097543475 | AP10: 0.048998554 | AQ10: 0.062681229 | AR10: 0.082300678 | AS10: 0.056650122 | AT10: 0.076802419 | AU10: 0.055641084 | AV10: 0.06258875 | AW10: 0.043423074 | AX10: 0.050289582 | AY10: 0.053807154 | AZ10: 0.065370874 | BA10: 0.059670275 | BB10: 0.063216829 | BC10: 0.07034309 | BD10: 0.053544687 | BF10: Microcellular PU | BG10: CMI_Trend_60 | BH10: CMI_Trend_38 | BI10: CMI_Trend_46 | BJ10: CMI_Trend_25 | BK10: CMI_Trend_52 | BL10: CMI_Trend_56 | BM10: CMI_Trend_38 | BN10: CMI_Trend_56 | BO10: CMI_Trend_20 | BP10: CMI_Trend_52 | BQ10: CMI_Trend_60 | BR10: CMI_Trend_52 | BS10: CMI_Trend_52 | BT10: CMI_Trend_46 | BU10: CMI_Trend_38 | BV10: CMI_Trend_25 | BW10: CMI_Trend_38 | BX10: CMI_Trend_20 | BY10: CMI_Trend_46 | BZ10: CMI_Trend_46 | CA10: CMI_Trend_52 | CB10: CMI_Trend_46 | CC10: CMI_Trend_56 | CD10: CMI_Trend_46 | CE10: CMI_Trend_52 | CF10: CMI_Trend_46
B11: Polystyrene (PS) Foams | C11: 0.2346 | D11: 0.2417 | E11: 0.2454 | F11: 0.2324 | G11: 0.2204 | H11: 0.2138 | I11: 0.222 | J11: 0.23 | K11: 0.2284 | L11: 0.2394 | M11: 0.2203 | N11: 0.2239 | O11: 0.2432 | P11: 0.2278 | Q11: 0.235 | R11: 0.2221 | S11: 0.2475 | T11: 0.2148 | U11: 0.2419 | V11: 0.242 | W11: 0.2414 | X11: 0.2249 | Y11: 0.2331 | Z11: 0.2261 | AA11: 0.2393 | AB11: 0.2406 | AD11: Polystyrene (PS) Foams | AE11: =SUMPRODUCT(AE12:AE13,C12:C13) -> 0.031759582 | AF11: =SUMPRODUCT(AF12:AF13,D12:D13) -> 0.019794372 | AG11: =SUMPRODUCT(AG12:AG13,E12:E13) -> 0.022731604 | AH11: =SUMPRODUCT(AH12:AH13,F12:F13) -> 0.031502387 | AI11: =SUMPRODUCT(AI12:AI13,G12:G13) -> 0.026050912 | AJ11: =SUMPRODUCT(AJ12:AJ13,H12:H13) -> 0.019180964 | AK11: =SUMPRODUCT(AK12:AK13,I12:I13) -> 0.034538045 | AL11: =SUMPRODUCT(AL12:AL13,J12:J13) -> 0.015941366 | ... BD11: =SUMPRODUCT(BD12:BD13,AB12:AB13) -> 0.031185372 | BF11: Polystyrene (PS) Foams | BG11: CMI_Trend_25 | BH11: CMI_Trend_60 | BI11: CMI_Trend_20 | BJ11: CMI_Trend_52 | BK11: CMI_Trend_38 | BL11: CMI_Trend_38 | BM11: CMI_Trend_52 | BN11: CMI_Trend_52 | BO11: CMI_Trend_38 | BP11: CMI_Trend_56 | BQ11: CMI_Trend_52 | BR11: CMI_Trend_46 | BS11: CMI_Trend_20 | BT11: CMI_Trend_60 | BU11: CMI_Trend_56 | BV11: CMI_Trend_20 | BW11: CMI_Trend_20 | BX11: CMI_Trend_60 | BY11: CMI_Trend_25 | BZ11: CMI_Trend_60 | CA11: CMI_Trend_56 | CB11: CMI_Trend_52 | CC11: CMI_Trend_56 | CD11: CMI_Trend_20 | CE11: CMI_Trend_60 | CF11: CMI_Trend_56
B12: Expanded Polystyrene (EPS) | C12: =1-C13 -> 0.7316 | D12: =1-D13 -> 0.7047 | E12: =1-E13 -> 0.7088 | F12: =1-F13 -> 0.7212 | G12: =1-G13 -> 0.7048 | H12: =1-H13 -> 0.7222 | I12: =1-I13 -> 0.7247 | J12: =1-J13 -> 0.736 | ... AB12: =1-AB13 -> 0.7043 | AD12: Expanded Polystyrene (EPS) | AE12: 0.029612382 | AF12: 0.017431972 | AG12: 0.020402004 | AH12: 0.029271987 | AI12: 0.023689312 | AJ12: 0.016958564 | AK12: 0.032335645 | AL12: 0.013829366 | AM12: 0.027104661 | AN12: 0.042563792 | AO12: 0.07281856 | AP12: 0.024273638 | AQ12: 0.037956314 | AR12: 0.057575762 | AS12: 0.031925207 | AT12: 0.052077504 | AU12: 0.030916169 | AV12: 0.037863835 | AW12: 0.018698159 | AX12: 0.025564667 | AY12: 0.029082238 | AZ12: 0.040645958 | BA12: 0.03494536 | BB12: 0.038491913 | BC12: 0.045618174 | BD12: 0.028819772 | BF12: Expanded Polystyrene (EPS) | BG12: CMI_Trend_46 | BH12: CMI_Trend_52 | BI12: CMI_Trend_60 | BJ12: CMI_Trend_46 | BK12: CMI_Trend_56 | BL12: CMI_Trend_25 | BM12: CMI_Trend_56 | BN12: CMI_Trend_46 | BO12: CMI_Trend_25 | BP12: CMI_Trend_56 | BQ12: CMI_Trend_46 | BR12: CMI_Trend_52 | BS12: CMI_Trend_60 | BT12: CMI_Trend_38 | BU12: CMI_Trend_38 | BV12: CMI_Trend_56 | BW12: CMI_Trend_46 | BX12: CMI_Trend_56 | BY12: CMI_Trend_38 | BZ12: CMI_Trend_25 | CA12: CMI_Trend_25 | CB12: CMI_Trend_56 | CC12: CMI_Trend_52 | CD12: CMI_Trend_60 | CE12: CMI_Trend_20 | CF12: CMI_Trend_52
B13: Extruded Polystyrene (XPS) | C13: 0.2684 | D13: 0.2953 | E13: 0.2912 | F13: 0.2788 | G13: 0.2952 | H13: 0.2778 | I13: 0.2753 | J13: 0.264 | K13: 0.277 | L13: 0.2684 | M13: 0.2695 | N13: 0.2721 | O13: 0.2872 | P13: 0.2889 | Q13: 0.2906 | R13: 0.2961 | S13: 0.2652 | T13: 0.2922 | U13: 0.2772 | V13: 0.2911 | W13: 0.2744 | X13: 0.2767 | Y13: 0.2664 | Z13: 0.2801 | AA13: 0.2956 | AB13: 0.2957 | AD13: Extruded Polystyrene (XPS) | AE13: 0.037612382 | AF13: 0.025431972 | AG13: 0.028402004 | AH13: 0.037271987 | AI13: 0.031689312 | AJ13: 0.024958564 | AK13: 0.040335645 | AL13: 0.021829366 | AM13: 0.035104661 | AN13: 0.050563792 | AO13: 0.08081856 | AP13: 0.032273638 | AQ13: 0.045956314 | AR13: 0.065575762 | AS13: 0.039925207 | AT13: 0.060077504 | AU13: 0.038916169 | AV13: 0.045863835 | AW13: 0.026698159 | AX13: 0.033564667 | AY13: 0.037082238 | AZ13: 0.048645958 | BA13: 0.04294536 | BB13: 0.046491913 | BC13: 0.053618174 | BD13: 0.036819772 | BF13: Extruded Polystyrene (XPS) | BG13: CMI_Trend_52 | BH13: CMI_Trend_52 | BI13: CMI_Trend_60 | BJ13: CMI_Trend_25 | BK13: CMI_Trend_20 | BL13: CMI_Trend_20 | BM13: CMI_Trend_60 | BN13: CMI_Trend_60 | BO13: CMI_Trend_25 | BP13: CMI_Trend_46 | BQ13: CMI_Trend_25 | BR13: CMI_Trend_52 | BS13: CMI_Trend_25 | BT13: CMI_Trend_46 | BU13: CMI_Trend_20 | BV13: CMI_Trend_60 | BW13: CMI_Trend_46 | BX13: CMI_Trend_52 | BY13: CMI_Trend_52 | BZ13: CMI_Trend_56 | CA13: CMI_Trend_38 | CB13: CMI_Trend_20 | CC13: CMI_Trend_25 | CD13: CMI_Trend_20 | CE13: CMI_Trend_25 | CF13: CMI_Trend_52
B14: Polyolefin Foams | C14: 0.1007 | D14: 0.0796 | E14: 0.1029 | F14: 0.1013 | G14: 0.0913 | H14: 0.1026 | I14: 0.0979 | J14: 0.0847 | K14: 0.079 | L14: 0.0912 | M14: 0.1021 | N14: 0.0976 | O14: 0.0965 | P14: 0.0862 | Q14: 0.0784 | R14: 0.0799 | S14: 0.0879 | T14: 0.0835 | U14: 0.1018 | V14: 0.0946 | W14: 0.0819 | X14: 0.1028 | Y14: 0.0822 | Z14: 0.0814 | AA14: 0.0952 | AB14: 0.1027 | AD14: Polyolefin Foams | AE14: =SUMPRODUCT(AE15:AE16,C15:C16) -> 0.043048182 | AF14: =SUMPRODUCT(AF15:AF16,D15:D16) -> 0.030596072 | AG14: =SUMPRODUCT(AG15:AG16,E15:E16) -> 0.033803704 | AH14: =SUMPRODUCT(AH15:AH16,F15:F16) -> 0.042511987 | AI14: =SUMPRODUCT(AI15:AI16,G15:G16) -> 0.036860012 | AJ14: =SUMPRODUCT(AJ15:AJ16,H15:H16) -> 0.030299764 | AK14: =SUMPRODUCT(AK15:AK16,I15:I16) -> 0.045648245 | AL14: =SUMPRODUCT(AL15:AL16,J15:J16) -> 0.027129866 | ... BD14: =SUMPRODUCT(BD15:BD16,AB15:AB16) -> 0.042193972 | BF14: Polyolefin Foams | BG14: CMI_Trend_52 | BH14: CMI_Trend_20 | BI14: CMI_Trend_60 | BJ14: CMI_Trend_52 | BK14: CMI_Trend_46 | BL14: CMI_Trend_56 | BM14: CMI_Trend_20 | BN14: CMI_Trend_25 | BO14: CMI_Trend_56 | BP14: CMI_Trend_56 | BQ14: CMI_Trend_60 | BR14: CMI_Trend_60 | BS14: CMI_Trend_20 | BT14: CMI_Trend_38 | BU14: CMI_Trend_56 | BV14: CMI_Trend_52 | BW14: CMI_Trend_46 | BX14: CMI_Trend_20 | BY14: CMI_Trend_25 | BZ14: CMI_Trend_60 | CA14: CMI_Trend_20 | CB14: CMI_Trend_46 | CC14: CMI_Trend_46 | CD14: CMI_Trend_20 | CE14: CMI_Trend_46 | CF14: CMI_Trend_52
B15: Polyethylene (PE) Foams | C15: =1-C16 -> 0.6122 | D15: =1-D16 -> 0.6369 | E15: =1-E16 -> 0.6153 | F15: =1-F16 -> 0.63 | G15: =1-G16 -> 0.6363 | H15: =1-H16 -> 0.6208 | I15: =1-I16 -> 0.6234 | J15: =1-J16 -> 0.6245 | ... AB15: =1-AB16 -> 0.6178 | AD15: Polyethylene (PE) Foams | AE15: 0.038782382 | AF15: 0.026601972 | AG15: 0.029572004 | AH15: 0.038441987 | AI15: 0.032859312 | AJ15: 0.026128564 | AK15: 0.041505645 | AL15: 0.022999366 | AM15: 0.036274661 | AN15: 0.051733792 | AO15: 0.08198856 | AP15: 0.033443638 | AQ15: 0.047126314 | AR15: 0.066745762 | AS15: 0.041095207 | AT15: 0.061247504 | AU15: 0.040086169 | AV15: 0.047033835 | AW15: 0.027868159 | AX15: 0.034734667 | AY15: 0.038252238 | AZ15: 0.049815958 | BA15: 0.04411536 | BB15: 0.047661913 | BC15: 0.054788174 | BD15: 0.037989772 | BF15: Polyethylene (PE) Foams | BG15: CMI_Trend_46 | BH15: CMI_Trend_25 | BI15: CMI_Trend_38 | BJ15: CMI_Trend_46 | BK15: CMI_Trend_25 | BL15: CMI_Trend_52 | BM15: CMI_Trend_25 | BN15: CMI_Trend_38 | BO15: CMI_Trend_60 | BP15: CMI_Trend_56 | BQ15: CMI_Trend_25 | BR15: CMI_Trend_60 | BS15: CMI_Trend_46 | BT15: CMI_Trend_38 | BU15: CMI_Trend_56 | BV15: CMI_Trend_20 | BW15: CMI_Trend_60 | BX15: CMI_Trend_25 | BY15: CMI_Trend_56 | BZ15: CMI_Trend_46 | CA15: CMI_Trend_56 | CB15: CMI_Trend_60 | CC15: CMI_Trend_25 | CD15: CMI_Trend_46 | CE15: CMI_Trend_20 | CF15: CMI_Trend_46
B16: Polypropylene (PP) Foams | C16: 0.3878 | D16: 0.3631 | E16: 0.3847 | F16: 0.37 | G16: 0.3637 | H16: 0.3792 | I16: 0.3766 | J16: 0.3755 | K16: 0.381 | L16: 0.3834 | M16: 0.3859 | N16: 0.3742 | O16: 0.3715 | P16: 0.3942 | Q16: 0.367 | R16: 0.3845 | S16: 0.3918 | T16: 0.3821 | U16: 0.3764 | V16: 0.38 | W16: 0.3702 | X16: 0.3796 | Y16: 0.3761 | Z16: 0.3972 | AA16: 0.3717 | AB16: 0.3822 | AD16: Polypropylene (PP) Foams | AE16: 0.049782382 | AF16: 0.037601972 | AG16: 0.040572004 | AH16: 0.049441987 | AI16: 0.043859312 | AJ16: 0.037128564 | AK16: 0.052505645 | AL16: 0.033999366 | AM16: 0.047274661 | AN16: 0.062733792 | AO16: 0.09298856 | AP16: 0.044443638 | AQ16: 0.058126314 | AR16: 0.077745762 | AS16: 0.052095207 | AT16: 0.072247504 | AU16: 0.051086169 | AV16: 0.058033835 | AW16: 0.038868159 | AX16: 0.045734667 | AY16: 0.049252238 | AZ16: 0.060815958 | BA16: 0.05511536 | BB16: 0.058661913 | BC16: 0.065788174 | BD16: 0.048989772 | BF16: Polypropylene (PP) Foams | BG16: CMI_Trend_20 | BH16: CMI_Trend_56 | BI16: CMI_Trend_46 | BJ16: CMI_Trend_38 | BK16: CMI_Trend_25 | BL16: CMI_Trend_20 | BM16: CMI_Trend_38 | BN16: CMI_Trend_52 | BO16: CMI_Trend_56 | BP16: CMI_Trend_46 | BQ16: CMI_Trend_60 | BR16: CMI_Trend_38 | BS16: CMI_Trend_46 | BT16: CMI_Trend_20 | BU16: CMI_Trend_25 | BV16: CMI_Trend_20 | BW16: CMI_Trend_52 | BX16: CMI_Trend_38 | BY16: CMI_Trend_46 | BZ16: CMI_Trend_52 | CA16: CMI_Trend_56 | CB16: CMI_Trend_60 | CC16: CMI_Trend_46 | CD16: CMI_Trend_56 | CE16: CMI_Trend_56 | CF16: CMI_Trend_52
B17: PVC Foams | C17: 0.0392 | D17: 0.0471 | E17: 0.0336 | F17: 0.0377 | G17: 0.037 | H17: 0.0358 | I17: 0.049 | J17: 0.0349 | K17: 0.0465 | L17: 0.0498 | M17: 0.0367 | N17: 0.0453 | O17: 0.0495 | P17: 0.0325 | Q17: 0.0353 | R17: 0.0491 | S17: 0.0358 | T17: 0.035 | U17: 0.0409 | V17: 0.047 | W17: 0.044 | X17: 0.0361 | Y17: 0.0491 | Z17: 0.0331 | AA17: 0.0492 | AB17: 0.0367 | AD17: PVC Foams | AE17: =SUMPRODUCT(AE18:AE20,C18:C20) -> 0.027061727 | AF17: =SUMPRODUCT(AF18:AF20,D18:D20) -> 0.017033762 | AG17: =SUMPRODUCT(AG18:AG20,E18:E20) -> 0.018028425 | AH17: =SUMPRODUCT(AH18:AH20,F18:F20) -> 0.026875556 | AI17: =SUMPRODUCT(AI18:AI20,G18:G20) -> 0.021142187 | AJ17: =SUMPRODUCT(AJ18:AJ20,H18:H20) -> 0.016865045 | AK17: =SUMPRODUCT(AK18:AK20,I18:I20) -> 0.029989817 | AL17: =SUMPRODUCT(AL18:AL20,J18:J20) -> 0.016806051 | ... BD17: =SUMPRODUCT(BD18:BD20,AB18:AB20) -> 0.02635223 | BF17: PVC Foams | BG17: CMI_Trend_38 | BH17: CMI_Trend_56 | BI17: CMI_Trend_25 | BJ17: CMI_Trend_25 | BK17: CMI_Trend_60 | BL17: CMI_Trend_46 | BM17: CMI_Trend_56 | BN17: CMI_Trend_38 | BO17: CMI_Trend_56 | BP17: CMI_Trend_20 | BQ17: CMI_Trend_38 | BR17: CMI_Trend_52 | BS17: CMI_Trend_20 | BT17: CMI_Trend_25 | BU17: CMI_Trend_20 | BV17: CMI_Trend_38 | BW17: CMI_Trend_46 | BX17: CMI_Trend_25 | BY17: CMI_Trend_52 | BZ17: CMI_Trend_25 | CA17: CMI_Trend_60 | CB17: CMI_Trend_52 | CC17: CMI_Trend_20 | CD17: CMI_Trend_25 | CE17: CMI_Trend_20 | CF17: CMI_Trend_60
B18: Rigid PVC Foam | C18: =1-SUM(C19:C20) -> 0.4776 | D18: =1-SUM(D19:D20) -> 0.4519 | E18: =1-SUM(E19:E20) -> 0.4776 | F18: =1-SUM(F19:F20) -> 0.4968 | G18: =1-SUM(G19:G20) -> 0.4848 | H18: =1-SUM(H19:H20) -> 0.4648 | I18: =1-SUM(I19:I20) -> 0.4693 | J18: =1-SUM(J19:J20) -> 0.4823 | ... AB18: =1-SUM(AB19:AB20) -> 0.4821 | AD18: Rigid PVC Foam | AE18: 0.026523218 | AF18: 0.016651554 | AG18: 0.01731284 | AH18: 0.026182823 | AI18: 0.020600148 | AJ18: 0.016589319 | AK18: 0.029246481 | AL18: 0.015740202 | AM18: 0.024015497 | AN18: 0.039474628 | AO18: 0.069729396 | AP18: 0.021184474 | AQ18: 0.03486715 | AR18: 0.054486598 | AS18: 0.028836043 | AT18: 0.04898834 | AU18: 0.027827005 | AV18: 0.034774671 | AW18: 0.018608995 | AX18: 0.022475503 | AY18: 0.025993074 | AZ18: 0.037556794 | BA18: 0.031856196 | BB18: 0.035402749 | BC18: 0.04252901 | BD18: 0.025730608 | BF18: Rigid PVC Foam | BG18: CMI_Trend_25 | BH18: CMI_Trend_46 | BI18: CMI_Trend_46 | BJ18: CMI_Trend_52 | BK18: CMI_Trend_25 | BL18: CMI_Trend_20 | BM18: CMI_Trend_60 | BN18: CMI_Trend_20 | BO18: CMI_Trend_56 | BP18: CMI_Trend_46 | BQ18: CMI_Trend_20 | BR18: CMI_Trend_46 | BS18: CMI_Trend_60 | BT18: CMI_Trend_56 | BU18: CMI_Trend_60 | BV18: CMI_Trend_46 | BW18: CMI_Trend_60 | BX18: CMI_Trend_25 | BY18: CMI_Trend_46 | BZ18: CMI_Trend_25 | CA18: CMI_Trend_38 | CB18: CMI_Trend_52 | CC18: CMI_Trend_20 | CD18: CMI_Trend_38 | CE18: CMI_Trend_46 | CF18: CMI_Trend_38
B19: Semi-Rigid PVC Foam | C19: 0.2323 | D19: 0.2373 | E19: 0.2382 | F19: 0.2079 | G19: 0.2281 | H19: 0.2211 | I19: 0.2181 | J19: 0.2221 | K19: 0.2035 | L19: 0.2173 | M19: 0.2077 | N19: 0.2206 | O19: 0.2383 | P19: 0.2153 | Q19: 0.204 | R19: 0.2241 | S19: 0.2153 | T19: 0.2143 | U19: 0.2273 | V19: 0.2376 | W19: 0.2221 | X19: 0.2091 | Y19: 0.2377 | Z19: 0.2127 | AA19: 0.2105 | AB19: 0.2223 | AD19: Semi-Rigid PVC Foam | AE19: 0.02146192 | AF19: 0.013546616 | AG19: 0.013266664 | AH19: 0.021121525 | AI19: 0.01553885 | AJ19: 0.013305665 | AK19: 0.024185183 | AL19: 0.014005398 | AM19: 0.018954199 | AN19: 0.03441333 | AO19: 0.064668098 | AP19: 0.016123176 | AQ19: 0.029805852 | AR19: 0.0494253 | AS19: 0.023774745 | AT19: 0.043927042 | AU19: 0.022765707 | AV19: 0.029713373 | AW19: 0.014547697 | AX19: 0.017414205 | AY19: 0.020931776 | AZ19: 0.032495496 | BA19: 0.026794898 | BB19: 0.030341451 | BC19: 0.037467712 | BD19: 0.02066931 | BF19: Semi-Rigid PVC Foam | BG19: CMI_Trend_56 | BH19: CMI_Trend_56 | BI19: CMI_Trend_38 | BJ19: CMI_Trend_60 | BK19: CMI_Trend_20 | BL19: CMI_Trend_38 | BM19: CMI_Trend_60 | BN19: CMI_Trend_60 | BO19: CMI_Trend_60 | BP19: CMI_Trend_52 | BQ19: CMI_Trend_46 | BR19: CMI_Trend_46 | BS19: CMI_Trend_25 | BT19: CMI_Trend_38 | BU19: CMI_Trend_38 | BV19: CMI_Trend_46 | BW19: CMI_Trend_46 | BX19: CMI_Trend_20 | BY19: CMI_Trend_56 | BZ19: CMI_Trend_52 | CA19: CMI_Trend_20 | CB19: CMI_Trend_20 | CC19: CMI_Trend_56 | CD19: CMI_Trend_20 | CE19: CMI_Trend_60 | CF19: CMI_Trend_20
B20: Closed-Cell PVC Structural Foam | C20: 0.2901 | D20: 0.3108 | E20: 0.2842 | F20: 0.2953 | G20: 0.2871 | H20: 0.3141 | I20: 0.3126 | J20: 0.2956 | K20: 0.3111 | L20: 0.2895 | M20: 0.3085 | N20: 0.2969 | O20: 0.2841 | P20: 0.3034 | Q20: 0.2938 | R20: 0.2927 | S20: 0.3178 | T20: 0.3104 | U20: 0.3133 | V20: 0.2887 | W20: 0.314 | X20: 0.2854 | Y20: 0.2981 | Z20: 0.3181 | AA20: 0.3165 | AB20: 0.2956 | AD20: Closed-Cell PVC Structural Foam | AE20: 0.032432382 | AF20: 0.020251972 | AG20: 0.023222004 | AH20: 0.032091987 | AI20: 0.026509312 | AJ20: 0.019778564 | AK20: 0.035155645 | AL20: 0.020649366 | AM20: 0.029924661 | AN20: 0.045383792 | AO20: 0.07563856 | AP20: 0.027093638 | AQ20: 0.040776314 | AR20: 0.060395762 | AS20: 0.034745207 | AT20: 0.054897504 | AU20: 0.033736169 | AV20: 0.040683835 | AW20: 0.021518159 | AX20: 0.028384667 | AY20: 0.031902238 | AZ20: 0.043465958 | BA20: 0.03776536 | BB20: 0.041311913 | BC20: 0.048438174 | BD20: 0.031639772 | BF20: Closed-Cell PVC Structural Foam | BG20: CMI_Trend_52 | BH20: CMI_Trend_20 | BI20: CMI_Trend_46 | BJ20: CMI_Trend_46 | BK20: CMI_Trend_20 | BL20: CMI_Trend_25 | BM20: CMI_Trend_60 | BN20: CMI_Trend_20 | BO20: CMI_Trend_46 | BP20: CMI_Trend_46 | BQ20: CMI_Trend_56 | BR20: CMI_Trend_46 | BS20: CMI_Trend_46 | BT20: CMI_Trend_20 | BU20: CMI_Trend_38 | BV20: CMI_Trend_52 | BW20: CMI_Trend_25 | BX20: CMI_Trend_60 | BY20: CMI_Trend_25 | BZ20: CMI_Trend_52 | CA20: CMI_Trend_56 | CB20: CMI_Trend_20 | CC20: CMI_Trend_38 | CD20: CMI_Trend_52 | CE20: CMI_Trend_56 | CF20: CMI_Trend_46
B21: High-Performance Engineering Polymer Foams | C21: 0.0593 | D21: 0.0531 | E21: 0.0413 | F21: 0.0413 | G21: 0.0464 | H21: 0.041 | I21: 0.0594 | J21: 0.045 | K21: 0.0425 | L21: 0.0498 | M21: 0.044 | N21: 0.06 | O21: 0.0499 | P21: 0.0558 | Q21: 0.0579 | R21: 0.0407 | S21: 0.0559 | T21: 0.0499 | U21: 0.0426 | V21: 0.0514 | W21: 0.0593 | X21: 0.0575 | Y21: 0.0522 | Z21: 0.0576 | AA21: 0.0424 | AB21: 0.0544 | AD21: High-Performance Engineering Polymer Foams | AE21: =SUMPRODUCT(AE22:AE24,C22:C24) -> 0.049209182 | AF21: =SUMPRODUCT(AF22:AF24,D22:D24) -> 0.037217272 | AG21: =SUMPRODUCT(AG22:AG24,E22:E24) -> 0.039715304 | AH21: =SUMPRODUCT(AH22:AH24,F22:F24) -> 0.048685987 | AI21: =SUMPRODUCT(AI22:AI24,G22:G24) -> 0.043124612 | AJ21: =SUMPRODUCT(AJ22:AJ24,H22:H24) -> 0.036365764 | AK21: =SUMPRODUCT(AK22:AK24,I22:I24) -> 0.051501745 | AL21: =SUMPRODUCT(AL22:AL24,J22:J24) -> 0.033561666 | ... BD21: =SUMPRODUCT(BD22:BD24,AB22:AB24) -> 0.048616172 | BF21: High-Performance Engineering Polymer Foams | BG21: CMI_Trend_60 | BH21: CMI_Trend_46 | BI21: CMI_Trend_60 | BJ21: CMI_Trend_20 | BK21: CMI_Trend_60 | BL21: CMI_Trend_60 | BM21: CMI_Trend_38 | BN21: CMI_Trend_25 | BO21: CMI_Trend_60 | BP21: CMI_Trend_20 | BQ21: CMI_Trend_56 | BR21: CMI_Trend_60 | BS21: CMI_Trend_52 | BT21: CMI_Trend_56 | BU21: CMI_Trend_52 | BV21: CMI_Trend_56 | BW21: CMI_Trend_52 | BX21: CMI_Trend_25 | BY21: CMI_Trend_52 | BZ21: CMI_Trend_38 | CA21: CMI_Trend_25 | CB21: CMI_Trend_25 | CC21: CMI_Trend_60 | CD21: CMI_Trend_46 | CE21: CMI_Trend_20 | CF21: CMI_Trend_25
B22: Polyimide (PI) Foams | C22: 0.3174 | D22: 0.3047 | E22: 0.2997 | F22: 0.2864 | G22: 0.3041 | H22: 0.318 | I22: 0.3126 | J22: 0.2993 | K22: 0.2878 | L22: 0.3083 | M22: 0.2894 | N22: 0.2844 | O22: 0.2926 | P22: 0.2913 | Q22: 0.2933 | R22: 0.2911 | S22: 0.2989 | T22: 0.3076 | U22: 0.2915 | V22: 0.3056 | W22: 0.3062 | X22: 0.287 | Y22: 0.2875 | Z22: 0.3064 | AA22: 0.3066 | AB22: 0.3033 | AD22: Polyimide (PI) Foams | AE22: 0.047432382 | AF22: 0.035251972 | AG22: 0.038222004 | AH22: 0.047091987 | AI22: 0.041509312 | AJ22: 0.034778564 | AK22: 0.050155645 | AL22: 0.031649366 | AM22: 0.044924661 | AN22: 0.060383792 | AO22: 0.09063856 | AP22: 0.042093638 | AQ22: 0.055776314 | AR22: 0.075395762 | AS22: 0.049745207 | AT22: 0.069897504 | AU22: 0.048736169 | AV22: 0.055683835 | AW22: 0.036518159 | AX22: 0.043384667 | AY22: 0.046902238 | AZ22: 0.058465958 | BA22: 0.05276536 | BB22: 0.056311913 | BC22: 0.063438174 | BD22: 0.046639772 | BF22: Polyimide (PI) Foams | BG22: CMI_Trend_25 | BH22: CMI_Trend_25 | BI22: CMI_Trend_46 | BJ22: CMI_Trend_60 | BK22: CMI_Trend_20 | BL22: CMI_Trend_60 | BM22: CMI_Trend_46 | BN22: CMI_Trend_56 | BO22: CMI_Trend_46 | BP22: CMI_Trend_25 | BQ22: CMI_Trend_20 | BR22: CMI_Trend_60 | BS22: CMI_Trend_20 | BT22: CMI_Trend_52 | BU22: CMI_Trend_46 | BV22: CMI_Trend_52 | BW22: CMI_Trend_25 | BX22: CMI_Trend_20 | BY22: CMI_Trend_20 | BZ22: CMI_Trend_56 | CA22: CMI_Trend_25 | CB22: CMI_Trend_60 | CC22: CMI_Trend_52 | CD22: CMI_Trend_52 | CE22: CMI_Trend_38 | CF22: CMI_Trend_25
B23: Phenolic Foams | C23: 0.3376 | D23: 0.3357 | E23: 0.3637 | F23: 0.3668 | G23: 0.3545 | H23: 0.3472 | I23: 0.3633 | J23: 0.3419 | K23: 0.333 | L23: 0.3639 | M23: 0.3334 | N23: 0.3553 | O23: 0.3568 | P23: 0.3377 | Q23: 0.3661 | R23: 0.3361 | S23: 0.3626 | T23: 0.3446 | U23: 0.3332 | V23: 0.3511 | W23: 0.3445 | X23: 0.3419 | Y23: 0.3562 | Z23: 0.3651 | AA23: 0.3455 | AB23: 0.336 | AD23: Phenolic Foams | AE23: 0.040432382 | AF23: 0.028251972 | AG23: 0.031222004 | AH23: 0.040091987 | AI23: 0.034509312 | AJ23: 0.027778564 | AK23: 0.043155645 | AL23: 0.024649366 | AM23: 0.037924661 | AN23: 0.053383792 | AO23: 0.08363856 | AP23: 0.035093638 | AQ23: 0.048776314 | AR23: 0.068395762 | AS23: 0.042745207 | AT23: 0.062897504 | AU23: 0.041736169 | AV23: 0.048683835 | AW23: 0.029518159 | AX23: 0.036384667 | AY23: 0.039902238 | AZ23: 0.051465958 | BA23: 0.04576536 | BB23: 0.049311913 | BC23: 0.056438174 | BD23: 0.039639772 | BF23: Phenolic Foams | BG23: CMI_Trend_38 | BH23: CMI_Trend_52 | BI23: CMI_Trend_46 | BJ23: CMI_Trend_20 | BK23: CMI_Trend_60 | BL23: CMI_Trend_56 | BM23: CMI_Trend_56 | BN23: CMI_Trend_60 | BO23: CMI_Trend_20 | BP23: CMI_Trend_25 | BQ23: CMI_Trend_56 | BR23: CMI_Trend_52 | BS23: CMI_Trend_60 | BT23: CMI_Trend_25 | BU23: CMI_Trend_46 | BV23: CMI_Trend_56 | BW23: CMI_Trend_20 | BX23: CMI_Trend_25 | BY23: CMI_Trend_52 | BZ23: CMI_Trend_56 | CA23: CMI_Trend_60 | CB23: CMI_Trend_52 | CC23: CMI_Trend_38 | CD23: CMI_Trend_46 | CE23: CMI_Trend_52 | CF23: CMI_Trend_52
B24: Advanced Thermoplastic Foams | C24: =1-SUM(C22:C23) -> 0.345 | D24: =1-SUM(D22:D23) -> 0.3596 | E24: =1-SUM(E22:E23) -> 0.3366 | F24: =1-SUM(F22:F23) -> 0.3468 | G24: =1-SUM(G22:G23) -> 0.3414 | H24: =1-SUM(H22:H23) -> 0.3348 | I24: =1-SUM(I22:I23) -> 0.3241 | J24: =1-SUM(J22:J23) -> 0.3588 | ... AB24: =1-SUM(AB22:AB23) -> 0.3607 | AD24: Advanced Thermoplastic Foams | AE24: 0.059432382 | AF24: 0.047251972 | AG24: 0.050222004 | AH24: 0.059091987 | AI24: 0.053509312 | AJ24: 0.046778564 | AK24: 0.062155645 | AL24: 0.043649366 | AM24: 0.056924661 | AN24: 0.072383792 | AO24: 0.10263856 | AP24: 0.054093638 | AQ24: 0.067776314 | AR24: 0.087395762 | AS24: 0.061745207 | AT24: 0.081897504 | AU24: 0.060736169 | AV24: 0.067683835 | AW24: 0.048518159 | AX24: 0.055384667 | AY24: 0.058902238 | AZ24: 0.070465958 | BA24: 0.06476536 | BB24: 0.068311913 | BC24: 0.075438174 | BD24: 0.058639772 | BF24: Advanced Thermoplastic Foams | BG24: CMI_Trend_46 | BH24: CMI_Trend_52 | BI24: CMI_Trend_20 | BJ24: CMI_Trend_52 | BK24: CMI_Trend_20 | BL24: CMI_Trend_52 | BM24: CMI_Trend_20 | BN24: CMI_Trend_20 | BO24: CMI_Trend_25 | BP24: CMI_Trend_46 | BQ24: CMI_Trend_38 | BR24: CMI_Trend_25 | BS24: CMI_Trend_20 | BT24: CMI_Trend_56 | BU24: CMI_Trend_38 | BV24: CMI_Trend_56 | BW24: CMI_Trend_56 | BX24: CMI_Trend_20 | BY24: CMI_Trend_38 | BZ24: CMI_Trend_56 | CA24: CMI_Trend_46 | CB24: CMI_Trend_60 | CC24: CMI_Trend_25 | CD24: CMI_Trend_52 | CE24: CMI_Trend_52 | CF24: CMI_Trend_25
B25: Melamine Foams | C25: 0.022 | D25: 0.0193 | E25: 0.0212 | F25: 0.0204 | G25: 0.0168 | H25: 0.0228 | I25: 0.0187 | J25: 0.0191 | K25: 0.0219 | L25: 0.0151 | M25: 0.0216 | N25: 0.0198 | O25: 0.0165 | P25: 0.0223 | Q25: 0.0127 | R25: 0.0219 | S25: 0.0198 | T25: 0.0172 | U25: 0.0184 | V25: 0.0213 | W25: 0.0124 | X25: 0.0202 | Y25: 0.0189 | Z25: 0.0161 | AA25: 0.0216 | AB25: 0.0161 | AD25: Melamine Foams | AE25: 0.035178354 | AF25: 0.022997944 | AG25: 0.025967976 | AH25: 0.03483796 | AI25: 0.029255285 | AJ25: 0.022524536 | AK25: 0.037901617 | AL25: 0.019395338 | AM25: 0.032670633 | AN25: 0.048129764 | AO25: 0.078384532 | AP25: 0.029839611 | AQ25: 0.043522286 | AR25: 0.063141735 | AS25: 0.037491179 | AT25: 0.057643477 | AU25: 0.036482141 | AV25: 0.043429807 | AW25: 0.024264131 | AX25: 0.03113064 | AY25: 0.034648211 | AZ25: 0.046211931 | BA25: 0.040511332 | BB25: 0.044057886 | BC25: 0.051184147 | BD25: 0.034385744 | BF25: Melamine Foams | BG25: CMI_Trend_52 | BH25: CMI_Trend_20 | BI25: CMI_Trend_46 | BJ25: CMI_Trend_25 | BK25: CMI_Trend_56 | BL25: CMI_Trend_52 | BM25: CMI_Trend_46 | BN25: CMI_Trend_52 | BO25: CMI_Trend_56 | BP25: CMI_Trend_56 | BQ25: CMI_Trend_60 | BR25: CMI_Trend_25 | BS25: CMI_Trend_52 | BT25: CMI_Trend_52 | BU25: CMI_Trend_56 | BV25: CMI_Trend_56 | BW25: CMI_Trend_25 | BX25: CMI_Trend_56 | BY25: CMI_Trend_56 | BZ25: CMI_Trend_56 | CA25: CMI_Trend_60 | CB25: CMI_Trend_56 | CC25: CMI_Trend_38 | CD25: CMI_Trend_20 | CE25: CMI_Trend_25 | CF25: CMI_Trend_52
B26: Elastomeric & Specialty Foams | C26: 0.0688 | D26: 0.0582 | E26: 0.0515 | F26: 0.0614 | G26: 0.0512 | H26: 0.0591 | I26: 0.0684 | J26: 0.0681 | K26: 0.0517 | L26: 0.0565 | M26: 0.064 | N26: 0.0653 | O26: 0.0676 | P26: 0.059 | Q26: 0.051 | R26: 0.0547 | S26: 0.0685 | T26: 0.0633 | U26: 0.0533 | V26: 0.0698 | W26: 0.0598 | X26: 0.0576 | Y26: 0.063 | Z26: 0.0563 | AA26: 0.0514 | AB26: 0.0674 | AD26: Elastomeric & Specialty Foams | AE26: 0.057102382 | AF26: 0.044921972 | AG26: 0.047892004 | AH26: 0.056761987 | AI26: 0.051179312 | AJ26: 0.044448564 | AK26: 0.059825645 | AL26: 0.041319366 | AM26: 0.054594661 | AN26: 0.070053792 | AO26: 0.10030856 | AP26: 0.051763638 | AQ26: 0.065446314 | AR26: 0.085065762 | AS26: 0.059415207 | AT26: 0.079567504 | AU26: 0.058406169 | AV26: 0.065353835 | AW26: 0.046188159 | AX26: 0.053054667 | AY26: 0.056572238 | AZ26: 0.068135958 | BA26: 0.06243536 | BB26: 0.065981913 | BC26: 0.073108174 | BD26: 0.056309772 | BF26: Elastomeric & Specialty Foams | BG26: CMI_Trend_46 | BH26: CMI_Trend_56 | BI26: CMI_Trend_60 | BJ26: CMI_Trend_56 | BK26: CMI_Trend_20 | BL26: CMI_Trend_38 | BM26: CMI_Trend_46 | BN26: CMI_Trend_20 | BO26: CMI_Trend_60 | BP26: CMI_Trend_52 | BQ26: CMI_Trend_56 | BR26: CMI_Trend_60 | BS26: CMI_Trend_60 | BT26: CMI_Trend_56 | BU26: CMI_Trend_38 | BV26: CMI_Trend_46 | BW26: CMI_Trend_52 | BX26: CMI_Trend_25 | BY26: CMI_Trend_46 | BZ26: CMI_Trend_46 | CA26: CMI_Trend_46 | CB26: CMI_Trend_20 | CC26: CMI_Trend_46 | CD26: CMI_Trend_46 | CE26: CMI_Trend_20 | CF26: CMI_Trend_25
B27: Bio-Based & Sustainable Foams | C27: 0.0538 | D27: 0.0439 | E27: 0.0395 | F27: 0.0531 | G27: 0.0399 | H27: 0.0547 | I27: 0.0545 | J27: 0.0512 | K27: 0.0491 | L27: 0.0535 | M27: 0.0489 | N27: 0.0538 | O27: 0.0396 | P27: 0.0375 | Q27: 0.0388 | R27: 0.0402 | S27: 0.0486 | T27: 0.0535 | U27: 0.0488 | V27: 0.0523 | W27: 0.0546 | X27: 0.048 | Y27: 0.04 | Z27: 0.05 | AA27: 0.0532 | AB27: 0.0528 | AD27: Bio-Based & Sustainable Foams | AE27: 0.069432382 | AF27: 0.057251972 | AG27: 0.060222004 | AH27: 0.069091987 | AI27: 0.063509312 | AJ27: 0.056778564 | AK27: 0.072155645 | AL27: 0.053649366 | AM27: 0.066924661 | AN27: 0.082383792 | AO27: 0.11263856 | AP27: 0.064093638 | AQ27: 0.077776314 | AR27: 0.097395762 | AS27: 0.071745207 | AT27: 0.091897504 | AU27: 0.070736169 | AV27: 0.077683835 | AW27: 0.058518159 | AX27: 0.065384667 | AY27: 0.068902238 | AZ27: 0.080465958 | BA27: 0.07476536 | BB27: 0.078311913 | BC27: 0.085438174 | BD27: 0.068639772 | BF27: Bio-Based & Sustainable Foams | BG27: CMI_Trend_38 | BH27: CMI_Trend_20 | BI27: CMI_Trend_46 | BJ27: CMI_Trend_60 | BK27: CMI_Trend_38 | BL27: CMI_Trend_60 | BM27: CMI_Trend_38 | BN27: CMI_Trend_38 | BO27: CMI_Trend_46 | BP27: CMI_Trend_38 | BQ27: CMI_Trend_46 | BR27: CMI_Trend_20 | BS27: CMI_Trend_38 | BT27: CMI_Trend_20 | BU27: CMI_Trend_60 | BV27: CMI_Trend_46 | BW27: CMI_Trend_56 | BX27: CMI_Trend_56 | BY27: CMI_Trend_46 | BZ27: CMI_Trend_46 | CA27: CMI_Trend_56 | CB27: CMI_Trend_20 | CC27: CMI_Trend_46 | CD27: CMI_Trend_25 | CE27: CMI_Trend_60 | CF27: CMI_Trend_56
B29: By Density | AD29: By Density | BF29: By Density
B30: Ultra-Low Density: < 15 | C30: =1-SUM(C31:C34) -> 0.1497 | D30: =1-SUM(D31:D34) -> 0.1656 | E30: =1-SUM(E31:E34) -> 0.1427 | F30: =1-SUM(F31:F34) -> 0.0985 | G30: =1-SUM(G31:G34) -> 0.1106 | H30: =1-SUM(H31:H34) -> 0.1578 | I30: =1-SUM(I31:I34) -> 0.143 | J30: =1-SUM(J31:J34) -> 0.142 | ... AB30: =1-SUM(AB31:AB34) -> 0.136 | AD30: Ultra-Low Density: < 15 | AE30: 0.032138565 | AF30: 0.019919679 | AG30: 0.022885417 | AH30: 0.031316901 | AI30: 0.025470446 | AJ30: 0.019555766 | AK30: 0.035320548 | AL30: 0.016707287 | AM30: 0.029441938 | AN30: 0.044723291 | AO30: 0.075868025 | AP30: 0.026795144 | AQ30: 0.039797344 | AR30: 0.060313003 | AS30: 0.034366083 | AT30: 0.053570044 | AU30: 0.033492595 | AV30: 0.040638695 | AW30: 0.02084272 | AX30: 0.028441756 | AY30: 0.031068855 | AZ30: 0.043372055 | BA30: 0.036652955 | BB30: 0.041417947 | BC30: 0.048426609 | BD30: 0.032028909 | BF30: Ultra-Low Density: < 15 | BG30: CMI_Trend_60 | BH30: CMI_Trend_52 | BI30: CMI_Trend_56 | BJ30: CMI_Trend_20 | BK30: CMI_Trend_46 | BL30: CMI_Trend_52 | BM30: CMI_Trend_56 | BN30: CMI_Trend_38 | BO30: CMI_Trend_46 | BP30: CMI_Trend_60 | BQ30: CMI_Trend_52 | BR30: CMI_Trend_20 | BS30: CMI_Trend_46 | BT30: CMI_Trend_56 | BU30: CMI_Trend_56 | BV30: CMI_Trend_20 | BW30: CMI_Trend_60 | BX30: CMI_Trend_20 | BY30: CMI_Trend_52 | BZ30: CMI_Trend_20 | CA30: CMI_Trend_38 | CB30: CMI_Trend_20 | CC30: CMI_Trend_60 | CD30: CMI_Trend_46 | CE30: CMI_Trend_25 | CF30: CMI_Trend_60
B31: Low Density: 15 – 30 | C31: 0.2668 | D31: 0.2769 | E31: 0.2936 | F31: 0.2968 | G31: 0.2916 | H31: 0.2668 | I31: 0.278 | J31: 0.2807 | K31: 0.2777 | L31: 0.2914 | M31: 0.2963 | N31: 0.2643 | O31: 0.2711 | P31: 0.2742 | Q31: 0.2646 | R31: 0.263 | S31: 0.2741 | T31: 0.2834 | U31: 0.2641 | V31: 0.2745 | W31: 0.2842 | X31: 0.282 | Y31: 0.2963 | Z31: 0.28 | AA31: 0.2878 | AB31: 0.2919 | AD31: Low Density: 15 – 30 | AE31: 0.035138565 | AF31: 0.022919679 | AG31: 0.025885417 | AH31: 0.034316901 | AI31: 0.028470446 | AJ31: 0.022555766 | AK31: 0.038320548 | AL31: 0.019707287 | AM31: 0.032441938 | AN31: 0.047723291 | AO31: 0.078868025 | AP31: 0.029795144 | AQ31: 0.042797344 | AR31: 0.063313003 | AS31: 0.037366083 | AT31: 0.056570044 | AU31: 0.036492595 | AV31: 0.043638695 | AW31: 0.02384272 | AX31: 0.031441756 | AY31: 0.034068855 | AZ31: 0.046372055 | BA31: 0.039652955 | BB31: 0.044417947 | BC31: 0.051426609 | BD31: 0.035028909 | BF31: Low Density: 15 – 30 | BG31: CMI_Trend_60 | BH31: CMI_Trend_56 | BI31: CMI_Trend_46 | BJ31: CMI_Trend_38 | BK31: CMI_Trend_20 | BL31: CMI_Trend_25 | BM31: CMI_Trend_25 | BN31: CMI_Trend_52 | BO31: CMI_Trend_56 | BP31: CMI_Trend_38 | BQ31: CMI_Trend_56 | BR31: CMI_Trend_25 | BS31: CMI_Trend_56 | BT31: CMI_Trend_46 | BU31: CMI_Trend_25 | BV31: CMI_Trend_25 | BW31: CMI_Trend_46 | BX31: CMI_Trend_46 | BY31: CMI_Trend_52 | BZ31: CMI_Trend_56 | CA31: CMI_Trend_46 | CB31: CMI_Trend_38 | CC31: CMI_Trend_60 | CD31: CMI_Trend_56 | CE31: CMI_Trend_38 | CF31: CMI_Trend_56
