Workbook

Sheet Data
B1: Market Name | C1: Process Analyzer Market | X1: 0.001 | AQ1: 0.001
C2: Market Share | AI2: =VLOOKUP(AI3,$B$106:$D$139,3,0) -> 0.053419198 | AJ2: =VLOOKUP(AJ3,$B$106:$D$139,3,0) -> 0.058513951 | AK2: =VLOOKUP(AK3,$B$106:$D$139,3,0) -> 0.040033006 | AL2: =VLOOKUP(AL3,$B$106:$D$139,3,0) -> 0.036132997 | AM2: =VLOOKUP(AM3,$B$106:$D$139,3,0) -> 0.048503574 | AN2: =VLOOKUP(AN3,$B$106:$D$139,3,0) -> 0.052106905 | AO2: =VLOOKUP(AO3,$B$106:$D$139,3,0) -> 0.031424638 | AP2: =VLOOKUP(AP3,$B$106:$D$139,3,0) -> 0.05650788 | ... BL2: =VLOOKUP(BL3,$B$106:$D$139,3,0) -> 0.064835425
A3: Segment Name in B Column Only | B3: Segment | C3: U.S. | D3: Canada | E3: Germany | F3: France | G3: Italy | H3: UK | I3: Russia | J3: Spain | K3: Poland | L3: Romania | M3: Croatia | N3: Sweden | O3: Denmark | P3: Finland | Q3: Norway | R3: Rest of Europe | S3: China | T3: India | U3: Japan | V3: South Korea | W3: Australia | X3: ASEAN | Y3: Rest of Asia Pacific | Z3: GCC | AA3: South Africa | AB3: Rest of Middle East & Africa | AC3: Brazil | AD3: Argentina | AE3: Mexico | AF3: Rest of Latin America | AI3: =C3 -> U.S. | AJ3: =D3 -> Canada | AK3: =E3 -> Germany | AL3: =F3 -> France | AM3: =G3 -> Italy | AN3: =H3 -> UK | AO3: =I3 -> Russia | AP3: =J3 -> Spain | ... BL3: =AF3 -> Rest of Latin America | BO3: =AI3 -> U.S. | BP3: =AJ3 -> Canada | BQ3: =AK3 -> Germany | BR3: =AL3 -> France | BS3: =AM3 -> Italy | BT3: =AN3 -> UK | BU3: =AO3 -> Russia | BV3: =AP3 -> Spain | ... CR3: =BL3 -> Rest of Latin America
B4: By Analyzer Type | AH4: By Analyzer Type | BN4: By Analyzer Type
B5: Gas Analyzers | C5: 0.5752 | D5: 0.5994 | E5: 0.5893 | F5: 0.5756 | G5: 0.5925 | H5: 0.5899 | I5: 0.5788 | J5: 0.5987 | K5: 0.5788 | L5: 0.5928 | M5: 0.5797 | N5: 0.5935 | O5: 0.5819 | P5: 0.5904 | Q5: 0.5995 | R5: 0.5918 | S5: 0.5816 | T5: 0.5697 | U5: 0.5917 | V5: 0.5713 | W5: 0.5941 | X5: 0.572 | Y5: 0.5924 | Z5: 0.5849 | AA5: 0.583 | AB5: 0.5971 | AC5: 0.5911 | AD5: 0.5747 | AE5: 0.5733 | AF5: 0.5793 | AH5: Gas Analyzers | AI5: =SUMPRODUCT(AI6:AI12,C6:C12) -> 0.058850573 | AJ5: =SUMPRODUCT(AJ6:AJ12,D6:D12) -> 0.063609462 | AK5: =SUMPRODUCT(AK6:AK12,E6:E12) -> 0.04569306 | AL5: =SUMPRODUCT(AL6:AL12,F6:F12) -> 0.041683796 | AM5: =SUMPRODUCT(AM6:AM12,G6:G12) -> 0.053731607 | AN5: =SUMPRODUCT(AN6:AN12,H6:H12) -> 0.057763821 | AO5: =SUMPRODUCT(AO6:AO12,I6:I12) -> 0.037080935 | AP5: =SUMPRODUCT(AP6:AP12,J6:J12) -> 0.061955378 | ... BL5: =SUMPRODUCT(BL6:BL12,AF6:AF12) -> 0.070209795 | BN5: Gas Analyzers | BO5: CMI_Trend_46 | BP5: CMI_Trend_46 | BQ5: CMI_Trend_46 | BR5: CMI_Trend_56 | BS5: CMI_Trend_20 | BT5: CMI_Trend_52 | BU5: CMI_Trend_20 | BV5: CMI_Trend_60 | BW5: CMI_Trend_56 | BX5: CMI_Trend_52 | BY5: CMI_Trend_20 | BZ5: CMI_Trend_60 | CA5: CMI_Trend_20 | CB5: CMI_Trend_52 | CC5: CMI_Trend_25 | CD5: CMI_Trend_52 | CE5: CMI_Trend_52 | CF5: CMI_Trend_56 | CG5: CMI_Trend_38 | CH5: CMI_Trend_20 | CI5: CMI_Trend_52 | CJ5: CMI_Trend_52 | CK5: CMI_Trend_56 | CL5: CMI_Trend_38 | CM5: CMI_Trend_60 | CN5: CMI_Trend_46 | CO5: CMI_Trend_56 | CP5: CMI_Trend_20 | CQ5: CMI_Trend_56 | CR5: CMI_Trend_20
B6: Natural Gas | C6: 0.2105 | D6: 0.1944 | E6: 0.2109 | F6: 0.2078 | G6: 0.1997 | H6: 0.1932 | I6: 0.2002 | J6: 0.196 | K6: 0.197 | L6: 0.193 | M6: 0.207 | N6: 0.2133 | O6: 0.2133 | P6: 0.2057 | Q6: 0.1895 | R6: 0.206 | S6: 0.2116 | T6: 0.2174 | U6: 0.1974 | V6: 0.1982 | W6: 0.2205 | X6: 0.1896 | Y6: 0.2128 | Z6: 0.2016 | AA6: 0.2025 | AB6: 0.2012 | AC6: 0.1954 | AD6: 0.2124 | AE6: 0.2094 | AF6: 0.2102 | AH6: Natural Gas | AI6: 0.050068103 | AJ6: 0.054893015 | AK6: 0.035914833 | AL6: 0.03260788 | AM6: 0.044905329 | AN6: 0.047973083 | AO6: 0.027655182 | AP6: 0.052384002 | AQ6: 0.077061737 | AR6: 0.080515655 | AS6: 0.072107497 | AT6: 0.060898357 | AU6: 0.068345423 | AV6: 0.055828049 | AW6: 0.063433183 | AX6: 0.040263071 | AY6: 0.068740716 | AZ6: 0.083653216 | BA6: 0.047309509 | BB6: 0.056891998 | BC6: 0.052645493 | BD6: 0.076769617 | BE6: 0.061549712 | BF6: 0.059733578 | BG6: 0.046020639 | BH6: 0.05227329 | BI6: 0.045415591 | BJ6: 0.050446844 | BK6: 0.056173725 | BL6: 0.061438219 | BN6: Natural Gas | BO6: CMI_Trend_20 | BP6: CMI_Trend_46 | BQ6: CMI_Trend_20 | BR6: CMI_Trend_60 | BS6: CMI_Trend_46 | BT6: CMI_Trend_20 | BU6: CMI_Trend_56 | BV6: CMI_Trend_46 | BW6: CMI_Trend_20 | BX6: CMI_Trend_38 | BY6: CMI_Trend_52 | BZ6: CMI_Trend_25 | CA6: CMI_Trend_20 | CB6: CMI_Trend_52 | CC6: CMI_Trend_38 | CD6: CMI_Trend_46 | CE6: CMI_Trend_52 | CF6: CMI_Trend_20 | CG6: CMI_Trend_46 | CH6: CMI_Trend_60 | CI6: CMI_Trend_25 | CJ6: CMI_Trend_56 | CK6: CMI_Trend_52 | CL6: CMI_Trend_60 | CM6: CMI_Trend_25 | CN6: CMI_Trend_38 | CO6: CMI_Trend_60 | CP6: CMI_Trend_60 | CQ6: CMI_Trend_25 | CR6: CMI_Trend_60
B7: Biogas | C7: 0.0556 | D7: 0.0589 | E7: 0.0763 | F7: 0.0708 | G7: 0.0749 | H7: 0.0757 | I7: 0.0718 | J7: 0.0698 | K7: 0.0584 | L7: 0.0768 | M7: 0.0779 | N7: 0.0569 | O7: 0.0621 | P7: 0.0626 | Q7: 0.0771 | R7: 0.0629 | S7: 0.0585 | T7: 0.0714 | U7: 0.0708 | V7: 0.0683 | W7: 0.0616 | X7: 0.0597 | Y7: 0.0616 | Z7: 0.0767 | AA7: 0.0618 | AB7: 0.0665 | AC7: 0.0577 | AD7: 0.0556 | AE7: 0.0569 | AF7: 0.0606 | AH7: Biogas | AI7: 0.071970897 | AJ7: 0.07679581 | AK7: 0.057817627 | AL7: 0.054510674 | AM7: 0.066808124 | AN7: 0.069875877 | AO7: 0.049557976 | AP7: 0.074286796 | AQ7: 0.098964532 | AR7: 0.10241845 | AS7: 0.094010291 | AT7: 0.082801152 | AU7: 0.090248218 | AV7: 0.077730843 | AW7: 0.085335978 | AX7: 0.062165865 | AY7: 0.090643511 | AZ7: 0.10555601 | BA7: 0.069212303 | BB7: 0.078794792 | BC7: 0.074548287 | BD7: 0.098672411 | BE7: 0.083452506 | BF7: 0.081636372 | BG7: 0.067923434 | BH7: 0.074176084 | BI7: 0.067318386 | BJ7: 0.072349639 | BK7: 0.078076519 | BL7: 0.083341013 | BN7: Biogas | BO7: CMI_Trend_56 | BP7: CMI_Trend_25 | BQ7: CMI_Trend_25 | BR7: CMI_Trend_60 | BS7: CMI_Trend_20 | BT7: CMI_Trend_25 | BU7: CMI_Trend_60 | BV7: CMI_Trend_56 | BW7: CMI_Trend_25 | BX7: CMI_Trend_46 | BY7: CMI_Trend_38 | BZ7: CMI_Trend_60 | CA7: CMI_Trend_20 | CB7: CMI_Trend_52 | CC7: CMI_Trend_56 | CD7: CMI_Trend_20 | CE7: CMI_Trend_25 | CF7: CMI_Trend_56 | CG7: CMI_Trend_38 | CH7: CMI_Trend_38 | CI7: CMI_Trend_25 | CJ7: CMI_Trend_56 | CK7: CMI_Trend_46 | CL7: CMI_Trend_56 | CM7: CMI_Trend_52 | CN7: CMI_Trend_20 | CO7: CMI_Trend_38 | CP7: CMI_Trend_25 | CQ7: CMI_Trend_38 | CR7: CMI_Trend_52
B8: Biomethane | C8: 0.0543 | D8: 0.0489 | E8: 0.0579 | F8: 0.0405 | G8: 0.0455 | H8: 0.0509 | I8: 0.0419 | J8: 0.0443 | K8: 0.0501 | L8: 0.0571 | M8: 0.0552 | N8: 0.0594 | O8: 0.0502 | P8: 0.0592 | Q8: 0.0563 | R8: 0.0573 | S8: 0.0414 | T8: 0.0516 | U8: 0.0589 | V8: 0.046 | W8: 0.0413 | X8: 0.0584 | Y8: 0.048 | Z8: 0.0393 | AA8: 0.0583 | AB8: 0.0542 | AC8: 0.0575 | AD8: 0.0457 | AE8: 0.0537 | AF8: 0.0493 | AH8: Biomethane | AI8: 0.080821139 | AJ8: 0.085646051 | AK8: 0.066667869 | AL8: 0.063360916 | AM8: 0.075658365 | AN8: 0.078726119 | AO8: 0.058408218 | AP8: 0.083137038 | AQ8: 0.10781477 | AR8: 0.11126869 | AS8: 0.10286053 | AT8: 0.091651393 | AU8: 0.099098459 | AV8: 0.086581085 | AW8: 0.094186219 | AX8: 0.071016107 | AY8: 0.099493752 | AZ8: 0.11440625 | BA8: 0.078062545 | BB8: 0.087645034 | BC8: 0.083398529 | BD8: 0.10752265 | BE8: 0.092302748 | BF8: 0.090486614 | BG8: 0.076773675 | BH8: 0.083026326 | BI8: 0.076168627 | BJ8: 0.08119988 | BK8: 0.086926761 | BL8: 0.092191255 | BN8: Biomethane | BO8: CMI_Trend_60 | BP8: CMI_Trend_56 | BQ8: CMI_Trend_46 | BR8: CMI_Trend_60 | BS8: CMI_Trend_52 | BT8: CMI_Trend_46 | BU8: CMI_Trend_60 | BV8: CMI_Trend_38 | BW8: CMI_Trend_60 | BX8: CMI_Trend_46 | BY8: CMI_Trend_52 | BZ8: CMI_Trend_25 | CA8: CMI_Trend_38 | CB8: CMI_Trend_38 | CC8: CMI_Trend_38 | CD8: CMI_Trend_38 | CE8: CMI_Trend_20 | CF8: CMI_Trend_52 | CG8: CMI_Trend_52 | CH8: CMI_Trend_56 | CI8: CMI_Trend_52 | CJ8: CMI_Trend_60 | CK8: CMI_Trend_38 | CL8: CMI_Trend_38 | CM8: CMI_Trend_60 | CN8: CMI_Trend_46 | CO8: CMI_Trend_60 | CP8: CMI_Trend_60 | CQ8: CMI_Trend_56 | CR8: CMI_Trend_46
B9: Industrial Gases (O₂, N₂, CO₂) | C9: 0.2521 | D9: 0.2481 | E9: 0.2314 | F9: 0.2313 | G9: 0.2525 | H9: 0.2289 | I9: 0.2315 | J9: 0.2305 | K9: 0.2516 | L9: 0.2288 | M9: 0.2286 | N9: 0.2378 | O9: 0.2432 | P9: 0.2313 | Q9: 0.2298 | R9: 0.236 | S9: 0.2384 | T9: 0.2306 | U9: 0.2316 | V9: 0.2454 | W9: 0.2332 | X9: 0.25 | Y9: 0.2378 | Z9: 0.2461 | AA9: 0.2428 | AB9: 0.231 | AC9: 0.2433 | AD9: 0.2515 | AE9: 0.2463 | AF9: 0.2418 | AH9: Industrial Gases (O₂, N₂, CO₂) | AI9: 0.044925993 | AJ9: 0.049750905 | AK9: 0.030772722 | AL9: 0.02746577 | AM9: 0.039763219 | AN9: 0.042830973 | AO9: 0.022513072 | AP9: 0.047241891 | AQ9: 0.071919627 | AR9: 0.075373544 | AS9: 0.066965386 | AT9: 0.055756247 | AU9: 0.063203313 | AV9: 0.050685938 | AW9: 0.058291073 | AX9: 0.03512096 | AY9: 0.063598606 | AZ9: 0.078511105 | BA9: 0.042167398 | BB9: 0.051749888 | BC9: 0.047503382 | BD9: 0.071627506 | BE9: 0.056407601 | BF9: 0.054591468 | BG9: 0.040878529 | BH9: 0.047131179 | BI9: 0.040273481 | BJ9: 0.045304734 | BK9: 0.051031615 | BL9: 0.056296109 | BN9: Industrial Gases (O₂, N₂, CO₂) | BO9: CMI_Trend_46 | BP9: CMI_Trend_60 | BQ9: CMI_Trend_20 | BR9: CMI_Trend_38 | BS9: CMI_Trend_56 | BT9: CMI_Trend_38 | BU9: CMI_Trend_52 | BV9: CMI_Trend_60 | BW9: CMI_Trend_46 | BX9: CMI_Trend_60 | BY9: CMI_Trend_20 | BZ9: CMI_Trend_46 | CA9: CMI_Trend_56 | CB9: CMI_Trend_56 | CC9: CMI_Trend_38 | CD9: CMI_Trend_20 | CE9: CMI_Trend_38 | CF9: CMI_Trend_52 | CG9: CMI_Trend_38 | CH9: CMI_Trend_38 | CI9: CMI_Trend_38 | CJ9: CMI_Trend_25 | CK9: CMI_Trend_56 | CL9: CMI_Trend_46 | CM9: CMI_Trend_20 | CN9: CMI_Trend_38 | CO9: CMI_Trend_38 | CP9: CMI_Trend_38 | CQ9: CMI_Trend_46 | CR9: CMI_Trend_52
B10: Hydrogen | C10: 0.0909 | D10: 0.0821 | E10: 0.1025 | F10: 0.0893 | G10: 0.0831 | H10: 0.0988 | I10: 0.1038 | J10: 0.0993 | K10: 0.088 | L10: 0.0964 | M10: 0.0914 | N10: 0.0854 | O10: 0.1015 | P10: 0.0984 | Q10: 0.0957 | R10: 0.092 | S10: 0.1016 | T10: 0.1019 | U10: 0.0896 | V10: 0.0952 | W10: 0.0971 | X10: 0.0903 | Y10: 0.0978 | Z10: 0.1019 | AA10: 0.102 | AB10: 0.1033 | AC10: 0.0886 | AD10: 0.0989 | AE10: 0.0947 | AF10: 0.0828 | AH10: Hydrogen | AI10: 0.089279945 | AJ10: 0.094104857 | AK10: 0.075126675 | AL10: 0.071819722 | AM10: 0.084117171 | AN10: 0.087184925 | AO10: 0.066867024 | AP10: 0.091595843 | AQ10: 0.11627358 | AR10: 0.1197275 | AS10: 0.11131934 | AT10: 0.1001102 | AU10: 0.10755727 | AV10: 0.095039891 | AW10: 0.10264503 | AX10: 0.079474913 | AY10: 0.10795256 | AZ10: 0.12286506 | BA10: 0.086521351 | BB10: 0.09610384 | BC10: 0.091857335 | BD10: 0.11598146 | BE10: 0.10076155 | BF10: 0.09894542 | BG10: 0.085232481 | BH10: 0.091485132 | BI10: 0.084627433 | BJ10: 0.089658686 | BK10: 0.095385567 | BL10: 0.10065006 | BN10: Hydrogen | BO10: CMI_Trend_20 | BP10: CMI_Trend_56 | BQ10: CMI_Trend_25 | BR10: CMI_Trend_46 | BS10: CMI_Trend_46 | BT10: CMI_Trend_56 | BU10: CMI_Trend_60 | BV10: CMI_Trend_38 | BW10: CMI_Trend_20 | BX10: CMI_Trend_60 | BY10: CMI_Trend_60 | BZ10: CMI_Trend_20 | CA10: CMI_Trend_52 | CB10: CMI_Trend_56 | CC10: CMI_Trend_52 | CD10: CMI_Trend_52 | CE10: CMI_Trend_60 | CF10: CMI_Trend_38 | CG10: CMI_Trend_56 | CH10: CMI_Trend_52 | CI10: CMI_Trend_46 | CJ10: CMI_Trend_52 | CK10: CMI_Trend_20 | CL10: CMI_Trend_56 | CM10: CMI_Trend_25 | CN10: CMI_Trend_56 | CO10: CMI_Trend_52 | CP10: CMI_Trend_52 | CQ10: CMI_Trend_60 | CR10: CMI_Trend_46
B11: Toxic & Hazardous Gases (H₂S, CO) | C11: 0.1616 | D11: 0.1742 | E11: 0.1493 | F11: 0.1623 | G11: 0.1507 | H11: 0.1602 | I11: 0.1803 | J11: 0.1614 | K11: 0.1726 | L11: 0.1725 | M11: 0.1495 | N11: 0.1772 | O11: 0.153 | P11: 0.1581 | Q11: 0.1672 | R11: 0.1521 | S11: 0.1631 | T11: 0.1516 | U11: 0.1523 | V11: 0.1724 | W11: 0.1629 | X11: 0.1541 | Y11: 0.1564 | Z11: 0.158 | AA11: 0.1511 | AB11: 0.1503 | AC11: 0.1631 | AD11: 0.1507 | AE11: 0.1649 | AF11: 0.1585 | AH11: Toxic & Hazardous Gases (H₂S, CO) | AI11: 0.056687777 | AJ11: 0.061512689 | AK11: 0.042534506 | AL11: 0.039227554 | AM11: 0.051525003 | AN11: 0.054592757 | AO11: 0.034274856 | AP11: 0.059003675 | AQ11: 0.083681411 | AR11: 0.087135328 | AS11: 0.07872717 | AT11: 0.067518031 | AU11: 0.074965097 | AV11: 0.062447722 | AW11: 0.070052857 | AX11: 0.046882744 | AY11: 0.07536039 | AZ11: 0.090272889 | BA11: 0.053929182 | BB11: 0.063511672 | BC11: 0.059265166 | BD11: 0.08338929 | BE11: 0.068169385 | BF11: 0.066353252 | BG11: 0.052640313 | BH11: 0.058892963 | BI11: 0.052035265 | BJ11: 0.057066518 | BK11: 0.062793399 | BL11: 0.068057893 | BN11: Toxic & Hazardous Gases (H₂S, CO) | BO11: CMI_Trend_60 | BP11: CMI_Trend_20 | BQ11: CMI_Trend_25 | BR11: CMI_Trend_20 | BS11: CMI_Trend_20 | BT11: CMI_Trend_20 | BU11: CMI_Trend_25 | BV11: CMI_Trend_38 | BW11: CMI_Trend_52 | BX11: CMI_Trend_38 | BY11: CMI_Trend_52 | BZ11: CMI_Trend_46 | CA11: CMI_Trend_56 | CB11: CMI_Trend_52 | CC11: CMI_Trend_25 | CD11: CMI_Trend_60 | CE11: CMI_Trend_56 | CF11: CMI_Trend_38 | CG11: CMI_Trend_38 | CH11: CMI_Trend_52 | CI11: CMI_Trend_52 | CJ11: CMI_Trend_52 | CK11: CMI_Trend_38 | CL11: CMI_Trend_52 | CM11: CMI_Trend_60 | CN11: CMI_Trend_38 | CO11: CMI_Trend_60 | CP11: CMI_Trend_25 | CQ11: CMI_Trend_25 | CR11: CMI_Trend_25
B12: Emission Gases (NOx, SO₂) | C12: =1-SUM(C6:C11) -> 0.175 | D12: =1-SUM(D6:D11) -> 0.1934 | E12: =1-SUM(E6:E11) -> 0.1717 | F12: =1-SUM(F6:F11) -> 0.198 | G12: =1-SUM(G6:G11) -> 0.1936 | H12: =1-SUM(H6:H11) -> 0.1923 | I12: =1-SUM(I6:I11) -> 0.1705 | J12: =1-SUM(J6:J11) -> 0.1987 | ... AF12: =1-SUM(AF6:AF11) -> 0.1968 | AH12: Emission Gases (NOx, SO₂) | AI12: 0.064679616 | AJ12: 0.069504528 | AK12: 0.050526345 | AL12: 0.047219393 | AM12: 0.059516842 | AN12: 0.062584596 | AO12: 0.042266694 | AP12: 0.066995514 | AQ12: 0.09167325 | AR12: 0.095127167 | AS12: 0.086719009 | AT12: 0.07550987 | AU12: 0.082956936 | AV12: 0.070439561 | AW12: 0.078044696 | AX12: 0.054874583 | AY12: 0.083352229 | AZ12: 0.098264728 | BA12: 0.061921021 | BB12: 0.07150351 | BC12: 0.067257005 | BD12: 0.091381129 | BE12: 0.076161224 | BF12: 0.074345091 | BG12: 0.060632152 | BH12: 0.066884802 | BI12: 0.060027104 | BJ12: 0.065058357 | BK12: 0.070785238 | BL12: 0.076049732 | BN12: Emission Gases (NOx, SO₂) | BO12: CMI_Trend_38 | BP12: CMI_Trend_52 | BQ12: CMI_Trend_20 | BR12: CMI_Trend_46 | BS12: CMI_Trend_60 | BT12: CMI_Trend_20 | BU12: CMI_Trend_60 | BV12: CMI_Trend_25 | BW12: CMI_Trend_52 | BX12: CMI_Trend_20 | BY12: CMI_Trend_38 | BZ12: CMI_Trend_52 | CA12: CMI_Trend_20 | CB12: CMI_Trend_20 | CC12: CMI_Trend_38 | CD12: CMI_Trend_56 | CE12: CMI_Trend_20 | CF12: CMI_Trend_56 | CG12: CMI_Trend_25 | CH12: CMI_Trend_52 | CI12: CMI_Trend_52 | CJ12: CMI_Trend_46 | CK12: CMI_Trend_25 | CL12: CMI_Trend_20 | CM12: CMI_Trend_56 | CN12: CMI_Trend_25 | CO12: CMI_Trend_38 | CP12: CMI_Trend_56 | CQ12: CMI_Trend_60 | CR12: CMI_Trend_60
B13: Liquid Analyzers | C13: =1-C5 -> 0.4248 | D13: =1-D5 -> 0.4006 | E13: =1-E5 -> 0.4107 | F13: =1-F5 -> 0.4244 | G13: =1-G5 -> 0.4075 | H13: =1-H5 -> 0.4101 | I13: =1-I5 -> 0.4212 | J13: =1-J5 -> 0.4013 | ... AF13: =1-AF5 -> 0.4207 | AH13: Liquid Analyzers | AI13: 0.046064851 | AJ13: 0.050889764 | AK13: 0.031911581 | AL13: 0.028604628 | AM13: 0.040902078 | AN13: 0.043969831 | AO13: 0.02365193 | AP13: 0.04838075 | AQ13: 0.073058485 | AR13: 0.076512403 | AS13: 0.068104245 | AT13: 0.056895105 | AU13: 0.064342172 | AV13: 0.051824797 | AW13: 0.059429932 | AX13: 0.036259819 | AY13: 0.064737464 | AZ13: 0.079649964 | BA13: 0.043306257 | BB13: 0.052888746 | BC13: 0.048642241 | BD13: 0.072766365 | BE13: 0.05754646 | BF13: 0.055730326 | BG13: 0.042017387 | BH13: 0.048270038 | BI13: 0.04141234 | BJ13: 0.046443593 | BK13: 0.052170473 | BL13: 0.057434967 | BN13: Liquid Analyzers | BO13: CMI_Trend_38 | BP13: CMI_Trend_20 | BQ13: CMI_Trend_46 | BR13: CMI_Trend_52 | BS13: CMI_Trend_52 | BT13: CMI_Trend_56 | BU13: CMI_Trend_25 | BV13: CMI_Trend_20 | BW13: CMI_Trend_38 | BX13: CMI_Trend_38 | BY13: CMI_Trend_20 | BZ13: CMI_Trend_60 | CA13: CMI_Trend_60 | CB13: CMI_Trend_56 | CC13: CMI_Trend_52 | CD13: CMI_Trend_46 | CE13: CMI_Trend_46 | CF13: CMI_Trend_38 | CG13: CMI_Trend_25 | CH13: CMI_Trend_20 | CI13: CMI_Trend_46 | CJ13: CMI_Trend_38 | CK13: CMI_Trend_46 | CL13: CMI_Trend_20 | CM13: CMI_Trend_56 | CN13: CMI_Trend_52 | CO13: CMI_Trend_25 | CP13: CMI_Trend_38 | CQ13: CMI_Trend_46 | CR13: CMI_Trend_25
B15: By Technology | AH15: By Technology | BN15: By Technology
B16: Spectroscopic Analyzers | C16: 0.2849 | D16: 0.2987 | E16: 0.3081 | F16: 0.2825 | G16: 0.3099 | H16: 0.2913 | I16: 0.298 | J16: 0.2803 | K16: 0.2986 | L16: 0.304 | M16: 0.2905 | N16: 0.3026 | O16: 0.2855 | P16: 0.2933 | Q16: 0.2873 | R16: 0.2873 | S16: 0.3042 | T16: 0.3038 | U16: 0.2914 | V16: 0.3056 | W16: 0.2973 | X16: 0.3015 | Y16: 0.3002 | Z16: 0.2856 | AA16: 0.2954 | AB16: 0.2985 | AC16: 0.2898 | AD16: 0.3072 | AE16: 0.2854 | AF16: 0.2879 | AH16: Spectroscopic Analyzers | AI16: 0.065239124 | AJ16: 0.069692642 | AK16: 0.051108885 | AL16: 0.047795279 | AM16: 0.059770558 | AN16: 0.0634081 | AO16: 0.042638676 | AP16: 0.068269213 | AQ16: 0.091483797 | AR16: 0.096136032 | AS16: 0.087077777 | AT16: 0.075927624 | AU16: 0.083449047 | AV16: 0.071189665 | AW16: 0.079225794 | AX16: 0.055823201 | AY16: 0.083755704 | AZ16: 0.098710489 | BA16: 0.062647568 | BB16: 0.071438397 | BC16: 0.067831066 | BD16: 0.091443663 | BE16: 0.076446445 | BF16: 0.07518142 | BG16: 0.06113861 | BH16: 0.067692811 | BI16: 0.060498302 | BJ16: 0.065265693 | BK16: 0.071125449 | BL16: 0.076230473 | BN16: Spectroscopic Analyzers | BO16: CMI_Trend_20 | BP16: CMI_Trend_20 | BQ16: CMI_Trend_56 | BR16: CMI_Trend_60 | BS16: CMI_Trend_38 | BT16: CMI_Trend_52 | BU16: CMI_Trend_20 | BV16: CMI_Trend_38 | BW16: CMI_Trend_52 | BX16: CMI_Trend_56 | BY16: CMI_Trend_38 | BZ16: CMI_Trend_60 | CA16: CMI_Trend_38 | CB16: CMI_Trend_56 | CC16: CMI_Trend_52 | CD16: CMI_Trend_60 | CE16: CMI_Trend_52 | CF16: CMI_Trend_56 | CG16: CMI_Trend_20 | CH16: CMI_Trend_46 | CI16: CMI_Trend_60 | CJ16: CMI_Trend_38 | CK16: CMI_Trend_38 | CL16: CMI_Trend_52 | CM16: CMI_Trend_60 | CN16: CMI_Trend_52 | CO16: CMI_Trend_56 | CP16: CMI_Trend_52 | CQ16: CMI_Trend_20 | CR16: CMI_Trend_60
B17: Chromatography Analyzers | C17: 0.2265 | D17: 0.2287 | E17: 0.2208 | F17: 0.2309 | G17: 0.2259 | H17: 0.2423 | I17: 0.2344 | J17: 0.2336 | K17: 0.229 | L17: 0.2189 | M17: 0.2427 | N17: 0.2356 | O17: 0.2288 | P17: 0.2323 | Q17: 0.2216 | R17: 0.24 | S17: 0.2234 | T17: 0.2216 | U17: 0.2363 | V17: 0.2304 | W17: 0.2284 | X17: 0.2403 | Y17: 0.2368 | Z17: 0.2365 | AA17: 0.2387 | AB17: 0.235 | AC17: 0.2427 | AD17: 0.2166 | AE17: 0.223 | AF17: 0.2363 | AH17: Chromatography Analyzers | AI17: 0.051239124 | AJ17: 0.055692642 | AK17: 0.037108885 | AL17: 0.033795279 | AM17: 0.045770558 | AN17: 0.0494081 | AO17: 0.028638676 | AP17: 0.054269213 | AQ17: 0.077483797 | AR17: 0.082136032 | AS17: 0.073077777 | AT17: 0.061927624 | AU17: 0.069449047 | AV17: 0.057189665 | AW17: 0.065225794 | AX17: 0.041823201 | AY17: 0.069755704 | AZ17: 0.084710489 | BA17: 0.048647568 | BB17: 0.057438397 | BC17: 0.053831066 | BD17: 0.077443663 | BE17: 0.062446445 | BF17: 0.06118142 | BG17: 0.04713861 | BH17: 0.053692811 | BI17: 0.046498302 | BJ17: 0.051265693 | BK17: 0.057125449 | BL17: 0.062230473 | BN17: Chromatography Analyzers | BO17: CMI_Trend_60 | BP17: CMI_Trend_38 | BQ17: CMI_Trend_38 | BR17: CMI_Trend_20 | BS17: CMI_Trend_25 | BT17: CMI_Trend_38 | BU17: CMI_Trend_25 | BV17: CMI_Trend_52 | BW17: CMI_Trend_56 | BX17: CMI_Trend_38 | BY17: CMI_Trend_56 | BZ17: CMI_Trend_20 | CA17: CMI_Trend_38 | CB17: CMI_Trend_46 | CC17: CMI_Trend_20 | CD17: CMI_Trend_60 | CE17: CMI_Trend_60 | CF17: CMI_Trend_25 | CG17: CMI_Trend_52 | CH17: CMI_Trend_60 | CI17: CMI_Trend_38 | CJ17: CMI_Trend_46 | CK17: CMI_Trend_60 | CL17: CMI_Trend_46 | CM17: CMI_Trend_56 | CN17: CMI_Trend_46 | CO17: CMI_Trend_60 | CP17: CMI_Trend_38 | CQ17: CMI_Trend_25 | CR17: CMI_Trend_46
B18: Electrochemical Analyzers | C18: 0.187 | D18: 0.2028 | E18: 0.2031 | F18: 0.2 | G18: 0.1875 | H18: 0.2 | I18: 0.196 | J18: 0.1957 | K18: 0.2106 | L18: 0.1817 | M18: 0.2117 | N18: 0.1792 | O18: 0.2046 | P18: 0.1999 | Q18: 0.2079 | R18: 0.1869 | S18: 0.1842 | T18: 0.1866 | U18: 0.2005 | V18: 0.2001 | W18: 0.1922 | X18: 0.1984 | Y18: 0.2036 | Z18: 0.1889 | AA18: 0.197 | AB18: 0.2019 | AC18: 0.1979 | AD18: 0.1869 | AE18: 0.204 | AF18: 0.1963 | AH18: Electrochemical Analyzers | AI18: 0.058239124 | AJ18: 0.062692642 | AK18: 0.044108885 | AL18: 0.040795279 | AM18: 0.052770558 | AN18: 0.0564081 | AO18: 0.035638676 | AP18: 0.061269213 | AQ18: 0.084483797 | AR18: 0.089136032 | AS18: 0.080077777 | AT18: 0.068927624 | AU18: 0.076449047 | AV18: 0.064189665 | AW18: 0.072225794 | AX18: 0.048823201 | AY18: 0.076755704 | AZ18: 0.091710489 | BA18: 0.055647568 | BB18: 0.064438397 | BC18: 0.060831066 | BD18: 0.084443663 | BE18: 0.069446445 | BF18: 0.06818142 | BG18: 0.05413861 | BH18: 0.060692811 | BI18: 0.053498302 | BJ18: 0.058265693 | BK18: 0.064125449 | BL18: 0.069230473 | BN18: Electrochemical Analyzers | BO18: CMI_Trend_20 | BP18: CMI_Trend_56 | BQ18: CMI_Trend_25 | BR18: CMI_Trend_25 | BS18: CMI_Trend_38 | BT18: CMI_Trend_20 | BU18: CMI_Trend_60 | BV18: CMI_Trend_56 | BW18: CMI_Trend_52 | BX18: CMI_Trend_25 | BY18: CMI_Trend_60 | BZ18: CMI_Trend_20 | CA18: CMI_Trend_52 | CB18: CMI_Trend_38 | CC18: CMI_Trend_20 | CD18: CMI_Trend_20 | CE18: CMI_Trend_25 | CF18: CMI_Trend_60 | CG18: CMI_Trend_56 | CH18: CMI_Trend_20 | CI18: CMI_Trend_25 | CJ18: CMI_Trend_56 | CK18: CMI_Trend_25 | CL18: CMI_Trend_25 | CM18: CMI_Trend_52 | CN18: CMI_Trend_56 | CO18: CMI_Trend_38 | CP18: CMI_Trend_56 | CQ18: CMI_Trend_38 | CR18: CMI_Trend_25
B19: Thermal Conductivity Analyzers | C19: 0.1535 | D19: 0.1386 | E19: 0.1304 | F19: 0.1378 | G19: 0.1323 | H19: 0.1318 | I19: 0.1455 | J19: 0.1399 | K19: 0.1372 | L19: 0.1581 | M19: 0.1285 | N19: 0.1482 | O19: 0.1532 | P19: 0.14 | Q19: 0.133 | R19: 0.1418 | S19: 0.1517 | T19: 0.1563 | U19: 0.1439 | V19: 0.1298 | W19: 0.1342 | X19: 0.1309 | Y19: 0.127 | Z19: 0.1416 | AA19: 0.1435 | AB19: 0.1298 | AC19: 0.1443 | AD19: 0.1445 | AE19: 0.1519 | AF19: 0.1554 | AH19: Thermal Conductivity Analyzers | AI19: 0.044239124 | AJ19: 0.048692642 | AK19: 0.030108885 | AL19: 0.026795279 | AM19: 0.038770558 | AN19: 0.0424081 | AO19: 0.024638676 | AP19: 0.047269213 | AQ19: 0.070483797 | AR19: 0.075136032 | AS19: 0.066077777 | AT19: 0.054927624 | AU19: 0.062449047 | AV19: 0.050189665 | AW19: 0.058225794 | AX19: 0.034823201 | AY19: 0.062755704 | AZ19: 0.077710489 | BA19: 0.041647568 | BB19: 0.050438397 | BC19: 0.046831066 | BD19: 0.070443663 | BE19: 0.055446445 | BF19: 0.05418142 | BG19: 0.04013861 | BH19: 0.046692811 | BI19: 0.039498302 | BJ19: 0.044265693 | BK19: 0.050125449 | BL19: 0.055230473 | BN19: Thermal Conductivity Analyzers | BO19: CMI_Trend_46 | BP19: CMI_Trend_60 | BQ19: CMI_Trend_56 | BR19: CMI_Trend_20 | BS19: CMI_Trend_46 | BT19: CMI_Trend_20 | BU19: CMI_Trend_52 | BV19: CMI_Trend_60 | BW19: CMI_Trend_46 | BX19: CMI_Trend_46 | BY19: CMI_Trend_60 | BZ19: CMI_Trend_60 | CA19: CMI_Trend_38 | CB19: CMI_Trend_56 | CC19: CMI_Trend_46 | CD19: CMI_Trend_25 | CE19: CMI_Trend_60 | CF19: CMI_Trend_60 | CG19: CMI_Trend_60 | CH19: CMI_Trend_20 | CI19: CMI_Trend_25 | CJ19: CMI_Trend_46 | CK19: CMI_Trend_52 | CL19: CMI_Trend_25 | CM19: CMI_Trend_46 | CN19: CMI_Trend_56 | CO19: CMI_Trend_46 | CP19: CMI_Trend_46 | CQ19: CMI_Trend_20 | CR19: CMI_Trend_52
B20: Paramagnetic Analyzers | C20: =1-SUM(C16:C19) -> 0.1481 | D20: =1-SUM(D16:D19) -> 0.1312 | E20: =1-SUM(E16:E19) -> 0.1376 | F20: =1-SUM(F16:F19) -> 0.1488 | G20: =1-SUM(G16:G19) -> 0.1444 | H20: =1-SUM(H16:H19) -> 0.1346 | I20: =1-SUM(I16:I19) -> 0.1261 | J20: =1-SUM(J16:J19) -> 0.1505 | ... AF20: =1-SUM(AF16:AF19) -> 0.1241 | AH20: Paramagnetic Analyzers | AI20: 0.037444219 | AJ20: 0.041897738 | AK20: 0.023313981 | AL20: 0.020000375 | AM20: 0.031975654 | AN20: 0.035613195 | AO20: 0.020843772 | AP20: 0.040474309 | AQ20: 0.063688893 | AR20: 0.068341128 | AS20: 0.059282873 | AT20: 0.048132719 | AU20: 0.055654142 | AV20: 0.043394761 | AW20: 0.051430889 | AX20: 0.028028297 | AY20: 0.0559608 | AZ20: 0.070915585 | BA20: 0.034852664 | BB20: 0.043643492 | BC20: 0.040036162 | BD20: 0.063648759 | BE20: 0.048651541 | BF20: 0.047386516 | BG20: 0.033343705 | BH20: 0.039897907 | BI20: 0.032703397 | BJ20: 0.037470788 | BK20: 0.043330545 | BL20: 0.048435569 | BN20: Paramagnetic Analyzers | BO20: CMI_Trend_60 | BP20: CMI_Trend_46 | BQ20: CMI_Trend_46 | BR20: CMI_Trend_25 | BS20: CMI_Trend_56 | BT20: CMI_Trend_46 | BU20: CMI_Trend_60 | BV20: CMI_Trend_60 | BW20: CMI_Trend_60 | BX20: CMI_Trend_25 | BY20: CMI_Trend_38 | BZ20: CMI_Trend_56 | CA20: CMI_Trend_60 | CB20: CMI_Trend_56 | CC20: CMI_Trend_25 | CD20: CMI_Trend_60 | CE20: CMI_Trend_56 | CF20: CMI_Trend_52 | CG20: CMI_Trend_60 | CH20: CMI_Trend_56 | CI20: CMI_Trend_52 | CJ20: CMI_Trend_56 | CK20: CMI_Trend_60 | CL20: CMI_Trend_46 | CM20: CMI_Trend_46 | CN20: CMI_Trend_38 | CO20: CMI_Trend_60 | CP20: CMI_Trend_60 | CQ20: CMI_Trend_56 | CR20: CMI_Trend_52
AI21: =AI22-AI$2 -> 0
B22: By Sampling Type | AH22: By Sampling Type | AI22: =SUMPRODUCT(AI23:AI24,C23:C24) -> 0.053419198 | BN22: By Sampling Type
B23: Continuous Sampling Analyzers | C23: 0.6929 | D23: 0.6865 | E23: 0.7075 | F23: 0.6872 | G23: 0.7001 | H23: 0.6841 | I23: 0.6866 | J23: 0.7023 | K23: 0.6852 | L23: 0.6877 | M23: 0.6881 | N23: 0.7066 | O23: 0.6921 | P23: 0.6998 | Q23: 0.7023 | R23: 0.7076 | S23: 0.6957 | T23: 0.7085 | U23: 0.7019 | V23: 0.7103 | W23: 0.7079 | X23: 0.6806 | Y23: 0.7085 | Z23: 0.7042 | AA23: 0.6957 | AB23: 0.6952 | AC23: 0.6831 | AD23: 0.7063 | AE23: 0.7079 | AF23: 0.6875 | AH23: Continuous Sampling Analyzers | AI23: 0.058025698 | AJ23: 0.063216451 | AK23: 0.044420506 | AL23: 0.040824997 | AM23: 0.053002074 | AN23: 0.056845405 | AO23: 0.036125638 | AP23: 0.06097338 | AQ23: 0.085181152 | AR23: 0.089347692 | AS23: 0.080659242 | AT23: 0.068927988 | AU23: 0.076659978 | AV23: 0.06436275 | AW23: 0.072165799 | AX23: 0.048560635 | AY23: 0.0769235 | AZ23: 0.0917315 | BA23: 0.0558305 | BB23: 0.0647045 | BC23: 0.0607405 | BD23: 0.08515 | BE23: 0.0697315 | BF23: 0.067914551 | BG23: 0.054483329 | BH23: 0.061088958 | BI23: 0.0539557 | BJ23: 0.05827129 | BK23: 0.06399528 | BL23: 0.069522925 | BN23: Continuous Sampling Analyzers | BO23: CMI_Trend_52 | BP23: CMI_Trend_38 | BQ23: CMI_Trend_38 | BR23: CMI_Trend_25 | BS23: CMI_Trend_52 | BT23: CMI_Trend_60 | BU23: CMI_Trend_20 | BV23: CMI_Trend_38 | BW23: CMI_Trend_46 | BX23: CMI_Trend_52 | BY23: CMI_Trend_60 | BZ23: CMI_Trend_38 | CA23: CMI_Trend_20 | CB23: CMI_Trend_25 | CC23: CMI_Trend_38 | CD23: CMI_Trend_25 | CE23: CMI_Trend_56 | CF23: CMI_Trend_25 | CG23: CMI_Trend_46 | CH23: CMI_Trend_38 | CI23: CMI_Trend_46 | CJ23: CMI_Trend_20 | CK23: CMI_Trend_38 | CL23: CMI_Trend_52 | CM23: CMI_Trend_56 | CN23: CMI_Trend_46 | CO23: CMI_Trend_46 | CP23: CMI_Trend_20 | CQ23: CMI_Trend_38 | CR23: CMI_Trend_46
B24: Batch Sampling Analyzers | C24: =1-C23 -> 0.3071 | D24: =1-D23 -> 0.3135 | E24: =1-E23 -> 0.2925 | F24: =1-F23 -> 0.3128 | G24: =1-G23 -> 0.2999 | H24: =1-H23 -> 0.3159 | I24: =1-I23 -> 0.3134 | J24: =1-J23 -> 0.2977 | ... AF24: =1-AF23 -> 0.3125 | AH24: Batch Sampling Analyzers | AI24: 0.043025698 | AJ24: 0.048216451 | AK24: 0.029420506 | AL24: 0.025824997 | AM24: 0.038002074 | AN24: 0.041845405 | AO24: 0.021125638 | AP24: 0.04597338 | AQ24: 0.070181152 | AR24: 0.074347692 | AS24: 0.065659242 | AT24: 0.053927988 | AU24: 0.061659978 | AV24: 0.04936275 | AW24: 0.057165799 | AX24: 0.033560635 | AY24: 0.0619235 | AZ24: 0.0767315 | BA24: 0.0408305 | BB24: 0.0497045 | BC24: 0.0457405 | BD24: 0.07015 | BE24: 0.0547315 | BF24: 0.052914551 | BG24: 0.039483329 | BH24: 0.046088958 | BI24: 0.0389557 | BJ24: 0.04327129 | BK24: 0.04899528 | BL24: 0.054522925 | BN24: Batch Sampling Analyzers | BO24: CMI_Trend_46 | BP24: CMI_Trend_60 | BQ24: CMI_Trend_46 | BR24: CMI_Trend_60 | BS24: CMI_Trend_56 | BT24: CMI_Trend_25 | BU24: CMI_Trend_25 | BV24: CMI_Trend_25 | BW24: CMI_Trend_60 | BX24: CMI_Trend_52 | BY24: CMI_Trend_52 | BZ24: CMI_Trend_56 | CA24: CMI_Trend_52 | CB24: CMI_Trend_56 | CC24: CMI_Trend_60 | CD24: CMI_Trend_20 | CE24: CMI_Trend_38 | CF24: CMI_Trend_20 | CG24: CMI_Trend_52 | CH24: CMI_Trend_20 | CI24: CMI_Trend_46 | CJ24: CMI_Trend_25 | CK24: CMI_Trend_20 | CL24: CMI_Trend_38 | CM24: CMI_Trend_46 | CN24: CMI_Trend_60 | CO24: CMI_Trend_56 | CP24: CMI_Trend_46 | CQ24: CMI_Trend_46 | CR24: CMI_Trend_46
B26: By Installation Type | AH26: By Installation Type | BN26: By Installation Type
B27: Fixed / Stationary Analyzers | C27: 0.7508 | D27: 0.7602 | E27: 0.7539604 | F27: 0.7438 | G27: 0.7657 | H27: 0.75973381 | I27: 0.7545 | J27: 0.7609 | K27: 0.7469 | L27: 0.73803832 | M27: 0.7582 | N27: 0.75027952 | O27: 0.7661 | P27: 0.7557 | Q27: 0.74984292 | R27: 0.7469 | S27: 0.7553 | T27: 0.7616 | U27: 0.7487 | V27: 0.7546 | W27: 0.76225346 | X27: 0.7407 | Y27: 0.7375 | Z27: 0.7661 | AA27: 0.7466 | AB27: 0.7539 | AC27: 0.768 | AD27: 0.7597 | AE27: 0.7448 | AF27: 0.75472993 | AH27: Fixed / Stationary Analyzers | AI27: 0.051390005 | AJ27: 0.0565613 | AK27: 0.038029548 | AL27: 0.034046804 | AM27: 0.046595709 | AN27: 0.050150459 | AO27: 0.029425574 | AP27: 0.054560929 | AQ27: 0.078398202 | AR27: 0.082530083 | AS27: 0.074011806 | AT27: 0.062493557 | AU27: 0.070136871 | AV27: 0.057870457 | AW27: 0.065663313 | AX27: 0.042113685 | AY27: 0.07036645 | AZ27: 0.08541775 | BA27: 0.049312707 | BB27: 0.05836075 | BC27: 0.054423071 | BD27: 0.078247564 | BE27: 0.063221507 | BF27: 0.061572943 | BG27: 0.047855436 | BH27: 0.054513007 | BI27: 0.047313064 | BJ27: 0.051909069 | BK27: 0.05753573 | BL27: 0.062838233 | BN27: Fixed / Stationary Analyzers | BO27: CMI_Trend_46 | BP27: CMI_Trend_52 | BQ27: CMI_Trend_38 | BR27: CMI_Trend_38 | BS27: CMI_Trend_20 | BT27: CMI_Trend_20 | BU27: CMI_Trend_46 | BV27: CMI_Trend_46 | BW27: CMI_Trend_56 | BX27: CMI_Trend_38 | BY27: CMI_Trend_46 | BZ27: CMI_Trend_46 | CA27: CMI_Trend_56 | CB27: CMI_Trend_20 | CC27: CMI_Trend_60 | CD27: CMI_Trend_25 | CE27: CMI_Trend_38 | CF27: CMI_Trend_25 | CG27: CMI_Trend_60 | CH27: CMI_Trend_38 | CI27: CMI_Trend_52 | CJ27: CMI_Trend_20 | CK27: CMI_Trend_20 | CL27: CMI_Trend_25 | CM27: CMI_Trend_38 | CN27: CMI_Trend_52 | CO27: CMI_Trend_46 | CP27: CMI_Trend_60 | CQ27: CMI_Trend_46 | CR27: CMI_Trend_46
B28: Portable / Handheld Analyzers | C28: 0.2492 | D28: 0.2398 | E28: 0.2460396 | F28: 0.2562 | G28: 0.2343 | H28: 0.24026619 | I28: 0.2455 | J28: 0.2391 | K28: 0.2531 | L28: 0.26196168 | M28: 0.2418 | N28: 0.24972048 | O28: 0.2339 | P28: 0.2443 | Q28: 0.25015708 | R28: 0.2531 | S28: 0.2447 | T28: 0.2384 | U28: 0.2513 | V28: 0.2454 | W28: 0.23774654 | X28: 0.2593 | Y28: 0.2625 | Z28: 0.2339 | AA28: 0.2534 | AB28: 0.2461 | AC28: 0.232 | AD28: 0.2403 | AE28: 0.2552 | AF28: 0.24527007 | AH28: Portable / Handheld Analyzers | AI28: 0.059532834 | AJ28: 0.064704129 | AK28: 0.046172377 | AL28: 0.042189634 | AM28: 0.054738538 | AN28: 0.058293288 | AO28: 0.037568403 | AP28: 0.062703759 | AQ28: 0.086541031 | AR28: 0.090672912 | AS28: 0.082154635 | AT28: 0.070636386 | AU28: 0.0782797 | AV28: 0.066013286 | AW28: 0.073806142 | AX28: 0.050256514 | AY28: 0.078509279 | AZ28: 0.093560579 | BA28: 0.057455536 | BB28: 0.066503579 | BC28: 0.0625659 | BD28: 0.086390394 | BE28: 0.071364336 | BF28: 0.069715772 | BG28: 0.055998265 | BH28: 0.062655837 | BI28: 0.055455893 | BJ28: 0.060051898 | BK28: 0.065678559 | BL28: 0.070981062 | BN28: Portable / Handheld Analyzers | BO28: CMI_Trend_52 | BP28: CMI_Trend_38 | BQ28: CMI_Trend_38 | BR28: CMI_Trend_56 | BS28: CMI_Trend_60 | BT28: CMI_Trend_25 | BU28: CMI_Trend_46 | BV28: CMI_Trend_38 | BW28: CMI_Trend_38 | BX28: CMI_Trend_25 | BY28: CMI_Trend_60 | BZ28: CMI_Trend_56 | CA28: CMI_Trend_20 | CB28: CMI_Trend_56 | CC28: CMI_Trend_60 | CD28: CMI_Trend_52 | CE28: CMI_Trend_20 | CF28: CMI_Trend_52 | CG28: CMI_Trend_56 | CH28: CMI_Trend_60 | CI28: CMI_Trend_25 | CJ28: CMI_Trend_25 | CK28: CMI_Trend_56 | CL28: CMI_Trend_46 | CM28: CMI_Trend_46 | CN28: CMI_Trend_38 | CO28: CMI_Trend_56 | CP28: CMI_Trend_25 | CQ28: CMI_Trend_20 | CR28: CMI_Trend_38
B30: By Application | AH30: By Application | BN30: By Application
B31: Process Monitoring | C31: 0.3469 | D31: 0.3479 | E31: 0.3493 | F31: 0.3607 | G31: 0.3605 | H31: 0.3569 | I31: 0.3417 | J31: 0.34 | K31: 0.3435 | L31: 0.3711 | M31: 0.3614 | N31: 0.3482 | O31: 0.355 | P31: 0.3591 | Q31: 0.354 | R31: 0.3613 | S31: 0.3665 | T31: 0.3586 | U31: 0.3527 | V31: 0.3383 | W31: 0.3425 | X31: 0.3646 | Y31: 0.3532 | Z31: 0.359 | AA31: 0.3657 | AB31: 0.3443 | AC31: 0.3408 | AD31: 0.3482 | AE31: 0.3435 | AF31: 0.3538 | AH31: Process Monitoring | AI31: 0.049888556 | AJ31: 0.054768095 | AK31: 0.035910957 | AL31: 0.032216254 | AM31: 0.044374419 | AN31: 0.048174197 | AO31: 0.027372385 | AP31: 0.052505899 | AQ31: 0.076121645 | AR31: 0.080850831 | AS31: 0.072018682 | AT31: 0.060471839 | AU31: 0.068043782 | AV31: 0.056021765 | AW31: 0.063746751 | AX31: 0.040373918 | AY31: 0.068489831 | AZ31: 0.083291125 | BA31: 0.047840162 | BB31: 0.056474662 | BC31: 0.052405351 | BD31: 0.076396349 | BE31: 0.061762874 | BF31: 0.059872456 | BG31: 0.045761299 | BH31: 0.052450709 | BI31: 0.044966445 | BJ31: 0.050172534 | BK31: 0.05544125 | BL31: 0.061005239 | BN31: Process Monitoring | BO31: CMI_Trend_20 | BP31: CMI_Trend_25 | BQ31: CMI_Trend_46 | BR31: CMI_Trend_25 | BS31: CMI_Trend_20 | BT31: CMI_Trend_20 | BU31: CMI_Trend_56 | BV31: CMI_Trend_25 | BW31: CMI_Trend_20 | BX31: CMI_Trend_20 | BY31: CMI_Trend_38 | BZ31: CMI_Trend_46 | CA31: CMI_Trend_20 | CB31: CMI_Trend_38 | CC31: CMI_Trend_56 | CD31: CMI_Trend_46 | CE31: CMI_Trend_52 | CF31: CMI_Trend_46 | CG31: CMI_Trend_25 | CH31: CMI_Trend_46 | CI31: CMI_Trend_56 | CJ31: CMI_Trend_60 | CK31: CMI_Trend_25 | CL31: CMI_Trend_56 | CM31: CMI_Trend_56 | CN31: CMI_Trend_38 | CO31: CMI_Trend_46 | CP31: CMI_Trend_60 | CQ31: CMI_Trend_52 | CR31: CMI_Trend_60
B32: Quality Control | C32: 0.2329 | D32: 0.2245 | E32: 0.2079 | F32: 0.2127 | G32: 0.2065 | H32: 0.2193 | I32: 0.2097 | J32: 0.2255 | K32: 0.2059 | L32: 0.2117 | M32: 0.2155 | N32: 0.2141 | O32: 0.2093 | P32: 0.2165 | Q32: 0.2229 | R32: 0.2184 | S32: 0.2167 | T32: 0.213 | U32: 0.2292 | V32: 0.2308 | W32: 0.2313 | X32: 0.2125 | Y32: 0.2315 | Z32: 0.2194 | AA32: 0.201 | AB32: 0.2183 | AC32: 0.2049 | AD32: 0.2331 | AE32: 0.2107 | AF32: 0.2218 | AH32: Quality Control | AI32: 0.042535372 | AJ32: 0.047414911 | AK32: 0.028557773 | AL32: 0.024863071 | AM32: 0.037021236 | AN32: 0.040821013 | AO32: 0.020019202 | AP32: 0.045152715 | AQ32: 0.068768462 | AR32: 0.073497647 | AS32: 0.064665499 | AT32: 0.053118655 | AU32: 0.060690598 | AV32: 0.048668582 | AW32: 0.056393567 | AX32: 0.033020734 | AY32: 0.061136647 | AZ32: 0.075937942 | BA32: 0.040486978 | BB32: 0.049121478 | BC32: 0.045052167 | BD32: 0.069043165 | BE32: 0.054409691 | BF32: 0.052519273 | BG32: 0.038408115 | BH32: 0.045097525 | BI32: 0.037613261 | BJ32: 0.04281935 | BK32: 0.048088066 | BL32: 0.053652056 | BN32: Quality Control | BO32: CMI_Trend_52 | BP32: CMI_Trend_46 | BQ32: CMI_Trend_25 | BR32: CMI_Trend_38 | BS32: CMI_Trend_38 | BT32: CMI_Trend_56 | BU32: CMI_Trend_52 | BV32: CMI_Trend_25 | BW32: CMI_Trend_25 | BX32: CMI_Trend_46 | BY32: CMI_Trend_56 | BZ32: CMI_Trend_46 | CA32: CMI_Trend_60 | CB32: CMI_Trend_52 | CC32: CMI_Trend_46 | CD32: CMI_Trend_56 | CE32: CMI_Trend_46 | CF32: CMI_Trend_46 | CG32: CMI_Trend_52 | CH32: CMI_Trend_52 | CI32: CMI_Trend_60 | CJ32: CMI_Trend_46 | CK32: CMI_Trend_20 | CL32: CMI_Trend_56 | CM32: CMI_Trend_25 | CN32: CMI_Trend_20 | CO32: CMI_Trend_52 | CP32: CMI_Trend_38 | CQ32: CMI_Trend_25 | CR32: CMI_Trend_25
B33: Environmental Monitoring | C33: 0.1647 | D33: 0.1688 | E33: 0.1784 | F33: 0.1818 | G33: 0.1859 | H33: 0.1882 | I33: 0.1726 | J33: 0.1927 | K33: 0.1892 | L33: 0.1721 | M33: 0.1874 | N33: 0.1819 | O33: 0.1757 | P33: 0.1792 | Q33: 0.1863 | R33: 0.1723 | S33: 0.179 | T33: 0.1904 | U33: 0.165 | V33: 0.1857 | W33: 0.1897 | X33: 0.1813 | Y33: 0.164 | Z33: 0.1604 | AA33: 0.188 | AB33: 0.1825 | AC33: 0.1795 | AD33: 0.1773 | AE33: 0.187 | AF33: 0.1814 | AH33: Environmental Monitoring | AI33: 0.069315995 | AJ33: 0.074195534 | AK33: 0.055338396 | AL33: 0.051643693 | AM33: 0.063801858 | AN33: 0.067601636 | AO33: 0.046799825 | AP33: 0.071933338 | AQ33: 0.095549085 | AR33: 0.10027827 | AS33: 0.091446122 | AT33: 0.079899278 | AU33: 0.087471221 | AV33: 0.075449205 | AW33: 0.08317419 | AX33: 0.059801357 | AY33: 0.08791727 | AZ33: 0.10271856 | BA33: 0.067267601 | BB33: 0.075902101 | BC33: 0.07183279 | BD33: 0.095823788 | BE33: 0.081190314 | BF33: 0.079299896 | BG33: 0.065188738 | BH33: 0.071878148 | BI33: 0.064393884 | BJ33: 0.069599973 | BK33: 0.074868689 | BL33: 0.080432679 | BN33: Environmental Monitoring | BO33: CMI_Trend_25 | BP33: CMI_Trend_60 | BQ33: CMI_Trend_20 | BR33: CMI_Trend_52 | BS33: CMI_Trend_25 | BT33: CMI_Trend_56 | BU33: CMI_Trend_20 | BV33: CMI_Trend_38 | BW33: CMI_Trend_46 | BX33: CMI_Trend_38 | BY33: CMI_Trend_56 | BZ33: CMI_Trend_60 | CA33: CMI_Trend_52 | CB33: CMI_Trend_60 | CC33: CMI_Trend_46 | CD33: CMI_Trend_46 | CE33: CMI_Trend_56 | CF33: CMI_Trend_38 | CG33: CMI_Trend_20 | CH33: CMI_Trend_25 | CI33: CMI_Trend_25 | CJ33: CMI_Trend_60 | CK33: CMI_Trend_56 | CL33: CMI_Trend_25 | CM33: CMI_Trend_52 | CN33: CMI_Trend_46 | CO33: CMI_Trend_56 | CP33: CMI_Trend_46 | CQ33: CMI_Trend_60 | CR33: CMI_Trend_20
B34: Safety and Compliance Monitoring | C34: 0.1561 | D34: 0.1506 | E34: 0.1504 | F34: 0.151 | G34: 0.1415 | H34: 0.1432 | I34: 0.1633 | J34: 0.1505 | K34: 0.1462 | L34: 0.1394 | M34: 0.1407 | N34: 0.1484 | O34: 0.1519 | P34: 0.1518 | Q34: 0.1321 | R34: 0.1395 | S34: 0.1321 | T34: 0.1404 | U34: 0.1587 | V34: 0.1478 | W34: 0.1322 | X34: 0.1364 | Y34: 0.1373 | Z34: 0.1575 | AA34: 0.1465 | AB34: 0.1419 | AC34: 0.1588 | AD34: 0.1424 | AE34: 0.1551 | AF34: 0.1495 | AH34: Safety and Compliance Monitoring | AI34: 0.05543311 | AJ34: 0.060312649 | AK34: 0.041455511 | AL34: 0.037760809 | AM34: 0.049918974 | AN34: 0.053718751 | AO34: 0.03291694 | AP34: 0.058050453 | AQ34: 0.0816662 | AR34: 0.086395386 | AS34: 0.077563237 | AT34: 0.066016393 | AU34: 0.073588336 | AV34: 0.06156632 | AW34: 0.069291305 | AX34: 0.045918472 | AY34: 0.074034386 | AZ34: 0.08883568 | BA34: 0.053384716 | BB34: 0.062019216 | BC34: 0.057949906 | BD34: 0.081940903 | BE34: 0.067307429 | BF34: 0.065417011 | BG34: 0.051305853 | BH34: 0.057995263 | BI34: 0.050510999 | BJ34: 0.055717088 | BK34: 0.060985805 | BL34: 0.066549794 | BN34: Safety and Compliance Monitoring | BO34: CMI_Trend_38 | BP34: CMI_Trend_60 | BQ34: CMI_Trend_20 | BR34: CMI_Trend_25 | BS34: CMI_Trend_46 | BT34: CMI_Trend_56 | BU34: CMI_Trend_25 | BV34: CMI_Trend_25 | BW34: CMI_Trend_46 | BX34: CMI_Trend_60 | BY34: CMI_Trend_25 | BZ34: CMI_Trend_52 | CA34: CMI_Trend_56 | CB34: CMI_Trend_38 | CC34: CMI_Trend_60 | CD34: CMI_Trend_38 | CE34: CMI_Trend_60 | CF34: CMI_Trend_56 | CG34: CMI_Trend_56 | CH34: CMI_Trend_20 | CI34: CMI_Trend_20 | CJ34: CMI_Trend_46 | CK34: CMI_Trend_46 | CL34: CMI_Trend_46 | CM34: CMI_Trend_52 | CN34: CMI_Trend_38 | CO34: CMI_Trend_60 | CP34: CMI_Trend_38 | CQ34: CMI_Trend_38 | CR34: CMI_Trend_52
B35: Others (Emission Monitoring, Leak Detection) | C35: =1-SUM(C31:C34) -> 0.0994 | D35: =1-SUM(D31:D34) -> 0.1082 | E35: =1-SUM(E31:E34) -> 0.114 | F35: =1-SUM(F31:F34) -> 0.0938 | G35: =1-SUM(G31:G34) -> 0.1056 | H35: =1-SUM(H31:H34) -> 0.0924 | I35: =1-SUM(I31:I34) -> 0.1127 | J35: =1-SUM(J31:J34) -> 0.0913 | ... AF35: =1-SUM(AF31:AF34) -> 0.0935 | AH35: Others (Emission Monitoring, Leak Detection) | AI35: 0.06173961 | AJ35: 0.066619149 | AK35: 0.047762011 | AL35: 0.044067309 | AM35: 0.056225474 | AN35: 0.060025251 | AO35: 0.03922344 | AP35: 0.064356953 | AQ35: 0.0879727 | AR35: 0.092701886 | AS35: 0.083869737 | AT35: 0.072322893 | AU35: 0.079894836 | AV35: 0.06787282 | AW35: 0.075597805 | AX35: 0.052224972 | AY35: 0.080340886 | AZ35: 0.09514218 | BA35: 0.059691216 | BB35: 0.068325716 | BC35: 0.064256406 | BD35: 0.088247403 | BE35: 0.073613929 | BF35: 0.071723511 | BG35: 0.057612353 | BH35: 0.064301763 | BI35: 0.056817499 | BJ35: 0.062023588 | BK35: 0.067292305 | BL35: 0.072856294 | BN35: Others (Emission Monitoring, Leak Detection) | BO35: CMI_Trend_20 | BP35: CMI_Trend_20 | BQ35: CMI_Trend_60 | BR35: CMI_Trend_46 | BS35: CMI_Trend_56 | BT35: CMI_Trend_46 | BU35: CMI_Trend_38 | BV35: CMI_Trend_56 | BW35: CMI_Trend_25 | BX35: CMI_Trend_38 | BY35: CMI_Trend_38 | BZ35: CMI_Trend_46 | CA35: CMI_Trend_60 | CB35: CMI_Trend_46 | CC35: CMI_Trend_46 | CD35: CMI_Trend_60 | CE35: CMI_Trend_46 | CF35: CMI_Trend_38 | CG35: CMI_Trend_52 | CH35: CMI_Trend_52 | CI35: CMI_Trend_38 | CJ35: CMI_Trend_20 | CK35: CMI_Trend_25 | CL35: CMI_Trend_25 | CM35: CMI_Trend_38 | CN35: CMI_Trend_20 | CO35: CMI_Trend_56 | CP35: CMI_Trend_38 | CQ35: CMI_Trend_52 | CR35: CMI_Trend_20
B37: By End-use Industry | AH37: By End-use Industry | BN37: By End-use Industry
B38: Oil and Gas | C38: =1-SUM(C42:C48) -> 0.2771 | D38: =1-SUM(D42:D48) -> 0.2986 | E38: =1-SUM(E42:E48) -> 0.3141 | F38: =1-SUM(F42:F48) -> 0.3023 | G38: =1-SUM(G42:G48) -> 0.2939 | H38: =1-SUM(H42:H48) -> 0.3088 | I38: =1-SUM(I42:I48) -> 0.2464 | J38: =1-SUM(J42:J48) -> 0.3215 | ... AF38: =1-SUM(AF42:AF48) -> 0.2871 | AH38: Oil and Gas | AI38: =SUMPRODUCT(AI39:AI41,C39:C41) -> 0.043827607 | AJ38: =SUMPRODUCT(AJ39:AJ41,D39:D41) -> 0.049149126 | AK38: =SUMPRODUCT(AK39:AK41,E39:E41) -> 0.031154155 | AL38: =SUMPRODUCT(AL39:AL41,F39:F41) -> 0.027704659 | AM38: =SUMPRODUCT(AM39:AM41,G39:G41) -> 0.039427744 | AN38: =SUMPRODUCT(AN39:AN41,H39:H41) -> 0.04312971 | AO38: =SUMPRODUCT(AO39:AO41,I39:I41) -> 0.024538002 | AP38: =SUMPRODUCT(AP39:AP41,J39:J41) -> 0.047668688 | ... BL38: =SUMPRODUCT(BL39:BL41,AF39:AF41) -> 0.055105246 | BN38: Oil and Gas | BO38: CMI_Trend_60 | BP38: CMI_Trend_38 | BQ38: CMI_Trend_60 | BR38: CMI_Trend_38 | BS38: CMI_Trend_56 | BT38: CMI_Trend_20 | BU38: CMI_Trend_52 | BV38: CMI_Trend_46 | BW38: CMI_Trend_25 | BX38: CMI_Trend_60 | BY38: CMI_Trend_46 | BZ38: CMI_Trend_60 | CA38: CMI_Trend_56 | CB38: CMI_Trend_46 | CC38: CMI_Trend_46 | CD38: CMI_Trend_25 | CE38: CMI_Trend_56 | CF38: CMI_Trend_38 | CG38: CMI_Trend_46 | CH38: CMI_Trend_60 | CI38: CMI_Trend_38 | CJ38: CMI_Trend_52 | CK38: CMI_Trend_25 | CL38: CMI_Trend_20 | CM38: CMI_Trend_60 | CN38: CMI_Trend_56 | CO38: CMI_Trend_20 | CP38: CMI_Trend_20 | CQ38: CMI_Trend_25 | CR38: CMI_Trend_60
B39: Upstream | C39: 0.2419 | D39: 0.2336 | E39: 0.2332 | F39: 0.2454 | G39: 0.252 | H39: 0.256 | I39: 0.2382 | J39: 0.2352 | K39: 0.2627 | L39: 0.248 | M39: 0.2601 | N39: 0.2588 | O39: 0.2637 | P39: 0.2338 | Q39: 0.2609 | R39: 0.2379 | S39: 0.2403 | T39: 0.2335 | U39: 0.2585 | V39: 0.233 | W39: 0.2561 | X39: 0.2375 | Y39: 0.2483 | Z39: 0.2499 | AA39: 0.2634 | AB39: 0.2504 | AC39: 0.2343 | AD39: 0.2341 | AE39: 0.2363 | AF39: 0.2371 | AH39: Upstream | AI39: 0.035935484 | AJ39: 0.041270047 | AK39: 0.02320828 | AL39: 0.022988243 | AM39: 0.031675156 | AN39: 0.035439905 | AO39: 0.025953635 | AP39: 0.039701579 | AQ39: 0.063606838 | AR39: 0.068233732 | AS39: 0.058966729 | AT39: 0.046995034 | AU39: 0.05472527 | AV39: 0.042297614 | AW39: 0.050485721 | AX39: 0.027104907 | AY39: 0.055275187 | AZ39: 0.070347705 | BA39: 0.034098332 | BB39: 0.043663424 | BC39: 0.039758741 | BD39: 0.063362113 | BE39: 0.04769191 | BF39: 0.046282516 | BG39: 0.033053113 | BH39: 0.038470535 | BI39: 0.032553088 | BJ39: 0.036760873 | BK39: 0.042745859 | BL39: 0.047238756 | BN39: Upstream | BO39: CMI_Trend_25 | BP39: CMI_Trend_38 | BQ39: CMI_Trend_60 | BR39: CMI_Trend_46 | BS39: CMI_Trend_46 | BT39: CMI_Trend_38 | BU39: CMI_Trend_25 | BV39: CMI_Trend_56 | BW39: CMI_Trend_20 | BX39: CMI_Trend_46 | BY39: CMI_Trend_60 | BZ39: CMI_Trend_25 | CA39: CMI_Trend_25 | CB39: CMI_Trend_20 | CC39: CMI_Trend_38 | CD39: CMI_Trend_25 | CE39: CMI_Trend_56 | CF39: CMI_Trend_20 | CG39: CMI_Trend_20 | CH39: CMI_Trend_20 | CI39: CMI_Trend_60 | CJ39: CMI_Trend_60 | CK39: CMI_Trend_38 | CL39: CMI_Trend_25 | CM39: CMI_Trend_52 | CN39: CMI_Trend_46 | CO39: CMI_Trend_25 | CP39: CMI_Trend_52 | CQ39: CMI_Trend_52 | CR39: CMI_Trend_38
B40: Midstream | C40: 0.3466 | D40: 0.3383 | E40: 0.3461 | F40: 0.3303 | G40: 0.3378 | H40: 0.3334 | I40: 0.3234 | J40: 0.3503 | K40: 0.3368 | L40: 0.3474 | M40: 0.3267 | N40: 0.3434 | O40: 0.3476 | P40: 0.3289 | Q40: 0.3446 | R40: 0.3221 | S40: 0.3379 | T40: 0.3328 | U40: 0.3505 | V40: 0.3403 | W40: 0.3404 | X40: 0.3412 | Y40: 0.3503 | Z40: 0.3336 | AA40: 0.328 | AB40: 0.3469 | AC40: 0.3516 | AD40: 0.353 | AE40: 0.3475 | AF40: 0.3396 | AH40: Midstream | AI40: 0.050809157 | AJ40: 0.05614372 | AK40: 0.038081953 | AL40: 0.033861916 | AM40: 0.046548829 | AN40: 0.050313579 | AO40: 0.028827308 | AP40: 0.054575252 | AQ40: 0.078480511 | AR40: 0.083107405 | AS40: 0.073840402 | AT40: 0.061868707 | AU40: 0.069598943 | AV40: 0.057171287 | AW40: 0.065359394 | AX40: 0.04197858 | AY40: 0.07014886 | AZ40: 0.085221378 | BA40: 0.048972005 | BB40: 0.058537097 | BC40: 0.054632414 | BD40: 0.078235786 | BE40: 0.062565583 | BF40: 0.061156189 | BG40: 0.047926786 | BH40: 0.053344208 | BI40: 0.047426761 | BJ40: 0.051634546 | BK40: 0.057619532 | BL40: 0.062112429 | BN40: Midstream | BO40: CMI_Trend_52 | BP40: CMI_Trend_38 | BQ40: CMI_Trend_56 | BR40: CMI_Trend_46 | BS40: CMI_Trend_56 | BT40: CMI_Trend_25 | BU40: CMI_Trend_25 | BV40: CMI_Trend_25 | BW40: CMI_Trend_52 | BX40: CMI_Trend_20 | BY40: CMI_Trend_52 | BZ40: CMI_Trend_25 | CA40: CMI_Trend_52 | CB40: CMI_Trend_20 | CC40: CMI_Trend_20 | CD40: CMI_Trend_20 | CE40: CMI_Trend_60 | CF40: CMI_Trend_46 | CG40: CMI_Trend_20 | CH40: CMI_Trend_52 | CI40: CMI_Trend_56 | CJ40: CMI_Trend_20 | CK40: CMI_Trend_38 | CL40: CMI_Trend_60 | CM40: CMI_Trend_52 | CN40: CMI_Trend_46 | CO40: CMI_Trend_56 | CP40: CMI_Trend_46 | CQ40: CMI_Trend_56 | CR40: CMI_Trend_25
B41: Downstream | C41: =1-SUM(C39:C40) -> 0.4115 | D41: =1-SUM(D39:D40) -> 0.4281 | E41: =1-SUM(E39:E40) -> 0.4207 | F41: =1-SUM(F39:F40) -> 0.4243 | G41: =1-SUM(G39:G40) -> 0.4102 | H41: =1-SUM(H39:H40) -> 0.4106 | I41: =1-SUM(I39:I40) -> 0.4384 | J41: =1-SUM(J39:J40) -> 0.4145 | ... AF41: =1-SUM(AF39:AF40) -> 0.4233 | AH41: Downstream | AI41: 0.042586536 | AJ41: 0.047921099 | AK41: 0.029859332 | AL41: 0.025639295 | AM41: 0.038326208 | AN41: 0.042090957 | AO41: 0.020604687 | AP41: 0.046352631 | AQ41: 0.07025789 | AR41: 0.074884784 | AS41: 0.065617781 | AT41: 0.053646086 | AU41: 0.061376322 | AV41: 0.048948666 | AW41: 0.057136773 | AX41: 0.033755959 | AY41: 0.061926239 | AZ41: 0.076998757 | BA41: 0.040749384 | BB41: 0.050314476 | BC41: 0.046409793 | BD41: 0.070013165 | BE41: 0.054342962 | BF41: 0.052933568 | BG41: 0.039704165 | BH41: 0.045121587 | BI41: 0.03920414 | BJ41: 0.043411925 | BK41: 0.049396911 | BL41: 0.053889808 | BN41: Downstream | BO41: CMI_Trend_25 | BP41: CMI_Trend_20 | BQ41: CMI_Trend_52 | BR41: CMI_Trend_38 | BS41: CMI_Trend_38 | BT41: CMI_Trend_38 | BU41: CMI_Trend_38 | BV41: CMI_Trend_38 | BW41: CMI_Trend_60 | BX41: CMI_Trend_38 | BY41: CMI_Trend_20 | BZ41: CMI_Trend_46 | CA41: CMI_Trend_20 | CB41: CMI_Trend_52 | CC41: CMI_Trend_46 | CD41: CMI_Trend_56 | CE41: CMI_Trend_38 | CF41: CMI_Trend_25 | CG41: CMI_Trend_25 | CH41: CMI_Trend_60 | CI41: CMI_Trend_46 | CJ41: CMI_Trend_60 | CK41: CMI_Trend_25 | CL41: CMI_Trend_25 | CM41: CMI_Trend_25 | CN41: CMI_Trend_20 | CO41: CMI_Trend_56 | CP41: CMI_Trend_20 | CQ41: CMI_Trend_56 | CR41: CMI_Trend_25
B42: Chemical and Petrochemical | C42: 0.23 | D42: 0.2287 | E42: 0.2096 | F42: 0.2097 | G42: 0.232 | H42: 0.213 | I42: 0.2122 | J42: 0.2147 | K42: 0.2153 | L42: 0.2193 | M42: 0.2201 | N42: 0.2346 | O42: 0.2236 | P42: 0.2191 | Q42: 0.2288 | R42: 0.2226 | S42: 0.2086 | T42: 0.2242 | U42: 0.2247 | V42: 0.2179 | W42: 0.2295 | X42: 0.2124 | Y42: 0.2252 | Z42: 0.2133 | AA42: 0.2107 | AB42: 0.2354 | AC42: 0.219 | AD42: 0.2058 | AE42: 0.2147 | AF42: 0.2317 | AH42: Chemical and Petrochemical | AI42: 0.055481036 | AJ42: 0.060815599 | AK42: 0.042753832 | AL42: 0.038533795 | AM42: 0.051220708 | AN42: 0.054985457 | AO42: 0.033499187 | AP42: 0.059247131 | AQ42: 0.08315239 | AR42: 0.087779284 | AS42: 0.078512281 | AT42: 0.066540586 | AU42: 0.074270822 | AV42: 0.061843166 | AW42: 0.070031273 | AX42: 0.046650459 | AY42: 0.074820739 | AZ42: 0.089893257 | BA42: 0.053643884 | BB42: 0.063208976 | BC42: 0.059304293 | BD42: 0.082907665 | BE42: 0.067237462 | BF42: 0.065828068 | BG42: 0.052598665 | BH42: 0.058016087 | BI42: 0.05209864 | BJ42: 0.056306425 | BK42: 0.062291411 | BL42: 0.066784308 | BN42: Chemical and Petrochemical | BO42: CMI_Trend_25 | BP42: CMI_Trend_20 | BQ42: CMI_Trend_38 | BR42: CMI_Trend_20 | BS42: CMI_Trend_60 | BT42: CMI_Trend_52 | BU42: CMI_Trend_52 | BV42: CMI_Trend_52 | BW42: CMI_Trend_25 | BX42: CMI_Trend_46 | BY42: CMI_Trend_46 | BZ42: CMI_Trend_56 | CA42: CMI_Trend_60 | CB42: CMI_Trend_38 | CC42: CMI_Trend_52 | CD42: CMI_Trend_60 | CE42: CMI_Trend_38 | CF42: CMI_Trend_20 | CG42: CMI_Trend_25 | CH42: CMI_Trend_52 | CI42: CMI_Trend_56 | CJ42: CMI_Trend_60 | CK42: CMI_Trend_38 | CL42: CMI_Trend_46 | CM42: CMI_Trend_20 | CN42: CMI_Trend_20 | CO42: CMI_Trend_60 | CP42: CMI_Trend_38 | CQ42: CMI_Trend_60 | CR42: CMI_Trend_60
B43: Pharmaceuticals and Biotechnology | C43: 0.0931 | D43: 0.105 | E43: 0.0962 | F43: 0.1122 | G43: 0.0987 | H43: 0.0946 | I43: 0.1175 | J43: 0.0943 | K43: 0.103 | L43: 0.097 | M43: 0.1089 | N43: 0.1197 | O43: 0.1086 | P43: 0.1187 | Q43: 0.1125 | R43: 0.1091 | S43: 0.1083 | T43: 0.0971 | U43: 0.1095 | V43: 0.1048 | W43: 0.0987 | X43: 0.1104 | Y43: 0.1165 | Z43: 0.1188 | AA43: 0.0984 | AB43: 0.1132 | AC43: 0.1002 | AD43: 0.1184 | AE43: 0.1141 | AF43: 0.1052 | AH43: Pharmaceuticals and Biotechnology | AI43: 0.062481036 | AJ43: 0.067815599 | AK43: 0.049753832 | AL43: 0.045533795 | AM43: 0.058220708 | AN43: 0.061985457 | AO43: 0.040499187 | AP43: 0.066247131 | AQ43: 0.09015239 | AR43: 0.094779284 | AS43: 0.085512281 | AT43: 0.073540586 | AU43: 0.081270822 | AV43: 0.068843166 | AW43: 0.077031273 | AX43: 0.053650459 | AY43: 0.081820739 | AZ43: 0.096893257 | BA43: 0.060643884 | BB43: 0.070208976 | BC43: 0.066304293 | BD43: 0.089907665 | BE43: 0.074237462 | BF43: 0.072828068 | BG43: 0.059598665 | BH43: 0.065016087 | BI43: 0.05909864 | BJ43: 0.063306425 | BK43: 0.069291411 | BL43: 0.073784308 | BN43: Pharmaceuticals and Biotechnology | BO43: CMI_Trend_60 | BP43: CMI_Trend_20 | BQ43: CMI_Trend_60 | BR43: CMI_Trend_38 | BS43: CMI_Trend_60 | BT43: CMI_Trend_38 | BU43: CMI_Trend_56 | BV43: CMI_Trend_46 | BW43: CMI_Trend_60 | BX43: CMI_Trend_46 | BY43: CMI_Trend_38 | BZ43: CMI_Trend_52 | CA43: CMI_Trend_20 | CB43: CMI_Trend_38 | CC43: CMI_Trend_56 | CD43: CMI_Trend_46 | CE43: CMI_Trend_60 | CF43: CMI_Trend_56 | CG43: CMI_Trend_46 | CH43: CMI_Trend_52 | CI43: CMI_Trend_38 | CJ43: CMI_Trend_20 | CK43: CMI_Trend_46 | CL43: CMI_Trend_25 | CM43: CMI_Trend_60 | CN43: CMI_Trend_25 | CO43: CMI_Trend_38 | CP43: CMI_Trend_60 | CQ43: CMI_Trend_20 | CR43: CMI_Trend_60
B44: Water and Wastewater Treatment | C44: 0.1485 | D44: 0.1506 | E44: 0.1406 | F44: 0.1332 | G44: 0.129 | H44: 0.1553 | I44: 0.1562 | J44: 0.1376 | K44: 0.1464 | L44: 0.1277 | M44: 0.1334 | N44: 0.1323 | O44: 0.1478 | P44: 0.1583 | Q44: 0.1315 | R44: 0.1467 | S44: 0.148 | T44: 0.1564 | U44: 0.1282 | V44: 0.1365 | W44: 0.1378 | X44: 0.1305 | Y44: 0.1459 | Z44: 0.1478 | AA44: 0.1328 | AB44: 0.1516 | AC44: 0.1416 | AD44: 0.1445 | AE44: 0.1276 | AF44: 0.1419 | AH44: Water and Wastewater Treatment | AI44: 0.068481036 | AJ44: 0.073815599 | AK44: 0.055753832 | AL44: 0.051533795 | AM44: 0.064220708 | AN44: 0.067985457 | AO44: 0.046499187 | AP44: 0.072247131 | AQ44: 0.09615239 | AR44: 0.10077928 | AS44: 0.091512281 | AT44: 0.079540586 | AU44: 0.087270822 | AV44: 0.074843166 | AW44: 0.083031273 | AX44: 0.059650459 | AY44: 0.087820739 | AZ44: 0.10289326 | BA44: 0.066643884 | BB44: 0.076208976 | BC44: 0.072304293 | BD44: 0.095907665 | BE44: 0.080237462 | BF44: 0.078828068 | BG44: 0.065598665 | BH44: 0.071016087 | BI44: 0.06509864 | BJ44: 0.069306425 | BK44: 0.075291411 | BL44: 0.079784308 | BN44: Water and Wastewater Treatment | BO44: CMI_Trend_20 | BP44: CMI_Trend_56 | BQ44: CMI_Trend_60 | BR44: CMI_Trend_46 | BS44: CMI_Trend_25 | BT44: CMI_Trend_38 | BU44: CMI_Trend_46 | BV44: CMI_Trend_46 | BW44: CMI_Trend_25 | BX44: CMI_Trend_46 | BY44: CMI_Trend_56 | BZ44: CMI_Trend_46 | CA44: CMI_Trend_25 | CB44: CMI_Trend_46 | CC44: CMI_Trend_60 | CD44: CMI_Trend_46 | CE44: CMI_Trend_56 | CF44: CMI_Trend_46 | CG44: CMI_Trend_20 | CH44: CMI_Trend_46 | CI44: CMI_Trend_46 | CJ44: CMI_Trend_52 | CK44: CMI_Trend_25 | CL44: CMI_Trend_56 | CM44: CMI_Trend_52 | CN44: CMI_Trend_38 | CO44: CMI_Trend_56 | CP44: CMI_Trend_56 | CQ44: CMI_Trend_52 | CR44: CMI_Trend_52
...

Sheet ASP
B2: =B44 -> 1077608.7 | C2: =C44 -> 326373.35 | D2: =D44 -> 42445.934 | E2: =E44 -> 51617.721 | F2: =F44 -> 27765.145 | G2: =G44 -> 22954.894 | H2: =H44 -> 29451.518 | I2: =I44 -> 23187.889 | ... AF2: =AF44 -> 11489.835
B3: Country | C3: U.S. | D3: Canada | E3: Germany | F3: France | G3: Italy | H3: UK | I3: Russia | J3: Spain | K3: Poland | L3: Romania | M3: Croatia | N3: Sweden | O3: Denmark | P3: Finland | Q3: Norway | R3: Rest of Europe | S3: China | T3: India | U3: Japan | V3: South Korea | W3: Australia | X3: ASEAN | Y3: Rest of Asia Pacific | Z3: GCC | AA3: South Africa | AB3: Rest of Middle East & Africa | AC3: Brazil | AD3: Argentina | AE3: Mexico | AF3: Rest of Latin America | AI3: U.S. | AJ3: Canada | AK3: Germany | AL3: France | AM3: Italy | AN3: UK | AO3: Russia | AP3: Spain | AQ3: Poland | AR3: Romania | AS3: Croatia | AT3: Sweden | AU3: Denmark | AV3: Finland | AW3: Norway | AX3: Rest of Europe | AY3: China | AZ3: India | BA3: Japan | BB3: South Korea | BC3: Australia | BD3: ASEAN | BE3: Rest of Asia Pacific | BF3: GCC | BG3: South Africa | BH3: Rest of Middle East & Africa | BI3: Brazil | BJ3: Argentina | BK3: Mexico | BL3: Rest of Latin America
B4: By Analyzer Type | AH4: By Analyzer Type
B5: Gas Analyzers | AH5: Gas Analyzers
B6: Natural Gas | C6: 10920 | D6: 10840 | E6: 11010 | F6: 10780 | G6: 10640 | H6: 10880 | I6: 10020 | J6: 10510 | K6: 10330 | L6: 10170 | M6: 10090 | N6: 10970 | O6: 10890 | P6: 10820 | Q6: 11030 | R6: 10460 | S6: 9830 | T6: 9660 | U6: 10950 | V6: 10720 | W6: 10860 | X6: 9740 | Y6: 9910 | Z6: 10610 | AA6: 9920 | AB6: 9810 | AC6: 10180 | AD6: 9860 | AE6: 10050 | AF6: 9940 | AH6: Natural Gas | AI6: ASP7 | AJ6: ASP4 | AK6: ASP5 | AL6: ASP8 | AM6: ASP1 | AN6: ASP4 | AO6: ASP3 | AP6: ASP1 | AQ6: ASP3 | AR6: ASP9 | AS6: ASP2 | AT6: ASP9 | AU6: ASP2 | AV6: ASP5 | AW6: ASP9 | AX6: ASP9 | AY6: ASP6 | AZ6: ASP5 | BA6: ASP3 | BB6: ASP9 | BC6: ASP5 | BD6: ASP2 | BE6: ASP1 | BF6: ASP6 | BG6: ASP6 | BH6: ASP4 | BI6: ASP8 | BJ6: ASP2 | BK6: ASP2 | BL6: ASP2
B7: Biogas | C7: 6920 | D7: 6840 | E7: 7030 | F7: 6880 | G7: 6720 | H7: 6940 | I7: 6120 | J7: 6640 | K7: 6420 | L7: 6280 | M7: 6210 | N7: 6980 | O7: 6910 | P7: 6850 | Q7: 7050 | R7: 6580 | S7: 6020 | T7: 5930 | U7: 6970 | V7: 6760 | W7: 6890 | X7: 6000 | Y7: 6110 | Z7: 6700 | AA7: 6100 | AB7: 6030 | AC7: 6290 | AD7: 6060 | AE7: 6200 | AF7: 6130 | AH7: Biogas | AI7: ASP5 | AJ7: ASP1 | AK7: ASP4 | AL7: ASP7 | AM7: ASP9 | AN7: ASP3 | AO7: ASP2 | AP7: ASP4 | AQ7: ASP6 | AR7: ASP2 | AS7: ASP4 | AT7: ASP5 | AU7: ASP9 | AV7: ASP3 | AW7: ASP2 | AX7: ASP7 | AY7: ASP1 | AZ7: ASP4 | BA7: ASP4 | BB7: ASP9 | BC7: ASP2 | BD7: ASP3 | BE7: ASP2 | BF7: ASP9 | BG7: ASP6 | BH7: ASP5 | BI7: ASP2 | BJ7: ASP8 | BK7: ASP3 | BL7: ASP6
B8: Biomethane | C8: 6310 | D8: 6220 | E8: 6420 | F8: 6290 | G8: 6130 | H8: 6350 | I8: 5710 | J8: 6060 | K8: 5890 | L8: 5760 | M8: 5680 | N8: 6380 | O8: 6320 | P8: 6250 | Q8: 6450 | R8: 6020 | S8: 5510 | T8: 5410 | U8: 6370 | V8: 6180 | W8: 6300 | X8: 5480 | Y8: 5600 | Z8: 6110 | AA8: 5610 | AB8: 5520 | AC8: 5770 | AD8: 5540 | AE8: 5690 | AF8: 5620 | AH8: Biomethane | AI8: ASP9 | AJ8: ASP4 | AK8: ASP8 | AL8: ASP3 | AM8: ASP9 | AN8: ASP4 | AO8: ASP6 | AP8: ASP4 | AQ8: ASP3 | AR8: ASP9 | AS8: ASP7 | AT8: ASP6 | AU8: ASP2 | AV8: ASP1 | AW8: ASP6 | AX8: ASP9 | AY8: ASP4 | AZ8: ASP2 | BA8: ASP1 | BB8: ASP9 | BC8: ASP4 | BD8: ASP9 | BE8: ASP4 | BF8: ASP8 | BG8: ASP3 | BH8: ASP1 | BI8: ASP3 | BJ8: ASP8 | BK8: ASP4 | BL8: ASP6
B9: Industrial Gases (O₂, N₂, CO₂) | C9: 9420 | D9: 9340 | E9: 9510 | F9: 9360 | G9: 9200 | H9: 9430 | I9: 8530 | J9: 9100 | K9: 8880 | L9: 8720 | M9: 8650 | N9: 9480 | O9: 9400 | P9: 9330 | Q9: 9520 | R9: 9040 | S9: 8420 | T9: 8260 | U9: 9470 | V9: 9260 | W9: 9380 | X9: 8330 | Y9: 8480 | Z9: 9170 | AA9: 8490 | AB9: 8390 | AC9: 8740 | AD9: 8440 | AE9: 8620 | AF9: 8500 | AH9: Industrial Gases (O₂, N₂, CO₂) | AI9: ASP4 | AJ9: ASP2 | AK9: ASP6 | AL9: ASP2 | AM9: ASP3 | AN9: ASP4 | AO9: ASP6 | AP9: ASP6 | AQ9: ASP9 | AR9: ASP8 | AS9: ASP3 | AT9: ASP3 | AU9: ASP5 | AV9: ASP3 | AW9: ASP7 | AX9: ASP7 | AY9: ASP5 | AZ9: ASP4 | BA9: ASP8 | BB9: ASP7 | BC9: ASP2 | BD9: ASP8 | BE9: ASP6 | BF9: ASP8 | BG9: ASP6 | BH9: ASP4 | BI9: ASP5 | BJ9: ASP5 | BK9: ASP2 | BL9: ASP5
B10: Hydrogen | C10: 7730 | D10: 7640 | E10: 7820 | F10: 7680 | G10: 7510 | H10: 7710 | I10: 6930 | J10: 7410 | K10: 7230 | L10: 7060 | M10: 6980 | N10: 7790 | O10: 7720 | P10: 7600 | Q10: 7830 | R10: 7360 | S10: 6810 | T10: 6690 | U10: 7780 | V10: 7550 | W10: 7700 | X10: 6770 | Y10: 6880 | Z10: 7480 | AA10: 6890 | AB10: 6800 | AC10: 7070 | AD10: 6830 | AE10: 6990 | AF10: 6910 | AH10: Hydrogen | AI10: ASP3 | AJ10: ASP8 | AK10: ASP3 | AL10: ASP3 | AM10: ASP6 | AN10: ASP2 | AO10: ASP9 | AP10: ASP5 | AQ10: ASP5 | AR10: ASP6 | AS10: ASP5 | AT10: ASP2 | AU10: ASP5 | AV10: ASP9 | AW10: ASP8 | AX10: ASP8 | AY10: ASP7 | AZ10: ASP8 | BA10: ASP2 | BB10: ASP5 | BC10: ASP6 | BD10: ASP1 | BE10: ASP9 | BF10: ASP1 | BG10: ASP1 | BH10: ASP5 | BI10: ASP6 | BJ10: ASP7 | BK10: ASP4 | BL10: ASP7
B11: Toxic & Hazardous Gases (H₂S, CO) | C11: 9210 | D11: 9130 | E11: 9320 | F11: 9180 | G11: 9020 | H11: 9240 | I11: 8240 | J11: 8910 | K11: 8620 | L11: 8450 | M11: 8370 | N11: 9290 | O11: 9220 | P11: 9140 | Q11: 9340 | R11: 8860 | S11: 8120 | T11: 8010 | U11: 9280 | V11: 9070 | W11: 9200 | X11: 8090 | Y11: 8200 | Z11: 8980 | AA11: 8210 | AB11: 8100 | AC11: 8470 | AD11: 8160 | AE11: 8360 | AF11: 8250 | AH11: Toxic & Hazardous Gases (H₂S, CO) | AI11: ASP3 | AJ11: ASP6 | AK11: ASP6 | AL11: ASP5 | AM11: ASP9 | AN11: ASP7 | AO11: ASP3 | AP11: ASP2 | AQ11: ASP2 | AR11: ASP4 | AS11: ASP9 | AT11: ASP6 | AU11: ASP4 | AV11: ASP1 | AW11: ASP4 | AX11: ASP4 | AY11: ASP8 | AZ11: ASP8 | BA11: ASP7 | BB11: ASP9 | BC11: ASP5 | BD11: ASP8 | BE11: ASP9 | BF11: ASP7 | BG11: ASP1 | BH11: ASP3 | BI11: ASP4 | BJ11: ASP1 | BK11: ASP2 | BL11: ASP4
B12: Emission Gases (NOx, SO₂) | C12: 8520 | D12: 8440 | E12: 8610 | F12: 8460 | G12: 8320 | H12: 8510 | I12: 7530 | J12: 8210 | K12: 8020 | L12: 7850 | M12: 7770 | N12: 8570 | O12: 8500 | P12: 8430 | Q12: 8620 | R12: 8170 | S12: 7480 | T12: 7360 | U12: 8560 | V12: 8360 | W12: 8480 | X12: 7440 | Y12: 7560 | Z12: 8290 | AA12: 7570 | AB12: 7470 | AC12: 7860 | AD12: 7510 | AE12: 7720 | AF12: 7600 | AH12: Emission Gases (NOx, SO₂) | AI12: ASP9 | AJ12: ASP6 | AK12: ASP1 | AL12: ASP7 | AM12: ASP4 | AN12: ASP7 | AO12: ASP1 | AP12: ASP5 | AQ12: ASP4 | AR12: ASP2 | AS12: ASP5 | AT12: ASP1 | AU12: ASP9 | AV12: ASP1 | AW12: ASP3 | AX12: ASP9 | AY12: ASP7 | AZ12: ASP8 | BA12: ASP7 | BB12: ASP8 | BC12: ASP2 | BD12: ASP1 | BE12: ASP7 | BF12: ASP8 | BG12: ASP2 | BH12: ASP7 | BI12: ASP7 | BJ12: ASP9 | BK12: ASP9 | BL12: ASP7
B13: Liquid Analyzers | C13: 9040 | D13: 8950 | E13: 9120 | F13: 8990 | G13: 8830 | H13: 9020 | I13: 8020 | J13: 8730 | K13: 8480 | L13: 8310 | M13: 8230 | N13: 9090 | O13: 9010 | P13: 8940 | Q13: 9140 | R13: 8670 | S13: 7900 | T13: 7790 | U13: 9080 | V13: 8870 | W13: 9000 | X13: 7890 | Y13: 8010 | Z13: 8790 | AA13: 8000 | AB13: 7920 | AC13: 8320 | AD13: 7960 | AE13: 8200 | AF13: 8050 | AH13: Liquid Analyzers | AI13: ASP2 | AJ13: ASP2 | AK13: ASP4 | AL13: ASP6 | AM13: ASP7 | AN13: ASP7 | AO13: ASP9 | AP13: ASP6 | AQ13: ASP7 | AR13: ASP2 | AS13: ASP5 | AT13: ASP3 | AU13: ASP3 | AV13: ASP4 | AW13: ASP7 | AX13: ASP5 | AY13: ASP3 | AZ13: ASP2 | BA13: ASP7 | BB13: ASP5 | BC13: ASP4 | BD13: ASP7 | BE13: ASP5 | BF13: ASP1 | BG13: ASP4 | BH13: ASP4 | BI13: ASP2 | BJ13: ASP6 | BK13: ASP1 | BL13: ASP5
